
# Created by Ruins mod version 14.7 Ingame Parser
# authoring Player: Barlock_James

weight=1
embed_into_distance=1
acceptable_target_blocks=
unacceptable_target_blocks=flowing_water,water,flowing_lava,lava
dimensions=10,15,18
allowable_overhang=0
max_leveling=2
leveling_buffer=0
preserve_water=0
preserve_lava=0

rule1=0,100,Railcraft:tile.railcraft.brick.sandy-5
rule2=0,100,minecraft:grass-0
rule3=0,100,ExtraUtilities:color_hellsand-1
rule4=0,100,minecraft:sand-1
rule5=0,100,minecraft:dirt-0
rule6=0,100,minecraft:sand-0
rule7=0,100,minecraft:red_flower-5
rule8=0,100,minecraft:tallgrass-1
rule9=0,100,minecraft:leaves2-4
rule10=0,100,minecraft:red_flower-0
rule11=0,100,minecraft:yellow_flower-0
rule12=0,100,minecraft:red_flower-3
rule13=0,100,chisel:acacia_planks-3
rule14=0,100,chisel:acacia_planks-5
rule15=0,100,ExtraUtilities:color_redstoneLight-1
rule16=0,100,minecraft:log2-0
rule17=0,100,chisel:acacia_planks-9
rule18=0,100,minecraft:red_flower-6
rule19=0,100,minecraft:red_flower-8
rule20=0,100,minecraft:acacia_stairs-1
rule21=0,100,minecraft:leaves2-12
rule22=0,100,ChestGenHook:dungeonChest:5-5
rule23=0,100,minecraft:crafting_table-0
rule24=0,100,minecraft:cauldron-3
rule25=0,100,minecraft:fence-0
rule26=0,100,minecraft:bed-3
rule27=0,100,minecraft:bed-11
rule28=0,100,Natura:door.redwood-2
rule29=0,100,IInventory;GardenContainers:wood_window_box;minecraft:red_flower#1#5#1-4
rule30=0,100,IInventory;GardenContainers:wood_window_box;minecraft:red_flower#1#5#1+minecraft:red_flower#1#5#3-4
rule31=0,100,minecraft:acacia_stairs-2
rule32=0,100,minecraft:acacia_stairs-7
rule33=0,100,minecraft:acacia_stairs-6
rule34=0,100,minecraft:acacia_stairs-3
rule35=0,100,chisel:acacia_planks-7
rule36=0,100,minecraft:planks-4
rule37=0,100,Natura:pressureplate.redwood-0
rule38=0,100,minecraft:furnace-5
rule39=0,100,minecraft:lever-9
rule40=0,100,minecraft:leaves2-0
rule41=0,100,Natura:door.redwood-8
rule42=0,100,GardenCore:garden_proxy-0
rule43=0,100,BiblioCraft:BiblioShelf-0
rule44=0,100,minecraft:wooden_slab-4
rule45=0,100,BiblioCraft:BiblioIronLantern-0

layer
2,2,2,2,2,4,2,1,2,2,2,2,2,2,2,3,2,1
2,2,2,2,2,4,2,1,5,6,5,5,5,2,2,3,2,1
2,2,3,3,2,2,2,5,3,5,1,5,6,1,4,2,6,2
2,2,2,2,2,6,5,4,5,5,5,5,3,5,5,2,2,2
2,2,2,2,2,5,3,5,5,4,4,5,5,5,4,5,2,2
2,2,1,1,2,3,5,5,5,6,5,3,1,5,6,4,3,2
2,2,2,2,5,1,5,4,5,3,5,5,5,5,5,5,2,1
2,2,6,6,2,5,6,5,4,5,5,5,4,5,5,5,2,2
2,2,2,2,2,5,5,5,5,5,1,4,6,5,1,5,4,2
2,2,2,2,4,2,5,5,4,5,5,3,5,5,3,6,2,4
2,2,3,3,2,2,1,4,6,5,5,4,5,5,4,2,2,2
2,2,2,2,6,2,2,2,5,5,2,5,1,2,6,2,3,2
2,2,2,2,2,2,6,1,4,3,2,2,4,5,4,1,6,2
2,2,2,2,4,2,2,2,2,2,2,2,2,2,2,2,2,2
2,2,2,2,2,2,2,2,2,2,2,2,2,2,2,2,2,2
endlayer

layer
0,8,8,7,8,0,8,0,0,8,8,8,8,8,0,0,7,0
8,10,8,8,8,0,8,9,2,2,2,2,2,9,8,0,0,0
0,8,0,0,8,8,9,2,2,2,2,1,2,2,9,11,0,8
8,12,8,8,8,9,2,5,5,5,5,5,5,5,2,9,8,0
8,8,8,0,9,2,1,5,13,13,13,13,13,5,3,2,9,0
8,8,0,0,9,2,2,5,13,14,14,14,13,5,2,2,9,11
8,8,8,0,16,2,2,5,13,14,15,14,13,5,2,2,9,0
12,8,0,0,9,2,6,5,13,14,14,14,13,5,2,2,9,8
8,8,8,0,9,2,2,4,13,13,13,13,13,5,1,2,9,8
0,8,19,18,0,9,2,5,5,5,17,3,5,5,2,9,8,0
8,8,0,0,8,11,9,2,2,6,17,3,2,2,9,8,8,8
8,8,11,0,0,8,19,9,2,2,20,2,2,9,0,8,0,8
0,0,8,8,8,8,0,0,9,9,0,21,21,16,0,0,0,8
0,8,8,8,0,8,8,10,8,9,0,9,8,8,8,8,8,8
0,0,8,8,8,8,8,8,8,9,0,9,19,8,8,8,8,8
endlayer

layer
0,0,0,0,0,0,0,0,0,0,0,0,0,0,0,0,0,0
0,0,0,0,0,0,0,0,8,12,12,8,8,0,0,0,0,0
0,0,0,0,0,0,0,8,8,8,8,0,8,0,0,0,0,0
0,0,0,0,0,0,8,16,16,16,16,16,16,16,0,0,0,0
0,0,0,0,0,8,0,16,25,24,23,22,17,16,0,8,0,0
0,0,0,0,0,8,0,16,0,0,0,0,0,16,8,19,0,0
0,0,0,0,16,0,8,16,0,0,0,0,0,16,0,8,0,0
0,0,0,0,0,8,0,16,26,0,0,0,0,16,8,8,0,0
0,0,0,0,0,0,0,16,27,0,0,0,0,16,0,8,0,0
0,0,0,0,0,0,8,16,16,16,28,16,16,16,8,0,0,0
0,0,0,0,0,0,0,0,30,0,0,0,29,0,0,0,0,0
0,0,0,0,0,0,0,0,0,0,0,0,0,0,0,0,0,0
0,0,0,0,0,0,0,0,0,0,0,0,0,16,0,0,0,0
0,0,0,0,0,0,0,0,0,0,0,0,0,0,0,0,0,0
0,0,0,0,0,0,0,0,0,0,0,0,0,0,0,0,0,0
endlayer

layer
0,0,0,0,0,0,0,0,0,0,0,0,0,0,0,0,0,0
0,0,0,0,0,0,0,0,0,0,0,0,0,0,0,0,0,0
0,0,0,0,0,0,34,33,0,0,0,0,0,32,31,0,0,0
0,0,0,0,0,0,34,16,16,35,16,35,16,16,31,0,0,0
0,0,40,40,40,0,34,36,37,39,38,0,37,36,31,0,0,0
0,40,40,40,40,40,34,36,0,0,0,0,0,36,31,0,0,0
0,40,40,16,16,40,34,36,0,0,0,0,0,36,31,0,0,0
0,40,40,40,40,40,34,36,0,0,0,0,0,36,31,0,0,0
0,0,40,40,40,0,34,36,0,0,0,0,0,36,31,0,0,0
0,0,0,0,0,0,34,16,35,16,41,16,35,16,31,0,0,0
0,0,0,0,0,0,34,33,42,0,0,0,42,32,31,0,0,0
0,0,0,0,0,0,0,0,0,0,0,0,0,0,0,0,0,0
0,0,0,0,0,0,0,0,0,0,0,0,0,16,0,0,0,0
0,0,0,0,0,0,0,0,0,0,0,0,0,0,0,0,0,0
0,0,0,0,0,0,0,0,0,0,0,0,0,0,0,0,0,0
endlayer

layer
0,0,0,0,0,0,0,0,0,0,0,0,0,0,0,0,0,0
0,0,0,0,0,0,0,0,0,0,0,0,0,0,0,0,0,0
0,0,0,0,0,0,0,34,33,0,0,0,32,31,0,0,0,0
0,0,0,0,0,0,0,34,16,16,35,16,16,31,0,0,0,0
0,0,0,0,0,0,0,34,43,43,0,43,43,31,0,0,0,0
0,0,40,40,40,0,0,34,0,0,0,0,0,31,0,0,0,0
0,0,40,40,16,0,0,34,0,0,0,0,0,31,0,0,0,0
0,0,40,40,40,0,0,34,0,0,0,0,0,31,0,0,0,0
0,0,0,0,0,0,0,34,0,0,0,0,0,31,0,0,0,0
0,0,0,0,0,0,0,34,16,16,16,16,16,31,0,0,0,0
0,0,0,0,0,0,0,34,33,44,44,44,32,31,0,0,0,0
0,0,0,0,0,0,0,0,0,0,0,0,0,0,0,0,0,0
0,0,0,0,0,0,0,0,0,0,0,0,0,16,0,0,0,0
0,0,0,0,0,0,0,0,0,0,0,0,0,0,0,0,0,0
0,0,0,0,0,0,0,0,0,0,0,0,0,0,0,0,0,0
endlayer

layer
0,0,0,0,0,0,0,0,0,0,0,0,0,0,0,0,0,0
0,0,0,0,0,0,0,0,0,0,0,0,0,0,0,0,0,0
0,0,0,0,0,0,0,0,34,33,0,32,31,0,0,0,0,0
0,0,0,0,0,0,0,0,34,16,16,16,31,0,0,0,0,0
0,0,0,0,0,0,0,0,34,0,45,0,31,0,0,0,0,0
0,0,0,0,16,0,0,0,34,0,0,0,31,0,0,0,0,0
0,0,0,0,0,0,0,0,34,0,0,0,31,0,0,0,0,0
0,0,0,0,0,0,0,0,34,0,0,0,31,0,0,0,0,0
0,0,0,0,0,0,0,0,34,0,45,0,31,0,0,0,0,0
0,0,0,0,0,0,0,0,34,16,16,16,31,0,0,0,0,0
0,0,0,0,0,0,0,0,34,33,45,32,31,0,0,0,0,0
0,0,0,0,0,0,0,0,0,0,0,0,0,0,0,0,0,0
0,0,0,0,0,0,0,0,0,0,0,0,0,16,0,0,0,0
0,0,0,0,0,0,0,0,0,0,0,0,0,0,0,0,0,0
0,0,0,0,0,0,0,0,0,0,0,0,0,0,0,0,0,0
endlayer

layer
0,0,0,0,0,0,0,0,0,0,0,0,0,0,0,0,0,0
0,0,40,40,40,40,40,0,0,0,0,0,0,0,0,0,0,0
0,40,40,40,40,40,40,40,0,44,36,44,0,0,0,0,0,0
0,40,40,40,40,40,40,40,0,44,36,44,0,0,0,0,0,0
0,40,40,40,16,40,40,40,0,44,36,44,0,0,0,0,0,0
0,40,40,40,40,40,40,40,0,44,36,44,0,0,0,0,0,0
0,40,40,40,40,40,40,40,0,44,36,44,0,0,0,0,0,0
0,0,40,40,40,40,40,0,0,44,36,44,0,0,0,0,0,0
0,0,0,0,0,0,0,0,0,44,36,44,0,0,0,0,0,0
0,0,0,0,0,0,0,0,0,44,36,44,0,0,0,0,0,0
0,0,0,0,0,0,0,0,0,44,36,44,0,0,0,0,0,0
0,0,0,0,0,0,0,0,0,0,0,0,0,0,0,0,0,0
0,0,0,0,0,0,0,0,0,0,0,0,0,16,16,0,0,0
0,0,0,0,0,0,0,0,0,0,0,0,0,0,0,0,0,0
0,0,0,0,0,0,0,0,0,0,0,0,0,0,0,0,0,0
endlayer

layer
0,0,0,0,0,0,0,0,0,0,0,0,0,0,0,0,0,0
0,0,0,0,0,0,0,0,0,0,0,0,0,0,0,0,0,0
0,0,0,0,40,0,0,0,0,0,0,0,0,0,0,0,0,0
0,0,0,40,40,40,0,0,0,0,0,0,0,0,0,0,0,0
0,0,40,40,40,40,40,0,0,0,0,0,0,0,0,0,0,0
0,0,0,40,40,40,0,0,0,0,0,0,0,0,0,0,0,0
0,0,0,0,40,0,0,0,0,0,0,0,0,0,0,0,0,0
0,0,0,0,0,0,0,0,0,0,0,0,0,0,0,0,0,0
0,0,0,0,0,0,0,0,0,0,0,0,0,0,0,0,0,0
0,0,0,0,0,0,0,0,0,0,0,0,0,0,0,0,0,0
0,0,0,0,0,0,0,0,0,0,0,0,0,0,40,40,40,0
0,0,0,0,0,0,0,0,0,0,0,0,0,16,40,40,40,40
0,0,0,0,0,0,0,0,0,0,0,0,0,40,40,16,40,40
0,0,0,0,0,0,0,0,0,0,0,0,0,40,40,40,40,40
0,0,0,0,0,0,0,0,0,0,0,0,0,0,40,40,40,0
endlayer

layer
0,0,0,0,0,0,0,0,0,0,0,0,0,0,0,0,0,0
0,0,0,0,0,0,0,0,0,0,0,0,0,0,0,0,0,0
0,0,0,0,0,0,0,0,0,0,0,0,0,0,0,0,0,0
0,0,0,0,0,0,0,0,0,0,0,0,0,0,0,0,0,0
0,0,0,0,0,0,0,0,0,0,0,0,0,0,0,0,0,0
0,0,0,0,0,0,0,0,0,0,0,0,0,0,0,0,0,0
0,0,0,0,0,0,0,0,0,0,0,0,0,0,0,0,0,0
0,0,0,0,0,0,0,0,0,0,0,0,0,0,0,0,0,0
0,0,0,0,0,0,0,0,0,0,0,40,40,40,40,40,0,0
0,0,0,0,0,0,0,0,0,0,40,40,40,40,40,40,40,0
0,0,0,0,0,0,0,0,0,0,40,40,40,40,40,40,40,0
0,0,0,0,0,0,0,0,0,0,40,40,40,16,40,40,40,0
0,0,0,0,0,0,0,0,0,0,40,40,40,40,40,40,40,0
0,0,0,0,0,0,0,0,0,0,40,40,40,40,40,40,40,0
0,0,0,0,0,0,0,0,0,0,0,40,40,40,40,40,0,0
endlayer

layer
0,0,0,0,0,0,0,0,0,0,0,0,0,0,0,0,0,0
0,0,0,0,0,0,0,0,0,0,0,0,0,0,0,0,0,0
0,0,0,0,0,0,0,0,0,0,0,0,0,0,0,0,0,0
0,0,0,0,0,0,0,0,0,0,0,0,0,0,0,0,0,0
0,0,0,0,0,0,0,0,0,0,0,0,0,0,0,0,0,0
0,0,0,0,0,0,0,0,0,0,0,0,0,0,0,0,0,0
0,0,0,0,0,0,0,0,0,0,0,0,0,0,0,0,0,0
0,0,0,0,0,0,0,0,0,0,0,0,0,0,0,0,0,0
0,0,0,0,0,0,0,0,0,0,0,0,0,0,0,0,0,0
0,0,0,0,0,0,0,0,0,0,0,0,0,40,0,0,0,0
0,0,0,0,0,0,0,0,0,0,0,0,40,40,40,0,0,0
0,0,0,0,0,0,0,0,0,0,0,40,40,40,40,40,0,0
0,0,0,0,0,0,0,0,0,0,0,0,40,40,40,0,0,0
0,0,0,0,0,0,0,0,0,0,0,0,0,40,0,0,0,0
0,0,0,0,0,0,0,0,0,0,0,0,0,0,0,0,0,0
endlayer

