
# Created by Ruins mod version 14.7 Ingame Parser
# authoring Player: Barlock_James

weight=1
embed_into_distance=0
acceptable_target_blocks=
unacceptable_target_blocks=flowing_water,water,flowing_lava,lava
dimensions=15,11,10
allowable_overhang=0
max_leveling=2
leveling_buffer=0
preserve_water=0
preserve_lava=0

rule1=0,100,minecraft:stone-0
rule2=0,100,ChestGenHook:dungeonChest:5-4
rule3=0,100,minecraft:dirt-0
rule4=0,100,minecraft:diamond_ore-0
rule5=0,100,minecraft:grass-0
rule6=0,100,minecraft:water-0
rule7=0,100,ExtraUtilities:color_brick-12
rule8=0,100,ExtraUtilities:colorStoneBrick-0
rule9=0,100,ExtraUtilities:colorStoneBrick-7
rule10=0,100,ExtraUtilities:color_redstoneLight-0
rule11=0,100,minecraft:nether_brick_fence-0
rule12=0,100,Railcraft:tile.railcraft.wall.alpha-9
rule13=0,100,witchery:alderwooddoor-0
rule14=0,100,minecraft:log-1
rule15=0,100,IInventory;BiblioCraft:BiblioSwordPedestal;witchery:silversword#1#0#0-0
rule16=0,100,IInventory;BiblioCraft:Armor Stand;minecraft:chainmail_chestplate#1#0#1+minecraft:chainmail_leggings#1#0#2+minecraft:chainmail_boots#1#0#3-2
rule17=0,100,DCsAppleMilk:defeatedcrow.flowerPot-4
rule18=0,100,CarpentersBlocks:blockCarpentersBed-0
rule19=0,100,cfm:chairwood-1
rule20=0,100,DCsAppleMilk:defeatedcrow.flowerPot-6
rule21=0,100,cfm:tablewood-1
rule22=0,100,cfm:bedsidecabinet-2
rule23=0,100,cfm:chairwood-3
rule24=0,100,cfm:oven-3
rule25=0,100,cfm:countersink-3
rule26=0,100,cfm:freezer-3
rule27=0,100,DCsAppleMilk:defeatedcrow.flowerPot-5
rule28=0,100,witchery:alderwooddoor-8
rule29=0,100,BiblioCraft:Armor Stand-6
rule30=0,100,Natura:trapdoor.willow-12
rule31=0,100,Natura:trapdoor.willow-13
rule32=0,100,ExtraUtilities:decorativeBlock2-9
rule33=0,100,cfm:curtainon-2
rule34=0,100,cfm:curtainon-0
rule35=0,100,Botania:miniIsland-0
rule36=0,100,EnderIO:blockElectricLight-1
rule37=0,100,cfm:fridge-3
rule38=0,100,Natura:trapdoor.willow-15
rule39=0,100,minecraft:stone_slab-6
rule40=0,100,minecraft:stone_slab-14
rule41=0,100,minecraft:double_stone_slab-6
rule42=0,100,cfm:cabinet-3
rule43=0,100,minecraft:log-5

layer
0,0,0,0,0,0,0,0,0,0
0,0,0,0,0,0,0,0,0,0
0,0,0,0,0,0,0,0,0,0
0,0,0,0,0,0,0,0,0,0
0,0,0,0,0,0,0,0,0,0
0,0,0,0,0,0,0,0,0,0
0,0,0,0,0,0,0,0,0,0
0,0,0,0,0,0,0,0,0,0
0,0,0,0,0,0,0,0,0,0
0,0,0,0,0,0,0,0,0,0
0,0,0,0,0,0,0,0,0,0
endlayer

layer
0,0,0,0,0,0,0,0,0,0
0,0,0,0,0,0,0,0,0,0
0,0,0,0,0,0,0,0,0,0
0,0,0,0,0,0,0,0,0,0
0,0,0,0,0,0,0,0,0,0
0,0,0,0,0,0,0,0,0,0
0,0,0,0,0,0,0,0,0,0
0,0,0,0,0,0,0,0,0,0
0,0,0,0,0,0,0,0,0,0
0,0,0,0,0,0,0,0,0,0
0,0,0,0,0,0,0,0,0,0
endlayer

layer
0,0,0,0,0,0,0,0,0,0
0,0,0,0,0,0,0,0,0,0
0,0,0,0,0,0,0,0,0,0
0,0,0,0,0,0,0,0,0,0
0,0,0,0,0,0,0,0,0,0
0,0,0,0,0,1,0,0,0,0
0,0,0,0,0,0,0,0,0,0
0,0,0,0,0,0,0,0,0,0
0,0,0,0,0,0,0,0,0,0
0,0,0,0,0,0,0,0,0,0
0,0,0,0,0,0,0,0,0,0
endlayer

layer
0,0,0,0,0,0,0,0,0,0
0,0,0,0,0,0,0,0,0,0
0,0,0,0,0,0,0,0,0,0
0,0,0,0,0,0,0,0,0,0
0,0,0,0,0,0,0,0,0,0
0,0,0,0,0,1,0,0,0,0
0,0,0,0,0,0,0,0,0,0
0,0,0,0,0,0,0,0,0,0
0,0,0,0,0,0,0,0,0,0
0,0,0,0,0,0,0,0,0,0
0,0,0,0,0,0,0,0,0,0
endlayer

layer
0,0,0,0,0,0,0,0,0,0
0,0,0,0,0,0,0,0,0,0
0,0,0,0,0,0,0,0,0,0
0,0,0,0,0,0,0,0,0,0
0,0,0,0,0,0,0,0,0,0
0,0,0,0,1,1,1,0,0,0
0,0,0,0,0,0,0,0,0,0
0,0,0,0,0,0,0,0,0,0
0,0,0,0,0,0,0,0,0,0
0,0,0,0,0,0,0,0,0,0
0,0,0,0,0,0,0,0,0,0
endlayer

layer
0,0,0,0,0,0,0,0,0,0
0,0,0,0,0,0,0,0,0,0
0,0,0,0,0,0,0,0,0,0
0,0,0,0,0,0,0,0,0,0
0,0,0,0,0,1,0,0,0,0
0,0,0,0,1,2,1,0,0,0
0,0,0,0,0,1,0,0,0,0
0,0,0,0,0,0,0,0,0,0
0,0,0,0,0,0,0,0,0,0
0,0,0,0,0,0,0,0,0,0
0,0,0,0,0,0,0,0,0,0
endlayer

layer
0,0,0,0,0,0,0,0,0,0
0,0,0,0,0,0,0,0,0,0
0,0,0,0,0,0,0,0,0,0
0,0,0,0,0,3,0,0,0,0
0,0,0,0,1,1,1,0,0,0
0,0,0,3,1,1,1,3,0,0
0,0,0,0,1,1,1,0,0,0
0,0,0,0,0,3,0,0,0,0
0,0,0,0,0,0,0,0,0,0
0,0,0,0,0,0,0,0,0,0
0,0,0,0,0,0,0,0,0,0
endlayer

layer
0,0,0,0,0,0,0,0,0,0
0,0,0,0,0,0,0,0,0,0
0,0,0,0,0,3,0,0,0,0
0,0,0,0,3,1,3,0,0,0
0,0,0,3,1,1,1,3,0,0
0,0,3,1,1,4,1,1,3,0
0,0,0,3,1,1,1,3,0,0
0,0,0,0,3,1,3,0,0,0
0,0,0,0,0,3,0,0,0,0
0,0,0,0,0,0,0,0,0,0
0,0,0,0,0,0,0,0,0,0
endlayer

layer
0,0,0,0,0,0,0,0,0,0
0,0,0,0,0,3,0,0,0,0
0,0,0,0,3,3,3,0,0,0
0,0,0,3,1,1,1,3,0,0
0,0,3,1,1,1,1,1,3,0
0,3,3,1,1,1,1,1,3,3
0,0,3,1,1,1,1,1,3,0
0,0,0,3,1,1,1,3,0,0
0,0,0,0,3,3,3,0,0,0
0,0,0,0,0,3,0,0,0,0
0,0,0,0,0,0,0,0,0,0
endlayer

layer
0,0,0,0,5,5,5,0,0,0
0,0,0,5,3,1,3,5,0,0
0,0,5,3,1,1,1,3,5,0
0,5,3,1,1,1,1,1,3,5
5,3,1,1,1,1,1,1,1,3
5,1,1,1,1,1,1,1,1,1
5,3,1,1,1,1,1,1,1,3
0,5,3,1,6,6,6,1,3,5
0,0,5,3,1,1,1,3,5,0
0,0,0,5,3,1,3,5,0,0
0,0,0,0,5,5,5,0,0,0
endlayer

layer
0,0,0,0,0,0,0,0,0,0
0,0,0,0,5,5,5,0,0,0
0,0,0,5,3,7,3,5,0,0
0,0,5,3,8,8,8,3,5,0
0,5,3,8,8,9,8,8,3,5
0,5,3,8,9,10,9,8,3,5
0,5,3,8,8,9,8,8,3,5
0,0,5,3,8,8,8,3,5,0
0,0,0,5,3,3,3,5,0,0
0,0,0,0,5,5,5,0,0,0
0,0,0,0,0,0,0,0,0,0
endlayer

layer
0,0,0,0,0,0,0,0,0,0
0,0,0,0,11,0,11,0,0,0
0,0,0,12,7,13,7,12,0,0
0,0,12,14,16,0,15,14,12,0
0,20,7,19,0,0,0,18,7,17
0,20,7,21,0,0,0,18,7,17
0,20,7,23,0,0,0,22,7,17
0,0,12,14,26,25,24,14,12,0
0,0,0,12,7,7,7,12,0,0
0,0,0,0,27,27,27,0,0,0
0,0,0,0,0,0,0,0,0,0
endlayer

layer
0,0,0,0,0,0,0,0,0,0
0,0,0,0,11,0,11,0,0,0
0,0,0,12,7,28,7,12,0,0
0,0,12,14,29,0,0,14,12,0
0,31,7,0,0,0,0,0,7,30
0,0,32,34,0,0,0,33,32,0
0,31,7,0,0,0,0,35,7,30
0,0,12,14,37,36,36,14,12,0
0,0,0,12,7,32,7,12,0,0
0,0,0,0,38,0,38,0,0,0
0,0,0,0,0,0,0,0,0,0
endlayer

layer
0,0,0,0,0,0,0,0,0,0
0,0,39,40,11,11,11,40,39,0
0,0,39,41,7,7,7,41,39,0
0,0,39,41,14,36,14,41,39,0
0,0,39,40,0,36,0,40,39,0
0,0,39,40,0,36,0,40,39,0
0,0,39,40,0,36,0,40,39,0
0,0,39,41,14,42,14,41,39,0
0,0,39,41,7,7,7,41,39,0
0,0,39,40,0,0,0,40,39,0
0,0,0,0,0,0,0,0,0,0
endlayer

layer
0,0,0,0,0,0,0,0,0,0
0,0,0,0,39,41,39,0,0,0
0,0,0,0,39,43,39,0,0,0
0,0,0,0,39,43,39,0,0,0
0,0,0,0,39,43,39,0,0,0
0,0,0,0,39,43,39,0,0,0
0,0,0,0,39,43,39,0,0,0
0,0,0,0,39,43,39,0,0,0
0,0,0,0,39,43,39,0,0,0
0,0,0,0,39,41,39,0,0,0
0,0,0,0,0,0,0,0,0,0
endlayer

