
# Created by Ruins mod version 14.7 Ingame Parser
# authoring Player: Barlock_James

weight=1
embed_into_distance=0
acceptable_target_blocks=
unacceptable_target_blocks=flowing_water,water,flowing_lava,lava
dimensions=4,13,13
allowable_overhang=0
max_leveling=2
leveling_buffer=0
preserve_water=0
preserve_lava=0

rule1=0,100,erebus:wallErebus-2
rule2=0,100,chisel:mossy_cobblestone-15
rule3=0,100,chisel:mossy_cobblestone-10
rule4=0,100,chisel:mossy_cobblestone-9
rule5=0,100,minecraft:water-0
rule6=0,100,erebus:umbercobbleStairs2-0
rule7=0,100,erebus:umbercobbleStairs2-3
rule8=0,100,erebus:umbercobbleStairs2-1
rule9=0,100,chisel:mossy_cobblestone-5
rule10=0,100,minecraft:vine-1
rule11=0,100,minecraft:vine-4
rule12=0,100,minecraft:vine-2
rule13=0,100,minecraft:vine-5
rule14=0,100,minecraft:vine-8

layer
1,1,1,1,0,0,0,0,0,1,1,1,1
1,0,0,0,0,0,0,0,0,0,0,0,1
0,0,2,3,0,0,3,3,0,0,2,0,1
1,0,3,3,0,0,3,3,3,3,3,0,0
1,0,3,3,0,4,3,4,3,3,3,0,0
0,6,3,3,3,3,5,3,3,3,3,0,0
0,7,3,3,3,5,5,5,3,3,3,0,1
0,8,3,3,3,5,4,3,3,3,3,0,1
0,0,3,3,3,3,3,3,3,3,3,0,0
1,0,3,3,3,3,3,3,3,3,3,0,1
1,0,2,3,3,3,3,3,3,3,2,0,0
0,0,0,0,0,0,0,0,0,0,0,0,0
1,1,0,0,0,1,1,1,0,0,0,0,0
endlayer

layer
1,0,0,0,0,0,0,0,0,0,0,1,1
0,0,0,0,0,0,0,0,0,0,0,0,1
0,0,2,9,0,0,4,9,0,0,2,0,0
0,0,9,0,0,0,0,0,0,0,0,0,0
0,0,4,0,0,0,0,0,0,0,4,0,0
0,0,2,0,0,1,0,1,0,0,0,0,0
0,0,0,0,0,0,0,0,0,0,9,0,0
0,0,2,0,0,0,0,1,0,0,9,0,0
0,0,9,0,0,0,0,0,0,11,9,10,0
0,0,4,0,0,0,0,0,0,0,12,0,0
0,0,0,9,13,9,4,4,0,0,0,0,0
0,0,0,0,0,12,0,0,0,0,0,0,0
1,0,0,0,0,0,1,0,0,0,0,0,0
endlayer

layer
0,0,0,0,0,0,0,0,0,0,0,0,1
0,0,0,0,0,0,0,0,0,0,0,0,0
0,0,2,0,0,0,9,0,4,9,2,0,0
0,0,9,0,0,0,0,0,0,0,9,0,0
0,0,0,0,0,0,0,0,0,0,0,10,0
0,0,0,0,0,1,0,1,0,0,0,0,0
0,0,0,0,0,0,0,0,0,0,0,0,0
0,11,2,0,0,0,0,0,0,0,4,0,0
0,0,4,0,0,0,0,0,0,0,9,10,0
0,0,0,0,0,0,0,0,0,0,12,0,0
0,0,0,0,9,0,0,0,4,0,0,0,0
0,0,0,0,0,12,0,0,0,0,0,0,0
0,0,0,0,0,0,0,0,0,0,0,0,0
endlayer

layer
0,0,0,0,0,0,0,0,0,0,0,0,0
0,0,0,0,0,0,0,0,0,0,14,0,0
0,0,0,0,0,0,0,0,9,9,2,0,0
0,0,0,0,0,0,0,0,0,0,9,0,0
0,0,0,0,0,0,0,0,0,0,9,10,0
0,0,0,0,0,0,0,1,0,0,0,0,0
0,0,0,0,0,0,0,0,0,0,9,10,0
0,11,2,0,0,0,0,0,0,0,9,10,0
0,0,12,0,0,0,0,0,0,0,9,10,0
0,0,0,0,0,0,0,0,0,0,0,0,0
0,0,0,0,0,9,9,9,9,4,0,0,0
0,0,0,0,0,12,12,0,0,0,0,0,0
0,0,0,0,0,0,0,0,0,0,0,0,0
endlayer

