
# Created by Ruins mod version 14.7 Ingame Parser
# authoring Player: saphrym

weight=1
embed_into_distance=1
acceptable_target_blocks=
unacceptable_target_blocks=flowing_water,water,flowing_lava,lava
dimensions=11,6,6
allowable_overhang=0
max_leveling=2
leveling_buffer=0
preserve_water=0
preserve_lava=0

rule1=0,100,minecraft:dirt-2
rule2=0,100,MobSpawner:witchery.treefyd
rule3=0,100,minecraft:red_mushroom-0
rule4=0,100,minecraft:redstone_wire-0
rule5=0,100,minecraft:log2-1
rule6=0,100,ChestGenHook:dungeonChest:5-4
rule7=0,100,minecraft:leaves2-13
rule8=0,100,minecraft:leaves2-5

layer
1,1,1,1,1,1
1,1,1,1,1,1
1,1,1,1,1,1
1,1,1,2,1,1
1,1,1,1,1,1
1,1,1,1,1,1
endlayer

layer
4,0,0,4,3,0
0,3,5,5,4,0
0,5,0,0,5,0
0,5,0,6,5,0
3,0,5,5,4,0
0,0,0,0,0,3
endlayer

layer
0,0,0,0,0,0
0,0,5,5,0,0
0,5,0,0,5,0
0,5,0,0,5,0
0,0,5,5,0,0
0,0,0,0,0,0
endlayer

layer
0,0,0,0,0,0
0,0,5,5,0,0
0,5,0,0,5,0
0,5,0,0,5,0
0,0,5,5,0,0
0,0,0,0,0,0
endlayer

layer
0,0,0,0,0,0
0,0,5,5,0,0
0,5,0,0,5,0
0,5,0,0,5,0
0,0,5,5,0,0
0,0,0,0,0,0
endlayer

layer
0,0,0,0,0,0
0,0,0,0,0,0
0,0,5,5,0,0
0,0,5,5,0,0
0,0,0,0,0,0
0,0,0,0,0,0
endlayer

layer
0,0,0,0,0,0
0,0,0,0,0,0
0,0,5,5,0,0
0,0,5,5,0,0
0,0,0,0,0,0
0,0,0,0,0,0
endlayer

layer
0,0,0,0,0,0
0,5,0,0,0,0
0,0,5,5,0,0
0,0,5,5,0,0
0,0,0,0,5,0
0,0,0,0,0,0
endlayer

layer
0,7,8,7,7,0
7,5,7,7,5,7
8,7,5,5,7,8
7,7,5,5,7,7
7,5,7,7,5,8
0,7,8,7,8,0
endlayer

layer
0,7,7,7,7,0
7,5,7,7,5,7
7,7,7,7,8,8
7,7,7,7,7,7
7,5,7,7,5,8
0,7,8,7,8,0
endlayer

layer
0,0,0,0,0,0
0,8,8,8,8,0
0,8,8,8,8,0
0,8,8,8,8,0
0,8,8,8,8,0
0,0,0,0,0,0
endlayer

