
# Created by Ruins mod version 14.7 Ingame Parser
# authoring Player: Barlock_James

weight=1
embed_into_distance=1
acceptable_target_blocks=
unacceptable_target_blocks=flowing_water,water,flowing_lava,lava
dimensions=13,15,15
allowable_overhang=0
max_leveling=2
leveling_buffer=0
preserve_water=0
preserve_lava=0

rule1=0,100,minecraft:grass-0
rule2=0,100,minecraft:dirt-0
rule3=0,100,DCsAppleMilk:defeatedcrow.WoodBox-1
rule4=0,100,ForbiddenMagic:InkFlower-0
rule5=0,100,minecraft:leaves2-5
rule6=0,100,harvestcraft:mushroomgarden-0
rule7=0,100,minecraft:brown_mushroom-0
rule8=0,100,minecraft:log-1
rule9=0,100,Natura:door.hopseed-0
rule10=0,100,ForbiddenMagic:UmbralBush-1
rule11=0,100,harvestcraft:herbgarden-0
rule12=0,100,LLadders:tile.lladders.block.vineladder-3
rule13=0,100,Natura:BerryBush-2
rule14=0,100,harvestcraft:groundgarden-0
rule15=0,100,harvestcraft:berrygarden-0
rule16=0,100,harvestcraft:leafygarden-0
rule17=0,100,Natura:door.hopseed-8
rule18=0,100,ForbiddenMagic:UmbralBush-0
rule19=0,100,minecraft:wooden_slab-5
rule20=2,100,minecraft:torch-1
rule21=0,100,ChestGenHook:dungeonChest:5-5
rule22=0,100,minecraft:bed-9
rule23=0,100,minecraft:crafting_table-0
rule24=0,100,minecraft:bed-1
rule25=0,100,witchery:witchesovenidle-3
rule26=0,100,IInventory;BiblioCraft:BookcaseFilled;minecraft:written_book#1#0#1+minecraft:written_book#1#0#3+minecraft:written_book#1#0#4+minecraft:written_book#1#0#5+minecraft:written_book#1#0#6+minecraft:written_book#1#0#7+minecraft:written_book#1#0#8+minecraft:written_book#1#0#11+minecraft:written_book#1#0#12+minecraft:written_book#1#0#13+minecraft:written_book#1#0#14+minecraft:written_book#1#0#15-0
rule27=0,100,minecraft:nether_brick_fence-0
rule28=0,100,witchery:filteredfumefunnel-3
rule29=0,100,BiblioCraft:BiblioShelf-0
rule30=0,100,minecraft:leaves2-13

layer
1,1,1,1,1,1,1,1,1,1,1,1,1,1,1
1,1,1,1,1,1,1,1,1,1,1,1,2,1,1
1,1,1,1,1,1,1,1,1,1,1,1,2,1,1
1,1,1,1,1,1,1,1,1,1,1,1,2,1,1
1,1,1,1,1,1,2,1,2,1,1,1,2,1,1
1,1,1,1,1,2,1,1,1,2,1,1,2,1,1
1,1,1,1,2,1,1,1,1,1,2,1,1,1,1
1,1,1,1,2,1,1,1,1,1,2,1,1,1,1
1,1,1,1,2,1,1,1,1,1,2,1,1,1,1
1,1,1,1,1,2,1,1,1,2,1,1,1,1,1
1,1,1,1,1,1,2,2,2,1,1,1,1,1,1
1,1,1,1,1,1,1,1,1,1,1,1,1,1,1
1,1,1,1,1,1,1,1,1,1,1,1,1,1,1
1,1,1,1,1,1,1,1,1,1,1,1,1,1,1
1,1,1,1,1,1,1,1,1,1,1,1,1,1,1
endlayer

layer
0,0,0,0,0,0,0,0,0,0,0,0,0,0,0
0,0,0,0,0,0,0,0,0,0,0,0,3,0,0
0,4,0,0,0,4,0,0,0,0,0,0,3,0,0
0,0,0,0,0,0,0,0,0,0,0,6,3,5,0
0,0,4,0,4,10,8,9,8,7,0,5,3,0,0
0,0,0,0,10,8,0,0,0,8,7,0,3,0,0
0,0,0,0,8,0,0,0,0,0,8,0,0,0,0
0,0,0,0,8,0,0,0,0,0,8,0,0,0,0
0,0,0,0,8,0,0,0,0,0,8,0,0,0,0
0,0,0,0,13,8,0,12,0,8,11,0,0,0,0
0,0,0,0,15,13,8,8,8,14,0,0,0,0,0
0,0,0,0,0,0,0,16,0,0,0,0,0,0,0
0,0,0,0,0,0,0,0,0,0,0,0,0,0,0
0,0,0,0,0,0,0,0,0,0,0,0,0,0,0
0,0,0,0,0,0,0,0,0,0,0,0,0,0,0
endlayer

layer
0,0,0,0,0,0,0,0,0,0,0,0,0,0,0
0,0,0,0,0,0,0,0,0,0,0,0,0,0,0
0,0,0,0,0,0,0,0,0,0,0,0,0,0,0
0,0,0,0,0,0,0,0,0,0,0,0,0,0,0
0,0,0,0,0,18,8,17,8,0,0,0,5,0,0
0,0,0,0,18,8,0,0,0,8,0,0,0,0,0
0,0,0,0,8,0,0,0,0,0,8,0,0,0,0
0,0,0,0,8,0,0,0,0,0,8,0,0,0,0
0,0,0,0,8,0,0,0,0,0,8,0,0,0,0
0,0,0,0,0,8,0,12,0,8,0,0,0,0,0
0,0,0,0,0,0,8,8,8,0,0,0,0,0,0
0,0,0,0,0,0,0,0,0,0,0,0,0,0,0
0,0,0,0,0,0,0,0,0,0,0,0,0,0,0
0,0,0,0,0,0,0,0,0,0,0,0,0,0,0
0,0,0,0,0,0,0,0,0,0,0,0,0,0,0
endlayer

layer
0,0,0,0,0,0,0,0,0,0,0,0,0,0,0
0,0,0,0,0,0,0,0,0,0,0,0,0,0,0
0,0,0,0,0,0,0,0,0,0,0,0,0,0,0
0,0,0,0,0,0,0,19,0,0,0,0,0,0,0
0,0,0,0,0,0,8,8,8,0,0,0,0,0,0
0,0,0,0,0,8,0,20,0,8,0,0,0,0,0
0,0,0,0,8,0,0,0,0,0,8,0,0,0,0
0,0,0,0,8,0,0,0,0,0,8,0,0,0,0
0,0,0,0,8,0,0,0,0,0,8,0,0,0,0
0,0,0,0,0,8,0,12,0,8,0,0,0,0,0
0,0,0,0,0,0,8,8,8,0,0,0,0,0,0
0,0,0,0,0,0,0,0,0,0,0,0,0,0,0
0,0,0,0,0,0,0,0,0,0,0,0,0,0,0
0,0,0,0,0,0,0,0,0,0,0,0,0,0,0
0,0,0,0,0,0,0,0,0,0,0,0,0,0,0
endlayer

layer
0,0,0,0,0,0,0,0,0,0,0,0,0,0,0
0,0,0,0,0,0,0,0,0,0,0,0,0,0,0
0,0,0,0,0,0,0,0,0,0,0,0,0,0,0
0,0,0,0,0,0,0,0,0,0,0,0,0,0,0
0,0,0,0,0,0,8,8,8,0,0,0,0,0,0
0,0,0,0,0,8,8,8,8,8,0,0,0,0,0
0,0,0,0,8,8,8,8,8,8,8,0,0,0,0
0,0,0,0,8,8,8,8,8,8,8,0,0,0,0
0,0,0,0,8,8,8,8,8,8,8,0,0,0,0
0,0,0,0,0,8,8,12,8,8,0,0,0,0,0
0,0,0,0,0,0,8,8,8,0,0,0,0,0,0
0,0,0,0,0,0,0,0,0,0,0,0,0,0,0
0,0,0,0,0,0,0,0,0,0,0,0,0,0,0
0,0,0,0,0,0,0,0,0,0,0,0,0,0,0
0,0,0,0,0,0,0,0,0,0,0,0,0,0,0
endlayer

layer
0,0,0,0,0,0,0,0,0,0,0,0,0,0,0
0,0,0,0,0,0,0,0,0,0,0,0,0,0,0
0,0,0,0,0,0,0,0,0,0,0,0,0,0,0
0,0,0,0,0,0,0,0,0,0,0,0,0,0,0
0,0,0,0,0,0,8,8,8,0,0,0,0,0,0
0,0,0,0,0,8,23,22,21,8,0,0,0,0,0
0,0,0,0,8,0,0,24,0,0,8,0,0,0,0
0,0,0,0,8,26,0,0,0,25,8,0,0,0,0
0,0,0,0,8,0,0,0,0,0,8,0,0,0,0
0,0,0,0,0,8,0,12,0,8,0,0,0,0,0
0,0,0,0,0,0,8,8,8,0,0,0,0,0,0
0,0,0,0,0,0,0,0,0,0,0,0,0,0,0
0,0,0,0,0,0,0,0,0,0,0,0,0,0,0
0,0,0,0,0,0,0,0,0,0,0,0,0,0,0
0,0,0,0,0,0,0,0,0,0,0,0,0,0,0
endlayer

layer
0,0,0,0,0,0,0,0,0,0,0,0,0,0,0
0,0,0,0,0,0,0,0,0,0,0,0,0,0,0
0,0,0,0,0,0,0,0,0,0,0,0,0,0,0
0,0,0,0,0,0,0,0,0,0,0,0,0,0,0
0,0,0,0,0,0,8,27,8,0,0,0,0,0,0
0,0,0,0,0,8,0,0,0,8,0,0,0,0,0
0,0,0,0,8,0,0,0,0,0,8,0,0,0,0
0,0,0,0,27,0,0,0,0,28,27,0,0,0,0
0,0,0,0,8,0,0,0,0,0,8,0,0,0,0
0,0,0,0,0,8,0,12,0,8,0,0,0,0,0
0,0,0,0,0,0,8,8,8,0,0,0,0,0,0
0,0,0,0,0,0,0,0,0,0,0,0,0,0,0
0,0,0,0,0,0,0,0,0,0,0,0,0,0,0
0,0,0,0,0,0,0,0,0,0,0,0,0,0,0
0,0,0,0,0,0,0,0,0,0,0,0,0,0,0
endlayer

layer
0,0,0,0,0,0,0,0,0,0,0,0,0,0,0
0,0,0,0,0,0,0,0,0,0,0,0,0,0,0
0,0,0,0,0,0,0,0,0,0,0,0,0,0,0
0,0,0,0,0,0,5,5,5,0,0,0,0,0,0
0,0,0,0,0,5,8,8,8,5,0,0,0,0,0
0,0,0,0,5,8,29,29,29,8,5,0,0,0,0
0,0,0,5,8,0,0,0,0,0,8,5,0,0,0
0,0,0,5,8,0,0,0,0,0,8,5,0,0,0
0,0,0,5,8,0,0,0,0,0,8,5,0,0,0
0,0,0,0,5,8,0,12,0,8,5,0,0,0,0
0,0,0,0,0,5,8,8,8,5,0,0,0,0,0
0,0,0,0,0,0,5,5,5,0,0,0,0,0,0
0,0,0,0,0,0,0,0,0,0,0,0,0,0,0
0,0,0,0,0,0,0,0,0,0,0,0,0,0,0
0,0,0,0,0,0,0,0,0,0,0,0,0,0,0
endlayer

layer
0,0,0,0,0,0,0,0,0,0,0,0,0,0,0
0,0,0,0,0,0,0,0,0,0,0,0,0,0,0
0,0,0,0,0,30,30,30,30,30,0,0,0,0,0
0,0,0,0,5,30,30,30,30,30,30,0,0,0,0
0,0,0,30,30,30,8,8,8,30,30,30,0,0,0
0,0,30,30,30,8,0,20,0,8,30,30,30,0,0
0,0,30,30,8,0,0,0,0,0,8,30,30,0,0
0,0,30,30,8,0,0,0,0,0,8,30,30,0,0
0,0,30,30,8,0,0,0,0,0,8,30,30,0,0
0,0,5,30,30,8,0,12,0,8,30,30,30,0,0
0,0,0,30,30,30,8,8,8,30,30,5,0,0,0
0,0,0,0,30,30,30,30,30,30,5,0,0,0,0
0,0,0,0,0,30,30,30,30,30,0,0,0,0,0
0,0,0,0,0,0,0,0,0,0,0,0,0,0,0
0,0,0,0,0,0,0,0,0,0,0,0,0,0,0
endlayer

layer
0,0,0,0,0,0,0,0,0,0,0,0,0,0,0
0,0,0,0,0,0,0,0,0,0,0,0,0,0,0
0,0,0,0,0,0,5,5,5,0,0,0,0,0,0
0,0,0,0,0,5,30,30,30,5,0,0,0,0,0
0,0,0,0,5,30,30,30,30,30,5,0,0,0,0
0,0,0,30,30,30,8,8,8,30,30,5,0,0,0
0,0,5,30,30,8,8,8,8,8,30,30,5,0,0
0,0,5,30,30,8,8,8,8,8,30,30,5,0,0
0,0,5,30,30,8,8,8,8,8,30,30,5,0,0
0,0,0,30,30,30,8,12,8,30,30,5,0,0,0
0,0,0,0,5,30,30,8,30,30,5,0,0,0,0
0,0,0,0,0,5,30,30,30,5,0,0,0,0,0
0,0,0,0,0,0,5,5,5,0,0,0,0,0,0
0,0,0,0,0,0,0,0,0,0,0,0,0,0,0
0,0,0,0,0,0,0,0,0,0,0,0,0,0,0
endlayer

layer
0,0,0,0,0,0,0,0,0,0,0,0,0,0,0
0,0,0,0,0,0,0,0,0,0,0,0,0,0,0
0,0,0,0,0,0,0,5,0,0,0,0,0,0,0
0,0,0,0,0,0,5,5,5,0,0,0,0,0,0
0,0,0,0,0,0,5,5,5,0,0,0,0,0,0
0,0,0,0,0,5,30,30,30,0,0,0,0,0,0
0,0,0,5,30,30,8,0,8,30,5,5,0,0,0
0,0,5,5,30,30,0,0,0,30,5,5,5,0,0
0,0,0,5,30,30,8,0,8,30,5,5,0,0,0
0,0,0,0,0,5,30,0,30,5,0,0,0,0,0
0,0,0,0,0,0,5,30,5,0,0,0,0,0,0
0,0,0,0,0,0,0,5,0,0,0,0,0,0,0
0,0,0,0,0,0,0,0,0,0,0,0,0,0,0
0,0,0,0,0,0,0,0,0,0,0,0,0,0,0
0,0,0,0,0,0,0,0,0,0,0,0,0,0,0
endlayer

layer
0,0,0,0,0,0,0,0,0,0,0,0,0,0,0
0,0,0,0,0,0,0,0,0,0,0,0,0,0,0
0,0,0,0,0,0,0,0,0,0,0,0,0,0,0
0,0,0,0,0,0,0,0,0,0,0,0,0,0,0
0,0,0,0,0,0,0,0,0,0,0,0,0,0,0
0,0,0,0,0,0,5,0,5,0,0,0,0,0,0
0,0,0,0,0,5,8,0,8,5,0,0,0,0,0
0,0,0,0,0,0,0,0,0,0,0,0,0,0,0
0,0,0,0,0,5,8,0,8,5,0,0,0,0,0
0,0,0,0,0,0,5,0,5,0,0,0,0,0,0
0,0,0,0,0,0,0,5,0,0,0,0,0,0,0
0,0,0,0,0,0,0,0,0,0,0,0,0,0,0
0,0,0,0,0,0,0,0,0,0,0,0,0,0,0
0,0,0,0,0,0,0,0,0,0,0,0,0,0,0
0,0,0,0,0,0,0,0,0,0,0,0,0,0,0
endlayer

layer
0,0,0,0,0,0,0,0,0,0,0,0,0,0,0
0,0,0,0,0,0,0,0,0,0,0,0,0,0,0
0,0,0,0,0,0,0,0,0,0,0,0,0,0,0
0,0,0,0,0,0,0,0,0,0,0,0,0,0,0
0,0,0,0,0,0,0,0,0,0,0,0,0,0,0
0,0,0,0,0,0,0,5,0,0,0,0,0,0,0
0,0,0,0,0,0,5,5,5,0,0,0,0,0,0
0,0,0,0,0,5,5,5,5,5,0,0,0,0,0
0,0,0,0,0,0,5,5,5,0,0,0,0,0,0
0,0,0,0,0,0,0,5,0,0,0,0,0,0,0
0,0,0,0,0,0,0,0,0,0,0,0,0,0,0
0,0,0,0,0,0,0,0,0,0,0,0,0,0,0
0,0,0,0,0,0,0,0,0,0,0,0,0,0,0
0,0,0,0,0,0,0,0,0,0,0,0,0,0,0
0,0,0,0,0,0,0,0,0,0,0,0,0,0,0
endlayer

