
# Created by Ruins mod version 14.7 Ingame Parser
# authoring Player: Barlock_James

weight=1
embed_into_distance=0
acceptable_target_blocks=
unacceptable_target_blocks=flowing_water,water,flowing_lava,lava
dimensions=12,42,29
allowable_overhang=0
max_leveling=2
leveling_buffer=0
preserve_water=1
preserve_lava=0

rule1=0,100,Botania:prismarine2Stairs-2
rule2=0,100,Botania:prismarine2Stairs-0
rule3=0,100,Botania:prismarine2Stairs-3
rule4=0,100,Botania:prismarine1Stairs-0
rule5=0,100,Botania:prismarine-2
rule6=0,100,Botania:prismarine2Stairs-1
rule7=0,100,Botania:prismarine-1
rule8=0,100,Botania:prismarine2Slab-0
rule9=0,100,Botania:prismarine1Stairs-1
rule10=0,100,Botania:prismarine1Slab-0
rule11=0,100,minecraft:stone_slab-7
rule12=0,100,Thaumcraft:blockTable-0
rule13=0,100,Botania:seaLamp-0
rule14=0,100,Botania:prismarine1Stairs-2
rule15=0,100,Botania:prismarine1Stairs-7
rule16=0,100,Botania:prismarine2Stairs-7
rule17=0,100,Botania:prismarine2Slab-8
rule18=0,100,Botania:prismarine1Stairs-3
rule19=0,100,chisel:fantasyblock2-10
rule20=0,100,BiblioCraft:Armor Stand-2
rule21=0,100,Natura:Natura.fence-12
rule22=0,100,chisel:fantasyblock-10
rule23=0,100,Thaumcraft:blockWoodenDevice-8
rule24=0,100,chisel:stained_glass_pane_lightgray-11
rule25=0,100,chisel:gold_block-4
rule26=0,100,Thaumcraft:blockAiry-0
rule27=0,100,chisel:stained_glass_lightgray-5
rule28=0,100,chisel:glass-6
rule29=0,100,chisel:fantasyblock2-7
rule30=0,100,chisel:redstone_block-7
rule31=0,100,BiblioCraft:Armor Stand-6
rule32=0,100,Botania:prismarine1Slab-8
rule33=0,100,chisel:emerald_block-5
rule34=0,100,chisel:diamond_block-12
rule35=0,100,chisel:fantasyblock-11
rule36=0,100,chisel:lapis_block-8
rule37=0,100,Botania:prismarine2Stairs-4
rule38=0,100,magicalcrops:EssenceLamps-3
rule39=0,100,ChestGenHook:dungeonChest:5-4
rule40=0,100,chisel:fantasyblock2-4
rule41=0,100,Botania:prismarine1Stairs-5
rule42=0,100,Botania:prismarine1Stairs-4
rule43=0,100,Botania:prismarine1Stairs-6
rule44=0,100,Botania:prismarine2Stairs-6
rule45=0,100,Botania:prismarine2Stairs-5
rule46=0,100,Botania:prismarine-0
rule47=0,100,invisibleblockmod:blockInvisibleSolid-0
rule48=0,100,Railcraft:tile.railcraft.wall.alpha-4
rule49=0,100,IInventory;Thaumcraft:blockStoneDevice;Thaumcraft:blockCrystal#1#6#0-1
rule50=0,100,ChestGenHook:dungeonChest:5-2
rule51=0,100,IInventory;Thaumcraft:blockStoneDevice;RandomThings:ingredient#1#6#0-1
rule52=0,100,ExtraUtilities:decorativeBlock2-7

layer
0,2,2,2,1,0,0,0,0,4,4,4,4,0,0,0,0,3,2,2,2,1,0,0,0,0,0,0,0
0,3,5,5,5,5,5,5,5,5,5,5,5,5,5,5,5,5,5,5,5,1,0,0,0,0,0,0,0
0,6,6,5,5,5,5,5,5,5,5,5,5,5,5,5,5,5,7,7,6,1,0,0,0,0,0,0,0
0,0,8,5,5,5,5,5,5,5,5,5,5,5,5,5,5,5,7,7,0,0,0,0,0,0,0,0,0
0,0,8,5,5,5,5,5,5,7,7,7,7,5,5,5,5,5,7,7,0,0,0,0,0,0,0,0,0
8,8,5,5,5,3,6,1,5,9,9,9,9,5,3,6,1,5,5,7,0,0,0,0,0,0,0,0,0
8,7,7,6,1,10,10,10,10,10,10,10,10,10,10,10,10,8,7,7,0,0,0,0,0,0,0,0,0
8,7,7,8,10,10,11,11,11,10,5,5,10,11,11,11,10,8,7,7,0,0,0,0,0,0,0,0,0
8,7,7,8,10,10,11,11,11,10,5,5,10,11,11,11,10,8,7,7,2,1,0,0,0,0,2,2,1
8,7,7,2,2,10,11,11,11,12,6,6,12,11,11,11,10,2,7,7,5,1,8,8,8,8,3,5,1
8,8,5,5,1,10,11,11,11,10,8,8,10,11,11,11,10,3,5,5,7,7,7,7,7,7,7,6,6
0,0,8,7,6,10,11,11,11,10,10,10,10,11,11,11,10,3,6,6,1,8,8,8,8,7,7,8,0
0,0,8,7,8,10,11,11,11,11,11,11,11,11,11,11,10,10,10,10,10,10,10,10,8,7,7,2,0
0,0,8,7,8,10,11,11,11,11,11,11,11,11,11,11,11,11,11,11,11,11,11,10,8,7,7,1,0
0,0,8,7,8,10,11,11,11,11,11,11,11,11,11,11,11,11,11,11,11,11,11,10,8,7,7,6,0
0,0,8,7,8,10,11,11,11,11,11,11,11,11,11,11,11,11,11,11,11,11,11,10,8,7,7,8,0
0,0,8,7,8,10,10,11,11,10,10,10,10,10,11,11,10,10,10,10,10,10,10,10,8,7,7,2,1
0,0,8,7,2,2,10,11,11,10,3,2,1,10,11,11,10,2,2,2,2,1,10,10,10,8,3,5,1
0,0,5,5,5,1,10,11,11,10,3,5,1,10,11,11,10,3,5,5,13,1,10,10,10,10,3,6,6
0,0,8,7,6,1,10,11,11,10,6,6,1,10,11,11,10,6,6,6,15,14,10,10,10,10,10,10,10
0,0,8,7,8,10,10,11,11,10,10,10,10,10,11,11,10,10,10,10,15,14,10,10,10,10,10,10,10
0,0,8,7,8,10,11,11,11,11,11,11,11,11,11,11,11,11,11,10,16,1,8,8,8,8,8,8,8
0,0,8,7,8,10,10,11,11,10,10,10,10,10,11,11,10,10,10,10,15,14,10,10,10,10,10,10,10
0,0,8,7,2,2,10,11,11,10,3,2,2,10,11,11,10,2,2,2,15,14,10,10,10,10,10,10,10
0,0,5,5,5,1,10,11,11,10,3,5,1,10,11,11,10,3,5,5,13,1,10,10,10,10,3,2,1
0,0,8,7,6,6,10,11,11,10,3,6,1,10,11,11,10,3,6,6,6,6,10,10,10,8,3,5,1
0,0,8,7,8,10,10,11,11,10,10,10,10,10,11,11,10,10,10,10,10,10,10,10,8,7,7,6,6
0,0,8,7,8,10,11,11,11,11,11,11,11,11,11,11,11,11,11,11,11,11,11,10,8,7,7,8,0
0,0,8,7,8,10,11,11,11,11,11,11,11,11,11,11,11,11,11,11,11,11,11,10,8,7,7,2,0
0,0,8,7,8,10,11,11,11,11,11,11,11,11,11,11,11,11,11,11,11,11,11,10,8,7,7,1,0
0,0,8,7,8,10,11,11,11,10,10,10,10,10,11,11,10,10,10,10,10,10,10,10,8,7,7,6,0
0,0,8,7,2,10,11,11,11,10,3,2,1,10,11,11,10,3,2,2,1,8,8,8,8,7,7,8,0
8,8,5,5,1,10,11,11,11,10,3,5,1,10,11,11,10,3,5,5,7,7,7,7,7,7,7,2,1
8,7,7,6,6,10,11,11,11,10,6,6,1,10,11,11,10,6,7,7,5,1,8,8,8,8,3,5,1
8,7,7,8,10,10,11,11,11,10,10,10,10,10,11,11,10,8,7,7,6,6,0,0,0,0,3,6,6
8,7,7,8,10,10,11,11,11,10,10,10,10,10,11,11,10,8,7,7,8,0,0,0,0,0,0,0,0
8,7,7,2,1,10,10,10,10,10,2,2,2,10,10,10,10,8,7,7,8,0,0,0,0,0,0,0,0
8,8,5,5,1,17,8,8,8,17,3,5,1,8,8,8,8,8,7,7,8,0,0,0,0,0,0,0,0
0,0,8,5,7,7,7,7,7,7,7,5,7,7,7,7,7,7,7,7,8,0,0,0,0,0,0,0,0
0,2,2,5,7,7,7,7,7,7,7,5,7,7,7,7,7,7,7,7,2,2,0,0,0,0,0,0,0
0,3,5,5,1,8,8,8,8,8,3,5,1,8,3,6,1,8,3,5,5,1,0,0,0,0,0,0,0
0,3,6,6,6,0,0,0,0,0,3,6,6,0,0,0,0,0,3,6,6,6,0,0,0,0,0,0,0
endlayer

layer
0,0,0,0,0,0,0,0,0,0,0,0,0,0,0,0,0,0,0,0,0,0,0,0,0,0,0,0,0
0,0,5,5,2,1,8,3,2,14,10,10,18,2,2,8,2,2,5,5,5,0,0,0,0,0,0,0,0
0,0,0,3,5,1,8,3,5,14,10,10,18,5,1,8,3,5,7,7,0,0,0,0,0,0,0,0,0
0,0,0,3,5,5,5,5,5,7,7,7,7,5,5,5,5,5,7,7,0,0,0,0,0,0,0,0,0
0,0,0,3,5,1,0,3,5,9,9,9,9,5,1,0,3,5,7,19,0,0,0,0,0,0,0,0,0
0,0,21,5,20,0,0,0,20,0,0,0,0,20,0,0,0,20,5,19,0,0,0,0,0,0,0,0,0
0,7,7,0,0,0,0,0,0,0,0,0,0,0,0,0,0,0,7,19,0,0,0,0,0,0,0,0,0
0,24,21,0,0,0,0,0,0,23,5,5,23,0,0,0,0,0,22,19,0,0,0,0,0,0,0,0,0
0,24,21,0,0,0,0,0,0,12,0,0,12,0,0,0,0,0,22,7,0,0,0,0,0,0,0,0,0
0,7,7,0,0,0,0,0,0,0,0,0,0,0,0,0,0,0,7,7,21,0,0,0,0,0,0,5,0
0,0,21,5,0,0,0,0,0,0,0,0,0,0,0,0,0,0,5,5,7,7,24,24,24,7,7,0,0
0,0,0,7,0,0,0,0,0,0,0,0,0,0,0,0,0,0,0,0,0,0,0,0,0,24,9,0,0
0,0,0,7,0,0,0,0,0,0,0,0,0,0,0,0,0,0,0,0,0,0,0,0,0,24,4,0,0
0,0,0,7,0,0,0,0,0,0,0,0,0,0,0,0,0,0,0,0,0,0,0,0,0,24,5,21,0
0,0,0,25,0,0,0,0,0,0,0,0,0,0,0,0,0,0,0,0,0,0,0,0,0,24,9,0,0
0,0,0,7,0,0,0,0,0,0,0,0,0,0,0,0,0,0,0,0,0,0,0,0,0,24,4,0,0
0,0,0,7,0,0,0,0,0,0,0,0,0,0,0,0,0,0,0,0,0,0,0,0,0,7,7,0,0
0,0,0,7,0,0,0,0,0,0,0,0,0,0,0,0,0,0,0,0,0,0,0,0,0,0,0,5,0
0,0,5,5,5,0,0,0,0,0,0,5,0,0,0,0,0,0,5,5,5,0,0,0,0,0,0,0,0
0,0,0,24,0,0,0,0,0,0,0,0,0,0,0,0,0,0,0,15,14,0,0,0,0,0,0,0,0
0,0,0,24,0,0,0,0,0,0,0,0,0,0,0,0,0,0,0,15,14,0,0,0,0,0,0,0,0
0,0,0,24,0,0,0,0,0,0,0,0,0,0,0,0,0,0,0,16,1,0,0,0,0,0,0,0,0
0,0,0,24,0,0,0,0,0,0,0,0,0,0,0,0,0,0,0,15,14,0,0,0,0,0,0,0,0
0,0,0,24,0,0,0,0,0,0,0,0,0,0,0,0,0,0,0,15,14,0,0,0,0,0,0,0,0
0,0,5,5,5,0,0,0,0,0,0,5,0,0,0,0,0,0,5,5,5,0,0,0,0,0,0,0,0
0,0,0,7,0,0,0,0,0,0,0,0,0,0,0,0,0,0,0,0,0,0,0,0,0,0,0,5,0
0,0,0,7,0,0,0,0,0,0,0,0,0,0,0,0,0,0,0,0,0,0,0,0,0,7,7,0,0
0,0,0,7,0,0,0,0,0,0,0,0,0,0,0,0,0,0,0,0,0,0,0,0,0,24,9,0,0
0,0,0,25,0,0,0,0,0,0,0,0,0,0,0,0,0,0,0,0,0,0,0,0,0,24,4,0,0
0,0,0,7,0,0,0,0,0,0,0,0,0,0,0,0,0,0,0,0,0,0,0,0,0,24,5,21,0
0,0,0,7,0,0,0,0,0,0,0,0,0,0,0,0,0,0,0,0,0,0,0,0,0,24,9,0,0
0,0,0,7,0,0,0,0,0,0,0,0,0,0,0,0,0,0,0,0,0,0,0,0,0,24,4,0,0
0,0,21,5,0,0,0,0,0,0,0,5,0,0,0,0,0,0,5,5,7,7,24,24,24,7,7,0,0
0,7,7,0,0,0,0,0,0,0,0,0,0,0,0,0,0,0,7,7,21,0,0,0,0,0,0,5,0
0,7,7,0,0,0,0,0,0,0,0,0,0,0,0,0,0,0,7,22,0,0,0,0,0,0,0,0,0
0,7,7,0,0,0,0,0,0,0,0,0,0,0,0,0,0,0,7,22,0,0,0,0,0,0,0,0,0
0,7,7,0,0,0,0,0,0,0,0,0,0,0,0,0,0,0,7,22,0,0,0,0,0,0,0,0,0
0,0,21,5,0,21,0,0,0,21,0,5,0,0,26,0,0,0,7,22,0,0,0,0,0,0,0,0,0
0,0,0,5,7,5,24,24,24,5,7,5,7,24,24,24,24,24,7,22,0,0,0,0,0,0,0,0,0
0,0,0,5,7,5,1,8,3,5,7,5,7,14,18,7,14,18,7,7,0,0,0,0,0,0,0,0,0
0,0,5,5,0,0,0,0,0,0,0,5,0,0,0,21,0,0,0,5,5,0,0,0,0,0,0,0,0
0,0,0,0,0,0,0,0,0,0,0,0,0,0,0,0,0,0,0,0,0,0,0,0,0,0,0,0,0
endlayer

layer
0,0,0,0,0,0,0,0,0,0,0,0,0,0,0,0,0,0,0,0,0,0,0,0,0,0,0,0,0
0,0,5,5,0,0,0,0,0,0,0,0,0,0,0,0,0,0,5,5,5,0,0,0,0,0,0,0,0
0,0,0,15,5,27,27,27,5,28,28,28,28,5,27,27,27,5,7,7,0,0,0,0,0,0,0,0,0
0,0,0,15,5,27,27,27,5,28,28,28,28,5,27,27,27,5,7,7,0,0,0,0,0,0,26,0,0
0,0,0,15,5,0,0,0,5,0,0,0,0,5,0,0,0,5,7,29,0,0,0,0,0,0,0,0,0
0,0,21,5,31,0,0,0,31,0,0,0,0,31,0,0,0,31,5,30,0,0,0,0,0,0,0,0,0
0,7,7,0,0,0,0,0,0,0,0,0,0,0,0,0,0,0,7,30,0,0,0,0,0,0,0,0,0
0,24,21,0,0,0,0,0,0,0,3,1,0,0,0,0,0,0,29,29,0,0,0,0,0,0,0,0,0
0,24,21,0,0,0,0,0,0,0,0,0,0,0,0,0,0,0,29,7,0,0,0,0,0,0,0,0,0
0,7,7,0,0,0,0,0,0,0,0,0,0,0,0,0,0,0,7,7,21,0,0,0,0,0,0,5,0
0,0,21,5,0,0,0,0,0,0,0,0,0,0,0,0,0,0,5,5,7,7,24,24,24,7,7,0,0
0,0,0,7,0,0,0,0,0,0,0,0,0,0,0,0,0,0,0,23,0,0,0,0,0,24,32,0,0
0,0,0,7,0,0,0,0,0,0,0,0,0,0,0,0,0,0,0,0,0,0,0,0,0,24,32,0,0
0,0,0,33,0,0,0,0,0,0,0,0,0,0,0,0,0,0,0,0,0,0,0,0,0,24,5,21,0
0,0,0,34,0,0,0,0,0,0,0,0,0,0,0,0,0,0,0,0,0,0,0,0,0,24,32,0,0
0,0,0,33,0,0,0,0,0,0,0,0,0,0,0,0,0,0,0,0,0,0,0,0,0,24,32,0,0
0,0,0,7,0,0,0,0,0,0,0,0,0,0,0,0,0,0,0,0,0,0,0,0,0,7,7,0,0
0,0,0,7,0,0,0,0,0,0,0,0,0,0,0,0,0,0,0,23,0,0,0,0,0,0,0,5,0
0,0,5,5,5,0,0,0,0,0,0,5,0,0,0,0,0,0,5,5,5,0,0,0,0,0,0,0,0
0,0,0,24,0,0,0,0,0,0,0,0,0,0,0,0,0,0,15,14,0,0,0,0,0,0,0,0,0
0,0,0,24,0,0,0,0,0,0,0,0,0,0,0,0,0,0,15,14,0,0,0,0,0,0,0,0,0
0,0,0,24,0,0,0,0,0,0,0,0,0,0,0,0,0,0,16,1,0,0,0,0,0,0,0,0,0
0,0,0,24,0,0,0,0,0,0,0,0,0,0,0,0,0,0,15,14,0,0,0,0,0,0,0,0,0
0,0,0,24,0,0,0,0,0,0,0,0,0,0,0,0,0,0,15,14,0,0,0,0,0,0,0,0,0
0,0,5,5,5,0,0,0,0,0,0,5,0,0,0,0,0,0,5,5,5,0,0,0,0,0,0,0,0
0,0,0,7,0,0,0,0,0,0,0,0,0,0,0,0,0,0,0,23,0,0,0,0,0,0,0,5,0
0,0,0,7,0,0,0,0,0,0,0,0,0,0,0,0,0,0,0,0,0,0,0,0,0,7,7,0,0
0,0,0,33,0,0,0,0,0,0,0,0,0,0,0,0,0,0,0,0,0,0,0,0,0,24,32,0,0
0,0,0,34,0,0,0,0,0,0,0,0,0,0,0,0,0,0,0,0,0,0,0,0,0,24,32,0,0
0,0,0,33,0,0,0,0,0,0,0,0,0,0,0,0,0,0,0,0,0,0,0,0,0,24,5,21,0
0,0,0,7,0,0,0,0,0,0,0,0,0,0,0,0,0,0,0,0,0,0,0,0,0,24,32,0,0
0,0,0,7,0,0,0,0,0,0,0,0,0,0,0,0,0,0,0,23,0,0,0,0,0,24,32,0,0
0,0,21,5,0,0,0,0,0,0,0,5,0,0,0,0,0,0,5,5,7,7,24,24,24,7,7,0,0
0,7,7,0,0,0,0,0,0,0,0,0,0,0,0,0,0,0,7,7,21,0,0,0,0,0,0,5,0
0,24,21,0,0,0,0,0,0,0,0,0,0,0,0,0,0,0,7,35,0,0,0,0,0,0,0,0,0
0,24,21,0,0,0,0,0,0,0,0,0,0,0,0,0,0,0,7,36,0,0,0,0,0,0,0,0,0
0,7,7,0,0,0,0,0,0,0,0,0,0,0,0,0,0,0,7,36,0,0,0,0,0,0,0,0,0
0,0,21,5,0,21,37,21,37,21,0,5,0,0,0,0,0,0,7,36,0,0,0,0,0,0,0,0,0
0,0,0,5,7,5,5,5,5,5,7,5,7,24,24,24,24,24,7,35,0,0,0,0,0,0,0,0,0
0,0,0,5,7,5,38,5,13,5,7,5,7,17,17,7,17,17,7,7,0,0,0,0,0,0,0,0,0
0,0,5,5,0,0,0,0,0,0,0,5,0,0,0,21,0,0,0,5,5,0,0,0,0,0,0,0,0
0,0,0,0,0,0,0,0,0,0,0,0,0,0,0,0,0,0,0,0,0,0,0,0,0,0,0,0,0
endlayer

layer
0,0,0,0,0,0,0,0,0,0,0,0,0,0,0,0,0,0,0,0,0,0,0,0,0,0,0,0,0
0,0,5,5,0,0,0,0,0,0,0,0,0,0,0,0,0,0,5,5,5,0,0,0,0,0,0,0,0
0,0,0,18,5,27,27,27,5,28,28,28,28,5,27,27,27,5,7,7,0,0,0,0,0,0,0,0,0
0,0,0,18,5,27,27,27,5,28,28,28,28,5,27,27,27,5,7,7,0,0,0,0,0,0,0,0,0
0,0,0,18,5,0,0,0,5,0,0,0,0,5,0,0,0,5,7,29,0,0,0,0,0,0,0,0,0
0,0,21,5,0,0,0,0,23,0,0,0,0,23,0,0,0,0,13,30,0,0,0,0,0,0,0,0,0
0,7,7,0,0,0,0,0,0,0,0,0,0,0,0,0,0,0,7,30,0,0,0,0,0,0,0,0,0
0,24,21,0,0,0,0,0,0,0,0,0,0,0,0,0,0,0,29,29,0,0,0,0,0,0,0,0,0
0,24,21,0,0,0,0,0,0,0,0,0,0,0,0,0,0,0,29,7,0,0,0,0,0,0,0,0,0
0,7,7,0,0,0,0,0,0,0,0,0,0,0,0,0,0,0,7,7,21,0,0,0,0,0,0,5,0
0,0,21,5,23,0,0,0,0,0,0,0,0,0,0,0,0,23,5,5,7,7,24,24,24,7,7,0,0
0,0,0,25,0,0,0,0,0,0,0,0,0,0,0,0,0,0,0,0,0,0,0,0,0,24,10,0,0
0,0,0,34,0,0,0,0,0,0,0,0,0,0,0,0,0,0,0,0,0,0,0,0,0,24,10,0,0
0,0,0,34,0,0,0,0,0,0,0,0,0,0,0,0,0,0,0,0,0,0,0,0,0,24,5,21,0
0,0,0,13,0,0,0,0,0,0,0,0,0,0,0,0,0,0,0,0,0,0,0,0,0,24,10,0,0
0,0,0,34,0,0,0,0,0,0,0,0,0,0,0,0,0,0,0,0,0,0,0,0,0,24,10,0,0
0,0,0,34,0,0,0,0,0,0,0,0,0,0,0,0,0,0,0,0,0,0,0,0,0,7,7,0,0
0,0,0,25,0,0,0,0,0,0,0,0,0,0,0,0,0,0,0,0,0,0,0,0,0,0,0,5,23
0,0,5,5,5,0,0,0,0,0,0,5,0,0,0,0,0,0,5,5,5,23,0,0,0,0,0,0,0
0,0,0,24,0,0,0,0,0,0,0,0,0,0,0,0,0,15,14,0,0,0,0,0,0,0,0,0,0
0,0,0,24,0,0,0,0,0,0,0,0,0,0,0,0,0,15,14,0,0,0,0,0,0,0,0,0,0
0,0,0,24,0,0,0,0,0,0,0,0,0,0,0,0,0,16,1,0,0,0,0,0,0,0,0,0,0
0,0,0,24,0,0,0,0,0,0,0,0,0,0,0,0,0,15,14,0,0,0,0,0,0,0,0,0,0
0,0,0,24,0,0,0,0,0,0,0,0,0,0,0,0,0,15,14,0,0,0,0,0,0,0,0,0,0
0,0,5,5,5,0,0,0,0,0,0,5,0,0,0,0,0,0,5,5,5,23,0,0,0,0,0,0,0
0,0,0,25,0,0,0,0,0,0,0,0,0,0,0,0,0,0,0,0,0,0,0,0,0,0,0,5,23
0,0,0,34,0,0,0,0,0,0,0,0,0,0,0,0,0,0,0,0,0,0,0,0,0,7,7,0,0
0,0,0,34,0,0,0,0,0,0,0,0,0,0,0,0,0,0,0,0,0,0,0,0,0,24,10,0,0
0,0,0,13,0,0,0,0,0,0,0,0,0,0,0,0,0,0,0,0,0,0,0,0,0,24,10,0,0
0,0,0,34,0,0,0,0,0,0,0,0,0,0,0,0,0,0,0,0,0,0,0,0,0,24,5,21,0
0,0,0,34,0,0,0,0,0,0,0,0,0,0,0,0,0,0,0,0,0,0,0,0,0,24,10,0,0
0,0,0,25,0,0,0,0,0,0,0,0,0,0,0,0,0,0,0,0,0,0,0,0,0,24,10,0,0
0,0,21,5,0,0,0,0,0,0,0,5,0,0,0,0,0,0,5,5,7,7,24,24,24,7,7,0,0
0,7,7,0,0,0,0,0,0,0,0,0,0,0,0,0,0,0,7,7,21,0,0,0,0,0,0,5,0
0,24,21,0,0,0,0,0,0,0,0,0,0,0,0,0,0,0,7,35,0,0,0,0,0,0,0,0,0
0,24,21,0,0,0,0,0,0,0,0,0,0,0,0,0,0,0,7,36,0,0,0,0,0,0,0,0,0
0,7,7,0,0,0,0,0,0,0,0,0,0,0,0,0,0,0,7,36,0,0,0,0,0,0,0,0,0
0,0,21,5,0,21,39,21,39,21,0,5,0,0,0,0,0,0,7,36,0,0,0,0,0,0,0,0,0
0,0,0,5,7,5,5,5,5,5,7,5,7,24,24,24,24,24,7,35,0,0,0,0,0,0,0,0,0
0,0,0,5,7,5,13,5,38,5,7,5,7,8,8,7,8,8,7,7,0,0,0,0,0,0,0,0,0
0,0,5,5,0,0,0,0,0,0,0,5,0,0,0,21,0,0,0,5,5,0,0,0,0,0,0,0,0
0,0,0,0,0,0,0,0,0,0,0,0,0,0,0,0,0,0,0,0,0,0,0,0,0,0,0,0,0
endlayer

layer
0,0,0,0,0,0,0,0,0,0,0,0,0,0,0,0,0,0,0,0,0,0,0,0,0,0,0,0,0
0,0,5,5,0,0,0,0,0,0,0,0,0,0,0,0,0,0,5,5,5,0,0,0,0,0,0,0,0
0,0,0,16,5,27,27,27,5,28,28,28,28,5,27,27,27,5,7,7,0,0,0,0,0,0,0,0,0
0,0,0,16,5,27,27,27,5,28,28,28,28,5,27,27,27,5,7,7,0,0,0,0,0,0,0,0,0
0,0,0,16,5,0,0,0,5,0,0,0,0,5,0,0,0,5,7,40,0,0,0,0,0,0,0,0,0
0,0,21,5,0,0,0,0,0,0,0,0,0,0,0,0,0,0,5,40,0,0,0,0,0,0,0,0,0
0,7,7,0,0,0,0,0,0,0,0,0,0,0,0,0,0,0,7,40,0,0,0,0,0,0,0,0,0
0,24,21,0,0,0,0,0,0,0,0,0,0,0,0,0,0,0,40,40,0,0,0,0,0,0,0,0,0
0,24,21,0,0,0,0,0,0,0,0,0,0,0,0,0,0,0,40,7,0,0,0,0,0,0,0,0,0
0,7,7,0,0,0,0,0,0,0,0,0,0,0,0,0,0,0,7,7,21,0,0,0,0,0,0,5,0
0,0,21,5,0,0,0,0,0,0,0,0,0,0,0,0,0,0,5,5,7,7,24,24,24,7,7,0,0
0,0,0,7,0,0,0,0,0,0,0,0,0,0,0,0,0,0,0,0,0,0,0,0,0,24,41,0,0
0,0,0,7,0,0,0,0,0,0,0,0,0,0,0,0,0,0,0,0,0,0,0,0,0,13,42,0,0
0,0,0,33,0,0,0,0,0,0,0,0,0,0,0,0,0,0,0,0,0,0,0,0,0,24,5,21,0
0,0,0,34,0,0,0,0,0,0,0,0,0,0,0,0,0,0,0,0,0,0,0,0,0,13,41,0,0
0,0,0,33,0,0,0,0,0,0,0,0,0,0,0,0,0,0,0,0,0,0,0,0,0,24,42,0,0
0,0,0,7,0,0,0,0,0,0,0,0,0,0,0,0,0,0,0,0,0,0,0,0,0,7,7,0,0
0,0,0,7,0,0,0,0,0,0,0,0,0,0,0,0,0,0,0,0,0,0,0,0,0,0,0,5,0
0,0,5,5,5,0,0,0,0,0,0,5,0,0,0,0,0,0,5,5,5,0,0,0,0,0,0,0,0
0,0,0,24,0,0,0,0,0,0,0,0,0,0,0,0,15,14,0,0,0,0,0,0,0,0,0,0,0
0,0,0,24,0,0,0,0,0,0,0,0,0,0,0,0,15,14,0,0,0,0,0,0,0,0,0,0,0
0,0,0,24,0,0,0,0,0,0,0,0,0,0,0,0,16,1,0,0,0,0,0,0,0,0,0,0,0
0,0,0,24,0,0,0,0,0,0,0,0,0,0,0,0,15,14,0,0,0,0,0,0,0,0,0,0,0
0,0,0,24,0,0,0,0,0,0,0,0,0,0,0,0,15,14,0,0,0,0,0,0,0,0,0,0,0
0,0,5,5,5,0,0,0,0,0,0,5,0,0,0,0,0,0,5,5,5,0,0,0,0,0,0,0,0
0,0,0,7,0,0,0,0,0,0,0,0,0,0,0,0,0,0,0,0,0,0,0,0,0,0,0,5,0
0,0,0,7,0,0,0,0,0,0,0,0,0,0,0,0,0,0,0,0,0,0,0,0,0,7,7,0,0
0,0,0,33,0,0,0,0,0,0,0,0,0,0,0,0,0,0,0,0,0,0,0,0,0,24,41,0,0
0,0,0,34,0,0,0,0,0,0,0,0,0,0,0,0,0,0,0,0,0,0,0,0,0,13,42,0,0
0,0,0,33,0,0,0,0,0,0,0,0,0,0,0,0,0,0,0,0,0,0,0,0,0,24,5,21,0
0,0,0,7,0,0,0,0,0,0,0,0,0,0,0,0,0,0,0,0,0,0,0,0,0,13,41,0,0
0,0,0,7,0,0,0,0,0,0,0,0,0,0,0,0,0,0,0,0,0,0,0,0,0,24,42,0,0
0,0,21,5,0,0,0,0,0,0,0,5,0,0,0,0,0,0,5,5,7,7,24,24,24,7,7,0,0
0,7,7,0,0,0,0,0,0,0,0,0,0,0,0,0,0,0,7,7,21,0,0,0,0,0,0,5,0
0,24,21,0,0,0,0,0,0,0,0,0,0,0,0,0,0,0,7,22,0,0,0,0,0,0,0,0,0
0,24,21,0,0,0,0,0,0,0,0,0,0,0,0,0,0,0,7,22,0,0,0,0,0,0,0,0,0
0,7,7,0,0,0,0,0,0,0,0,0,0,0,0,0,0,0,7,22,0,0,0,0,0,0,0,0,0
0,0,21,5,0,21,0,0,0,21,0,5,0,0,0,0,0,0,7,22,0,0,0,0,0,0,0,0,0
0,0,0,5,7,5,24,24,24,5,7,5,7,24,24,24,24,24,7,22,0,0,0,0,0,0,0,0,0
0,0,0,5,7,5,44,17,16,5,7,5,7,43,15,7,43,15,7,7,0,0,0,0,0,0,0,0,0
0,0,5,5,0,0,0,0,0,0,0,5,0,0,0,21,0,0,0,5,5,0,0,0,0,0,0,0,0
0,0,0,0,0,0,0,0,0,0,0,0,0,0,0,0,0,0,0,0,0,0,0,0,0,0,0,0,0
endlayer

layer
0,0,0,0,0,0,0,0,0,0,0,0,0,0,0,0,0,0,0,0,0,0,0,0,0,0,0,0,0
0,0,5,5,17,17,17,16,37,44,0,0,16,37,37,17,37,37,5,5,5,0,0,0,0,0,0,0,0
0,0,17,5,5,44,0,16,5,43,32,32,15,5,44,0,16,5,7,7,17,0,0,0,0,0,0,0,0
0,0,17,5,5,5,5,5,5,7,13,13,7,5,5,5,5,5,7,7,17,0,0,0,0,0,0,0,0
0,0,17,5,5,45,45,45,5,7,7,7,7,5,45,45,45,5,7,7,17,0,0,0,0,0,0,0,0
17,17,21,5,44,0,0,0,45,41,41,41,41,45,0,0,0,0,5,7,17,0,0,0,0,0,0,0,0
17,7,7,45,0,0,0,0,0,0,0,0,0,0,0,0,0,0,7,7,17,0,0,0,0,0,0,0,0
17,7,7,0,0,0,0,0,0,0,0,0,0,0,0,0,0,0,7,7,17,0,0,0,0,0,0,0,0
17,7,7,0,0,0,0,0,0,0,0,0,0,0,0,0,0,0,7,7,17,0,0,0,0,0,0,0,0
17,7,7,37,44,0,0,0,0,0,0,0,0,0,0,0,0,0,7,7,21,17,17,17,17,17,17,5,0
17,17,21,5,44,0,0,0,0,0,0,0,0,0,0,0,0,0,5,5,7,7,7,7,7,7,7,17,0
0,0,17,7,45,0,0,0,0,0,0,0,0,0,0,0,0,0,45,45,44,0,0,0,0,7,7,17,0
0,0,17,7,0,0,0,0,0,0,0,0,0,0,0,0,0,0,0,0,0,0,0,0,0,7,7,17,0
0,0,17,7,0,0,0,0,0,0,0,0,0,0,0,0,0,0,0,0,0,0,0,0,0,7,7,44,0
0,0,17,25,0,0,0,0,0,0,0,0,0,0,0,0,0,0,0,0,0,0,0,0,0,7,7,17,0
0,0,17,7,0,0,0,0,0,0,0,0,0,0,0,0,0,0,0,0,0,0,0,0,0,7,7,17,0
0,0,17,7,0,0,0,0,0,0,0,0,0,0,0,0,0,0,0,0,0,0,0,0,0,7,7,17,0
0,0,17,7,0,0,0,0,0,0,0,0,0,0,0,0,0,37,37,37,37,37,0,0,0,0,16,5,0
0,0,5,5,5,44,0,0,0,0,0,5,0,0,0,0,0,16,5,5,5,44,0,0,0,0,45,45,0
0,0,17,7,45,44,0,0,0,0,0,0,0,0,0,15,14,0,0,0,16,45,0,0,0,0,0,0,0
0,0,17,7,0,0,0,0,0,0,0,0,0,0,0,15,14,0,0,0,0,0,0,0,0,0,0,0,0
0,0,17,7,0,0,0,0,0,0,0,0,0,0,0,0,1,0,0,0,0,0,0,0,0,0,0,0,0
0,0,17,7,0,0,0,0,0,0,0,0,0,0,0,15,14,0,0,0,0,0,0,0,0,0,0,0,0
0,0,17,7,37,44,0,0,0,0,16,37,37,0,0,15,14,0,0,0,16,37,0,0,0,0,0,0,0
0,0,5,5,5,44,0,0,0,0,16,5,44,0,0,0,0,16,5,5,5,44,0,0,0,0,37,37,0
0,0,17,7,45,45,0,0,0,0,16,45,44,0,0,0,0,16,45,45,45,45,0,0,0,0,16,5,0
0,0,17,7,0,0,0,0,0,0,0,0,0,0,0,0,0,0,0,0,0,0,0,0,0,7,7,17,0
0,0,17,7,0,0,0,0,0,0,0,0,0,0,0,0,0,0,0,0,0,0,0,0,0,7,7,17,0
0,0,17,25,0,0,0,0,0,0,0,0,0,0,0,0,0,0,0,0,0,0,0,0,0,7,7,17,0
0,0,17,7,0,0,0,0,0,0,0,0,0,0,0,0,0,0,0,0,0,0,0,0,0,7,5,44,0
0,0,17,7,0,0,0,0,0,0,0,0,0,0,0,0,0,0,0,0,0,0,0,0,0,7,7,17,0
0,0,17,7,37,0,0,0,0,0,16,37,37,0,0,0,0,16,37,37,44,0,0,0,0,7,7,17,0
17,17,5,5,44,0,0,0,0,0,16,5,44,0,0,0,0,16,5,5,7,7,7,7,7,7,7,17,0
17,7,7,45,44,0,0,0,0,0,45,45,44,0,0,0,0,45,7,7,21,17,17,17,17,17,17,5,0
17,7,7,0,0,0,0,0,0,0,0,0,0,0,0,0,0,0,7,7,17,0,0,0,0,0,0,0,0
17,7,7,0,0,0,0,0,0,0,0,0,0,0,0,0,0,0,7,7,17,0,0,0,0,0,0,0,0
17,7,7,37,44,0,0,0,0,0,16,37,44,0,0,0,0,0,7,7,17,0,0,0,0,0,0,0,0
17,17,5,5,44,8,8,8,8,8,16,5,44,0,0,0,0,0,7,7,17,0,0,0,0,0,0,0,0
0,0,17,5,7,7,7,7,7,7,7,5,7,7,7,7,7,7,7,7,17,0,0,0,0,0,0,0,0
0,0,17,5,7,7,7,7,7,7,7,5,7,7,7,7,7,7,7,7,17,0,0,0,0,0,0,0,0
0,0,5,5,17,17,17,17,17,17,17,5,17,17,17,45,17,17,17,5,5,0,0,0,0,0,0,0,0
0,0,0,0,0,0,0,0,0,0,0,0,0,0,0,0,0,0,0,0,0,0,0,0,0,0,0,0,0
endlayer

layer
0,37,37,37,44,17,17,17,17,17,17,17,17,17,17,17,17,17,16,37,37,37,0,0,0,0,0,0,0
0,16,5,5,5,5,5,5,5,5,5,5,5,5,5,5,5,5,5,5,5,44,0,0,0,0,0,0,0
0,45,16,5,5,5,13,5,5,5,5,5,5,5,5,13,5,5,5,5,45,44,0,0,0,0,0,0,0
0,0,16,5,7,7,7,7,7,7,7,7,7,7,7,7,7,7,5,5,44,0,0,0,0,0,0,0,0
0,0,16,5,7,7,7,7,7,7,7,7,7,7,7,7,7,7,5,5,44,0,0,0,0,0,0,0,0
37,37,5,5,5,5,5,5,5,5,5,5,5,5,5,5,5,5,5,5,44,0,0,0,0,0,0,0,0
16,5,5,5,7,7,7,7,5,27,27,27,27,5,7,7,7,7,5,5,44,0,0,0,0,0,0,0,0
16,5,5,5,7,27,27,7,5,27,7,7,27,5,7,27,27,7,5,5,44,0,0,0,0,0,0,0,0
16,5,5,5,7,27,27,7,5,27,7,7,27,5,7,27,27,7,5,5,44,0,0,0,0,0,16,37,37
16,5,5,5,7,7,7,7,5,27,27,27,27,5,7,7,7,7,5,5,5,37,37,37,37,37,16,5,44
16,45,5,5,5,5,5,5,5,5,5,5,5,5,5,5,5,5,5,5,5,5,5,5,5,5,5,45,45
0,0,16,5,7,7,7,7,7,7,7,5,46,46,46,46,5,5,5,5,7,7,7,7,7,5,5,44,0
0,0,16,5,7,5,5,5,5,5,7,5,46,7,7,46,5,5,5,5,7,46,5,46,7,5,5,44,0
0,0,16,5,7,5,46,46,46,5,7,5,46,7,7,46,5,5,5,5,7,5,7,5,7,5,5,44,0
0,0,16,5,7,5,46,13,46,5,7,5,46,7,7,46,5,5,5,5,7,46,5,46,7,5,5,44,0
0,0,16,5,7,5,46,46,46,5,7,5,46,7,7,46,5,5,5,5,7,7,7,7,7,5,5,44,0
0,0,16,5,7,5,5,5,5,5,7,5,46,7,7,46,16,37,5,5,37,37,37,7,7,5,5,44,0
0,0,16,5,7,7,7,7,7,7,7,5,46,46,46,46,16,5,5,5,5,5,44,7,7,5,5,44,0
0,16,5,5,5,5,5,5,5,5,5,5,5,5,5,5,5,5,5,5,5,5,5,5,5,5,5,5,0
0,17,16,5,5,46,46,46,46,46,46,5,46,7,46,14,0,0,0,0,5,5,44,32,32,32,32,45,0
0,17,16,5,5,46,7,7,7,7,46,5,46,7,46,14,0,0,0,0,45,45,44,32,17,17,32,13,0
0,17,16,5,5,46,7,5,5,7,46,5,5,13,5,0,0,0,0,0,17,17,17,32,17,17,32,17,0
0,17,16,5,5,46,7,7,7,7,46,5,46,7,46,14,0,0,0,0,37,37,44,32,17,17,32,13,0
0,17,16,5,5,46,46,46,46,46,46,5,46,7,46,14,0,0,0,0,5,5,44,32,32,32,32,37,0
0,16,5,5,5,5,5,5,5,5,5,5,5,5,5,5,5,5,5,5,5,5,5,5,5,5,5,5,0
0,0,16,5,7,7,7,7,7,7,7,5,46,46,46,46,16,5,5,5,5,5,44,7,7,5,5,44,0
0,0,16,5,7,5,5,5,5,5,7,5,46,7,7,46,16,45,5,5,45,45,45,7,7,5,5,44,0
0,0,16,5,7,5,46,46,46,5,7,5,46,7,7,46,17,17,5,5,7,7,7,7,7,5,5,44,0
0,0,16,5,7,5,46,13,46,5,7,5,46,7,7,46,17,17,5,5,7,46,5,46,7,5,5,44,0
0,0,16,5,7,5,46,46,46,5,7,5,46,7,7,46,17,17,5,5,7,5,7,5,7,5,5,44,0
0,0,16,5,7,5,5,5,5,5,7,5,46,7,7,46,37,37,5,5,7,46,5,46,7,5,5,44,0
0,0,16,5,7,7,7,7,7,7,7,5,46,46,46,46,16,5,5,5,7,7,7,7,7,5,5,44,0
37,37,37,5,5,5,5,5,5,5,5,5,5,5,5,5,5,5,5,5,5,5,5,5,5,5,5,37,44
16,5,5,5,46,46,46,46,46,46,46,5,7,7,7,7,7,7,5,5,5,45,45,45,45,45,16,5,44
16,5,5,5,46,7,7,7,7,7,46,5,7,46,46,46,46,7,5,5,44,0,0,0,0,0,16,45,45
16,5,5,5,46,7,5,5,5,7,46,5,7,46,5,5,46,7,5,5,44,0,0,0,0,0,0,0,0
16,5,5,5,46,7,7,7,7,7,46,5,7,46,46,46,46,7,5,5,44,0,0,0,0,0,0,0,0
16,45,16,5,46,46,46,46,46,46,46,5,7,7,7,7,7,7,5,5,44,0,0,0,0,0,0,0,0
0,0,16,5,5,5,5,5,5,5,5,5,5,5,5,5,5,5,5,5,44,0,0,0,0,0,0,0,0
0,37,37,5,5,5,5,5,5,5,5,5,5,5,5,5,5,5,5,5,37,37,0,0,0,0,0,0,0
0,16,5,5,44,45,45,45,45,45,16,5,44,45,45,45,45,45,16,5,5,44,0,0,0,0,0,0,0
0,16,45,45,45,0,0,0,0,0,16,45,45,0,0,0,0,0,16,45,45,45,0,0,0,0,0,0,0
endlayer

layer
0,10,10,10,8,8,8,8,8,8,8,8,8,8,8,8,8,8,8,10,10,10,0,0,0,0,0,0,0
0,10,7,10,5,7,7,7,7,7,7,7,7,7,7,7,7,7,5,10,7,10,0,0,0,0,0,0,0
0,10,10,10,7,5,5,5,5,5,5,5,5,5,5,5,5,5,7,5,10,10,0,0,0,0,0,0,0
0,0,8,5,5,0,0,0,47,0,0,0,0,0,0,0,0,0,5,7,8,0,0,0,0,0,0,0,0
0,0,5,7,5,0,47,0,47,0,47,0,47,0,0,47,0,0,5,7,8,0,0,0,0,0,0,0,0
8,8,7,7,0,0,47,0,47,0,47,0,0,0,0,47,0,0,7,7,8,0,0,0,0,0,0,0,0
8,7,46,0,0,0,47,0,47,0,47,47,0,47,0,47,0,0,0,46,7,0,0,0,0,0,0,0,0
8,7,46,0,0,0,47,0,0,0,0,0,0,47,47,47,47,0,0,46,7,0,0,0,0,0,0,0,0
8,7,46,0,47,47,47,47,47,47,0,47,0,47,0,0,0,0,0,46,7,0,0,0,0,0,10,4,10
8,7,46,0,0,0,0,0,0,47,0,47,0,47,0,0,0,0,0,46,7,7,7,7,7,5,18,13,14
8,8,5,7,0,0,0,0,0,47,0,7,0,47,0,0,7,7,7,7,46,46,46,46,46,7,5,9,10
0,0,7,46,0,0,47,0,0,47,0,0,0,0,0,0,0,0,0,0,0,0,0,0,0,46,7,8,0
0,0,7,46,0,0,47,0,0,47,47,47,0,0,0,0,47,47,47,47,47,47,47,47,47,46,7,8,0
0,0,7,46,0,0,47,0,0,0,0,0,0,0,0,0,0,0,0,0,0,0,0,0,0,46,7,1,0
0,0,7,46,0,0,47,0,0,0,0,0,0,0,0,0,0,0,0,0,0,0,0,0,0,46,7,8,0
0,0,7,46,0,0,47,47,47,47,47,47,0,0,0,0,47,47,47,47,47,47,47,0,0,46,7,1,0
0,0,7,46,0,0,0,0,0,0,0,0,0,0,0,0,0,0,0,0,0,0,47,0,0,46,7,8,0
0,0,7,46,0,0,0,0,0,0,0,0,0,0,0,0,0,0,0,0,0,0,47,0,0,46,7,8,0
0,7,7,7,7,7,7,47,7,7,7,7,47,0,47,7,48,48,48,48,7,0,47,0,0,7,7,2,2
0,7,7,7,50,0,0,0,0,0,49,47,0,0,0,0,0,0,0,0,48,0,47,0,0,0,0,7,1
0,7,7,7,25,0,0,0,0,0,0,47,0,0,0,0,0,0,0,0,48,0,47,47,47,0,0,7,1
0,7,7,7,50,0,0,0,0,0,51,47,0,0,0,0,0,0,0,0,48,0,47,0,0,0,0,7,1
0,7,7,7,25,0,0,0,0,0,0,47,0,0,0,0,0,0,0,0,48,0,47,47,47,0,0,7,1
0,7,7,7,50,0,0,0,0,0,49,47,0,0,0,0,0,0,0,0,48,0,47,0,0,0,0,7,1
0,7,7,7,7,7,7,0,7,7,7,7,47,0,47,7,48,48,48,48,7,0,47,0,0,7,7,6,6
0,0,7,46,0,0,0,0,0,0,0,47,0,0,0,0,0,0,0,0,47,0,47,0,0,46,7,8,0
0,0,7,46,0,47,47,47,47,47,47,47,0,0,0,0,47,47,47,0,47,0,47,0,0,46,7,8,0
0,0,7,46,0,0,0,47,0,0,0,47,0,0,0,0,47,0,0,0,47,0,0,0,0,46,7,1,0
0,0,7,46,0,47,0,47,0,47,0,47,0,0,0,0,47,0,47,47,47,0,0,0,0,46,7,8,0
0,0,7,46,0,47,0,47,0,47,0,47,0,0,0,0,47,0,0,0,47,0,0,0,0,46,7,1,0
0,0,7,46,0,47,0,47,0,47,0,47,0,0,0,0,47,47,47,0,47,0,0,0,0,46,7,8,0
0,0,7,46,0,47,0,0,0,47,0,47,0,0,0,0,47,0,0,0,47,25,0,0,25,46,7,8,0
8,8,5,7,0,47,0,47,47,47,0,7,47,47,47,47,7,47,0,47,7,46,46,46,46,7,5,4,10
8,7,7,46,0,47,0,0,0,47,0,47,0,0,0,0,0,47,0,7,7,7,7,7,7,5,18,13,14
8,7,7,46,0,47,47,47,0,47,0,47,0,47,47,47,47,47,0,46,7,0,0,0,0,0,10,9,10
8,7,7,46,0,47,0,0,0,47,0,47,0,0,0,0,0,0,0,46,7,0,0,0,0,0,0,0,0
8,7,7,46,0,0,0,47,47,47,0,47,47,47,47,47,47,47,0,46,7,0,0,0,0,0,0,0,0
8,7,7,46,0,0,0,0,0,47,0,0,0,0,0,0,0,0,0,7,5,0,0,0,0,0,0,0,0
0,0,5,7,46,46,46,46,46,46,46,7,46,46,46,46,46,46,7,5,0,0,0,0,0,0,0,0,0
0,10,10,7,7,7,7,7,7,7,7,5,7,7,7,7,7,7,5,10,10,10,0,0,0,0,0,0,0
0,10,7,10,0,8,8,8,8,8,3,6,1,8,8,8,8,8,0,10,7,10,0,0,0,0,0,0,0
0,10,10,10,0,0,0,0,0,0,8,8,8,0,0,0,0,0,0,10,10,10,0,0,0,0,0,0,0
endlayer

layer
0,0,0,0,0,0,0,0,0,0,0,0,0,0,0,0,0,0,0,0,0,0,0,0,0,0,0,0,0
0,0,7,0,21,7,2,7,2,7,2,7,2,7,2,7,2,7,21,0,7,0,0,0,0,0,0,0,0
0,0,0,0,7,5,5,5,5,5,5,5,5,5,5,5,5,5,7,21,0,0,0,0,0,0,0,0,0
0,0,0,21,5,0,0,0,47,0,0,0,0,0,0,0,0,0,5,7,0,0,0,0,0,0,0,0,0
0,0,21,7,5,0,47,0,47,0,47,0,47,0,0,47,0,0,5,1,0,0,0,0,0,0,0,0,0
0,0,7,7,0,0,47,0,47,0,47,0,0,0,0,47,0,0,7,7,0,0,0,0,0,0,0,0,0
0,7,46,0,0,0,47,0,47,0,47,47,0,47,0,47,0,0,0,46,7,0,0,0,0,0,0,0,0
0,3,1,0,0,0,47,0,0,0,0,0,0,47,47,47,47,0,0,3,1,0,0,0,0,0,0,0,0
0,3,1,0,47,47,47,47,47,47,0,47,0,47,0,0,0,0,0,3,7,0,0,0,0,0,0,0,0
0,7,46,0,0,0,0,0,0,47,0,47,0,47,0,0,0,0,0,46,7,2,7,2,7,21,0,0,0
0,0,21,7,0,0,0,0,0,47,0,7,0,47,0,0,7,7,7,7,46,6,46,6,46,7,21,0,0
0,0,7,46,0,0,47,0,0,47,0,0,0,0,0,0,0,0,0,0,0,0,0,0,0,46,7,0,0
0,0,3,1,0,0,47,0,0,47,47,47,0,0,0,0,47,47,47,47,47,47,47,47,47,3,1,0,0
0,0,7,7,0,0,47,0,0,0,0,0,0,0,0,0,0,0,0,0,0,0,0,0,0,46,7,0,0
0,0,3,1,0,0,47,0,0,0,0,0,0,0,0,0,0,0,0,0,0,0,0,0,0,13,21,0,0
0,0,7,7,0,0,47,47,47,47,47,47,0,0,0,0,47,47,47,47,47,47,47,0,0,46,7,0,0
0,0,3,1,0,0,0,0,0,0,0,0,0,0,0,0,0,0,0,0,0,0,47,0,0,3,1,0,0
0,0,7,46,0,0,0,0,0,0,0,0,0,0,0,0,0,0,0,0,0,0,47,0,0,46,7,0,0
0,7,7,7,7,6,7,47,7,6,7,7,47,0,47,7,0,0,0,0,7,0,47,0,0,7,7,0,0
0,3,7,1,23,0,23,0,23,0,0,47,0,0,0,0,0,0,0,0,0,0,47,0,0,0,0,7,0
0,7,7,13,50,0,0,0,0,0,0,47,0,0,0,0,0,0,0,0,0,0,47,47,47,0,0,52,0
0,3,7,1,23,0,0,0,0,0,0,47,0,0,0,0,0,0,0,0,0,0,47,0,0,0,0,52,0
0,7,7,13,50,0,0,0,0,0,0,47,0,0,0,0,0,0,0,0,0,0,47,47,47,0,0,52,0
0,3,7,1,23,0,23,0,23,0,0,47,0,0,0,0,0,0,0,0,0,0,47,0,0,0,0,7,0
0,7,7,7,7,2,7,0,7,2,7,7,47,0,47,7,0,0,0,0,7,0,47,0,0,7,7,0,0
0,0,7,46,0,0,0,0,0,0,0,47,0,0,0,0,0,0,0,0,47,0,47,0,0,46,7,0,0
0,0,3,1,0,47,47,47,47,47,47,47,0,0,0,0,47,47,47,0,47,0,47,0,0,3,1,0,0
0,0,7,7,0,0,0,47,0,0,0,47,0,0,0,0,47,0,0,0,47,0,0,0,0,46,7,0,0
0,0,3,1,0,47,0,47,0,47,0,47,0,0,0,0,47,0,47,47,47,0,0,0,0,13,21,0,0
0,0,7,7,0,47,0,47,0,47,0,47,0,0,0,0,47,0,0,0,47,0,0,0,0,46,7,0,0
0,0,3,1,0,47,0,47,0,47,0,47,0,0,0,0,47,47,47,0,47,0,0,0,0,3,1,0,0
0,0,7,46,0,47,0,0,0,47,0,47,0,0,0,0,47,0,0,0,47,39,0,0,39,46,7,0,0
0,0,21,7,0,47,0,47,47,47,0,7,47,47,47,47,7,47,0,47,7,46,2,2,46,7,21,0,0
0,7,7,46,0,47,0,0,0,47,0,47,0,0,0,0,0,47,0,7,7,7,6,6,7,21,0,0,0
0,3,7,1,0,47,47,47,0,47,0,47,0,47,47,47,47,47,0,46,7,0,0,0,0,0,0,0,0
0,7,7,46,0,47,0,0,0,47,0,47,0,0,0,0,0,0,0,3,1,0,0,0,0,0,0,0,0
0,3,7,1,0,0,0,47,47,47,0,47,47,47,47,47,47,47,0,46,7,0,0,0,0,0,0,0,0
0,7,7,46,0,0,0,0,0,47,0,0,0,0,0,0,0,0,0,7,21,0,0,0,0,0,0,0,0
0,0,21,7,46,2,46,38,46,2,46,7,46,2,46,46,2,46,7,21,0,0,0,0,0,0,0,0,0
0,0,0,21,7,6,7,13,7,6,7,21,7,6,7,7,6,7,21,0,0,0,0,0,0,0,0,0,0
0,0,7,0,0,0,0,0,0,0,0,0,0,0,0,0,0,0,0,0,7,0,0,0,0,0,0,0,0
0,0,0,0,0,0,0,0,0,0,0,0,0,0,0,0,0,0,0,0,0,0,0,0,0,0,0,0,0
endlayer

layer
0,0,42,0,0,0,0,0,0,0,0,0,0,0,0,0,0,0,0,0,42,0,0,0,0,0,0,0,0
0,15,13,43,21,7,37,7,37,7,37,7,37,7,37,7,37,7,21,15,13,43,0,0,0,0,0,0,0
0,0,41,0,7,5,5,5,5,5,5,5,5,5,5,5,5,5,7,21,41,0,0,0,0,0,0,0,0
0,0,0,21,5,0,0,0,47,0,0,0,0,0,0,0,0,0,5,7,0,0,0,0,0,0,0,0,0
0,0,21,7,5,0,47,0,47,0,47,0,47,0,0,47,0,0,5,44,0,0,0,0,0,0,0,0,0
0,0,7,7,0,0,47,0,47,0,47,0,0,0,0,47,0,0,7,7,0,0,0,0,0,0,0,0,0
0,7,46,0,0,0,47,0,47,0,47,47,0,47,0,47,0,0,0,46,7,0,0,0,0,0,0,0,0
0,16,44,0,0,0,47,0,0,0,0,0,0,47,47,47,47,0,0,16,44,0,0,0,0,0,0,0,0
0,16,44,0,47,47,47,47,47,47,0,47,0,47,0,0,0,0,0,16,7,0,0,0,0,0,0,0,0
0,7,46,0,0,0,0,0,0,47,0,47,0,47,0,0,0,0,0,46,7,37,7,37,7,21,0,0,0
0,0,21,7,0,0,0,0,0,47,0,7,0,47,0,0,7,7,7,7,46,45,46,45,46,7,21,0,0
0,0,7,46,0,0,47,0,0,47,0,0,0,0,0,0,0,0,0,0,0,0,0,0,0,46,7,0,0
0,0,16,44,0,0,47,0,0,47,47,47,0,0,0,0,47,47,47,47,47,47,47,47,47,16,44,0,0
0,0,7,7,0,0,47,0,0,0,0,0,0,0,0,0,0,0,0,0,0,0,0,0,0,46,7,0,0
0,0,16,44,0,0,47,0,0,0,0,0,0,0,0,0,0,0,0,0,0,0,0,0,0,13,21,0,0
0,0,7,7,0,0,47,47,47,47,47,47,0,0,0,0,47,47,47,47,47,47,47,0,0,46,7,0,0
0,0,16,44,0,0,0,0,0,0,0,0,0,0,0,0,0,0,0,0,0,0,47,0,0,16,44,0,0
0,0,7,46,0,0,0,0,0,0,0,0,0,0,0,0,0,0,0,0,0,0,47,0,0,46,7,0,0
0,7,7,7,7,45,7,13,7,45,7,7,47,47,47,7,0,0,0,0,7,0,47,0,0,7,7,0,0
0,16,7,44,0,0,0,0,0,0,0,47,0,0,0,0,0,0,0,0,0,0,47,0,0,0,0,7,0
0,7,7,13,0,0,0,0,0,0,0,47,0,0,0,0,0,0,0,0,0,0,47,47,47,0,0,52,0
0,16,7,44,0,0,0,0,0,0,0,47,0,0,0,0,0,0,0,0,0,0,47,0,0,0,0,52,0
0,7,7,13,0,0,0,0,0,0,0,47,0,0,0,0,0,0,0,0,0,0,47,47,47,0,0,52,0
0,16,7,44,0,0,0,0,0,0,0,47,0,0,0,0,0,0,0,0,0,0,47,0,0,0,0,7,0
0,7,7,7,7,37,7,13,7,37,7,7,47,47,47,7,0,0,0,0,7,0,47,0,0,7,7,0,0
0,0,7,46,0,0,0,0,0,0,0,47,0,0,0,0,0,0,0,0,47,0,47,0,0,46,7,0,0
0,0,16,44,0,47,47,47,47,47,47,47,0,0,0,0,47,47,47,0,47,0,47,0,0,16,44,0,0
0,0,7,7,0,0,0,47,0,0,0,47,0,0,0,0,47,0,0,0,47,0,0,0,0,46,7,0,0
0,0,16,44,0,47,0,47,0,47,0,47,0,0,0,0,47,0,47,47,47,0,0,0,0,13,21,0,0
0,0,7,7,0,47,0,47,0,47,0,47,0,0,0,0,47,0,0,0,47,0,0,0,0,46,7,0,0
0,0,16,44,0,47,0,47,0,47,0,47,0,0,0,0,47,47,47,0,47,0,0,0,0,16,44,0,0
0,0,7,46,0,47,0,0,0,47,0,47,0,0,0,0,47,0,0,0,47,0,0,0,0,46,7,0,0
0,0,21,7,0,47,0,47,47,47,0,7,47,47,47,47,7,47,47,47,7,46,37,37,46,7,21,0,0
0,7,7,46,0,47,0,0,0,47,0,47,0,0,0,0,0,47,0,7,7,7,45,45,7,21,0,0,0
0,16,7,44,0,47,47,47,0,47,0,47,0,47,47,47,47,47,0,46,7,0,0,0,0,0,0,0,0
0,7,7,46,0,47,0,0,0,47,0,47,0,0,0,0,0,0,0,16,44,0,0,0,0,0,0,0,0
0,16,7,44,0,0,0,47,47,47,0,47,47,47,47,47,47,47,0,46,7,0,0,0,0,0,0,0,0
0,7,7,46,0,0,0,0,0,47,0,0,0,0,0,0,0,0,0,7,21,0,0,0,0,0,0,0,0
0,0,21,7,46,37,46,38,46,37,46,7,46,37,46,46,37,46,7,21,0,0,0,0,0,0,0,0,0
0,0,42,21,7,45,7,13,7,45,7,21,7,45,7,7,45,7,21,0,42,0,0,0,0,0,0,0,0
0,15,13,43,0,0,0,0,0,0,0,0,0,0,0,0,0,0,0,15,13,43,0,0,0,0,0,0,0
0,0,41,0,0,0,0,0,0,0,0,0,0,0,0,0,0,0,0,0,41,0,0,0,0,0,0,0,0
endlayer

layer
0,0,10,0,0,0,0,0,0,0,0,0,0,0,0,0,0,0,0,0,9,0,0,0,0,0,0,0,0
0,10,0,10,21,7,7,7,7,7,7,7,7,7,7,7,7,7,21,14,0,18,0,0,0,0,0,0,0
0,0,10,0,7,5,5,5,5,5,5,5,5,5,5,5,5,5,7,21,4,0,0,0,0,0,0,0,0
0,0,0,21,5,0,0,0,47,0,0,0,0,0,0,0,0,0,5,7,0,0,0,0,0,0,0,0,0
0,0,21,7,5,0,47,0,47,0,47,0,47,0,0,47,0,0,5,7,0,0,0,0,0,0,0,0,0
0,0,7,7,0,0,47,0,47,0,47,0,0,0,0,47,0,0,7,7,0,0,0,0,0,0,0,0,0
0,7,46,0,0,0,47,0,47,0,47,47,0,47,0,47,0,0,0,46,7,0,0,0,0,0,0,0,0
0,7,46,0,0,0,47,0,0,0,0,0,0,47,47,47,47,0,0,46,7,0,0,0,0,0,0,0,0
0,7,46,0,47,47,47,47,47,47,0,47,0,47,0,0,0,0,0,46,7,0,0,0,0,0,0,0,0
0,7,46,0,0,0,0,0,0,47,0,42,0,47,0,0,0,0,0,46,7,7,7,7,7,21,0,0,0
0,0,21,7,43,32,32,32,32,32,15,7,43,32,32,15,7,7,7,7,46,46,46,46,46,7,21,0,0
0,0,7,46,0,0,47,0,0,47,0,41,0,0,0,41,0,0,0,0,41,0,0,0,0,46,7,0,0
0,0,7,46,0,0,47,0,0,47,47,32,0,0,0,32,47,47,47,47,32,47,47,47,47,46,7,0,0
0,0,7,46,0,0,47,0,0,0,0,32,0,0,0,32,0,0,0,0,32,0,0,0,0,46,7,0,0
0,0,7,46,0,0,47,0,0,0,0,32,0,0,0,32,0,0,0,0,32,0,0,0,0,46,7,0,0
0,0,7,46,0,0,47,47,47,47,47,32,0,0,0,32,47,47,47,47,32,47,47,0,0,46,7,0,0
0,0,7,46,0,0,0,0,0,0,0,32,0,0,0,32,0,0,0,0,32,0,47,0,0,46,7,0,0
0,0,7,46,0,0,0,0,0,0,0,42,0,0,0,42,0,0,0,0,42,0,47,0,0,46,7,0,0
0,7,7,7,7,7,7,7,7,7,7,7,43,32,15,7,48,48,48,48,7,43,32,32,15,7,7,0,0
0,7,7,7,34,36,52,33,52,36,34,41,0,0,0,48,0,0,0,0,48,0,47,0,0,0,0,7,0
0,7,7,7,36,34,36,33,36,34,36,32,0,0,0,48,0,0,0,0,48,0,47,47,47,0,0,7,0
0,7,7,7,33,33,34,25,34,33,33,32,0,0,0,48,0,0,0,0,48,0,47,0,0,0,0,7,0
0,7,7,7,36,34,36,33,36,34,36,32,0,0,0,48,0,0,0,0,48,0,47,47,47,0,0,7,0
0,7,7,7,34,36,52,33,52,36,34,42,0,0,0,48,0,0,0,0,48,0,0,0,0,0,0,7,0
0,7,7,7,7,7,7,7,7,7,7,7,43,32,15,7,48,48,48,48,7,43,32,32,15,7,7,0,0
0,0,7,46,0,0,0,0,0,0,0,41,0,0,0,41,0,0,0,0,41,0,47,0,0,46,7,0,0
0,0,7,46,0,47,47,47,47,47,47,32,0,0,0,32,47,47,47,0,32,0,47,0,0,46,7,0,0
0,0,7,46,0,0,0,47,0,0,0,32,0,0,0,32,47,0,0,0,32,0,0,0,0,46,7,0,0
0,0,7,46,0,47,0,47,0,47,0,32,0,0,0,32,47,0,47,47,32,0,0,0,0,46,7,0,0
0,0,7,46,0,47,0,47,0,47,0,32,0,0,0,32,47,0,0,0,32,0,0,0,0,46,7,0,0
0,0,7,46,0,47,0,47,0,47,0,32,0,0,0,32,47,47,47,0,32,0,0,0,0,46,7,0,0
0,0,7,46,0,47,0,0,0,47,0,42,0,0,0,42,47,0,0,0,42,0,0,0,0,46,7,0,0
0,0,21,7,43,32,32,32,32,32,15,7,43,32,32,15,7,43,32,15,7,46,46,46,46,7,21,0,0
0,7,7,46,0,47,0,0,0,47,0,41,0,0,0,0,0,47,0,7,7,7,7,7,7,21,0,0,0
0,7,7,46,0,47,47,47,0,47,0,32,0,47,47,47,47,47,0,46,7,0,0,0,0,0,0,0,0
0,7,7,46,0,47,0,0,0,47,0,32,0,0,0,0,0,0,0,46,7,0,0,0,0,0,0,0,0
0,7,7,46,0,0,0,47,47,47,0,32,47,47,47,47,47,47,0,46,7,0,0,0,0,0,0,0,0
0,7,7,46,0,0,0,0,0,47,0,42,0,0,0,0,0,0,0,7,21,0,0,0,0,0,0,0,0
0,0,21,7,46,46,46,46,46,46,46,7,46,46,46,46,46,46,7,21,0,0,0,0,0,0,0,0,0
0,0,10,21,7,7,7,7,7,7,7,21,7,7,7,7,7,7,21,0,9,0,0,0,0,0,0,0,0
0,10,0,10,0,0,0,0,0,0,0,0,0,0,0,0,0,0,0,14,0,18,0,0,0,0,0,0,0
0,0,10,0,0,0,0,0,0,0,0,0,0,0,0,0,0,0,0,0,4,0,0,0,0,0,0,0,0
endlayer

layer
0,0,0,0,0,5,5,5,5,5,5,5,5,5,5,5,5,5,0,0,0,0,0,0,0,0,0,0,0
0,0,0,0,5,5,5,5,5,5,5,5,5,5,5,5,5,5,5,0,0,0,0,0,0,0,0,0,0
0,0,0,5,5,5,5,5,5,5,5,5,5,5,5,5,5,5,37,5,0,0,0,0,0,0,0,0,0
0,0,5,5,5,5,5,5,5,5,5,5,5,5,5,5,5,5,5,5,5,0,0,0,0,0,0,0,0
0,5,5,5,5,5,5,5,5,5,5,5,5,5,5,5,5,5,5,5,5,5,0,0,0,0,0,0,0
5,5,5,5,5,5,5,5,5,5,5,5,5,5,5,5,5,5,5,5,5,5,5,0,0,0,0,0,0
5,5,5,5,5,5,5,5,5,5,5,5,5,5,5,5,5,5,5,5,5,5,5,5,0,0,0,0,0
5,5,5,5,5,5,5,5,5,5,5,5,5,5,5,5,5,5,5,5,5,5,5,5,5,0,0,0,0
5,5,5,5,5,5,5,5,5,5,5,5,5,5,5,5,5,5,5,5,5,5,5,5,5,5,0,0,0
5,5,5,5,5,5,5,5,5,5,5,5,5,5,5,5,5,5,5,5,5,5,5,5,5,5,0,0,0
0,5,5,5,5,5,5,5,5,5,5,5,5,5,5,5,5,5,5,5,5,5,5,5,5,5,5,0,0
0,5,5,5,5,5,5,5,5,5,5,5,5,5,5,5,5,5,5,5,5,5,5,5,5,5,5,5,0
0,5,5,5,5,5,5,5,5,5,5,5,5,5,5,5,5,5,5,5,5,5,5,5,5,5,5,5,5
0,5,5,5,5,5,5,5,5,5,5,5,5,5,5,5,5,5,5,5,5,5,5,5,5,5,5,5,5
0,5,5,5,5,5,5,5,5,5,5,5,5,5,5,5,5,5,5,5,5,5,5,5,5,5,5,5,5
0,5,5,5,5,5,5,5,5,5,5,5,5,5,5,5,5,5,5,5,5,5,5,5,5,5,5,5,5
0,5,5,5,5,5,5,5,5,5,5,5,5,5,5,5,5,5,5,5,5,5,5,5,5,5,5,5,5
0,5,5,5,5,5,5,5,5,5,5,5,5,5,5,5,5,5,5,5,5,5,5,5,5,5,5,5,5
5,5,5,5,5,5,5,5,5,5,5,5,5,5,5,5,5,5,5,5,5,5,5,5,5,5,5,5,5
5,5,5,5,5,5,5,5,5,5,5,5,5,5,5,5,5,5,5,5,5,5,5,5,5,5,5,5,5
5,5,5,5,5,5,5,5,5,5,5,5,5,5,5,5,5,5,5,5,5,5,5,5,5,5,5,5,5
5,5,5,5,5,5,5,5,5,5,5,5,5,5,5,5,5,5,5,5,5,5,5,5,5,5,5,5,5
5,5,5,5,5,5,5,5,5,5,5,5,5,5,5,5,5,5,5,5,5,5,5,5,5,5,5,5,5
5,5,5,5,5,5,5,5,5,5,5,5,5,5,5,5,5,5,5,5,5,5,5,5,5,5,5,5,5
5,5,5,5,5,5,5,5,5,5,5,5,5,5,5,5,5,5,5,5,5,5,5,5,5,5,5,5,5
0,5,5,5,5,5,5,5,5,5,5,5,5,5,5,5,5,5,5,5,5,5,5,5,5,5,5,5,5
0,5,5,5,5,5,5,5,5,5,5,5,5,5,5,5,5,5,5,5,5,5,5,5,5,5,5,5,5
0,5,5,5,5,5,5,5,5,5,5,5,5,5,5,5,5,5,5,5,5,5,5,5,5,5,5,5,5
0,5,5,5,5,5,5,5,5,5,5,5,5,5,5,5,5,5,5,5,5,5,5,5,5,5,5,5,5
0,5,5,5,5,5,5,5,5,5,5,5,5,5,5,5,5,5,5,5,5,5,5,5,5,5,5,5,5
0,5,5,5,5,5,5,5,5,5,5,5,5,5,5,5,5,5,5,5,5,5,5,5,5,5,5,5,5
0,5,5,5,5,5,5,5,5,5,5,5,5,5,5,5,5,5,5,5,5,5,5,5,5,5,5,5,0
5,5,5,5,5,5,5,5,5,5,5,5,5,5,5,5,5,5,5,5,5,5,5,5,5,5,5,0,0
5,5,5,5,5,5,5,5,5,5,5,5,5,5,5,5,5,5,5,5,5,5,5,5,5,5,0,0,0
5,5,5,5,5,5,5,5,5,5,5,5,5,5,5,5,5,5,5,5,5,5,5,5,5,0,0,0,0
5,5,5,5,5,5,5,5,5,5,5,5,5,5,5,5,5,5,5,5,5,5,5,5,0,0,0,0,0
5,5,5,5,5,5,5,5,5,5,5,5,5,5,5,5,5,5,5,5,5,5,5,0,0,0,0,0,0
0,5,5,5,5,5,5,5,5,5,5,5,5,5,5,5,5,5,5,5,5,5,0,0,0,0,0,0,0
0,0,5,5,5,5,5,5,5,5,5,5,5,5,5,5,5,5,5,5,5,0,0,0,0,0,0,0,0
0,0,0,5,5,5,5,5,5,5,5,5,5,5,5,5,5,5,5,5,0,0,0,0,0,0,0,0,0
0,0,0,0,5,5,5,5,5,5,5,5,5,5,5,5,5,5,5,0,0,0,0,0,0,0,0,0,0
0,0,0,0,0,0,0,0,0,0,0,0,0,0,0,0,0,0,0,0,0,0,0,0,0,0,0,0,0
endlayer

