
# Created by Ruins mod version 14.7 Ingame Parser
# authoring Player: Barlock_James

weight=1
embed_into_distance=29
acceptable_target_blocks=
unacceptable_target_blocks=flowing_water,water,flowing_lava,lava
dimensions=125,31,31
allowable_overhang=0
max_leveling=2
leveling_buffer=0
preserve_water=0
preserve_lava=0

rule1=0,100,minecraft:stone-0
rule2=0,100,minecraft:fence-0
rule3=0,100,minecraft:rail-1
rule4=1,100,minecraft:redstone_torch-5
rule5=0,100,minecraft:golden_rail-11
rule6=0,100,minecraft:rail-7
rule7=0,100,minecraft:rail-0
rule8=0,100,minecraft:rail-9
rule9=0,100,ChestGenHook:dungeonChest:5-4
rule10=0,100,minecraft:planks-0
rule11=2,100,minecraft:torch-1
rule12=2,100,minecraft:torch-4
rule13=2,100,minecraft:torch-3
rule14=2,100,minecraft:torch-2
rule15=0,100,minecraft:gravel-0
rule16=0,100,minecraft:rail-6
rule17=0,100,minecraft:golden_rail-13
rule18=2,100,minecraft:redstone_torch-4
rule19=0,100,minecraft:lava-8
rule20=0,100,minecraft:lava-10
rule21=0,100,minecraft:golden_rail-10
rule22=0,100,minecraft:lava-0
rule23=0,100,minecraft:stonebrick-0
rule24=0,100,minecraft:monster_egg-0
rule25=0,100,minecraft:stonebrick-2
rule26=0,100,minecraft:stonebrick-1
rule27=0,100,minecraft:rail-8
rule28=0,100,minecraft:water-8
rule29=0,100,ChestGenHook:dungeonChest:5-5
rule30=0,100,minecraft:golden_rail-9
rule31=0,100,minecraft:golden_rail-8
rule32=0,100,ChestGenHook:dungeonChest:5-3
rule33=0,100,minecraft:lava-2
rule34=0,100,minecraft:sand-0
rule35=0,100,minecraft:water-0
rule36=0,100,minecraft:stone_brick_stairs-0
rule37=0,100,Railcraft:tile.railcraft.wall.alpha-5
rule38=0,100,minecraft:fence_gate-0
rule39=0,100,ChestGenHook:dungeonChest:5-2
rule40=0,100,minecraft:stone_brick_stairs-3
rule41=0,100,minecraft:golden_rail-12
rule42=0,100,minecraft:stone_brick_stairs-4
rule43=0,100,minecraft:stone_brick_stairs-7
rule44=0,100,minecraft:stone_brick_stairs-6
rule45=0,100,minecraft:stone_brick_stairs-5
rule46=0,100,Railcraft:tile.railcraft.lantern.stone-9
rule47=0,100,minecraft:stone_slab-13
rule48=0,100,minecraft:stone_slab-5
rule49=0,100,minecraft:stone_brick_stairs-1
rule50=0,100,minecraft:dirt-0
rule51=0,100,Railcraft:tile.railcraft.brick.quarried-1
rule52=0,100,Railcraft:tile.railcraft.stair-2
rule53=0,100,Railcraft:tile.railcraft.stair-7
rule54=0,100,ExtraUtilities:colorStoneBrick-0
rule55=0,100,Railcraft:tile.railcraft.stair-3
rule56=0,100,Railcraft:tile.railcraft.stair-1
rule57=0,100,Railcraft:tile.railcraft.stair-0
rule58=0,100,Railcraft:tile.railcraft.slab-0
rule59=0,100,Railcraft:tile.railcraft.stair-6
rule60=0,100,Railcraft:tile.railcraft.stair-5
rule61=0,100,ExtraUtilities:color_redstoneLight-0
rule62=0,100,Railcraft:tile.railcraft.stair-4
rule63=0,100,minecraft:grass-0
rule64=0,100,minecraft:nether_brick-0
rule65=0,100,chisel:marble-11
rule66=0,100,minecraft:stone_slab-14
rule67=0,100,ExtraUtilities:color_redstoneLight-10
rule68=0,100,minecraft:nether_brick_stairs-2
rule69=0,100,minecraft:nether_brick_stairs-0
rule70=0,100,minecraft:nether_brick_stairs-3
rule71=0,100,minecraft:stone_brick_stairs-2
rule72=0,100,minecraft:nether_brick_stairs-1
rule73=0,100,chisel:glass-15
rule74=0,100,Railcraft:tile.railcraft.wall.alpha-14
rule75=0,100,minecraft:obsidian-0
rule76=0,100,minecraft:iron_door-1
rule77=0,100,minecraft:nether_brick_fence-0
rule78=0,100,minecraft:carpet-10
rule79=0,100,minecraft:iron_door-9
rule80=0,100,IInventory;BiblioCraft:BiblioSeats;minecraft:carpet#1#10#0-0
rule81=0,100,IInventory;BiblioCraft:BiblioSeats;minecraft:carpet#1#10#0+BiblioCraft:item.seatBack5#1#0#1-0
rule82=0,100,minecraft:iron_door-8
rule83=0,100,BiblioCraft:BiblioLantern-0
rule84=0,100,minecraft:nether_brick_stairs-6
rule85=0,100,minecraft:nether_brick_stairs-4
rule86=0,100,minecraft:nether_brick_stairs-7
rule87=0,100,minecraft:netherrack-0
rule88=0,100,minecraft:double_stone_slab-5
rule89=0,100,minecraft:nether_brick_stairs-5
rule90=0,100,ExtraUtilities:decorativeBlock2-7
rule91=0,100,minecraft:fire-15
rule92=0,100,minecraft:wooden_slab-13
rule93=0,100,minecraft:stone_slab-6
rule94=0,100,Railcraft:tile.railcraft.wall.alpha-9
rule95=0,100,minecraft:trapdoor-12
rule96=0,100,minecraft:trapdoor-4
rule97=0,100,Natura:Cloud-0

layer
1,1,1,1,1,1,1,1,1,1,1,1,1,2,3,2,1,1,1,1,1,1,1,1,1,1,1,1,1,1,1
1,1,1,1,1,1,1,1,1,1,1,1,1,0,3,0,1,1,1,1,1,1,1,1,1,1,1,1,1,1,1
1,1,1,1,1,1,1,1,1,1,1,1,1,0,3,0,1,1,1,1,1,1,1,1,1,1,1,1,1,1,1
1,1,1,1,1,1,1,1,1,1,1,0,0,0,3,0,1,1,1,1,1,1,1,1,1,1,1,1,1,1,1
1,1,1,1,1,1,1,1,1,1,1,1,1,0,3,0,1,1,1,1,1,1,1,1,1,1,1,1,1,1,1
1,1,1,1,1,1,1,1,1,1,1,1,1,0,3,0,1,1,1,1,1,1,1,1,1,1,1,1,1,1,1
1,1,1,1,1,1,1,1,1,1,1,1,1,2,3,2,1,1,1,1,1,1,1,1,1,1,1,1,1,1,1
1,1,1,1,1,1,1,1,1,1,1,1,1,0,3,0,1,1,1,1,1,1,1,1,1,1,1,1,1,1,1
1,1,1,1,1,1,1,1,1,1,1,1,1,0,3,0,1,1,1,1,1,1,1,1,1,1,1,1,1,1,1
1,1,1,1,1,1,1,1,1,1,1,1,1,0,3,0,1,1,1,1,1,1,1,1,1,1,1,1,1,1,1
1,1,1,1,1,1,1,1,1,1,1,1,1,0,3,0,1,1,1,1,1,1,1,1,1,1,1,1,1,1,1
1,1,1,1,1,1,1,1,1,1,1,1,1,0,3,0,1,1,1,1,1,1,1,1,1,1,1,1,1,1,1
1,1,1,1,1,1,1,1,1,1,1,1,1,2,3,2,1,1,1,1,1,1,1,1,1,1,1,1,1,1,1
1,1,1,1,1,1,1,1,1,1,1,1,1,0,3,0,1,1,1,1,1,1,1,1,1,1,1,1,1,1,1
2,0,0,0,0,0,2,0,0,0,0,0,2,0,3,0,1,1,1,1,1,1,1,1,1,1,1,1,1,1,1
7,7,7,7,7,7,7,7,7,7,7,7,7,7,6,0,5,4,2,0,0,0,0,0,2,0,0,0,0,0,2
2,0,0,0,0,0,2,0,0,0,0,0,2,0,8,7,6,7,7,7,7,7,7,7,7,7,7,7,7,7,7
1,1,1,1,1,1,1,1,1,1,1,1,1,0,3,0,0,0,2,0,0,0,0,0,2,0,0,0,0,0,2
1,1,1,1,1,1,1,1,1,1,1,1,1,2,3,2,1,1,1,1,1,1,1,1,1,1,1,1,1,1,1
1,1,1,1,1,1,1,1,1,1,1,1,1,0,3,0,1,1,1,1,1,1,1,1,1,1,1,1,1,1,1
1,1,1,1,1,1,1,1,1,1,1,1,1,0,3,0,1,1,1,1,1,1,1,1,1,1,1,1,1,1,1
1,1,1,1,1,1,1,1,1,1,1,1,1,0,3,0,1,1,1,1,1,1,1,1,1,1,1,1,1,1,1
1,1,1,1,1,1,1,1,1,1,1,1,1,0,3,0,1,1,1,1,1,1,1,1,1,1,1,1,1,1,1
1,1,1,1,1,1,1,1,1,1,1,1,1,0,3,0,1,1,1,1,1,1,1,1,1,1,1,1,1,1,1
1,1,1,1,1,1,1,1,1,1,1,1,1,2,3,2,1,1,1,1,1,1,1,1,1,1,1,1,1,1,1
1,1,1,1,1,1,1,1,1,1,1,1,1,0,3,0,1,1,1,1,1,1,1,1,1,1,1,1,1,1,1
1,1,1,1,1,1,1,1,1,1,1,1,1,0,3,0,1,1,1,1,1,1,1,1,1,1,1,1,1,1,1
1,1,1,1,1,1,1,1,1,1,1,1,1,0,3,0,1,1,1,1,1,1,1,1,1,1,1,1,1,1,1
1,1,1,1,1,1,1,1,1,1,1,1,1,0,3,0,1,1,1,1,1,1,1,1,1,1,1,1,1,1,1
1,1,1,1,1,1,1,1,1,1,1,1,1,0,3,0,1,1,1,1,1,1,1,1,1,1,1,1,1,1,1
1,1,1,1,1,1,1,1,1,1,1,1,1,2,3,2,1,1,1,1,1,1,1,1,1,1,1,1,1,1,1
endlayer

layer
1,1,1,1,1,1,1,1,1,1,1,1,1,2,0,2,1,1,1,1,1,1,1,1,1,1,1,1,1,1,1
1,1,1,1,1,1,1,1,1,1,1,1,1,0,0,0,1,1,1,1,1,1,1,1,1,1,1,1,1,1,1
1,1,1,1,1,1,1,1,1,1,1,1,1,0,0,0,1,1,1,1,1,1,1,1,1,1,1,1,1,1,1
1,1,0,0,0,0,0,0,0,0,0,0,0,0,0,0,1,1,1,1,1,1,1,1,1,1,1,1,1,1,1
1,1,0,0,0,0,0,0,0,0,0,0,1,0,0,0,1,1,1,1,1,1,1,1,1,1,1,1,1,1,1
1,1,0,0,0,0,0,0,0,0,0,0,1,0,0,0,1,1,1,1,1,1,1,1,1,1,1,1,1,1,1
1,1,0,0,0,0,0,0,0,0,0,0,1,2,0,2,1,1,1,1,1,1,1,1,1,1,1,1,1,1,1
1,1,0,0,0,0,0,0,0,0,0,0,1,0,0,0,1,1,1,1,1,1,1,1,1,1,1,1,1,1,1
1,1,0,0,0,0,0,0,0,0,0,0,1,0,0,0,1,1,1,1,1,1,1,1,1,1,1,1,1,1,1
1,1,0,0,0,0,0,0,0,0,0,0,1,0,0,0,1,1,1,1,1,1,1,1,1,1,1,1,1,1,1
1,1,0,0,0,0,0,0,0,0,0,0,1,0,0,0,1,1,1,1,1,1,1,1,1,1,1,1,1,1,1
1,1,0,0,0,0,0,0,0,0,0,0,1,0,0,0,1,1,1,1,1,1,1,1,1,1,1,1,1,1,1
1,1,9,9,0,0,0,0,0,0,0,0,1,2,0,2,1,1,1,1,1,1,1,1,1,1,1,1,1,1,1
1,1,1,1,1,1,1,1,1,1,1,1,1,0,0,0,1,1,1,1,1,1,1,1,1,1,1,1,1,1,1
2,0,0,0,0,0,2,0,0,0,0,0,2,0,0,0,5,1,1,1,1,1,1,1,1,1,1,1,1,1,1
0,0,0,0,0,0,0,0,0,0,0,0,0,0,0,0,0,0,2,0,0,0,0,0,2,0,0,0,0,0,2
2,0,0,0,0,0,2,0,0,0,0,0,2,0,0,0,0,0,0,0,0,0,0,0,0,0,0,0,0,0,0
1,1,1,1,1,1,1,1,1,1,1,1,1,0,0,0,0,0,2,0,0,0,0,0,2,0,0,0,0,0,2
1,1,1,1,1,1,1,1,1,1,1,1,1,2,0,2,1,1,1,1,1,1,1,1,1,1,1,1,1,1,1
1,1,1,1,1,1,1,1,1,1,1,1,1,0,0,0,1,1,1,1,1,1,1,1,1,1,1,1,1,1,1
1,1,1,1,1,1,1,1,1,1,1,1,1,0,0,0,1,1,1,1,1,1,1,1,1,1,1,1,1,1,1
1,1,1,1,1,1,1,1,1,1,1,1,1,0,0,0,1,1,1,1,1,1,1,1,1,1,1,1,1,1,1
1,1,1,1,1,1,1,1,1,1,1,1,1,0,0,0,1,1,1,1,1,1,1,1,1,1,1,1,1,1,1
1,1,1,1,1,1,1,1,1,1,1,1,1,0,0,0,1,1,1,1,1,1,1,1,1,1,1,1,1,1,1
1,1,1,1,1,1,1,1,1,1,1,1,1,2,0,2,1,1,1,1,1,1,1,1,1,1,1,1,1,1,1
1,1,1,1,1,1,1,1,1,1,1,1,1,0,0,0,1,1,1,1,1,1,1,1,1,1,1,1,1,1,1
1,1,1,1,1,1,1,1,1,1,1,1,1,0,0,0,1,1,1,1,1,1,1,1,1,1,1,1,1,1,1
1,1,1,1,1,1,1,1,1,1,1,1,1,0,0,0,1,1,1,1,1,1,1,1,1,1,1,1,1,1,1
1,1,1,1,1,1,1,1,1,1,1,1,1,0,0,0,1,1,1,1,1,1,1,1,1,1,1,1,1,1,1
1,1,1,1,1,1,1,1,1,1,1,1,1,0,0,0,1,1,1,1,1,1,1,1,1,1,1,1,1,1,1
1,1,1,1,1,1,1,1,1,1,1,1,1,2,0,2,1,1,1,1,1,1,1,1,1,1,1,1,1,1,1
endlayer

layer
1,1,1,1,1,1,1,1,1,1,1,1,1,10,10,10,1,1,1,1,1,1,1,1,1,1,1,1,1,1,1
1,1,1,1,1,1,1,1,1,1,1,1,1,0,11,0,1,1,1,1,1,1,1,1,1,1,1,1,1,1,1
1,1,1,1,1,1,1,1,1,1,1,1,1,0,0,0,1,1,1,1,1,1,1,1,1,1,1,1,1,1,1
1,1,0,0,0,0,0,0,0,0,0,0,1,0,0,0,1,1,1,1,1,1,1,1,1,1,1,1,1,1,1
1,1,0,0,0,0,0,0,0,0,0,0,1,0,0,0,1,1,1,1,1,1,1,1,1,1,1,1,1,1,1
1,1,0,0,0,0,0,0,0,0,0,0,1,0,0,0,1,1,1,1,1,1,1,1,1,1,1,1,1,1,1
1,1,0,0,0,0,0,0,0,0,0,0,1,10,10,10,1,1,1,1,1,1,1,1,1,1,1,1,1,1,1
1,1,0,0,0,0,0,0,0,0,0,0,1,0,11,0,1,1,1,1,1,1,1,1,1,1,1,1,1,1,1
1,1,0,0,0,0,0,0,0,0,0,0,1,0,0,0,1,1,1,1,1,1,1,1,1,1,1,1,1,1,1
1,1,0,0,0,0,0,0,0,0,0,0,1,0,0,0,1,1,1,1,1,1,1,1,1,1,1,1,1,1,1
1,1,0,0,0,0,0,0,0,0,0,0,1,0,0,0,1,1,1,1,1,1,1,1,1,1,1,1,1,1,1
1,1,0,0,0,0,0,0,0,0,0,0,1,0,0,0,1,1,1,1,1,1,1,1,1,1,1,1,1,1,1
1,1,0,0,0,0,0,0,0,0,0,0,1,10,10,10,1,1,1,1,1,1,1,1,1,1,1,1,1,1,1
1,1,1,1,1,1,1,1,1,1,1,1,1,0,11,0,5,1,1,1,1,1,1,1,1,1,1,1,1,1,1
10,0,0,0,0,0,10,0,0,0,0,0,10,0,0,0,0,1,1,1,1,1,1,1,1,1,1,1,1,1,1
10,12,0,0,0,0,10,12,0,0,0,13,10,12,0,0,0,0,10,0,0,0,0,0,10,0,0,0,0,0,10
10,0,0,0,0,0,10,0,0,0,0,0,10,0,0,0,0,13,10,0,0,0,0,13,10,0,0,0,0,13,10
1,1,1,1,1,1,1,1,1,1,1,1,1,0,14,0,0,0,10,0,0,0,0,0,10,0,0,0,0,0,10
1,1,1,1,1,1,1,1,1,1,1,1,1,10,10,10,1,1,1,1,1,1,1,1,1,1,1,1,1,1,1
1,1,1,1,1,1,1,1,1,1,1,1,1,0,0,0,1,1,1,1,1,1,1,1,1,1,1,1,1,1,1
1,1,1,1,1,1,1,1,1,1,1,1,1,0,0,0,1,1,1,1,1,1,1,1,1,1,1,1,1,1,1
1,1,1,1,1,1,1,1,1,1,1,1,1,0,0,0,1,1,1,1,1,1,1,1,1,1,1,1,1,1,1
1,1,1,1,1,1,1,1,1,1,1,1,1,0,0,0,1,1,1,1,1,1,1,1,1,1,1,1,1,1,1
1,1,1,1,1,1,1,1,1,1,1,1,1,0,14,0,1,1,1,1,1,1,1,1,1,1,1,1,1,1,1
1,1,1,1,1,1,1,1,1,1,1,1,1,10,10,10,1,1,1,1,1,1,1,1,1,1,1,1,1,1,1
1,1,1,1,1,1,1,1,1,1,1,1,1,0,0,0,1,1,1,1,1,1,1,1,1,1,1,1,1,1,1
1,1,1,1,1,1,1,1,1,1,1,1,1,0,0,0,1,1,1,1,1,1,1,1,1,1,1,1,1,1,1
1,1,1,1,1,1,1,1,1,1,1,1,1,0,0,0,1,1,1,1,1,1,1,1,1,1,1,1,1,1,1
1,1,1,1,1,1,1,1,1,1,1,1,1,0,0,0,1,1,1,1,1,1,1,1,1,1,1,1,1,1,1
1,1,1,1,1,1,1,1,1,1,1,1,1,0,14,0,1,1,1,1,1,1,1,1,1,1,1,1,1,1,1
1,1,1,1,1,1,1,1,1,1,1,1,1,10,10,10,1,1,1,1,1,1,1,1,1,1,1,1,1,1,1
endlayer

layer
1,1,1,1,1,1,1,1,1,1,1,1,1,1,1,1,1,1,1,1,1,1,1,1,1,1,1,1,1,1,1
1,1,1,1,1,1,1,1,1,1,1,1,1,1,1,1,1,1,1,1,1,1,1,1,1,1,1,1,1,1,1
1,1,1,1,1,1,1,1,1,1,1,1,1,1,1,1,1,1,1,1,1,1,1,1,1,1,1,1,1,1,1
1,1,1,1,1,1,1,1,1,1,1,1,1,1,1,1,1,1,1,1,1,1,1,1,1,1,1,1,1,1,1
1,1,1,1,1,1,1,1,1,1,1,1,1,1,1,1,1,1,1,1,1,1,1,1,1,1,1,1,1,1,1
1,1,1,1,1,1,1,1,1,1,1,1,1,1,1,1,1,1,1,1,1,1,1,1,1,1,1,1,1,1,1
1,1,1,1,1,1,1,1,1,1,1,1,1,15,15,15,1,1,1,1,1,1,1,1,1,1,1,1,1,1,1
1,1,1,1,1,1,1,1,1,1,1,1,1,1,1,1,1,1,1,1,1,1,1,1,1,1,1,1,1,1,1
1,1,1,1,1,1,1,1,1,1,1,1,1,1,1,1,1,1,1,1,1,1,1,1,1,1,1,1,1,1,1
1,1,1,1,1,1,1,1,1,1,1,1,1,1,1,1,1,1,1,1,1,1,1,1,1,1,1,1,1,1,1
1,1,1,1,1,1,1,1,1,1,1,1,1,1,1,1,1,1,1,1,1,1,1,1,1,1,1,1,1,1,1
1,1,1,1,1,1,1,1,1,1,1,1,1,1,1,1,1,1,1,1,1,1,1,1,1,1,1,1,1,1,1
1,1,1,1,1,1,1,1,1,1,1,1,1,17,7,7,16,1,1,1,1,1,1,1,1,1,1,1,1,1,1
1,1,1,1,1,1,1,1,1,1,1,1,1,18,0,0,0,1,1,1,1,1,1,1,1,1,1,1,1,1,1
1,1,1,1,1,1,19,1,1,1,1,1,1,0,0,0,0,1,1,1,1,1,1,1,1,1,1,1,1,1,1
1,1,1,1,1,1,19,1,1,1,1,1,1,0,0,0,0,1,15,1,1,1,1,1,15,1,1,1,1,1,1
1,1,1,1,1,1,20,1,1,1,1,1,1,0,0,0,0,1,15,1,1,1,1,1,15,1,1,1,1,1,1
1,1,1,1,1,1,1,1,1,1,1,1,1,0,0,0,0,1,15,1,1,1,1,1,15,1,1,1,1,1,1
1,1,1,1,1,1,1,1,1,1,1,1,1,1,1,1,1,1,1,1,1,1,1,1,1,1,1,1,1,1,1
1,1,1,1,1,1,1,1,1,1,1,1,1,1,1,1,1,1,1,1,1,1,1,1,1,1,1,1,1,1,1
1,1,1,1,1,1,1,1,1,1,1,1,1,1,1,1,1,1,1,1,1,1,1,1,1,1,1,1,1,1,1
1,1,1,1,1,1,1,1,1,1,1,1,1,1,1,1,1,1,1,1,1,1,1,1,1,1,1,1,1,1,1
1,1,1,1,1,1,1,1,1,1,1,1,1,1,1,1,1,1,1,1,1,1,1,1,1,1,1,1,1,1,1
1,1,1,1,1,1,1,1,1,1,1,1,1,1,1,1,1,1,1,1,1,1,1,1,1,1,1,1,1,1,1
1,1,1,1,1,1,1,1,1,1,1,1,1,19,19,19,1,1,1,1,1,1,1,1,1,1,1,1,1,1,1
1,1,1,1,1,1,1,1,1,1,1,1,1,1,1,1,1,1,1,1,1,1,1,1,1,1,1,1,1,1,1
1,1,1,1,1,1,1,1,1,1,1,1,1,1,1,1,1,1,1,1,1,1,1,1,1,1,1,1,1,1,1
1,1,1,1,1,1,1,1,1,1,1,1,1,1,1,1,1,1,1,1,1,1,1,1,1,1,1,1,1,1,1
1,1,1,1,1,1,1,1,1,1,1,1,1,1,1,1,1,1,1,1,1,1,1,1,1,1,1,1,1,1,1
1,1,1,1,1,1,1,1,1,1,1,1,1,1,1,1,1,1,1,1,1,1,1,1,1,1,1,1,1,1,1
1,1,1,1,1,1,1,1,1,1,1,1,1,1,1,1,1,1,1,1,1,1,1,1,1,1,1,1,1,1,1
endlayer

layer
1,1,1,1,1,1,1,1,1,1,1,1,1,1,1,1,1,1,1,1,1,1,1,1,1,1,1,1,1,1,1
1,1,1,1,1,1,1,1,1,1,1,1,1,1,1,1,1,1,1,1,1,1,1,1,1,1,1,1,1,1,1
1,1,1,1,1,1,1,1,1,1,1,1,1,1,1,1,1,1,1,1,1,1,1,1,1,1,1,1,1,1,1
1,1,1,1,1,1,1,1,1,1,1,1,1,1,1,1,1,1,1,1,1,1,1,1,1,1,1,1,1,1,1
1,1,1,1,1,1,1,1,1,1,1,1,1,1,1,1,1,1,1,1,1,1,1,1,1,1,1,1,1,1,1
1,1,1,1,1,1,1,1,1,1,1,1,1,1,1,1,1,1,1,1,1,1,1,1,1,1,1,1,1,1,1
1,1,1,1,1,1,1,1,1,1,1,1,1,15,15,15,1,1,1,1,1,1,1,1,1,1,1,1,1,1,1
1,1,1,1,1,1,1,1,1,1,1,1,1,1,1,1,1,1,1,1,1,1,1,1,1,1,1,1,1,1,1
1,1,1,1,1,1,1,1,1,1,1,1,1,1,1,1,1,1,1,1,1,1,1,1,1,1,1,1,1,1,1
1,1,1,1,1,1,1,1,1,1,1,1,1,1,1,1,1,1,1,1,1,1,1,1,1,1,1,1,1,1,1
1,1,1,1,1,1,1,1,1,1,1,1,1,1,1,1,1,1,1,1,1,1,1,1,1,1,1,1,1,1,1
1,1,1,1,1,1,1,1,1,1,1,1,1,1,1,1,1,1,1,1,1,1,1,1,1,1,1,1,1,1,1
1,1,1,1,1,1,1,1,1,1,1,1,8,0,0,0,0,1,1,1,1,1,1,1,1,1,1,1,1,1,1
1,1,1,1,1,1,1,1,1,1,1,1,21,0,0,0,0,1,1,1,1,1,1,1,1,1,1,1,1,1,1
1,1,1,1,1,1,19,1,1,1,1,1,1,0,0,0,0,1,1,1,1,1,1,1,1,1,1,1,1,1,1
1,1,1,1,1,1,19,1,1,1,1,1,1,0,0,0,0,1,15,1,1,1,1,1,15,1,1,1,1,1,1
1,1,1,1,1,1,20,1,1,1,1,1,1,0,0,0,0,1,15,1,1,1,1,1,15,1,1,1,1,1,1
1,1,1,1,1,1,1,1,1,1,1,1,1,0,0,0,0,1,15,1,1,1,1,1,15,1,1,1,1,1,1
1,1,1,1,1,1,1,1,1,1,1,1,1,1,1,1,1,1,1,1,1,1,1,1,1,1,1,1,1,1,1
1,1,1,1,1,1,1,1,1,1,1,1,1,1,1,1,1,1,1,1,1,1,1,1,1,1,1,1,1,1,1
1,1,1,1,1,1,1,1,1,1,1,1,1,1,1,1,1,1,1,1,1,1,1,1,1,1,1,1,1,1,1
1,1,1,1,1,1,1,1,1,1,1,1,1,1,1,1,1,1,1,1,1,1,1,1,1,1,1,1,1,1,1
1,1,1,1,1,1,1,1,1,1,1,1,1,1,1,1,1,1,1,1,1,1,1,1,1,1,1,1,1,1,1
1,1,1,1,1,1,1,1,1,1,1,1,1,1,1,1,1,1,1,1,1,1,1,1,1,1,1,1,1,1,1
1,1,1,1,1,1,1,1,1,1,1,1,1,19,19,19,1,1,1,1,1,1,1,1,1,1,1,1,1,1,1
1,1,1,1,1,1,1,1,1,1,1,1,1,1,1,1,1,1,1,1,1,1,1,1,1,1,1,1,1,1,1
1,1,1,1,1,1,1,1,1,1,1,1,1,1,1,1,1,1,1,1,1,1,1,1,1,1,1,1,1,1,1
1,1,1,1,1,1,1,1,1,1,1,1,1,1,1,1,1,1,1,1,1,1,1,1,1,1,1,1,1,1,1
1,1,1,1,1,1,1,1,1,1,1,1,1,1,1,1,1,1,1,1,1,1,1,1,1,1,1,1,1,1,1
1,1,1,1,1,1,1,1,1,1,1,1,1,1,1,1,1,1,1,1,1,1,1,1,1,1,1,1,1,1,1
1,1,1,1,1,1,1,1,1,1,1,1,1,1,1,1,1,1,1,1,1,1,1,1,1,1,1,1,1,1,1
endlayer

layer
1,1,1,1,1,1,1,1,1,1,1,1,1,1,1,1,1,1,1,1,1,1,1,1,1,1,1,1,1,1,1
1,1,1,1,1,1,1,1,1,1,1,1,1,1,1,1,1,1,1,1,1,1,1,1,1,1,1,1,1,1,1
1,1,1,1,1,1,1,1,1,1,1,1,1,1,1,1,1,1,1,1,1,1,1,1,1,1,1,1,1,1,1
1,1,1,1,1,1,1,1,1,1,1,1,1,1,1,1,1,1,1,1,1,1,1,1,1,1,1,1,1,1,1
1,1,1,1,1,1,1,1,1,1,1,1,1,1,1,1,1,1,1,1,1,1,1,1,1,1,1,1,1,1,1
1,1,1,1,1,1,1,1,1,1,1,1,1,1,1,1,1,1,1,1,1,1,1,1,1,1,1,1,1,1,1
1,1,1,1,1,1,1,1,1,1,1,1,1,15,15,15,1,1,1,1,1,1,1,1,1,1,1,1,1,1,1
1,1,1,1,1,1,1,1,1,1,1,1,1,1,1,1,1,1,1,1,1,1,1,1,1,1,1,1,1,1,1
1,1,1,1,1,1,1,1,1,1,1,1,1,1,1,1,1,1,1,1,1,1,1,1,1,1,1,1,1,1,1
1,1,1,1,1,1,1,1,1,1,1,1,1,1,1,1,1,1,1,1,1,1,1,1,1,1,1,1,1,1,1
1,1,1,1,1,1,1,1,1,1,1,1,1,1,1,1,1,1,1,1,1,1,1,1,1,1,1,1,1,1,1
1,1,1,1,1,1,1,1,1,1,1,1,1,1,1,1,1,1,1,1,1,1,1,1,1,1,1,1,1,1,1
1,1,1,1,1,1,1,1,1,1,1,1,0,0,0,0,0,1,1,1,1,1,1,1,1,1,1,1,1,1,1
1,1,1,1,1,1,1,1,1,1,1,1,0,0,0,0,0,1,1,1,1,1,1,1,1,1,1,1,1,1,1
1,1,1,1,1,1,19,1,1,1,1,1,21,0,0,0,0,1,1,1,1,1,1,1,1,1,1,1,1,1,1
1,1,1,1,1,1,19,1,1,1,1,1,1,0,0,0,0,1,15,1,1,1,1,1,15,1,1,1,1,1,1
1,1,1,1,1,1,20,1,1,1,1,1,1,0,0,0,0,1,15,1,1,1,1,1,15,1,1,1,1,1,1
1,1,1,1,1,1,1,1,1,1,1,1,1,0,0,0,0,1,15,1,1,1,1,1,15,1,1,1,1,1,1
1,1,1,1,1,1,1,1,1,1,1,1,1,1,1,1,1,1,1,1,1,1,1,1,1,1,1,1,1,1,1
1,1,1,1,1,1,1,1,1,1,1,1,1,1,1,1,1,1,1,1,1,1,1,1,1,1,1,1,1,1,1
1,1,1,1,1,1,1,1,1,1,1,1,1,1,1,1,1,1,1,1,1,1,1,1,1,1,1,1,1,1,1
1,1,1,1,1,1,1,1,1,1,1,1,1,1,1,1,1,1,1,1,1,1,1,1,1,1,1,1,1,1,1
1,1,1,1,1,1,1,1,1,1,1,1,1,1,1,1,1,1,1,1,1,1,1,1,1,1,1,1,1,1,1
1,1,1,1,1,1,1,1,1,1,1,1,1,1,1,1,1,1,1,1,1,1,1,1,1,1,1,1,1,1,1
1,1,1,1,1,1,1,1,1,1,1,1,1,19,19,19,1,1,1,1,1,1,1,1,1,1,1,1,1,1,1
1,1,1,1,1,1,1,1,1,1,1,1,1,1,1,1,1,1,1,1,1,1,1,1,1,1,1,1,1,1,1
1,1,1,1,1,1,1,1,1,1,1,1,1,1,1,1,1,1,1,1,1,1,1,1,1,1,1,1,1,1,1
1,1,1,1,1,1,1,1,1,1,1,1,1,1,1,1,1,1,1,1,1,1,1,1,1,1,1,1,1,1,1
1,1,1,1,1,1,1,1,1,1,1,1,1,1,1,1,1,1,1,1,1,1,1,1,1,1,1,1,1,1,1
1,1,1,1,1,1,1,1,1,1,1,1,1,1,1,1,1,1,1,1,1,1,1,1,1,1,1,1,1,1,1
1,1,1,1,1,1,1,1,1,1,1,1,1,1,1,1,1,1,1,1,1,1,1,1,1,1,1,1,1,1,1
endlayer

layer
1,1,1,1,1,1,1,1,1,1,1,1,1,1,1,1,1,1,1,1,1,1,1,1,1,1,1,1,1,1,1
1,1,1,1,1,1,1,1,1,1,1,1,1,1,1,1,1,1,1,1,1,1,1,1,1,1,1,1,1,1,1
1,1,1,1,1,1,1,1,1,1,1,1,1,1,1,1,1,1,1,1,1,1,1,1,1,1,1,1,1,1,1
1,1,1,1,1,1,1,1,1,1,1,1,1,1,1,1,1,1,1,1,1,1,1,1,1,1,1,1,1,1,1
1,1,1,1,1,1,1,1,1,1,1,1,1,1,1,1,1,1,1,1,1,1,1,1,1,1,1,1,1,1,1
1,1,1,1,1,1,1,1,1,1,1,1,1,1,1,1,1,1,1,1,1,1,1,1,1,1,1,1,1,1,1
1,1,1,1,1,1,1,1,1,1,1,1,1,15,15,15,1,1,1,1,1,1,1,1,1,1,1,1,1,1,1
1,1,1,1,1,1,1,1,1,1,1,1,1,1,1,1,1,1,1,1,1,1,1,1,1,1,1,1,1,1,1
1,1,1,1,1,1,1,1,1,1,1,1,1,1,1,1,1,1,1,1,1,1,1,1,1,1,1,1,1,1,1
1,1,1,1,1,1,1,1,1,1,1,1,1,1,1,1,1,1,1,1,1,1,1,1,1,1,1,1,1,1,1
1,1,1,1,1,1,1,1,1,1,1,1,1,1,1,1,1,1,1,1,1,1,1,1,1,1,1,1,1,1,1
1,1,1,1,1,1,1,1,1,1,1,1,1,1,1,1,1,1,1,1,1,1,1,1,1,1,1,1,1,1,1
1,1,1,1,1,1,1,1,1,1,1,1,0,0,0,0,13,1,1,1,1,1,1,1,1,1,1,1,1,1,1
1,1,1,1,1,1,1,1,1,1,1,1,0,0,0,0,0,1,1,1,1,1,1,1,1,1,1,1,1,1,1
1,1,1,1,1,1,19,1,1,1,1,1,0,0,0,0,0,1,1,1,1,1,1,1,1,1,1,1,1,1,1
1,1,1,1,1,1,19,1,1,1,1,1,21,0,0,0,0,1,15,1,1,1,1,1,15,1,1,1,1,1,1
1,1,1,1,1,1,20,1,1,1,1,1,1,0,0,0,0,1,15,1,1,1,1,1,15,1,1,1,1,1,1
1,1,1,1,1,1,1,1,1,1,1,1,1,14,0,0,0,1,15,1,1,1,1,1,15,1,1,1,1,1,1
1,1,1,1,1,1,1,1,1,1,1,1,1,1,1,1,1,1,1,1,1,1,1,1,1,1,1,1,1,1,1
1,1,1,1,1,1,1,1,1,1,1,1,1,1,1,1,1,1,1,1,1,1,1,1,1,1,1,1,1,1,1
1,1,1,1,1,1,1,1,1,1,1,1,1,1,1,1,1,1,1,1,1,1,1,1,1,1,1,1,1,1,1
1,1,1,1,1,1,1,1,1,1,1,1,1,1,1,1,1,1,1,1,1,1,1,1,1,1,1,1,1,1,1
1,1,1,1,1,1,1,1,1,1,1,1,1,1,1,1,1,1,1,1,1,1,1,1,1,1,1,1,1,1,1
1,1,1,1,1,1,1,1,1,1,1,1,1,1,1,1,1,1,1,1,1,1,1,1,1,1,1,1,1,1,1
1,1,1,1,1,1,1,1,1,1,1,1,1,22,22,22,1,1,1,1,1,1,1,1,1,1,1,1,1,1,1
1,1,1,1,1,1,1,1,1,1,1,1,1,1,1,1,1,1,1,1,1,1,1,1,1,1,1,1,1,1,1
1,1,1,1,1,1,1,1,1,1,1,1,1,1,1,1,1,1,1,1,1,1,1,1,1,1,1,1,1,1,1
1,1,1,1,1,1,1,1,1,1,1,1,1,1,1,1,1,1,1,1,1,1,1,1,1,1,1,1,1,1,1
1,1,1,1,1,1,1,1,1,1,1,1,1,1,1,1,1,1,1,1,1,1,1,1,1,1,1,1,1,1,1
1,1,1,1,1,1,1,1,1,1,1,1,1,1,1,1,1,1,1,1,1,1,1,1,1,1,1,1,1,1,1
1,1,1,1,1,1,1,1,1,1,1,1,1,1,1,1,1,1,1,1,1,1,1,1,1,1,1,1,1,1,1
endlayer

layer
1,1,1,1,1,1,1,1,1,1,1,1,1,1,1,1,1,1,1,1,1,1,1,1,1,1,1,1,1,1,1
1,1,1,1,1,1,1,1,1,1,1,1,1,1,1,1,1,1,1,1,1,1,1,1,1,1,1,1,1,1,1
1,1,1,1,1,1,1,1,1,1,1,1,1,1,1,1,1,1,1,1,1,1,1,1,1,1,1,1,1,1,1
1,1,1,1,1,1,1,1,1,1,1,1,1,1,1,1,1,1,1,1,1,1,1,1,1,1,1,1,1,1,1
1,1,1,1,1,1,1,1,1,1,1,1,1,1,1,1,1,1,1,1,1,1,1,1,1,1,1,1,1,1,1
1,1,1,1,1,1,1,1,23,1,1,1,1,1,1,1,1,1,1,1,1,1,1,1,1,1,1,1,1,1,1
1,1,1,1,1,1,1,1,1,1,1,1,1,1,1,1,1,1,1,1,1,1,1,1,1,1,1,1,1,1,1
1,1,1,1,1,1,1,1,1,1,1,1,1,1,1,1,1,1,1,1,1,1,1,1,1,1,1,1,1,1,1
1,1,1,1,1,1,1,1,1,1,1,1,1,1,1,1,23,23,23,23,23,23,23,23,23,23,23,1,1,1,1
1,1,1,1,1,1,1,1,1,1,1,1,1,1,1,23,23,23,23,23,23,23,23,23,23,23,23,1,1,1,1
1,1,1,1,1,1,1,1,1,1,1,1,1,1,1,0,23,23,23,23,23,23,23,23,23,23,23,1,1,1,1
1,1,1,1,1,1,1,1,1,1,1,1,1,1,1,1,23,23,23,23,23,23,23,23,23,23,23,1,1,1,1
1,1,1,1,1,1,1,1,1,1,1,1,0,1,1,1,23,23,23,23,23,23,23,23,23,23,23,1,1,1,1
1,1,1,1,1,1,1,1,1,1,1,1,0,1,1,1,23,23,23,23,23,23,23,23,23,23,23,1,1,1,1
1,1,1,1,1,1,19,1,1,1,1,1,0,1,1,1,23,23,23,23,23,23,23,23,23,23,23,1,1,1,1
1,1,1,1,1,1,19,1,1,1,1,1,0,1,1,1,23,23,23,23,23,23,23,23,23,23,23,1,1,1,1
1,1,1,1,1,1,20,1,1,1,1,1,21,1,1,1,23,23,23,23,23,23,23,23,23,23,1,1,1,1,1
1,1,1,1,1,1,1,1,1,1,1,1,1,1,1,1,1,1,1,1,1,1,1,1,1,1,1,1,1,1,1
1,1,1,1,1,1,1,1,1,1,1,1,1,1,1,1,1,1,1,1,1,1,1,1,1,1,1,1,1,1,1
1,1,1,1,1,1,1,1,1,1,1,1,1,1,1,1,1,1,1,1,1,1,1,1,1,1,1,1,1,1,1
1,1,1,1,1,1,1,1,1,1,1,1,1,1,1,1,1,1,1,1,1,1,1,1,1,1,1,1,1,1,1
1,1,1,1,1,1,1,1,1,1,1,1,1,1,1,1,1,1,1,1,1,1,1,1,1,1,1,1,1,1,1
1,1,1,1,1,1,1,1,1,1,1,1,1,1,1,1,1,1,1,1,1,1,1,1,1,1,1,1,1,1,1
1,1,1,1,1,1,1,1,1,1,1,1,1,1,1,1,1,1,1,1,1,1,1,1,1,1,1,1,1,1,1
1,1,1,1,1,1,1,1,1,1,1,1,1,1,24,1,1,1,1,1,1,1,1,1,1,1,1,1,1,1,1
1,1,1,1,1,1,1,1,1,1,1,1,1,1,1,1,1,1,1,1,1,1,1,1,1,1,1,1,1,1,1
1,1,1,1,1,1,1,1,1,1,1,1,1,1,1,1,1,1,1,1,1,1,1,1,1,1,1,1,1,1,1
1,1,1,1,1,1,1,1,1,1,1,1,1,1,1,1,1,1,1,1,1,1,1,1,1,1,1,1,1,1,1
1,1,1,1,1,1,1,1,1,1,1,1,1,1,1,1,1,1,1,1,1,1,1,1,1,1,1,1,1,1,1
1,1,1,1,1,1,1,1,1,1,1,1,1,1,1,1,1,1,1,1,1,1,1,1,1,1,1,1,1,1,1
1,1,1,1,1,1,1,1,1,1,1,1,1,1,1,1,1,1,1,1,1,1,1,1,1,1,1,1,1,1,1
endlayer

layer
1,1,1,1,1,1,1,1,1,23,0,0,0,23,1,1,1,1,1,1,1,1,1,1,1,1,1,1,1,1,1
1,1,1,1,1,1,1,1,1,25,0,0,0,23,1,1,1,1,1,1,1,1,1,1,1,1,1,1,1,1,1
1,1,1,1,1,1,1,1,1,23,2,0,2,23,1,1,1,1,1,1,1,1,1,1,1,1,1,1,1,1,1
1,1,1,1,1,1,1,1,1,25,0,3,0,23,1,1,1,1,1,1,1,1,1,1,1,1,1,1,1,1,1
1,1,1,1,1,1,1,1,0,23,0,3,0,26,1,1,1,1,1,1,1,1,1,1,1,1,1,1,1,1,1
1,1,1,1,1,1,1,1,23,28,23,27,16,0,23,1,1,1,1,1,1,1,1,1,1,1,1,1,1,1,1
23,23,23,23,23,23,23,23,23,23,0,0,3,0,23,1,1,1,1,1,1,1,1,1,1,1,1,1,1,1,1
0,0,0,2,0,0,0,0,0,2,0,0,3,0,23,1,1,1,1,1,1,1,1,1,1,1,1,1,1,1,1
7,7,7,7,7,7,7,7,7,7,7,7,16,0,23,1,23,23,23,23,23,23,23,23,23,23,23,1,1,1,1
0,0,0,2,0,0,0,0,0,2,0,0,3,0,23,23,0,0,0,0,0,0,0,0,0,29,23,1,1,1,1
23,23,23,23,23,23,23,23,23,23,23,23,27,16,0,26,0,0,0,0,0,0,0,0,0,0,23,1,1,1,1
1,1,1,1,1,1,1,1,1,1,1,23,2,3,2,25,0,0,0,0,0,0,0,0,0,0,23,1,1,1,1
1,1,1,1,1,1,1,1,1,1,1,25,0,3,0,23,0,0,0,0,0,0,0,0,0,0,23,1,1,1,1
1,1,1,1,1,1,1,1,1,1,1,25,0,3,0,23,0,0,0,0,0,0,0,0,0,0,23,1,1,1,1
1,1,1,1,1,1,19,1,1,1,1,25,0,3,0,25,0,0,0,0,0,0,0,0,0,0,23,1,1,1,1
1,1,1,1,1,1,19,1,1,1,1,23,0,3,0,23,0,0,0,0,0,0,0,0,0,0,25,4,5,0,26
1,1,1,1,1,1,20,1,1,1,1,23,0,0,0,0,23,23,23,23,26,23,23,26,23,25,0,0,3,0,26
1,1,1,1,1,1,1,1,1,1,1,23,30,4,0,0,2,0,0,0,0,0,4,2,0,0,0,0,3,0,25
1,1,1,1,1,1,1,1,1,1,1,25,27,7,7,7,7,7,7,7,7,7,31,31,31,7,7,7,6,0,25
1,1,1,1,1,1,1,1,1,1,1,26,2,0,2,23,2,0,0,0,0,0,0,2,0,0,0,0,0,0,23
1,1,1,1,1,1,1,1,1,1,1,23,0,3,0,25,23,23,23,23,25,23,23,23,23,26,23,23,23,23,1
1,1,1,1,1,1,0,0,0,0,32,26,0,3,0,23,1,1,1,1,1,1,1,1,1,1,1,1,1,1,1
1,1,1,1,1,1,0,0,0,0,0,23,0,3,0,23,1,1,1,1,1,1,1,1,1,1,1,1,1,1,1
1,1,1,1,1,1,0,0,0,0,0,0,0,3,0,26,1,1,1,1,1,1,1,1,1,1,1,1,1,1,1
1,1,1,1,1,1,0,0,0,0,0,25,0,3,0,23,1,1,1,1,1,1,1,1,1,1,1,1,1,1,1
1,1,1,1,1,1,0,0,0,0,32,26,2,3,2,23,1,1,1,1,1,1,1,1,1,1,1,1,1,1,1
1,1,1,1,1,1,1,1,1,1,1,23,0,3,0,26,1,1,1,1,1,1,1,1,1,1,1,1,1,1,1
1,1,1,1,1,1,1,1,1,1,1,26,0,0,0,23,1,1,1,1,1,1,1,1,1,1,1,1,1,1,1
1,1,1,1,1,1,1,1,1,1,1,25,0,0,0,23,1,1,1,1,1,1,1,1,1,1,1,1,1,1,1
1,1,1,1,1,1,1,1,1,1,1,25,0,0,0,25,1,1,1,1,1,1,1,1,1,1,1,1,1,1,1
1,1,1,1,1,1,1,1,1,1,1,26,2,15,2,25,1,1,1,1,1,1,1,1,1,1,1,1,1,1,1
endlayer

layer
1,1,1,1,1,1,1,1,1,23,0,0,0,26,1,1,1,1,1,1,1,1,1,1,1,1,1,1,1,1,1
1,1,1,1,1,1,1,1,1,23,0,0,0,26,1,1,1,1,1,1,1,1,1,1,1,1,1,1,1,1,1
1,1,1,1,1,1,1,1,1,23,2,0,2,26,1,1,1,1,1,1,1,1,1,1,1,1,1,1,1,1,1
1,1,1,1,1,1,1,1,1,23,0,0,0,23,1,1,1,1,1,1,1,1,1,1,1,1,1,1,1,1,1
1,1,1,1,1,1,1,1,0,23,0,0,0,23,1,1,1,1,1,1,1,1,1,1,1,1,1,1,1,1,1
1,1,1,1,1,1,1,1,23,28,26,0,0,0,26,1,1,1,1,1,1,1,1,1,1,1,1,1,1,1,1
23,23,23,23,23,23,23,23,23,23,0,0,0,0,23,1,1,1,1,1,1,1,1,1,1,1,1,1,1,1,1
0,0,0,2,0,0,0,0,0,2,0,0,0,0,23,1,1,1,1,1,1,1,1,1,1,1,1,1,1,1,1
0,0,0,0,0,0,0,0,0,0,0,0,0,0,26,1,23,23,23,23,23,23,23,23,23,23,23,1,1,1,1
0,0,0,2,0,0,0,0,0,2,0,0,0,0,25,23,0,0,0,0,0,0,0,0,0,0,23,1,1,1,1
23,23,23,23,23,23,23,23,23,23,23,23,0,0,0,23,0,0,0,0,0,0,0,0,0,0,23,1,1,1,1
1,1,1,1,1,1,1,1,1,1,1,25,2,0,2,23,0,0,0,0,0,0,0,0,0,0,23,1,1,1,1
1,1,1,1,1,1,1,1,1,1,1,23,0,0,0,23,0,0,0,0,0,0,0,0,0,0,23,0,5,0,23
1,1,1,1,1,1,1,1,1,1,1,23,0,0,0,26,0,0,0,0,0,0,0,0,0,0,23,0,30,0,23
1,1,1,1,1,1,19,1,1,1,1,26,0,0,0,23,0,0,0,0,0,0,0,0,0,0,23,2,30,2,23
1,1,1,1,1,1,19,1,1,1,1,23,0,0,0,23,0,0,0,0,0,0,0,0,0,0,23,0,0,0,23
1,1,1,1,1,1,20,1,1,1,1,26,0,0,0,0,26,23,23,26,26,23,0,23,25,23,0,0,0,0,23
1,1,1,1,1,1,1,1,1,1,1,23,0,0,0,0,2,0,0,0,0,0,0,2,0,0,0,0,0,0,23
1,1,1,1,1,1,1,1,1,1,1,23,0,0,0,0,0,0,0,0,0,0,0,0,0,0,0,0,0,0,23
1,1,1,1,1,1,1,1,1,1,1,25,2,0,2,25,2,0,0,0,0,0,0,2,0,0,0,0,0,0,23
1,1,1,1,1,1,1,1,1,1,1,23,0,0,0,25,25,23,23,23,23,25,23,23,23,23,26,23,23,23,1
1,1,1,1,1,1,0,0,0,0,0,23,0,0,0,23,1,1,1,1,1,1,1,1,1,1,1,1,1,1,1
1,1,1,1,1,1,0,0,0,0,0,26,0,0,0,23,1,1,1,1,1,1,1,1,1,1,1,1,1,1,1
1,1,1,1,1,1,0,0,0,0,0,25,0,0,0,26,1,1,1,1,1,1,1,1,1,1,1,1,1,1,1
1,1,1,1,1,1,0,0,0,0,0,23,0,0,0,26,1,1,1,1,1,1,1,1,1,1,1,1,1,1,1
1,1,1,1,1,1,0,0,0,0,0,23,2,0,2,25,1,1,1,1,1,1,1,1,1,1,1,1,1,1,1
1,1,1,1,1,1,1,1,1,1,1,25,0,0,0,25,1,1,1,1,1,1,1,1,1,1,1,1,1,1,1
1,1,1,1,1,1,1,1,1,1,1,23,0,0,0,23,1,1,1,1,1,1,1,1,1,1,1,1,1,1,1
1,1,1,1,1,1,1,1,1,1,1,23,0,0,0,23,1,1,1,1,1,1,1,1,1,1,1,1,1,1,1
1,1,1,1,1,1,1,1,1,1,1,23,0,0,0,26,1,1,1,1,1,1,1,1,1,1,1,1,1,1,1
1,1,1,1,1,1,1,1,1,1,1,23,10,10,2,26,1,1,1,1,1,1,1,1,1,1,1,1,1,1,1
endlayer

layer
1,1,1,1,1,1,1,1,1,23,0,0,0,23,1,1,1,1,1,1,1,1,1,1,1,1,1,1,1,1,1
1,1,1,1,1,1,1,1,1,23,0,14,0,23,1,1,1,1,1,1,1,1,1,1,1,1,1,1,1,1,1
1,1,1,1,1,1,1,1,1,23,10,10,10,23,1,1,1,1,1,1,1,1,1,1,1,1,1,1,1,1,1
1,1,1,1,1,1,1,1,1,23,0,0,0,23,1,1,1,1,1,1,1,1,1,1,1,1,1,1,1,1,1
1,1,1,1,1,1,1,1,0,23,0,0,0,23,1,1,1,1,1,1,1,1,1,1,1,1,1,1,1,1,1
1,1,1,1,1,1,1,1,23,28,23,0,0,0,23,1,1,1,1,1,1,1,1,1,1,1,1,1,1,1,1
23,23,23,23,23,23,23,23,23,23,0,0,0,0,23,1,1,1,1,1,1,1,1,1,1,1,1,1,1,1,1
0,0,0,10,0,0,0,0,0,10,0,0,0,0,23,1,1,1,1,1,1,1,1,1,1,1,1,1,1,1,1
0,0,13,10,0,0,0,0,13,10,12,0,0,0,23,0,23,23,23,23,23,23,23,23,23,23,1,1,1,1,1
0,0,0,10,0,0,0,0,0,10,0,0,0,0,23,23,0,0,0,0,0,0,0,0,0,0,23,0,5,0,23
23,23,23,23,23,23,23,23,23,23,23,26,0,0,0,23,0,0,0,0,0,0,0,0,0,0,23,0,30,0,23
1,1,1,1,1,1,1,1,1,1,1,23,10,10,10,23,0,0,0,0,0,0,0,0,0,0,23,2,30,2,23
1,1,1,1,1,1,1,1,1,1,1,25,0,11,0,23,0,0,0,0,0,0,0,0,0,0,23,0,0,0,23
1,1,1,1,1,1,1,1,1,1,1,23,0,0,0,23,0,0,0,0,0,0,0,0,0,0,23,0,0,0,23
1,1,1,1,1,1,22,1,1,1,1,23,0,0,0,23,0,0,0,0,0,0,0,0,0,0,23,2,0,2,23
1,1,1,1,1,1,22,1,1,1,1,23,0,0,0,23,0,0,0,0,0,0,0,0,0,0,23,0,0,0,23
1,1,1,1,1,1,33,1,1,1,1,25,0,0,0,0,23,23,23,23,23,23,0,0,23,23,0,0,0,0,25
1,1,1,1,1,1,1,1,1,1,1,23,0,0,0,0,10,0,0,0,0,0,0,10,0,0,0,0,0,0,23
1,1,1,1,1,1,1,1,1,1,1,23,0,0,0,0,10,12,0,0,0,0,0,10,12,0,0,0,0,0,23
1,1,1,1,1,1,1,1,1,1,1,23,10,10,10,23,10,0,0,0,0,0,0,10,0,0,0,0,0,14,26
1,1,1,1,1,1,1,1,1,1,1,25,0,11,0,26,23,26,23,23,23,23,23,23,25,23,23,23,23,26,1
1,1,1,1,1,1,0,0,0,0,0,23,0,0,0,26,1,1,1,1,1,1,1,1,1,1,1,1,1,1,1
1,1,1,1,1,1,0,0,0,0,0,23,0,0,0,25,1,1,1,1,1,1,1,1,1,1,1,1,1,1,1
1,1,1,1,1,1,0,0,0,0,0,23,0,0,0,25,1,1,1,1,1,1,1,1,1,1,1,1,1,1,1
1,1,1,1,1,1,0,0,0,0,0,23,0,0,0,23,1,1,1,1,1,1,1,1,1,1,1,1,1,1,1
1,1,1,1,1,1,0,0,0,0,0,23,10,10,10,23,1,1,1,1,1,1,1,1,1,1,1,1,1,1,1
1,1,1,1,1,1,1,1,1,1,1,23,0,11,0,26,1,1,1,1,1,1,1,1,1,1,1,1,1,1,1
1,1,1,1,1,1,1,1,1,1,1,23,0,0,0,26,1,1,1,1,1,1,1,1,1,1,1,1,1,1,1
1,1,1,1,1,1,1,1,1,1,1,23,0,0,0,25,1,1,1,1,1,1,1,1,1,1,1,1,1,1,1
1,1,1,1,1,1,1,1,1,1,1,26,0,0,0,25,1,1,1,1,1,1,1,1,1,1,1,1,1,1,1
1,1,1,1,1,1,1,1,1,1,1,25,23,23,10,23,1,1,1,1,1,1,1,1,1,1,1,1,1,1,1
endlayer

layer
1,1,1,1,1,1,1,1,1,23,23,23,23,23,1,1,1,1,1,1,1,1,1,1,1,1,1,1,1,1,1
1,1,1,1,1,1,1,1,1,23,23,23,23,23,1,1,1,1,1,1,1,1,1,1,1,1,1,1,1,1,1
1,1,1,1,1,1,1,1,1,23,34,34,34,23,1,1,1,1,1,1,1,1,1,1,1,1,1,1,1,1,1
1,1,1,1,1,1,1,1,1,23,23,25,23,23,1,1,1,1,1,1,1,1,1,1,1,1,23,23,23,23,1
1,1,1,1,1,1,1,1,0,23,23,23,23,23,1,1,1,1,1,1,1,1,1,1,1,1,0,0,0,0,23
1,1,1,1,1,1,1,1,23,28,23,23,23,23,23,1,1,1,1,1,1,1,1,1,1,1,0,0,0,0,23
1,1,1,1,1,1,1,1,23,23,23,25,23,26,23,1,1,1,1,1,1,1,1,1,1,1,17,7,16,0,23
23,23,23,23,23,23,23,23,23,34,23,23,23,23,23,1,1,1,1,1,1,1,1,1,1,1,4,0,30,0,23
23,23,23,23,23,23,23,23,23,34,23,23,23,23,23,0,23,23,23,23,23,23,23,23,23,23,23,2,30,2,23
23,23,23,23,23,23,23,23,23,34,23,26,23,25,23,23,0,0,0,0,0,0,0,0,0,0,23,0,0,0,23
1,1,1,1,1,1,1,1,23,23,23,23,23,23,23,23,0,0,0,0,0,0,0,0,0,0,23,0,0,0,23
1,1,1,1,1,1,1,1,0,0,0,23,34,34,34,23,0,0,0,0,0,0,0,0,0,0,23,2,0,2,23
1,1,1,1,1,1,1,1,1,1,1,23,25,23,23,23,0,0,0,0,0,0,0,0,0,0,23,0,0,0,23
1,1,1,1,1,1,1,1,1,1,1,26,23,23,26,23,0,0,0,0,0,0,0,0,0,0,23,0,14,0,23
1,1,1,1,1,1,1,1,1,1,1,23,23,23,25,23,0,0,0,0,0,0,0,0,0,0,23,10,10,10,23
1,1,1,1,1,1,1,1,1,1,1,23,23,23,23,23,0,0,0,0,0,0,0,0,0,0,23,0,0,0,23
1,1,1,1,1,1,1,1,1,1,1,23,26,23,23,26,0,0,0,0,0,0,0,0,23,23,23,23,23,23,23
1,1,1,1,1,1,1,1,1,1,1,23,23,23,26,23,23,26,23,23,23,23,0,0,25,23,23,23,23,23,23
1,1,1,1,1,1,1,1,1,1,1,25,25,25,25,25,25,23,23,23,25,23,23,0,25,23,23,23,23,25,23
1,1,1,1,1,1,1,1,1,1,1,26,34,34,34,26,26,23,23,23,23,23,23,0,25,23,25,23,26,23,1
1,1,1,1,1,1,1,1,1,1,1,23,23,23,23,23,23,23,23,23,23,23,23,23,23,23,23,23,23,1,1
1,1,1,1,1,1,1,1,1,1,1,23,23,23,23,23,1,1,1,1,1,1,1,1,1,1,1,1,1,1,1
1,1,1,1,1,1,1,1,1,1,1,23,23,23,23,23,1,1,1,1,1,1,1,1,1,1,1,1,1,1,1
1,1,1,1,1,1,1,1,1,1,1,23,23,23,23,23,1,1,1,1,1,1,1,1,1,1,1,1,1,1,1
1,1,1,1,1,1,1,1,1,1,1,26,26,26,26,26,1,1,1,1,1,1,1,1,1,1,1,1,1,1,1
1,1,1,1,1,1,1,1,1,1,1,26,34,34,34,26,1,1,1,1,1,1,1,1,1,1,1,1,1,1,1
1,1,1,1,1,1,1,1,1,1,1,25,25,25,25,25,1,1,1,1,1,1,1,1,1,1,1,1,1,1,1
1,1,1,1,1,1,1,1,1,1,1,23,23,23,23,23,1,1,1,1,1,1,1,1,1,1,1,1,1,1,1
1,1,1,1,1,1,1,1,1,1,1,23,23,23,23,23,1,1,1,1,1,1,1,1,1,1,1,1,1,1,1
1,1,1,1,1,1,1,1,1,1,1,23,23,23,23,23,1,1,1,1,1,1,1,1,1,1,1,1,1,1,1
1,1,1,1,1,1,1,1,1,1,1,23,23,23,23,23,1,1,1,1,1,1,1,1,1,1,1,1,1,1,1
endlayer

layer
1,1,1,1,1,1,1,1,1,1,1,1,1,1,1,1,1,1,1,1,1,1,1,1,1,1,1,1,1,1,1
1,1,1,1,1,1,1,1,1,1,1,1,1,1,1,1,1,1,1,1,1,1,1,1,1,1,1,1,1,1,1
1,1,1,1,1,1,1,1,1,1,34,34,34,1,1,1,1,1,1,1,1,1,1,1,1,1,1,1,1,1,1
1,1,1,1,1,1,1,1,1,1,1,1,1,1,1,1,1,1,1,1,1,1,1,23,23,23,23,23,23,23,1
1,1,1,1,1,1,1,1,0,23,1,1,1,1,1,1,1,1,1,1,1,1,1,0,0,2,0,0,0,0,23
1,1,1,1,1,1,1,1,23,28,23,1,1,1,1,1,1,1,1,1,1,1,1,0,0,0,0,0,0,0,23
1,1,1,1,1,1,1,1,1,23,1,1,1,1,1,1,1,1,1,1,1,1,1,17,31,31,0,0,0,0,23
1,1,1,1,1,1,1,1,1,34,1,1,1,1,1,1,1,1,1,1,1,1,1,0,0,2,0,0,0,0,23
1,1,1,1,1,1,1,1,1,34,1,1,1,1,1,1,23,23,23,23,23,23,23,23,23,23,23,2,0,2,23
1,1,1,1,1,1,1,1,1,34,1,1,1,1,1,23,0,0,0,0,0,0,0,0,0,0,23,0,0,0,23
1,1,1,1,1,1,1,1,1,1,1,1,1,1,1,23,0,0,0,0,0,0,0,0,0,0,23,0,14,0,23
1,1,1,1,1,1,1,1,1,1,1,1,34,34,34,23,0,0,0,0,0,0,0,0,0,0,23,10,10,10,23
1,1,1,1,1,1,1,1,1,1,1,1,1,1,1,23,0,0,0,0,0,0,0,0,0,0,23,23,23,23,23
1,1,1,1,1,1,1,1,1,1,1,1,1,1,1,23,0,0,0,0,0,0,0,0,0,0,23,23,23,23,23
1,1,1,1,1,1,1,1,1,1,1,1,1,1,1,23,0,0,0,0,0,0,0,0,0,0,23,15,15,15,23
1,1,1,1,1,1,1,1,1,1,1,1,1,1,1,23,0,0,0,0,0,0,0,0,0,0,23,23,23,23,23
1,1,1,1,1,1,1,1,1,1,1,1,1,1,1,23,0,0,0,0,0,0,0,0,23,23,23,1,1,1,1
1,1,1,1,1,1,1,1,1,1,1,1,1,1,1,23,0,0,0,0,0,0,0,0,0,0,0,1,1,1,1
1,1,1,1,1,1,1,1,1,1,1,1,1,1,1,1,23,23,23,23,23,23,23,0,0,0,0,1,1,1,1
1,1,1,1,1,1,1,1,1,1,1,1,34,34,34,1,1,1,1,1,1,1,1,0,0,0,0,1,1,1,1
1,1,1,1,1,1,1,1,1,1,1,1,1,1,1,1,1,1,1,1,1,1,1,1,1,1,1,1,1,1,1
1,1,1,1,1,1,1,1,1,1,1,1,1,1,1,1,1,1,1,1,1,1,1,1,1,1,1,1,1,1,1
1,1,1,1,1,1,1,1,1,1,1,1,1,1,1,1,1,1,1,1,1,1,1,1,1,1,1,1,1,1,1
1,1,1,1,1,1,1,1,1,1,1,1,1,1,1,1,1,1,1,1,1,1,1,1,1,1,1,1,1,1,1
1,1,1,1,1,1,1,1,1,1,1,1,1,1,1,1,1,1,1,1,1,1,1,1,1,1,1,1,1,1,1
1,1,1,1,1,1,1,1,1,1,1,1,34,34,34,1,1,1,1,1,1,1,1,1,1,1,1,1,1,1,1
1,1,1,1,1,1,1,1,1,1,1,1,1,1,1,1,1,1,1,1,1,1,1,1,1,1,1,1,1,1,1
1,1,1,1,1,1,1,1,1,1,1,1,1,1,1,1,1,1,1,1,1,1,1,1,1,1,1,1,1,1,1
1,1,1,1,1,1,1,1,1,1,1,1,1,1,1,1,1,1,1,1,1,1,1,1,1,1,1,1,1,1,1
1,1,1,1,1,1,1,1,1,1,1,1,1,1,1,1,1,1,1,1,1,1,1,1,1,1,1,1,1,1,1
1,1,1,1,1,1,1,1,1,1,1,1,1,1,1,1,1,1,1,1,1,1,1,1,1,1,1,1,1,1,1
endlayer

layer
1,1,1,1,1,1,1,1,1,1,1,1,1,1,1,1,1,1,1,1,1,1,1,1,1,1,1,1,1,1,1
1,1,1,1,1,1,1,1,1,1,1,1,1,1,1,1,1,1,1,1,1,1,1,1,1,1,1,1,1,1,1
1,1,1,1,1,1,1,1,1,1,34,34,34,1,1,1,1,1,1,1,1,1,1,1,1,1,1,1,1,1,1
1,1,1,1,1,1,1,1,1,1,1,1,1,1,1,1,1,1,1,1,23,23,23,23,23,23,23,23,23,23,1
1,1,1,1,1,1,1,1,0,23,1,1,1,1,1,1,1,1,1,1,0,0,2,0,0,2,0,0,0,0,23
1,1,1,1,1,1,1,1,23,28,23,1,1,1,1,1,1,1,1,1,0,0,0,0,0,0,0,0,0,0,23
1,1,1,1,1,1,1,1,1,23,1,1,1,1,1,1,1,1,1,1,17,31,31,0,0,0,0,0,0,0,23
1,1,1,1,1,1,1,1,1,34,1,1,1,1,1,1,1,1,1,1,0,0,2,0,0,2,0,0,14,0,23
1,1,1,1,1,1,1,1,1,34,1,1,1,1,1,1,23,23,23,23,23,23,23,23,23,23,23,10,10,10,23
1,1,1,1,1,1,1,1,1,34,1,1,1,1,1,23,0,0,0,0,0,0,0,0,0,0,23,23,23,23,23
1,1,1,1,1,1,1,1,1,1,1,1,1,1,1,23,0,0,0,0,0,0,0,0,0,0,23,23,23,23,23
1,1,1,1,1,1,1,1,1,1,1,1,34,34,34,23,0,0,0,0,0,0,0,0,0,0,23,15,15,15,23
1,1,1,1,1,1,1,1,1,1,1,1,1,1,1,23,0,0,0,0,0,0,0,0,0,0,23,23,23,23,23
1,1,1,1,1,1,1,1,1,1,1,1,1,1,1,23,0,0,0,0,0,0,0,0,0,0,23,1,1,1,1
1,1,1,1,1,1,1,1,1,1,1,1,1,1,1,23,0,0,0,0,0,0,0,0,0,0,23,15,15,15,1
1,1,1,1,1,1,1,1,1,1,1,1,1,1,1,23,0,0,0,0,0,0,0,0,0,0,23,1,1,1,1
1,1,1,1,1,1,1,1,1,1,1,1,1,1,1,23,0,0,0,0,0,0,0,0,23,23,23,1,1,1,1
1,1,1,1,1,1,1,1,1,1,1,1,1,1,1,23,0,0,0,0,0,0,0,23,0,0,0,1,1,1,1
1,1,1,1,1,1,1,1,1,1,1,1,1,1,1,1,23,23,23,23,23,23,23,0,0,0,0,1,1,1,1
1,1,1,1,1,1,1,1,1,1,1,1,34,34,34,1,1,1,1,1,1,1,1,0,0,0,0,1,1,1,1
1,1,1,1,1,1,1,1,1,1,1,1,1,1,1,1,1,1,1,1,1,1,1,1,1,1,1,1,1,1,1
1,1,1,1,1,1,1,1,1,1,1,1,1,1,1,1,1,1,1,1,1,1,1,1,1,1,1,1,1,1,1
1,1,1,1,1,1,1,1,1,1,1,1,1,1,1,1,1,1,1,1,1,1,1,1,1,1,1,1,1,1,1
1,1,1,1,1,1,1,1,1,1,1,1,1,1,1,1,1,1,1,1,1,1,1,1,1,1,1,1,1,1,1
1,1,1,1,1,1,1,1,1,1,1,1,1,1,1,1,1,1,1,1,1,1,1,1,1,1,1,1,1,1,1
1,1,1,1,1,1,1,1,1,1,1,1,34,34,34,1,1,1,1,1,1,1,1,1,1,1,1,1,1,1,1
1,1,1,1,1,1,1,1,1,1,1,1,1,1,1,1,1,1,1,1,1,1,1,1,1,1,1,1,1,1,1
1,1,1,1,1,1,1,1,1,1,1,1,1,1,1,1,1,1,1,1,1,1,1,1,1,1,1,1,1,1,1
1,1,1,1,1,1,1,1,1,1,1,1,1,1,1,1,1,1,1,1,1,1,1,1,1,1,1,1,1,1,1
1,1,1,1,1,1,1,1,1,1,1,1,1,1,1,1,1,1,1,1,1,1,1,1,1,1,1,1,1,1,1
1,1,1,1,1,1,1,1,1,1,1,1,1,1,1,1,1,1,1,1,1,1,1,1,1,1,1,1,1,1,1
endlayer

layer
1,1,1,1,1,1,1,1,1,1,1,1,1,1,1,1,1,1,1,1,1,1,1,1,1,1,1,1,1,1,1
1,1,1,1,1,1,1,1,1,1,1,1,1,1,1,1,1,1,1,1,1,1,1,1,1,1,1,1,1,1,1
1,1,1,1,1,1,1,1,1,1,1,1,23,1,1,1,1,1,1,1,1,1,1,1,1,1,1,1,1,1,1
1,1,1,1,1,1,1,1,1,1,1,23,23,23,1,1,1,23,23,23,23,23,23,23,23,23,23,23,23,23,1
1,1,1,1,1,1,1,1,23,23,23,23,23,23,1,1,1,0,0,2,0,0,2,0,13,10,23,23,23,23,23
1,1,1,1,1,1,1,1,23,35,23,23,23,23,1,1,1,0,0,0,0,0,0,0,0,10,23,23,23,23,23
1,1,1,1,1,1,1,1,23,23,23,23,23,23,1,1,1,17,31,31,0,0,0,0,0,10,23,23,23,23,23
1,1,1,1,1,1,1,1,23,23,23,23,23,23,1,1,1,4,0,2,0,0,2,0,13,10,23,23,23,23,23
1,1,1,1,1,1,1,1,1,1,1,23,23,23,1,1,23,23,23,23,23,23,23,23,23,23,23,15,15,15,23
1,1,1,1,1,1,1,23,23,23,23,23,23,23,23,23,0,0,0,0,0,0,0,0,0,0,23,23,23,23,23
1,1,1,1,1,1,1,23,23,23,23,23,23,23,23,23,0,0,0,0,0,0,0,0,0,0,23,1,1,1,1
1,1,1,1,1,1,1,23,23,23,23,23,23,23,23,23,0,0,0,0,0,0,0,0,0,0,23,15,15,15,1
1,1,1,1,1,1,1,23,23,23,23,23,23,23,23,23,0,0,0,0,0,0,0,0,0,0,23,1,1,1,1
1,1,1,1,1,1,1,1,1,1,1,23,23,23,1,23,0,0,0,0,0,0,0,0,0,0,23,1,1,1,1
1,1,1,1,1,1,23,23,23,23,23,23,23,23,23,23,0,0,0,0,0,0,0,0,0,0,23,15,15,15,1
1,1,1,1,1,1,23,23,23,23,23,23,23,23,23,23,0,0,0,0,0,0,0,0,0,0,23,1,1,1,1
1,1,1,1,1,1,23,23,23,23,23,23,23,23,23,23,0,0,0,0,0,0,0,0,23,23,23,1,1,1,1
1,1,1,1,1,1,23,23,23,23,23,23,23,23,23,23,0,0,0,0,0,0,0,23,0,0,0,1,1,1,1
1,1,1,1,1,1,1,1,1,1,1,23,23,23,1,1,23,23,23,23,23,23,23,0,0,0,0,1,1,1,1
1,1,23,23,23,23,23,23,23,23,23,23,23,23,23,23,23,1,1,1,1,1,1,0,0,0,0,1,1,1,1
1,1,23,23,23,23,23,23,23,23,23,23,23,23,23,23,23,1,1,1,1,1,1,1,1,1,1,1,1,1,1
1,1,1,23,23,23,23,23,23,23,23,23,23,23,23,23,23,1,1,1,1,1,1,1,1,1,1,1,1,1,1
1,1,1,1,1,1,1,1,1,1,1,23,23,23,1,1,1,1,1,1,1,1,1,1,1,1,1,1,1,1,1
1,1,1,1,1,1,1,1,1,1,1,23,23,23,1,1,1,1,1,1,1,1,1,1,1,1,1,1,1,1,1
1,1,1,1,1,1,1,1,1,1,1,23,23,23,1,1,1,1,1,1,1,1,1,1,1,1,1,1,1,1,1
1,1,1,1,1,1,1,1,1,1,1,23,23,23,1,1,1,1,1,1,1,1,1,1,1,1,1,1,1,1,1
1,1,1,1,1,1,1,1,1,1,1,23,23,23,1,1,1,1,1,1,1,1,1,1,1,1,1,1,1,1,1
1,1,1,1,1,1,1,1,1,1,1,23,23,23,1,1,1,1,1,1,1,1,1,1,1,1,1,1,1,1,1
1,1,1,1,1,1,1,1,1,1,1,23,23,23,1,1,1,1,1,1,1,1,1,1,1,1,1,1,1,1,1
1,1,1,1,1,1,1,1,1,1,1,23,23,23,1,1,1,1,1,1,1,1,1,1,1,1,1,1,1,1,1
1,1,1,1,1,1,1,1,1,1,1,23,23,23,1,1,1,1,1,1,1,1,1,1,1,1,1,1,1,1,1
endlayer

layer
1,1,1,1,1,1,1,1,1,1,0,0,0,0,0,1,1,1,1,1,1,1,1,1,1,1,1,1,1,1,1
1,1,1,1,1,1,1,1,1,23,0,0,0,0,0,23,1,1,1,1,1,1,1,1,1,1,1,1,1,1,1
1,1,1,1,1,1,1,1,1,23,36,0,0,0,36,23,1,1,1,1,1,1,1,1,1,1,1,1,1,1,1
1,1,1,1,1,1,1,23,23,23,23,0,0,0,23,23,23,23,23,23,23,23,23,23,23,23,1,1,1,1,1
1,1,1,1,1,1,1,23,37,37,37,0,0,0,0,0,0,0,0,2,0,13,10,23,23,35,23,1,1,1,1
1,1,1,1,1,1,1,23,37,0,38,0,0,0,0,0,0,0,0,0,0,0,10,23,23,35,23,1,1,1,1
1,1,1,1,1,1,1,23,37,37,37,0,8,7,7,31,31,0,0,0,0,0,10,23,23,35,23,1,1,1,1
1,1,1,1,1,1,1,23,0,0,0,0,3,0,0,0,0,0,0,2,0,13,10,23,23,35,23,1,1,1,1
1,1,1,1,1,1,23,23,23,23,23,0,3,0,26,23,23,23,23,23,23,23,23,23,23,23,23,15,15,15,1
1,1,1,1,1,1,23,0,0,0,0,0,3,0,0,0,0,0,0,0,0,0,0,0,0,0,23,1,1,1,1
1,1,1,1,1,1,23,39,0,0,0,0,3,0,0,0,0,0,0,0,0,0,0,0,0,0,23,1,1,1,1
1,1,1,1,1,1,23,39,0,0,0,0,3,0,0,0,0,0,0,0,0,0,0,0,0,0,23,15,15,15,1
1,1,1,1,1,1,23,0,0,0,0,0,30,0,0,0,0,0,0,0,0,0,0,0,0,0,23,1,1,1,1
1,1,23,23,23,23,23,23,23,23,23,0,30,4,23,0,0,0,0,0,0,0,0,0,0,0,23,1,1,1,1
1,1,23,0,0,0,0,0,0,0,0,0,30,0,0,0,0,0,0,0,0,0,0,0,0,0,23,15,15,15,1
1,1,23,0,0,0,0,0,0,0,0,0,3,0,0,0,0,0,0,0,0,0,0,0,0,0,23,1,1,1,1
1,1,23,0,0,0,0,0,0,0,0,0,3,0,0,0,0,0,0,0,0,0,0,0,23,23,23,1,1,1,1
1,1,23,0,0,0,0,0,0,0,0,0,3,0,0,0,0,0,0,0,0,0,0,23,0,0,0,1,1,1,1
1,1,23,23,0,23,23,23,23,23,23,0,3,0,23,23,23,23,23,23,23,23,23,0,0,0,0,1,1,1,1
0,0,0,0,0,0,0,0,0,0,0,0,3,0,0,40,23,23,1,1,1,1,1,0,0,0,0,1,1,1,1
0,0,0,0,0,0,0,0,0,0,0,0,27,7,31,41,23,23,1,1,1,1,1,1,1,1,1,1,1,1,1
0,0,0,0,0,0,0,0,0,0,0,0,0,0,4,40,23,23,1,1,1,1,1,1,1,1,1,1,1,1,1
1,1,23,23,23,23,23,23,23,23,23,0,0,0,23,23,1,1,1,1,1,1,1,1,1,1,1,1,1,1,1
1,1,1,1,1,1,1,1,1,1,23,0,0,0,23,1,1,1,1,1,1,1,1,1,1,1,1,1,1,1,1
1,1,1,1,1,1,1,1,1,1,23,0,0,0,23,1,1,1,1,1,1,1,1,1,1,1,1,1,1,1,1
1,1,1,1,1,1,1,1,1,1,23,0,0,0,23,1,1,1,1,1,1,1,1,1,1,1,1,1,1,1,1
1,1,1,1,1,1,1,1,1,1,23,0,0,0,23,1,1,1,1,1,1,1,1,1,1,1,1,1,1,1,1
1,1,1,1,1,1,1,1,1,1,23,0,0,0,23,1,1,1,1,1,1,1,1,1,1,1,1,1,1,1,1
1,1,1,1,1,1,1,1,1,1,23,0,0,0,23,1,1,1,1,1,1,1,1,1,1,1,1,1,1,1,1
1,1,1,1,1,1,1,1,1,1,23,0,0,0,23,1,1,1,1,1,1,1,1,1,1,1,1,1,1,1,1
1,1,1,1,1,1,1,1,1,1,23,0,0,0,23,1,1,1,1,1,1,1,1,1,1,1,1,1,1,1,1
endlayer

layer
1,1,1,1,1,1,1,1,1,1,0,0,0,0,0,1,1,1,1,1,1,1,1,1,1,1,1,1,1,1,1
1,1,1,1,1,1,1,1,1,23,0,0,0,0,0,23,1,1,1,1,1,1,1,1,1,1,1,1,1,1,1
1,1,1,1,1,1,1,1,1,23,0,0,0,0,0,23,1,1,1,1,1,1,1,1,1,1,1,1,1,1,1
1,1,1,1,1,1,1,23,23,23,23,0,0,0,23,23,23,23,23,23,1,1,23,1,1,1,1,1,1,1,1
1,1,1,1,1,1,1,23,0,0,0,0,0,0,0,0,0,0,13,10,23,23,35,23,1,35,1,1,1,1,1
1,1,1,1,1,1,1,23,0,0,0,0,0,0,0,0,0,0,0,10,23,23,35,23,1,35,1,1,1,1,1
1,1,1,1,1,1,1,23,0,0,0,0,0,0,0,0,0,0,0,10,23,23,35,23,1,35,1,1,1,1,1
1,1,1,1,1,1,1,23,0,0,0,0,0,0,0,0,0,0,13,10,23,23,35,23,1,35,1,1,1,1,1
1,1,1,1,1,1,23,23,23,23,23,0,0,0,23,23,23,23,23,23,23,23,23,23,23,23,23,15,15,15,1
1,1,1,1,1,1,23,0,0,0,0,0,0,0,0,0,0,0,0,0,0,0,0,0,0,0,23,1,1,1,1
1,1,1,1,1,1,23,0,0,0,0,0,0,0,0,0,0,0,0,0,0,0,0,0,0,0,23,1,1,1,1
1,1,1,1,1,1,23,0,0,0,0,0,0,0,0,0,0,0,0,0,0,0,0,0,0,0,23,15,15,15,1
1,1,1,1,1,1,23,0,0,0,0,0,0,0,0,0,0,0,0,0,0,0,0,0,0,0,23,1,1,1,1
1,1,23,23,23,23,23,23,23,23,23,0,0,0,23,0,0,0,0,0,0,0,0,0,0,0,23,1,1,1,1
1,1,23,0,0,0,0,0,0,0,0,0,0,0,0,0,0,0,0,0,0,0,0,0,0,0,23,15,15,15,1
1,1,23,0,0,0,0,0,0,0,0,0,0,0,0,0,0,0,0,0,0,0,0,0,0,0,23,1,1,1,1
1,1,23,0,0,0,0,0,0,0,0,0,0,0,0,0,0,0,0,0,0,0,0,0,23,23,23,1,1,1,1
1,1,23,0,0,0,0,0,0,0,0,0,0,0,0,0,0,0,0,0,0,0,0,23,0,0,0,1,1,1,1
1,1,23,0,0,0,23,23,23,23,23,0,0,0,23,23,23,23,23,23,23,23,23,0,0,0,0,1,1,1,1
0,0,0,0,0,0,0,0,0,0,0,0,0,0,0,0,40,23,23,1,1,1,1,0,0,0,0,1,1,1,1
0,0,0,0,0,0,0,0,0,0,0,0,0,0,0,0,41,23,23,1,1,1,1,1,1,1,1,1,1,1,1
0,0,0,0,0,0,0,0,0,0,0,0,0,0,0,0,40,23,23,1,1,1,1,1,1,1,1,1,1,1,1
1,1,1,23,23,23,23,23,23,23,23,0,0,0,23,23,23,1,1,1,1,1,1,1,1,1,1,1,1,1,1
1,1,1,1,1,1,1,1,1,1,23,0,0,0,23,1,1,1,1,1,1,1,1,1,1,1,1,1,1,1,1
1,1,1,1,1,1,1,1,1,1,23,0,0,0,23,1,1,1,1,1,1,1,1,1,1,1,1,1,1,1,1
1,1,1,1,1,1,1,1,1,1,23,0,0,0,23,1,1,1,1,1,1,1,1,1,1,1,1,1,1,1,1
1,1,1,1,1,1,1,1,1,1,23,0,0,0,23,1,1,1,1,1,1,1,1,1,1,1,1,1,1,1,1
1,1,1,1,1,1,1,1,1,1,23,0,0,0,23,1,1,1,1,1,1,1,1,1,1,1,1,1,1,1,1
1,1,1,1,1,1,1,1,1,1,23,0,0,0,23,1,1,1,1,1,1,1,1,1,1,1,1,1,1,1,1
1,1,1,1,1,1,1,1,1,1,23,0,0,0,23,1,1,1,1,1,1,1,1,1,1,1,1,1,1,1,1
1,1,1,1,1,1,1,1,1,1,23,0,0,0,23,1,1,1,1,1,1,1,1,1,1,1,1,1,1,1,1
endlayer

layer
1,1,1,1,1,1,1,1,1,1,0,0,0,0,0,1,1,1,1,1,1,1,1,1,1,1,1,1,1,1,1
1,1,1,1,1,1,1,1,1,23,0,0,0,0,0,23,1,1,1,1,1,1,1,1,1,1,1,1,1,1,1
1,1,1,1,1,1,1,1,1,23,42,0,0,0,42,23,1,1,1,1,1,1,1,1,1,1,1,1,1,1,1
1,1,1,1,1,1,1,23,23,23,23,44,0,43,23,23,23,23,1,23,1,1,23,1,1,1,1,1,1,1,1
1,1,1,1,1,1,1,23,45,0,45,0,0,0,45,0,0,0,23,35,23,23,35,23,1,35,1,1,1,1,1
1,1,1,1,1,1,1,23,0,46,0,0,0,0,0,0,0,0,23,35,23,23,35,23,1,35,1,1,1,1,1
1,1,1,1,1,1,1,23,0,0,0,0,0,0,0,0,0,0,23,35,23,23,35,23,1,35,1,1,1,1,1
1,1,1,1,1,1,1,23,42,0,42,0,0,0,42,0,0,0,23,35,23,23,35,23,1,35,1,1,1,1,1
1,1,1,1,1,1,23,23,23,23,23,0,0,0,23,23,23,23,23,23,23,23,23,23,23,23,23,15,15,15,1
1,1,1,1,1,1,23,45,0,0,45,0,0,0,45,0,0,0,0,0,0,0,0,0,0,0,23,1,1,1,1
1,1,1,1,1,1,23,0,0,0,0,0,0,0,0,0,0,0,0,0,0,0,0,0,0,0,23,1,1,1,1
1,1,1,1,1,1,23,0,0,0,0,0,0,0,0,0,0,0,0,0,0,0,0,0,0,0,23,15,15,15,1
1,1,1,1,1,1,23,42,0,0,42,0,0,0,42,0,0,0,0,0,0,0,0,0,0,0,23,1,1,1,1
1,1,23,23,23,23,23,23,23,23,23,0,0,0,26,0,0,0,0,0,0,0,0,0,0,0,23,1,1,1,1
1,1,23,0,0,0,45,0,0,0,45,0,0,0,45,0,0,0,0,0,0,0,0,0,0,0,23,15,15,15,1
1,1,23,0,0,0,0,0,0,0,0,0,0,0,0,0,0,0,0,0,0,0,0,0,0,0,23,1,1,1,1
1,1,23,0,0,0,0,0,0,0,0,0,0,0,0,0,0,0,0,0,0,0,0,0,23,23,23,1,1,1,1
1,1,23,0,0,0,0,0,0,0,42,0,0,0,42,0,0,0,0,0,0,0,0,23,0,0,0,1,1,1,1
1,1,23,23,0,0,0,23,23,23,23,0,0,0,23,23,23,23,23,23,23,23,23,0,0,0,0,1,1,1,1
0,0,0,0,0,0,0,0,0,0,45,0,0,0,0,0,0,40,23,23,1,1,1,0,0,0,0,1,1,1,1
0,0,0,0,0,0,0,0,0,46,47,0,0,0,0,0,0,41,23,23,1,1,1,1,1,1,1,1,1,1,1
0,0,0,0,0,0,0,0,0,0,42,0,0,0,0,0,0,40,23,23,1,1,1,1,1,1,1,1,1,1,1
1,1,1,1,23,23,23,23,23,23,23,0,0,0,23,23,23,23,1,1,1,1,1,1,1,1,1,1,1,1,1
1,1,1,1,1,1,1,1,1,1,23,0,0,0,23,1,1,1,1,1,1,1,1,1,1,1,1,1,1,1,1
1,1,1,1,1,1,1,1,1,1,23,0,0,0,23,1,1,1,1,1,1,1,1,1,1,1,1,1,1,1,1
1,1,1,1,1,1,1,1,1,1,23,0,0,0,23,1,1,1,1,1,1,1,1,1,1,1,1,1,1,1,1
1,1,1,1,1,1,1,1,1,1,23,0,0,0,23,1,1,1,1,1,1,1,1,1,1,1,1,1,1,1,1
1,1,1,1,1,1,1,1,1,1,23,0,0,0,23,1,1,1,1,1,1,1,1,1,1,1,1,1,1,1,1
1,1,1,1,1,1,1,1,1,1,23,0,0,0,23,1,1,1,1,1,1,1,1,1,1,1,1,1,1,1,1
1,1,1,1,1,1,1,1,1,1,23,0,0,0,23,1,1,1,1,1,1,1,1,1,1,1,1,1,1,1,1
1,1,1,1,1,1,1,1,1,1,23,0,0,0,23,1,1,1,1,1,1,1,1,1,1,1,1,1,1,1,1
endlayer

layer
1,1,1,1,1,1,1,1,1,1,1,1,1,1,1,1,1,1,1,1,1,1,1,1,1,1,1,1,1,1,1
1,1,1,1,1,1,1,1,1,23,23,23,23,23,23,23,1,1,1,1,1,1,1,1,1,1,1,1,1,1,1
1,1,1,1,1,1,1,23,23,23,26,23,46,23,26,23,1,1,1,1,1,1,1,1,1,1,1,1,1,1,1
1,1,1,1,1,1,1,23,23,23,23,23,45,23,23,23,23,23,1,23,1,1,23,1,1,1,1,1,1,1,1
1,1,1,1,1,1,1,23,23,23,23,0,47,0,23,46,0,23,23,35,23,23,35,23,1,35,1,1,1,1,1
1,1,1,1,1,1,1,23,23,23,48,0,46,0,48,0,0,23,23,35,23,23,35,23,1,35,1,1,1,1,1
1,1,1,1,1,1,1,23,23,23,48,0,46,0,48,0,0,23,23,35,23,23,35,23,1,35,1,1,1,1,1
1,1,1,1,1,1,23,23,23,23,23,0,47,0,23,46,0,23,23,35,23,23,35,23,1,35,1,1,1,1,1
1,1,1,1,1,1,23,23,23,23,26,44,47,43,26,23,23,23,23,23,23,23,23,23,23,23,23,15,15,15,1
1,1,1,1,1,1,23,23,23,23,26,0,47,0,23,46,0,0,0,0,0,0,0,0,0,0,23,1,1,1,1
1,1,1,1,1,1,23,23,23,23,48,0,46,0,48,0,0,0,0,0,0,0,0,0,0,0,23,1,1,1,1
1,1,1,1,1,1,23,23,23,23,48,0,46,0,48,0,0,0,0,0,0,0,0,0,0,0,23,15,15,15,1
1,1,23,23,23,23,23,23,23,23,23,0,47,0,23,0,0,0,0,0,0,0,0,0,0,0,23,1,1,1,1
1,1,23,23,23,23,23,23,23,23,23,44,47,43,23,46,0,0,0,0,0,0,0,0,0,0,23,1,1,1,1
1,1,23,23,23,23,23,23,23,23,23,0,47,0,23,0,0,0,0,0,0,0,0,0,0,0,23,15,15,15,1
1,1,48,48,48,48,48,48,48,48,48,0,46,0,48,0,0,0,0,0,0,0,0,0,0,0,23,1,1,1,1
1,1,48,48,48,48,48,48,48,48,48,0,46,0,48,0,0,0,0,0,0,0,0,0,23,23,23,1,1,1,1
1,1,23,23,23,23,23,23,23,23,23,0,47,0,26,46,0,0,0,0,0,0,0,23,0,0,0,1,1,1,1
1,1,23,23,23,23,23,23,23,23,23,44,47,43,23,23,23,23,23,23,23,23,23,0,0,0,0,1,1,1,1
0,0,0,0,0,0,0,0,0,0,49,0,0,0,0,0,0,0,40,23,23,1,1,0,0,0,0,1,1,1,1
0,0,0,0,0,0,0,0,0,0,48,0,0,0,0,0,0,0,41,23,23,1,1,1,1,1,1,1,1,1,1
0,0,0,0,0,0,0,0,0,0,36,0,0,0,0,0,0,0,40,23,23,1,1,1,1,1,1,1,1,1,1
1,1,1,1,1,23,23,23,23,23,23,44,47,43,23,23,23,23,23,1,1,1,1,1,1,1,1,1,1,1,1
1,1,1,1,1,1,1,1,1,1,23,0,47,0,23,1,1,1,1,1,1,1,1,1,1,1,1,1,1,1,1
1,1,1,1,1,1,1,1,1,1,23,0,46,0,23,1,1,1,1,1,1,1,1,1,1,1,1,1,1,1,1
1,1,1,1,1,1,1,1,1,1,23,0,47,0,23,1,1,1,1,1,1,1,1,1,1,1,1,1,1,1,1
1,1,1,1,1,1,1,1,1,1,23,44,47,43,23,1,1,1,1,1,1,1,1,1,1,1,1,1,1,1,1
1,1,1,1,1,1,1,1,1,1,23,0,0,0,23,1,1,1,1,1,1,1,1,1,1,1,1,1,1,1,1
1,1,1,1,1,1,1,1,1,1,23,0,0,0,23,1,1,1,1,1,1,1,1,1,1,1,1,1,1,1,1
1,1,1,1,1,1,1,1,1,1,23,0,0,0,23,1,1,1,1,1,1,1,1,1,1,1,1,1,1,1,1
1,1,1,1,1,1,1,1,1,1,23,0,0,0,23,1,1,1,1,1,1,1,1,1,1,1,1,1,1,1,1
endlayer

layer
1,1,1,1,1,1,1,1,1,1,1,1,1,1,1,1,1,1,1,1,1,1,1,1,1,1,1,1,1,1,1
1,1,1,1,1,1,1,1,1,1,23,23,23,23,23,23,1,1,1,1,1,1,1,1,1,1,1,1,1,1,1
1,1,1,1,1,1,1,1,1,1,23,23,23,23,23,23,1,1,1,1,1,1,1,1,1,1,1,1,1,1,1
1,1,1,1,1,1,1,1,1,1,23,23,23,23,23,23,23,23,1,23,1,1,23,1,1,1,1,1,1,1,1
1,1,1,1,1,1,1,1,1,1,23,23,23,23,23,23,23,23,23,35,23,23,35,23,1,35,1,1,1,1,1
1,1,1,1,1,1,1,1,1,1,23,23,23,23,23,23,23,23,23,35,23,23,35,23,1,35,1,1,1,1,1
1,1,1,1,1,1,1,1,1,1,23,23,23,23,23,23,23,23,23,35,23,23,35,23,1,35,1,1,1,1,1
1,1,1,1,1,1,1,1,1,1,23,23,23,23,23,23,23,23,23,35,23,23,35,23,1,35,1,1,1,1,1
1,1,1,1,1,1,1,1,1,1,23,23,23,23,23,23,23,23,23,23,23,23,23,23,23,23,23,15,15,15,1
1,1,1,1,1,1,1,1,1,1,23,23,23,23,23,0,0,0,0,0,0,0,0,0,0,0,23,1,1,1,1
1,1,1,1,1,1,1,1,1,1,23,23,23,23,23,0,0,0,0,0,0,0,0,0,0,0,23,1,1,1,1
1,1,1,1,1,1,1,1,1,1,23,23,23,23,23,0,0,0,0,0,0,0,0,0,0,0,23,15,15,15,1
1,1,1,1,1,1,1,1,1,1,23,23,23,23,23,0,0,0,0,0,0,0,0,0,0,0,23,1,1,1,1
1,1,1,1,1,1,1,1,1,1,23,23,23,23,23,0,0,0,0,0,0,0,0,0,0,0,23,1,1,1,1
1,1,1,1,1,1,1,1,1,1,23,23,23,23,23,0,0,0,0,0,0,0,0,0,0,0,23,15,15,15,1
1,1,1,1,1,1,1,1,1,1,23,23,23,23,23,0,0,0,0,0,0,0,0,0,0,0,23,1,1,1,1
1,1,1,1,1,1,1,1,1,1,23,23,23,23,23,0,0,0,0,0,0,0,0,0,23,23,23,1,1,1,1
1,1,1,1,1,1,1,1,1,1,23,23,23,23,23,0,0,0,0,0,0,0,0,23,0,0,0,1,1,1,1
1,1,1,1,1,1,1,1,1,1,23,23,23,23,23,23,23,23,23,23,23,23,23,0,0,0,0,1,1,1,1
1,1,1,0,0,0,0,0,0,0,45,0,0,0,0,0,0,0,0,40,23,23,23,0,0,0,0,1,1,1,1
1,1,1,0,0,0,0,0,0,0,47,0,0,0,0,0,0,0,0,41,23,23,23,1,1,1,1,1,1,1,1
1,1,1,0,0,0,0,0,0,0,42,0,0,0,0,0,0,0,0,40,23,23,23,1,1,1,1,1,1,1,1
1,1,1,1,1,1,1,1,1,1,23,23,23,23,23,23,23,23,23,23,1,1,1,1,1,1,1,1,1,1,1
1,1,1,1,1,1,1,1,1,1,23,23,23,23,23,1,1,1,1,1,1,1,1,1,1,1,1,1,1,1,1
1,1,1,1,1,1,1,1,1,1,23,23,23,23,23,1,1,1,1,1,1,1,1,1,1,1,1,1,1,1,1
1,1,1,1,1,1,1,1,1,1,23,23,23,23,23,1,1,1,1,1,1,1,1,1,1,1,1,1,1,1,1
1,1,1,1,1,1,1,1,1,1,23,23,23,23,23,1,1,1,1,1,1,1,1,1,1,1,1,1,1,1,1
1,1,1,1,1,1,1,1,1,1,23,23,23,23,23,1,1,1,1,1,1,1,1,1,1,1,1,1,1,1,1
1,1,1,1,1,1,1,1,1,1,23,23,23,23,23,1,1,1,1,1,1,1,1,1,1,1,1,1,1,1,1
1,1,1,1,1,1,1,1,1,1,23,23,23,23,23,1,1,1,1,1,1,1,1,1,1,1,1,1,1,1,1
1,1,1,1,1,1,1,1,1,1,23,23,23,23,23,1,1,1,1,1,1,1,1,1,1,1,1,1,1,1,1
endlayer

layer
1,1,1,1,1,1,1,1,1,1,1,1,1,1,1,1,1,1,1,1,1,1,1,1,1,1,1,1,1,1,1
1,1,1,1,1,1,1,1,1,1,23,23,23,23,23,1,1,1,1,1,1,1,1,1,1,1,1,1,1,1,1
1,1,1,1,1,1,1,1,1,1,23,23,23,23,23,1,1,1,1,1,1,1,1,1,1,1,1,1,1,1,1
1,1,1,1,1,1,1,1,1,1,23,23,23,23,23,1,1,23,1,23,1,1,23,1,1,1,1,1,1,1,1
1,1,1,1,1,1,1,1,1,1,23,23,23,23,23,1,23,23,23,0,23,23,0,23,1,0,1,1,1,1,1
1,1,1,1,1,1,1,1,1,1,23,23,23,23,23,1,23,23,23,0,23,23,0,23,1,0,1,1,1,1,1
1,1,1,1,1,1,1,1,1,1,23,23,23,23,23,1,23,23,23,0,23,23,0,23,1,0,1,1,1,1,1
1,1,1,1,1,1,1,1,1,1,23,23,23,23,23,1,23,23,23,0,23,23,0,23,1,0,1,1,1,1,1
1,1,1,1,1,1,1,1,1,1,23,23,23,23,23,1,23,23,23,23,23,23,23,23,23,23,23,15,15,15,1
1,1,1,1,1,1,1,1,1,1,23,23,23,23,23,0,0,0,0,0,0,0,0,0,0,0,23,1,1,1,1
1,1,1,1,1,1,1,1,1,1,23,23,23,23,23,0,0,0,0,0,0,0,0,0,0,0,23,1,1,1,1
1,1,1,1,1,1,1,1,1,1,23,23,23,23,23,0,0,0,0,0,0,0,0,0,0,0,23,15,15,15,1
1,1,1,1,1,1,1,1,1,1,23,23,23,23,23,0,0,0,0,0,0,0,0,0,0,0,23,1,1,1,1
1,1,1,1,1,1,1,1,1,1,23,23,23,23,23,0,0,0,0,0,0,0,0,0,0,0,23,1,1,1,1
1,1,1,1,1,1,1,1,1,1,23,23,23,23,23,0,0,0,0,0,0,0,0,0,0,0,23,15,15,15,1
1,1,1,1,1,1,1,1,1,1,23,23,23,23,23,0,0,0,0,0,0,0,0,0,0,0,23,1,1,1,1
1,1,1,1,1,1,1,1,1,1,23,23,23,23,23,0,0,0,0,0,0,0,0,0,23,23,23,1,1,1,1
1,1,1,1,1,1,1,1,1,1,23,23,23,23,23,23,23,23,23,23,23,23,23,23,0,0,0,1,1,1,1
1,1,1,1,1,1,1,1,1,1,23,23,23,23,23,23,23,23,23,23,49,23,49,23,0,0,0,1,1,1,1
1,1,1,0,0,0,0,0,0,0,49,0,0,0,0,46,0,0,0,0,0,5,4,23,0,0,0,1,1,1,1
1,1,1,0,0,0,0,0,0,0,48,0,0,0,0,0,0,0,0,0,31,6,0,23,1,1,1,1,1,1,1
1,1,1,0,0,0,0,0,0,0,36,0,0,0,0,46,0,0,0,0,0,0,0,23,1,1,1,1,1,1,1
1,1,1,1,1,1,1,1,1,1,23,23,23,23,23,23,23,23,23,23,23,23,23,23,1,1,1,1,1,1,1
1,1,1,1,1,1,1,1,1,1,1,1,1,1,1,1,1,1,1,1,1,1,1,1,1,1,1,1,1,1,1
1,1,1,1,1,1,1,1,1,1,1,1,1,1,1,1,1,1,1,1,1,1,1,1,1,1,1,1,1,1,1
1,1,1,1,1,1,1,1,1,1,1,1,1,1,1,1,1,1,1,1,1,1,1,1,1,1,1,1,1,1,1
1,1,1,1,1,1,1,1,1,1,1,1,1,1,1,1,1,1,1,1,1,1,1,1,1,1,1,1,1,1,1
1,1,1,1,1,1,1,1,1,1,1,1,1,1,1,1,1,1,1,1,1,1,1,1,1,1,1,1,1,1,1
1,1,1,1,1,1,1,1,1,1,1,1,1,1,1,1,1,1,1,1,1,1,1,1,1,1,1,1,1,1,1
1,1,1,1,1,1,1,1,1,1,1,1,1,1,1,1,1,1,1,1,1,1,1,1,1,1,1,1,1,1,1
1,1,1,1,1,1,1,1,1,1,1,1,1,1,1,1,1,1,1,1,1,1,1,1,1,1,1,1,1,1,1
endlayer

layer
1,1,1,1,1,1,1,1,1,1,1,1,1,1,1,1,1,1,1,1,1,1,1,1,1,1,1,1,1,1,1
1,23,23,23,23,23,23,23,23,23,23,23,23,23,23,23,23,23,23,23,23,23,23,23,23,23,23,23,23,23,1
1,23,23,23,23,23,23,23,23,23,23,23,23,23,23,23,23,23,23,23,23,23,23,23,23,23,23,23,23,23,1
1,23,23,23,23,23,23,23,23,23,23,23,23,23,23,23,23,23,23,23,23,23,23,23,23,23,23,23,23,23,1
1,23,23,23,23,23,23,23,23,23,23,23,23,23,23,23,23,23,23,23,23,23,23,23,23,23,23,23,23,23,1
1,23,23,23,23,23,23,23,23,23,23,23,23,23,23,23,23,23,23,23,23,23,23,23,23,23,23,23,23,23,1
1,23,23,23,23,23,23,23,23,23,23,23,23,23,23,23,23,23,23,23,23,23,23,23,23,23,23,23,23,23,1
1,23,23,23,23,23,23,23,23,23,23,23,23,23,23,23,23,23,23,23,23,23,23,23,23,23,23,23,23,23,1
1,23,23,23,23,23,23,23,23,23,23,23,23,23,23,23,23,23,23,23,23,23,23,23,23,23,23,23,23,23,1
1,23,23,23,23,23,23,23,23,23,23,23,23,23,23,23,23,23,23,23,23,23,23,23,23,23,23,23,23,23,1
1,23,23,23,23,23,23,23,23,23,23,23,23,23,23,23,23,23,23,23,23,23,23,23,23,23,23,23,23,23,1
1,23,23,23,23,23,23,23,23,23,23,23,23,23,23,23,23,23,23,23,23,23,23,23,23,23,23,23,23,23,1
1,23,23,23,23,23,23,23,23,23,23,23,23,23,23,23,23,23,23,23,23,23,23,23,23,23,23,23,23,23,1
1,23,23,23,23,23,23,23,23,23,23,23,23,23,23,23,23,23,23,23,23,23,23,23,23,23,23,23,23,23,1
1,23,23,23,23,23,23,23,23,23,23,23,23,23,23,23,23,23,23,23,23,23,23,23,23,23,23,23,23,23,1
1,23,23,23,23,23,23,23,23,23,23,23,23,23,23,23,23,23,23,23,23,23,23,23,23,23,23,23,23,23,1
1,23,23,23,23,23,23,23,23,23,23,23,23,23,23,23,23,23,23,23,23,23,23,23,23,23,23,23,23,23,1
1,23,23,23,23,23,23,23,23,23,23,23,23,23,23,23,23,23,23,23,49,23,49,23,23,23,23,23,23,23,1
1,23,23,23,23,23,23,23,23,23,23,23,23,23,23,23,0,0,0,0,0,5,0,23,23,23,23,23,23,23,1
1,23,23,23,23,23,23,23,23,23,23,23,23,23,23,23,0,0,0,0,0,0,0,23,23,23,23,23,23,23,1
1,23,23,23,23,23,23,23,23,23,23,23,23,23,23,23,0,0,0,0,0,0,0,23,23,23,23,23,23,23,1
1,23,23,23,23,23,23,23,23,23,23,23,23,23,23,23,0,0,0,0,0,0,0,23,23,23,23,23,23,23,1
1,23,23,23,23,23,23,23,23,23,23,23,23,23,23,23,23,23,23,23,23,23,23,23,23,23,23,23,23,23,1
1,23,23,23,23,23,23,23,23,23,23,23,23,23,23,23,23,23,23,23,23,23,23,23,23,23,23,23,23,23,1
1,23,23,23,23,23,23,23,23,23,23,23,23,23,23,23,23,23,23,23,23,23,23,23,23,23,23,23,23,23,1
1,23,23,23,23,23,23,23,23,23,23,23,23,23,23,23,23,23,23,23,23,23,23,23,23,23,23,23,23,23,1
1,23,23,23,23,23,23,23,23,23,23,23,23,23,23,23,23,23,23,23,23,23,23,23,23,23,23,23,23,23,1
1,23,23,23,23,23,23,23,23,23,23,23,23,23,23,23,23,23,23,23,23,23,23,23,23,23,23,23,23,23,1
1,23,23,23,23,23,23,23,23,23,23,23,23,23,23,23,23,23,23,23,23,23,23,23,23,23,23,23,23,23,1
1,23,23,23,23,23,23,23,23,23,23,23,23,23,23,23,23,23,23,23,23,23,23,23,23,23,23,23,23,23,1
1,1,1,23,23,23,23,23,23,23,23,23,23,23,23,23,23,23,23,23,23,23,23,23,23,23,23,23,23,23,1
endlayer

layer
50,50,50,50,50,50,50,50,50,50,50,50,50,50,50,50,50,50,50,50,50,50,50,50,50,50,50,50,1,50,50
50,50,50,50,50,50,50,50,50,50,50,50,50,50,50,50,50,50,50,50,50,50,50,50,50,50,50,50,50,50,50
1,50,50,50,50,50,50,50,50,50,50,50,50,50,50,50,50,50,50,50,50,50,50,50,50,50,50,50,50,50,50
50,50,50,50,50,50,50,50,23,23,0,0,0,23,0,0,0,23,0,0,0,23,0,0,0,23,50,50,50,50,50
50,50,50,50,23,23,0,23,23,23,23,0,23,23,23,0,23,23,23,0,23,23,23,0,23,23,23,50,50,50,50
50,50,51,51,0,0,51,0,0,0,0,51,0,0,0,51,0,0,0,51,0,3,0,51,0,0,0,51,50,50,50
50,50,23,0,0,0,0,0,0,0,0,0,0,0,0,0,0,0,0,0,0,3,0,0,0,0,0,0,23,50,50
50,50,23,0,0,0,0,0,0,0,0,0,0,0,0,0,0,0,0,0,0,3,0,0,0,0,0,0,23,23,50
50,50,51,51,0,0,0,0,0,0,0,0,0,0,0,0,0,0,0,0,0,3,0,0,0,0,0,0,23,50,50
50,50,23,0,0,0,0,0,0,0,0,51,0,0,0,51,0,0,0,51,0,3,0,51,0,0,0,51,50,50,50
50,23,23,0,0,0,0,0,0,0,0,0,0,0,0,0,0,0,0,0,0,3,0,0,0,0,0,0,23,50,50
50,50,23,0,0,0,0,0,0,0,0,0,0,0,0,0,0,0,0,0,0,3,0,0,0,0,0,0,23,23,50
50,50,51,51,0,0,0,0,51,0,0,0,0,0,0,0,0,0,0,0,0,3,0,0,0,0,0,0,23,0,50
50,50,50,50,23,23,23,51,51,51,51,51,0,0,0,51,0,0,0,51,0,3,0,51,0,0,0,51,0,0,50
50,50,50,50,50,50,50,50,50,53,52,0,0,0,0,0,0,0,0,0,0,3,0,0,0,0,0,0,23,0,50
50,50,50,50,50,50,50,50,50,53,52,0,0,0,0,0,0,0,0,0,0,3,0,0,0,0,0,0,23,23,50
50,50,50,50,50,50,50,50,50,53,52,0,0,0,0,0,0,0,0,0,0,30,0,0,0,0,0,0,23,50,50
50,50,50,50,50,50,50,51,51,51,51,51,0,0,0,51,51,51,51,54,0,30,0,54,0,0,0,51,50,50,50
50,50,50,50,50,50,50,51,0,0,0,0,0,0,0,51,0,0,0,0,0,0,0,51,0,0,0,0,23,50,50
50,50,50,50,50,50,23,0,0,0,0,0,0,0,0,51,0,0,0,0,0,0,0,51,0,0,0,0,23,23,50
50,50,50,50,50,23,23,0,0,0,0,0,0,0,0,51,0,0,0,0,0,0,0,51,0,0,0,0,23,23,50
50,50,50,50,50,50,23,0,0,0,0,0,0,0,0,51,0,0,0,0,0,0,0,51,0,0,0,0,23,50,50
50,50,50,50,50,50,0,51,0,0,0,51,0,0,0,51,51,51,51,51,51,51,51,51,0,0,0,51,50,50,50
50,50,50,50,50,50,23,0,0,0,0,0,0,0,0,0,0,0,0,0,0,0,0,0,0,0,0,0,23,50,50
50,50,50,50,50,23,23,0,0,0,0,0,0,0,0,0,0,0,0,0,0,0,0,0,0,0,0,0,23,23,50
50,50,50,50,50,50,23,0,0,0,0,0,0,0,0,0,0,0,0,0,0,0,0,0,0,0,0,0,23,50,50
50,50,50,50,50,50,50,51,0,0,0,51,0,0,0,51,0,0,0,51,0,0,0,51,0,0,0,51,50,50,50
50,50,50,50,50,50,50,50,23,23,23,50,23,23,23,50,23,23,23,50,23,23,23,50,23,23,23,50,50,50,50
50,50,50,50,50,50,50,50,50,23,50,50,50,23,50,50,50,23,50,50,50,23,50,50,50,23,50,50,50,50,1
50,50,50,50,50,50,50,50,50,50,50,50,50,50,50,50,50,50,50,50,50,50,50,50,50,50,50,50,50,50,50
50,50,1,50,50,50,50,50,50,50,50,50,50,50,50,50,50,50,50,50,50,50,50,50,50,50,50,50,50,50,50
endlayer

layer
50,50,50,50,50,50,50,50,50,50,50,50,50,50,50,50,50,50,50,50,50,50,50,50,50,50,50,50,1,50,50
50,50,50,50,50,50,50,50,50,50,50,50,50,50,50,50,50,50,50,50,50,50,50,50,50,50,50,50,50,50,50
1,50,50,50,50,50,50,50,50,50,50,50,50,50,50,50,50,50,50,50,50,50,50,50,50,50,50,50,50,50,50
50,50,50,50,50,50,50,50,23,23,0,0,0,23,0,0,0,23,0,0,0,23,0,0,0,23,50,50,50,50,50
50,50,50,50,23,23,0,23,0,0,23,0,23,0,23,0,23,0,23,0,23,0,23,0,23,0,23,50,50,50,50
50,50,51,51,0,0,51,0,0,0,0,51,0,0,0,51,0,0,0,51,0,0,0,51,0,0,0,51,50,50,50
50,50,23,0,0,0,0,0,0,0,0,0,0,0,0,0,0,0,0,0,0,0,0,0,0,0,0,0,23,50,50
50,50,23,0,0,0,0,0,0,0,0,0,0,0,0,0,0,0,0,0,0,0,0,0,0,0,0,0,0,23,50
50,50,51,51,0,0,0,0,0,0,0,0,0,0,0,0,0,0,0,0,0,0,0,0,0,0,0,0,23,50,50
50,50,23,0,0,0,0,0,0,0,0,51,0,0,0,51,0,0,0,51,0,0,0,51,0,0,0,51,50,50,50
50,23,39,0,0,0,0,0,0,0,0,0,0,0,0,0,0,0,0,0,0,0,0,0,0,0,0,0,23,50,50
50,50,23,0,0,0,0,0,0,0,0,0,0,0,0,0,0,0,0,0,0,0,0,0,0,0,0,0,0,23,50
50,50,51,51,0,0,0,0,51,0,0,0,0,0,0,0,0,0,0,0,0,0,0,0,0,0,0,0,23,0,50
50,50,50,50,23,23,23,51,51,51,51,51,0,0,0,51,0,0,0,51,0,0,0,51,0,0,0,51,0,0,50
50,50,50,50,50,50,50,50,53,52,0,0,0,0,0,0,0,0,0,0,0,0,0,0,0,0,0,0,23,0,50
50,50,50,50,50,50,50,50,53,52,0,0,0,0,0,0,0,0,0,0,0,0,0,0,0,0,0,0,0,23,50
50,50,50,50,50,50,50,50,53,52,0,0,0,0,0,0,0,0,0,0,0,0,0,0,0,0,0,0,23,50,50
50,50,50,50,50,50,50,51,51,51,51,51,0,0,0,51,52,0,55,54,0,0,0,54,0,0,0,51,50,50,50
50,50,50,50,50,50,50,51,0,0,0,0,0,0,0,56,0,0,0,0,0,0,0,56,0,0,0,0,23,50,50
50,50,50,50,50,50,23,0,0,0,0,0,0,0,0,0,0,0,0,0,0,0,0,0,0,0,0,0,32,23,50
50,50,50,50,50,23,0,0,0,0,0,0,0,0,0,0,0,0,0,0,0,0,0,0,0,0,0,0,32,23,50
50,50,50,50,50,50,23,0,0,0,0,0,0,0,0,57,0,0,0,0,0,0,0,57,0,0,0,0,23,50,50
50,50,50,50,50,50,0,51,0,0,0,51,0,0,0,51,52,0,0,51,0,0,55,51,0,0,0,51,50,50,50
50,50,50,50,50,50,23,0,0,0,0,0,0,0,0,0,0,0,0,0,0,0,0,0,0,0,0,0,23,50,50
50,50,50,50,50,23,0,0,0,0,0,0,0,0,0,0,0,0,0,0,0,0,0,0,0,0,0,0,0,23,50
50,50,50,50,50,50,23,0,0,0,0,0,0,0,0,0,0,0,0,0,0,0,0,0,0,0,0,0,23,50,50
50,50,50,50,50,50,50,51,0,0,0,51,0,0,0,51,0,0,0,51,0,0,0,51,0,0,0,51,50,50,50
50,50,50,50,50,50,50,50,23,0,23,50,23,0,23,50,23,9,23,50,23,0,23,50,23,0,23,50,50,50,50
50,50,50,50,50,50,50,50,50,23,50,50,50,23,50,50,50,23,50,50,50,23,50,50,50,23,50,50,50,50,1
50,50,50,50,50,50,50,50,50,50,50,50,50,50,50,50,50,50,50,50,50,50,50,50,50,50,50,50,50,50,50
50,50,1,50,50,50,50,50,50,50,50,50,50,50,50,50,50,50,50,50,50,50,50,50,50,50,50,50,50,50,50
endlayer

layer
50,50,50,50,50,50,50,50,50,50,50,50,50,50,50,50,50,50,50,50,50,50,50,50,50,50,50,50,1,50,50
50,50,50,50,50,50,50,50,50,50,50,50,50,50,50,50,50,50,50,50,50,50,50,50,50,50,50,50,50,50,50
1,50,50,50,50,50,50,50,50,50,50,50,50,50,50,50,50,50,50,50,50,50,50,50,50,50,50,50,50,50,50
50,50,50,50,50,50,50,50,23,23,0,0,0,23,0,0,0,23,0,0,0,23,0,0,0,23,50,50,50,50,50
50,50,50,50,23,23,0,23,0,0,23,0,23,0,23,0,23,0,23,0,23,0,23,0,23,0,23,50,50,50,50
50,50,51,51,0,0,51,0,0,0,0,51,0,0,0,51,0,0,0,51,0,0,0,51,0,0,0,51,50,50,50
50,50,23,0,0,0,0,0,0,0,0,0,0,0,0,0,0,0,0,0,0,0,0,0,0,0,0,0,23,50,50
50,50,23,0,0,0,0,0,0,0,0,0,0,0,0,0,0,0,0,0,0,0,0,0,0,0,0,0,0,23,50
50,50,51,51,0,0,0,0,0,0,0,0,0,0,0,0,0,0,0,0,0,0,0,0,0,0,0,0,23,50,50
50,50,23,0,0,0,0,0,0,0,0,51,0,0,0,51,0,0,0,51,0,0,0,51,0,0,0,51,50,50,50
50,23,0,0,0,0,0,0,0,0,0,0,0,0,0,0,0,0,0,0,0,0,0,0,0,0,0,0,23,50,50
50,50,23,0,0,0,0,0,0,0,0,0,0,0,0,0,0,0,0,0,0,0,0,0,0,0,0,0,0,23,50
50,50,51,51,0,0,0,0,51,0,0,0,0,0,0,0,0,0,0,0,0,0,0,0,0,0,0,0,23,0,50
50,50,50,50,23,23,23,51,51,51,51,51,0,0,0,51,0,0,0,51,0,0,0,51,0,0,0,51,0,0,50
50,50,50,50,50,50,50,53,52,0,0,0,0,0,0,0,0,0,0,0,0,0,0,0,0,0,0,0,23,0,50
50,50,50,50,50,50,50,53,52,0,0,0,0,0,0,0,0,0,0,0,0,0,0,0,0,0,0,0,0,23,50
50,50,50,50,50,50,50,53,52,0,0,0,0,0,0,0,0,0,0,0,0,0,0,0,0,0,0,0,23,0,50
50,50,50,50,50,50,50,51,51,51,51,51,0,0,0,51,0,0,0,54,0,0,0,54,0,0,0,51,50,0,50
50,50,50,50,50,50,50,51,0,0,0,0,0,0,0,0,0,0,0,0,0,0,0,0,0,0,0,0,23,0,50
50,50,50,50,50,50,23,0,0,0,0,0,0,0,0,0,0,0,0,0,0,0,0,0,0,0,0,0,0,23,50
50,50,50,50,50,23,0,0,0,0,0,0,0,0,0,0,0,0,0,0,0,0,0,0,0,0,0,0,0,23,50
50,50,50,50,50,50,23,0,0,0,0,0,0,0,0,0,0,0,0,0,0,0,0,0,0,0,0,0,23,50,50
50,50,50,50,50,50,0,51,0,0,0,51,0,0,0,51,0,0,0,51,0,0,0,51,0,0,0,51,50,50,50
50,50,50,50,50,50,23,0,0,0,0,0,0,0,0,0,0,0,0,0,0,0,0,0,0,0,0,0,23,50,50
50,50,50,50,50,23,0,0,0,0,0,0,0,0,0,0,0,0,0,0,0,0,0,0,0,0,0,0,0,23,50
50,50,50,50,50,50,23,0,0,0,0,0,0,0,0,0,0,0,0,0,0,0,0,0,0,0,0,0,23,50,50
50,50,50,50,50,50,50,51,0,0,0,51,0,0,0,51,0,0,0,51,0,0,0,51,0,0,0,51,50,50,50
50,50,50,50,50,50,50,50,23,0,23,50,23,0,23,50,23,0,23,50,23,0,23,50,23,0,23,50,50,50,50
50,50,50,50,50,50,50,50,50,23,50,50,50,23,50,50,50,23,50,50,50,23,50,50,50,23,50,50,50,50,1
50,50,50,50,50,50,50,50,50,50,50,50,50,50,50,50,50,50,50,50,50,50,50,50,50,50,50,50,50,50,50
50,50,1,50,50,50,50,50,50,50,50,50,50,50,50,50,50,50,50,50,50,50,50,50,50,50,50,50,50,50,50
endlayer

layer
50,50,50,50,50,50,50,50,50,50,50,50,50,50,50,50,50,50,50,50,50,50,50,50,50,50,50,50,1,50,50
50,50,50,50,50,50,50,50,50,50,50,50,50,50,50,50,50,50,50,50,50,50,50,50,50,50,50,50,50,50,50
1,50,50,50,50,50,50,50,50,50,50,50,50,50,50,50,50,50,50,50,50,50,50,50,50,50,50,50,50,50,50
50,50,50,50,50,50,50,50,50,50,50,50,50,50,50,50,50,50,50,50,50,50,50,50,50,50,50,50,50,50,50
50,50,50,50,23,23,0,23,23,23,23,0,23,23,23,0,23,23,23,0,23,23,23,0,23,23,23,50,50,50,50
50,50,51,51,59,53,51,59,58,58,53,51,59,58,53,51,59,58,53,51,59,58,53,51,59,58,53,51,50,50,50
50,50,23,60,0,0,60,0,0,0,0,60,0,0,0,60,0,0,0,60,0,0,0,60,0,0,0,60,23,50,50
50,50,23,62,0,0,0,0,0,0,0,58,0,61,0,58,0,61,0,58,0,61,0,58,0,61,0,58,23,50,50
50,50,51,51,59,0,0,0,0,0,0,62,0,0,0,62,0,0,0,62,0,0,0,62,0,0,0,62,23,50,50
50,50,23,60,0,0,0,0,0,0,53,51,59,58,53,51,59,58,53,51,59,58,53,51,59,58,53,51,59,50,50
50,50,23,58,0,0,0,0,0,0,0,60,0,0,0,60,0,0,0,60,0,0,0,60,0,0,0,60,23,50,50
50,50,23,62,0,0,0,0,62,0,0,58,0,61,0,58,0,61,0,58,0,61,0,58,0,61,0,58,23,50,50
50,50,51,51,51,51,51,51,51,0,0,62,0,0,0,62,0,0,0,62,0,0,0,62,0,0,0,62,23,50,50
50,50,51,51,51,51,51,51,51,51,51,51,59,58,53,51,59,58,53,51,59,58,53,51,59,58,53,51,59,50,50
50,50,51,51,51,51,51,52,0,0,0,60,0,0,0,60,0,0,0,60,0,0,0,60,0,0,0,60,23,50,50
50,50,51,51,51,51,51,52,0,0,0,58,0,61,0,58,0,61,0,58,0,61,0,58,0,61,0,58,23,50,50
50,50,51,51,51,51,51,52,0,0,0,62,0,0,0,62,0,0,0,62,0,0,0,62,0,0,0,62,23,50,50
50,50,50,51,51,51,51,51,51,51,51,51,59,58,53,51,59,58,53,54,59,58,53,54,59,58,53,51,59,50,50
50,50,50,50,51,51,51,51,0,0,0,60,0,0,0,60,0,0,0,60,0,0,0,60,0,0,0,60,23,50,50
50,50,50,50,50,50,23,60,0,61,0,58,0,61,0,58,0,61,0,58,0,61,0,58,0,61,0,58,23,50,50
50,50,50,50,50,50,23,58,0,61,0,58,0,61,0,58,0,61,0,58,0,61,0,58,0,61,0,58,23,50,50
50,50,50,50,50,50,23,62,0,0,0,62,0,0,0,62,0,0,0,62,0,0,0,62,0,0,0,62,23,50,50
50,50,50,50,50,50,53,51,59,58,53,51,59,58,53,51,59,58,53,51,59,58,53,51,59,58,53,51,59,50,50
50,50,50,50,50,50,23,60,0,0,0,60,0,0,0,60,0,0,0,60,0,0,0,60,0,0,0,60,23,50,50
50,50,50,50,50,50,23,58,0,61,0,58,0,61,0,58,0,61,0,58,0,61,0,58,0,61,0,58,23,50,50
50,50,50,50,50,50,23,62,0,0,0,62,0,0,0,62,0,0,0,62,0,0,0,62,0,0,0,62,23,50,50
50,50,50,50,50,50,53,51,59,58,53,51,59,58,53,51,59,58,53,51,59,58,53,51,59,58,53,51,59,50,50
50,50,50,50,50,50,50,60,23,23,23,60,23,23,23,60,23,23,23,60,23,23,23,60,23,23,23,60,50,50,50
50,50,50,50,50,50,50,50,50,50,50,50,50,50,50,50,50,50,50,50,50,50,50,50,50,50,50,50,50,50,1
50,50,50,50,50,50,50,50,50,50,50,50,50,50,50,50,50,50,50,50,50,50,50,50,50,50,50,50,50,50,50
50,50,1,50,50,50,50,50,50,50,50,50,50,50,50,50,50,50,50,50,50,50,50,50,50,50,50,50,50,50,50
endlayer

layer
50,50,50,50,50,50,50,50,50,50,50,50,50,50,50,50,50,50,50,50,50,50,50,50,50,50,50,50,1,50,50
50,50,50,50,50,50,50,50,50,50,63,50,63,50,50,50,50,50,50,50,50,50,50,50,50,50,50,50,50,50,50
1,50,50,50,50,50,50,50,50,50,63,63,50,50,50,50,50,50,50,50,50,50,50,50,50,50,50,50,50,50,50
50,50,50,50,50,50,50,50,50,50,50,63,50,50,50,50,50,50,50,50,50,50,50,50,50,50,50,50,50,50,50
50,50,50,50,50,50,50,50,50,50,50,50,50,50,50,50,50,50,50,50,50,50,50,50,50,50,50,50,50,50,50
50,50,51,51,51,51,51,51,51,51,51,51,50,50,50,50,50,50,50,50,50,50,50,50,50,50,50,50,50,50,50
50,50,51,51,61,58,51,58,58,58,61,51,58,58,58,0,58,58,58,0,58,58,58,0,58,58,58,50,50,50,50
50,50,51,51,58,58,60,58,58,58,58,51,58,0,58,0,58,0,58,0,58,0,58,0,58,0,58,50,50,50,50
50,50,51,51,51,59,58,58,58,58,58,51,58,58,58,0,58,58,58,0,58,58,58,0,58,58,58,50,50,50,50
50,50,51,51,58,58,58,58,58,53,51,51,50,50,50,50,50,50,50,50,50,50,50,50,50,50,50,50,50,50,50
50,50,51,51,58,58,58,58,62,58,58,51,58,58,58,50,58,58,58,50,58,58,58,50,58,58,58,50,50,50,50
50,50,51,51,61,62,62,62,51,58,58,51,58,0,58,50,58,0,58,50,58,0,58,50,58,0,58,50,50,50,50
50,50,51,51,56,56,56,51,51,58,61,51,58,58,58,50,58,58,58,50,58,58,58,50,58,58,58,50,50,50,50
50,50,51,51,0,0,0,51,51,51,51,51,50,50,50,50,50,50,50,50,50,50,50,50,50,50,50,50,50,50,50
50,50,51,0,0,0,0,0,0,0,0,51,58,58,58,50,58,58,58,50,58,58,58,50,58,58,58,50,50,50,50
50,50,51,0,0,0,0,0,0,0,0,51,58,0,58,50,58,0,58,50,58,0,58,50,58,0,58,50,50,50,50
50,50,51,0,0,0,0,0,0,0,0,51,58,58,58,50,58,58,58,50,58,58,58,50,58,58,58,50,50,50,50
50,50,50,51,0,0,0,51,51,51,51,51,50,50,50,50,50,50,50,50,50,50,50,50,50,50,50,50,50,50,50
50,50,50,51,57,57,57,51,58,58,58,50,58,58,58,50,58,58,58,50,58,58,58,50,58,58,58,50,50,50,50
50,50,50,50,60,60,60,0,58,0,58,50,58,0,58,50,58,0,58,50,58,0,58,50,58,0,58,50,50,50,50
50,50,50,50,50,50,50,50,58,0,58,50,58,0,58,50,58,0,58,50,58,0,58,50,58,0,58,50,50,50,50
50,50,50,50,50,50,50,50,58,58,58,50,58,58,58,50,58,58,58,50,58,58,58,50,58,58,58,50,50,50,50
50,50,50,50,50,50,50,50,50,50,50,50,50,50,50,50,50,50,50,50,50,50,50,50,50,50,50,50,50,50,50
50,50,50,50,50,50,50,50,58,58,58,50,58,58,58,50,58,58,58,50,58,58,58,50,58,58,58,50,50,50,50
50,50,50,50,50,50,50,50,58,0,58,50,58,0,58,50,58,0,58,50,58,0,58,50,58,0,58,50,50,50,50
50,50,50,50,50,50,50,50,58,58,58,50,58,58,58,50,58,58,58,50,58,58,58,50,58,58,58,50,50,50,50
50,50,50,50,50,50,50,50,50,50,50,50,50,50,50,50,50,50,50,50,50,50,50,50,50,50,50,50,50,50,50
50,50,50,50,50,50,50,50,50,50,50,50,50,50,50,50,50,50,50,50,50,50,50,50,50,50,50,50,50,50,50
50,50,50,50,50,50,50,50,50,50,50,50,50,50,50,50,50,50,50,50,50,50,50,50,50,50,50,50,50,50,1
50,50,50,50,50,50,50,50,50,50,50,50,50,50,50,50,50,50,50,50,50,50,50,50,50,50,50,50,50,50,50
50,50,1,50,50,50,50,50,50,50,50,50,50,50,50,50,50,50,50,50,50,50,50,50,50,50,50,50,50,50,50
endlayer

layer
50,50,50,50,50,50,50,50,50,50,50,50,50,50,50,50,50,50,50,50,50,50,50,50,50,50,50,50,1,50,50
50,50,50,50,50,50,50,50,50,50,0,50,0,50,50,50,50,50,50,50,50,50,50,50,50,50,50,50,50,50,50
1,50,50,50,50,50,50,50,50,50,0,0,50,50,50,50,50,50,50,50,50,50,50,50,50,50,50,50,50,50,50
50,50,50,50,50,50,50,50,50,50,50,0,50,50,50,50,50,50,50,50,50,50,50,50,50,50,50,50,50,50,50
50,50,50,50,50,50,50,50,50,50,50,50,50,50,50,50,50,50,50,50,50,50,50,50,50,50,50,50,50,50,50
50,50,50,50,50,50,50,50,50,50,50,50,50,50,50,50,50,50,50,50,50,50,50,50,50,50,50,50,50,50,50
50,50,50,50,50,50,50,50,50,50,50,50,50,50,50,50,50,50,50,50,50,50,50,50,50,50,50,50,50,50,50
50,50,50,50,50,50,50,50,50,50,50,50,50,50,50,50,50,50,50,50,50,50,50,50,50,50,50,50,50,50,50
50,50,50,50,50,50,50,50,50,50,50,50,50,50,50,50,50,50,50,50,50,50,50,50,50,50,50,50,50,50,50
50,50,50,50,50,50,50,50,50,50,50,50,50,50,50,50,50,50,50,50,50,50,50,50,50,50,50,50,50,50,50
50,50,50,50,62,62,62,62,50,50,50,50,50,50,50,50,50,50,50,50,50,50,50,50,50,50,50,50,50,50,50
50,50,51,51,56,56,56,51,50,50,50,50,50,50,50,50,50,50,50,50,50,50,50,50,50,50,50,50,50,50,50
50,50,51,51,0,0,0,51,50,50,50,50,50,50,50,50,50,50,50,50,50,50,50,50,50,50,50,50,50,50,50
50,50,51,51,0,0,0,51,51,51,51,50,50,50,50,50,50,50,50,50,50,50,50,50,50,50,50,50,50,50,50
50,50,51,0,0,0,0,0,0,0,0,51,50,50,50,50,50,50,50,50,50,50,50,50,50,50,50,50,50,50,50
50,50,51,0,0,0,0,0,0,0,0,51,50,50,50,50,50,50,50,50,50,50,50,50,50,50,50,50,50,50,50
50,50,51,0,0,0,0,0,0,0,0,51,50,50,50,50,50,50,50,50,50,50,50,50,50,50,50,50,50,50,50
50,50,50,51,0,0,0,51,51,51,51,50,50,50,50,50,50,50,50,50,50,50,50,50,50,50,50,50,50,50,50
50,50,50,51,0,0,0,51,50,50,50,50,50,50,50,50,50,50,50,50,50,50,50,50,50,50,50,50,50,50,50
50,50,50,51,57,57,57,51,50,50,50,50,50,50,50,50,50,50,50,50,50,50,50,50,50,50,50,50,50,50,50
50,50,50,50,60,60,60,0,50,50,50,50,50,50,50,50,50,50,50,50,50,50,50,50,50,50,50,50,50,50,50
50,50,50,50,50,50,50,50,50,50,50,50,50,50,50,50,50,50,50,50,50,50,50,50,50,50,50,50,50,50,50
50,50,50,50,50,50,50,50,50,50,50,50,50,50,50,50,50,50,50,50,50,50,50,50,50,50,50,50,50,50,50
50,50,50,50,50,50,50,50,50,50,50,50,50,50,50,50,50,50,50,50,50,50,50,50,50,50,50,50,50,50,50
50,50,50,50,50,50,50,50,50,50,50,50,50,50,50,50,50,50,50,50,50,50,50,50,50,50,50,50,50,50,50
50,50,50,50,50,50,50,50,50,50,50,50,50,50,50,50,50,50,50,50,50,50,50,50,50,50,50,50,50,50,50
50,50,50,50,50,50,50,50,50,50,50,50,50,50,50,50,50,50,50,50,50,50,50,50,50,50,50,50,50,50,50
50,50,50,50,50,50,50,50,50,50,50,50,50,50,50,50,50,50,50,50,50,50,50,50,50,50,50,50,50,50,50
50,50,50,50,50,50,50,50,50,50,50,50,50,50,50,50,50,50,50,50,50,50,50,50,50,50,50,50,50,50,1
50,50,50,50,50,50,50,50,50,50,50,50,50,50,50,50,50,50,50,50,50,50,50,50,50,50,50,50,50,50,50
50,50,1,50,50,50,50,50,50,50,50,50,50,50,50,50,50,50,50,50,50,50,50,50,50,50,50,50,50,50,50
endlayer

layer
50,50,50,50,50,50,50,50,50,50,50,50,50,50,50,50,50,50,50,50,50,50,50,50,50,50,50,50,1,50,50
50,50,50,50,50,50,50,50,50,50,0,50,0,50,50,50,50,50,50,50,50,50,50,50,50,50,50,50,50,50,50
1,50,50,50,50,50,50,50,50,50,0,0,50,50,50,50,50,50,50,50,50,50,50,50,50,50,50,50,50,50,50
50,50,50,50,50,50,50,50,50,50,50,0,50,50,50,50,50,50,50,50,50,50,50,50,50,50,50,50,50,50,50
50,50,50,50,50,50,50,50,50,50,50,50,50,50,50,50,50,50,50,50,50,50,50,50,50,50,50,50,50,50,50
50,50,50,50,50,50,50,50,50,50,50,50,50,50,50,50,50,50,50,50,50,50,50,50,50,50,50,50,50,50,50
50,50,50,50,50,50,50,50,50,50,50,50,50,50,50,50,50,50,50,50,50,50,50,50,50,50,50,50,50,50,50
50,50,50,50,50,50,50,50,50,50,50,50,50,50,50,50,50,50,50,50,50,50,50,50,50,50,50,50,50,50,50
50,50,50,50,50,50,50,50,50,50,50,50,50,50,50,50,50,50,50,50,50,50,50,50,50,50,50,50,50,50,50
50,50,50,50,62,62,62,62,0,0,0,0,0,0,0,0,0,0,0,0,0,0,0,0,0,0,50,50,50,50,50
50,50,51,51,56,56,56,51,0,0,0,0,0,0,0,0,0,0,0,0,50,50,50,50,50,0,50,50,50,50,50
50,50,51,51,0,0,0,51,0,50,50,50,50,50,50,50,50,50,50,50,50,50,50,50,50,50,50,50,50,50,50
50,50,51,51,0,0,0,51,0,50,50,50,50,50,50,50,50,50,50,50,50,50,50,50,50,50,50,50,50,50,50
50,50,51,51,0,0,0,51,51,51,51,50,50,50,50,50,50,50,50,50,50,50,50,50,50,50,50,50,50,50,50
50,50,51,0,0,0,0,0,0,0,0,51,50,50,50,50,50,50,50,50,50,50,50,50,50,50,50,50,50,50,50
50,50,51,0,0,0,0,0,0,0,46,51,50,50,50,50,50,50,50,50,50,50,50,50,50,50,50,50,50,50,50
50,50,51,0,0,0,0,0,0,0,0,51,50,50,50,50,50,50,50,50,50,50,50,50,50,50,50,50,50,50,50
50,50,50,51,0,0,0,51,51,51,51,50,50,50,50,50,50,50,50,50,50,50,50,50,50,50,50,50,50,50,50
50,50,50,51,0,0,0,51,50,50,50,50,50,50,50,50,50,50,50,50,50,50,50,50,50,50,50,50,50,50,50
50,50,50,51,0,0,0,51,50,50,50,50,50,50,50,50,50,50,50,50,50,50,50,50,50,50,50,50,50,50,50
50,50,50,51,57,57,57,51,50,50,50,50,50,50,50,50,50,50,50,50,50,50,50,50,50,50,50,50,50,50,50
50,50,50,50,60,60,60,50,50,50,50,50,50,50,50,50,50,50,50,50,50,50,50,50,50,50,50,50,50,50,50
50,50,50,50,50,50,50,50,50,50,50,50,50,50,50,50,50,50,50,50,50,50,50,50,50,50,50,50,50,50,50
50,50,50,50,50,50,50,50,50,50,50,50,50,50,50,50,50,50,50,50,50,50,50,50,50,50,50,50,50,50,50
50,50,50,50,50,50,50,50,50,50,50,50,50,50,50,50,50,50,50,50,50,50,50,50,50,50,50,50,50,50,50
50,50,50,50,50,50,50,50,50,50,50,50,50,50,50,50,50,50,50,50,50,50,50,50,50,50,50,50,50,50,50
50,50,50,50,50,50,50,50,50,50,50,50,50,50,50,50,50,50,50,50,50,50,50,50,50,50,50,50,50,50,50
50,50,50,50,50,50,50,50,50,50,50,50,50,50,50,50,50,50,50,50,50,50,50,50,50,50,50,50,50,50,50
50,50,50,50,50,50,50,50,50,50,50,50,50,50,50,50,50,50,50,50,50,50,50,50,50,50,50,50,50,50,1
50,50,50,50,50,50,50,50,50,50,50,50,50,50,50,50,50,50,50,50,50,50,50,50,50,50,50,50,50,50,50
50,50,1,50,50,50,50,50,50,50,50,50,50,50,50,50,50,50,50,50,50,50,50,50,50,50,50,50,50,50,50
endlayer

layer
63,64,64,64,64,64,64,64,64,64,63,63,63,63,63,63,63,63,63,63,63,63,63,63,63,63,63,63,63,63,63
64,51,51,51,51,51,51,51,51,51,63,63,63,63,63,63,63,63,63,63,63,63,63,63,63,63,63,63,63,50,63
64,51,51,51,51,51,51,51,51,51,63,63,63,63,63,63,63,63,63,63,63,63,63,63,63,63,63,63,63,63,63
64,51,51,51,51,51,51,51,51,51,63,63,63,63,63,63,63,63,63,63,63,63,63,63,63,63,63,63,63,63,63
64,51,51,51,51,51,51,51,51,51,51,51,51,51,51,51,51,51,51,51,51,51,51,51,51,51,51,63,63,63,63
64,51,51,51,51,51,51,51,51,51,51,51,51,51,51,51,51,51,51,51,51,51,51,51,51,51,51,63,63,63,63
64,66,51,51,51,51,51,65,65,65,65,65,65,65,65,65,65,65,65,65,65,65,65,65,65,65,51,51,63,63,63
64,66,51,51,51,51,51,65,65,65,65,65,65,65,65,65,65,65,65,65,65,65,65,65,65,65,65,51,51,63,63
64,66,51,51,51,51,51,65,65,65,65,65,65,65,65,65,65,65,65,65,65,65,65,65,65,65,65,65,51,51,64
64,51,51,51,56,56,56,65,65,65,65,65,65,65,65,65,65,65,65,65,65,65,65,65,65,65,65,65,65,51,64
64,66,51,51,0,0,0,51,65,65,65,65,65,65,65,65,65,65,65,65,65,65,65,65,65,65,65,65,65,51,64
64,66,51,51,0,0,0,51,65,65,65,65,65,65,65,65,65,65,65,65,65,65,65,65,65,65,65,65,65,51,64
64,66,51,51,0,0,0,51,65,65,65,65,65,65,65,65,65,65,65,65,65,65,65,65,65,65,65,65,65,51,64
64,51,51,51,0,0,0,51,51,51,51,51,51,51,51,51,51,51,51,51,65,65,65,65,65,65,65,65,65,51,64
64,66,51,0,0,0,0,58,58,58,58,51,23,23,23,23,23,23,23,51,65,65,65,65,65,65,65,65,65,51,64
64,66,51,0,0,0,0,58,58,58,58,51,67,64,64,67,64,64,67,51,65,65,65,65,65,65,65,65,65,65,65
64,66,51,0,0,0,0,58,58,9,9,51,23,23,23,23,23,23,23,51,65,65,65,65,65,65,65,65,65,65,65
64,51,51,51,0,0,0,51,51,51,51,51,51,51,51,51,51,51,51,51,65,65,65,65,65,65,65,65,65,51,64
64,66,51,51,0,0,0,51,65,65,65,65,65,65,65,65,65,65,65,65,65,65,65,65,65,65,65,65,65,51,64
64,66,51,51,0,0,0,51,65,65,65,65,65,65,65,65,65,65,65,65,65,65,65,65,65,65,65,65,65,51,64
64,66,51,51,0,0,0,51,65,65,65,65,65,65,65,65,65,65,65,65,65,65,65,65,65,65,65,65,65,51,64
64,51,51,51,57,57,57,51,65,65,65,65,65,65,65,65,65,65,65,65,65,65,65,65,65,65,65,65,65,51,64
64,66,51,51,51,51,51,65,65,65,65,65,65,65,65,65,65,65,65,65,65,65,65,65,65,65,65,65,65,51,64
64,66,51,51,51,51,51,65,65,65,65,65,65,65,65,65,65,65,65,65,65,65,65,65,65,65,65,65,51,51,64
64,66,51,51,51,51,51,65,65,65,65,65,65,65,65,65,65,65,65,65,65,65,65,65,65,65,65,51,51,63,63
64,51,51,51,51,51,51,65,65,65,65,65,65,65,65,65,65,65,65,65,65,65,65,65,65,65,51,51,63,63,63
64,51,51,51,51,51,51,51,51,51,51,51,51,51,51,51,51,51,51,51,51,51,51,51,51,51,51,63,63,63,63
64,51,51,51,51,51,51,51,51,51,51,51,51,51,51,51,51,51,51,51,51,51,51,51,51,51,51,63,63,63,63
64,51,51,51,51,51,51,51,51,51,63,63,63,63,63,63,63,63,63,63,63,63,63,63,63,63,63,63,63,63,63
64,51,51,51,51,51,51,51,51,51,63,63,63,63,63,63,63,63,63,63,63,63,63,63,63,63,63,63,63,50,63
63,64,64,64,64,64,64,64,64,63,63,63,63,63,63,63,63,63,63,63,63,63,63,63,63,63,63,63,63,63,63
endlayer

layer
0,70,69,69,69,69,69,69,68,0,0,0,0,0,0,0,0,0,0,0,0,0,0,0,0,0,0,0,0,36,0
69,66,23,23,23,23,23,23,64,69,0,0,0,0,0,0,0,0,0,0,0,0,0,0,0,0,0,0,40,23,71
70,23,0,0,0,43,68,0,23,68,0,0,0,0,0,0,0,0,0,0,0,0,0,0,0,0,0,0,0,49,0
70,23,0,0,0,0,0,0,23,68,0,0,0,0,0,0,0,0,0,0,0,0,0,0,0,0,0,0,0,0,0
70,23,0,0,0,0,0,0,23,68,69,69,69,69,69,69,69,69,69,69,69,69,69,69,69,69,68,0,0,0,0
72,70,23,64,0,0,0,64,23,23,23,23,23,64,23,23,23,23,23,64,23,23,23,23,23,64,64,0,0,0,0
0,0,73,0,0,0,0,0,0,0,0,0,70,64,68,0,0,0,70,64,68,0,0,0,70,64,23,64,0,0,0
0,0,73,0,0,0,0,0,0,0,0,0,0,0,0,0,0,0,0,0,0,0,0,0,0,0,0,23,64,0,0
0,0,73,0,0,0,0,0,0,0,0,0,0,0,0,0,0,0,0,0,0,0,0,0,0,0,0,0,23,64,69
0,70,23,64,0,0,0,64,68,0,0,0,70,64,68,0,0,0,70,64,68,0,0,0,70,64,0,0,0,64,68
0,0,73,0,0,0,0,74,0,0,0,0,0,72,0,0,0,0,0,72,0,0,0,0,0,72,0,0,0,23,68
0,0,73,0,0,0,0,64,0,0,0,0,0,0,0,0,0,0,0,0,0,0,0,0,0,0,0,0,0,23,68
0,0,73,0,0,0,0,74,0,0,0,0,0,0,0,0,0,0,0,0,0,0,0,0,0,0,0,0,0,23,68
0,70,23,64,0,0,0,64,74,74,74,74,0,0,0,0,0,0,0,0,0,0,0,0,0,69,0,0,0,23,68
0,0,73,0,0,0,0,75,47,47,47,71,0,0,0,0,0,0,0,0,0,0,0,0,70,64,0,0,0,64,64
0,0,73,0,0,0,0,75,47,47,47,71,0,0,0,0,0,0,0,0,0,0,0,0,0,0,0,0,0,76,0
0,0,73,0,0,0,0,75,47,47,47,71,0,0,0,0,0,0,0,0,0,0,0,0,0,0,0,0,0,76,0
0,70,23,64,0,0,0,64,74,74,74,74,0,0,0,0,0,0,0,0,0,0,0,0,70,64,0,0,0,64,64
0,0,73,0,0,0,0,74,0,0,0,0,0,0,0,0,0,0,0,0,0,0,0,0,0,72,0,0,0,23,68
0,0,73,0,0,0,0,64,0,0,0,0,0,0,0,0,0,0,0,0,0,0,0,0,0,0,0,0,0,23,68
0,0,73,0,0,0,0,74,0,0,0,0,0,0,0,0,0,0,0,69,0,0,0,0,0,69,0,0,0,23,68
0,70,23,64,0,0,0,64,68,0,0,0,70,64,68,0,0,0,70,64,68,0,0,0,70,64,0,0,0,23,68
0,0,73,0,0,0,0,0,0,0,0,0,0,0,0,0,0,0,0,0,0,0,0,0,0,0,0,0,0,64,68
0,0,73,0,0,0,0,0,0,0,0,0,0,0,0,0,0,0,0,0,0,0,0,0,0,0,0,0,23,64,72
0,0,73,0,0,0,0,0,0,0,0,0,0,0,0,0,0,0,0,0,0,0,0,0,0,0,0,23,64,0,0
69,70,23,64,0,0,0,64,68,0,0,0,70,64,68,0,0,0,70,64,68,0,0,0,0,0,23,64,0,0,0
70,23,0,0,0,0,0,0,23,23,23,23,23,64,23,23,23,23,23,64,23,23,23,23,23,64,64,0,0,0,0
70,23,0,0,0,0,0,0,23,68,72,72,72,72,72,72,72,72,72,72,72,72,72,72,72,72,68,0,0,0,0
70,23,0,0,0,43,68,0,23,68,0,0,0,0,0,0,0,0,0,0,0,0,0,0,0,0,0,0,0,36,0
72,64,23,23,23,23,23,23,64,72,0,0,0,0,0,0,0,0,0,0,0,0,0,0,0,0,0,0,40,23,71
0,70,72,72,72,72,72,72,68,0,0,0,0,0,0,0,0,0,0,0,0,0,0,0,0,0,0,0,0,49,0
endlayer

layer
0,0,0,0,0,0,0,0,0,0,0,0,0,0,0,0,0,0,0,0,0,0,0,0,0,0,0,0,0,0,0
0,77,23,73,23,23,73,23,77,0,0,0,0,0,0,0,0,0,0,0,0,0,0,0,0,0,0,0,0,23,0
0,23,0,0,43,68,0,0,23,0,0,0,0,0,0,0,0,0,0,0,0,0,0,0,0,0,0,0,0,0,0
0,73,0,0,0,0,0,0,73,0,0,0,0,0,0,0,0,0,0,0,0,0,0,0,0,0,0,0,0,0,0
0,23,0,0,0,0,0,0,23,0,0,0,0,77,0,0,0,0,0,77,0,0,0,0,0,77,0,0,0,0,0
0,77,23,64,0,0,0,64,23,23,73,73,23,64,23,73,73,73,23,64,23,73,73,73,23,64,37,0,0,0,0
0,0,73,0,0,0,0,0,0,0,0,0,0,64,0,0,0,0,0,64,0,0,0,0,0,64,23,77,0,0,0
0,0,73,0,0,0,0,0,0,0,0,0,0,0,0,0,0,0,0,0,0,0,0,0,0,0,0,23,77,0,0
0,0,73,0,0,0,0,0,0,0,0,0,0,0,0,0,0,0,0,0,0,0,0,0,0,0,0,0,23,37,0
0,77,23,64,0,0,0,64,0,0,0,0,0,64,0,0,0,0,0,64,0,0,0,0,0,64,0,0,0,64,77
0,0,73,0,0,0,0,74,0,0,0,0,0,0,0,0,0,0,0,0,0,0,0,0,0,0,0,0,0,23,0
0,0,73,0,0,0,0,64,0,0,0,0,0,0,0,0,0,0,0,0,0,0,0,0,0,0,0,0,0,73,0
0,0,73,0,0,0,0,74,0,0,0,0,0,0,0,0,0,0,0,0,0,0,0,0,0,0,0,0,0,73,0
0,77,23,64,0,0,0,64,74,74,74,74,0,0,0,0,0,0,0,0,0,0,0,0,0,0,0,0,0,23,0
0,0,73,0,0,0,0,75,78,78,78,0,0,0,0,0,0,0,0,0,0,0,0,0,0,64,0,0,0,64,77
0,0,73,0,0,0,0,73,78,81,80,0,0,0,0,0,0,0,0,0,0,0,0,0,0,0,0,0,0,79,0
0,0,73,0,0,0,0,75,78,78,78,0,0,0,0,0,0,0,0,0,0,0,0,0,0,0,0,0,0,82,0
0,77,23,64,0,0,0,64,74,74,74,74,0,0,0,0,0,0,0,0,0,0,0,0,0,64,0,0,0,64,77
0,0,73,0,0,0,0,74,0,0,0,0,0,0,0,0,0,0,0,0,0,0,0,0,0,0,0,0,0,23,0
0,0,73,0,0,0,0,64,0,0,0,0,0,0,0,0,0,0,0,0,0,0,0,0,0,0,0,0,0,73,0
0,0,73,0,0,0,0,74,0,0,0,0,0,0,0,0,0,0,0,0,0,0,0,0,0,0,0,0,0,73,0
0,77,23,64,0,0,0,64,0,0,0,0,0,64,0,0,0,0,0,64,0,0,0,0,0,64,0,0,0,23,0
0,0,73,0,0,0,0,0,0,0,0,0,0,0,0,0,0,0,0,0,0,0,0,0,0,0,0,0,0,64,77
0,0,73,0,0,0,0,0,0,0,0,0,0,0,0,0,0,0,0,0,0,0,0,0,0,0,0,0,23,37,0
0,0,73,0,0,0,0,0,0,0,0,0,0,0,0,0,0,0,0,0,0,0,0,0,0,0,0,23,77,0,0
0,77,23,64,0,0,0,64,0,0,0,0,0,64,0,0,0,0,0,64,0,0,0,0,0,0,23,77,0,0,0
0,23,0,0,0,0,0,0,23,23,73,73,23,64,23,73,73,73,23,64,23,73,73,73,23,64,37,0,0,0,0
0,73,0,0,0,0,0,0,73,0,0,0,0,0,0,0,0,0,0,0,0,0,0,0,0,77,0,0,0,0,0
0,23,0,0,43,68,0,0,23,0,0,0,0,0,0,0,0,0,0,0,0,0,0,0,0,0,0,0,0,0,0
0,77,23,73,23,23,73,23,77,0,0,0,0,0,0,0,0,0,0,0,0,0,0,0,0,0,0,0,0,23,0
0,0,0,0,0,0,0,0,0,0,0,0,0,0,0,0,0,0,0,0,0,0,0,0,0,0,0,0,0,0,0
endlayer

layer
0,0,0,0,0,0,0,0,0,0,0,0,0,0,0,0,0,0,0,0,0,0,0,0,0,0,0,0,0,0,0
0,77,23,73,23,23,73,23,77,0,0,0,0,0,0,0,0,0,0,0,0,0,0,0,0,0,0,0,0,23,0
0,23,0,43,68,0,0,0,23,0,0,0,0,0,0,0,0,0,0,0,0,0,0,0,0,0,0,0,0,0,0
0,73,0,0,0,0,0,0,73,0,0,0,0,0,0,0,0,0,0,0,0,0,0,0,0,0,0,0,0,0,0
0,23,83,0,0,0,0,83,23,0,0,0,0,77,0,0,0,0,0,77,0,0,0,0,0,77,0,0,0,0,0
0,77,23,64,0,0,0,64,23,23,73,73,23,64,23,73,73,73,23,64,23,73,73,73,23,64,37,0,0,0,0
0,0,73,83,0,0,0,0,0,0,0,0,0,64,0,0,0,0,0,64,0,0,0,0,0,64,23,77,0,0,0
0,0,73,0,0,0,0,0,0,0,0,0,0,0,0,0,0,0,0,0,0,0,0,0,0,0,0,23,77,0,0
0,0,73,83,0,0,0,0,0,0,0,0,0,0,0,0,0,0,0,0,0,0,0,0,0,0,0,0,23,37,0
0,77,23,64,0,0,0,64,0,0,0,0,0,64,0,0,0,0,0,64,0,0,0,0,0,64,0,0,0,64,77
0,0,73,83,0,0,0,74,0,0,0,0,0,0,0,0,0,0,0,0,0,0,0,0,0,0,0,0,0,23,0
0,0,73,0,0,0,0,64,0,0,0,0,0,0,0,0,0,0,0,0,0,0,0,0,0,0,0,0,0,73,0
0,0,73,83,0,0,0,74,0,0,0,0,0,0,0,0,0,0,0,0,0,0,0,0,0,0,0,0,0,73,0
0,77,23,64,0,0,0,64,0,0,0,74,0,0,0,0,0,0,0,0,0,0,0,0,0,0,0,0,0,23,0
0,0,73,83,0,0,0,75,0,0,0,0,0,0,0,0,0,0,0,0,0,0,0,0,0,64,0,0,0,64,83
0,0,73,0,0,0,0,73,0,0,0,0,0,0,0,0,0,0,0,0,0,0,0,0,0,0,0,0,0,64,0
0,0,73,83,0,0,0,75,0,0,0,0,0,0,0,0,0,0,0,0,0,0,0,0,0,0,0,0,0,64,0
0,77,23,64,0,0,0,64,0,0,0,74,0,0,0,0,0,0,0,0,0,0,0,0,0,64,0,0,0,64,83
0,0,73,83,0,0,0,74,0,0,0,0,0,0,0,0,0,0,0,0,0,0,0,0,0,0,0,0,0,23,0
0,0,73,0,0,0,0,64,0,0,0,0,0,0,0,0,0,0,0,0,0,0,0,0,0,0,0,0,0,73,0
0,0,73,83,0,0,0,74,0,0,0,0,0,0,0,0,0,0,0,0,0,0,0,0,0,0,0,0,0,73,0
0,77,23,64,0,0,0,64,0,0,0,0,0,64,0,0,0,0,0,64,0,0,0,0,0,64,0,0,0,23,0
0,0,73,83,0,0,0,0,0,0,0,0,0,0,0,0,0,0,0,0,0,0,0,0,0,0,0,0,0,64,77
0,0,73,0,0,0,0,0,0,0,0,0,0,0,0,0,0,0,0,0,0,0,0,0,0,0,0,0,23,37,0
0,0,73,83,0,0,0,0,0,0,0,0,0,0,0,0,0,0,0,0,0,0,0,0,0,0,0,23,77,0,0
0,77,23,64,0,0,0,64,0,0,0,0,0,64,0,0,0,0,0,64,0,0,0,0,0,0,23,77,0,0,0
0,23,0,0,0,0,0,0,23,23,73,73,23,64,23,73,73,73,23,64,23,73,73,73,23,64,37,0,0,0,0
0,73,0,0,0,0,0,0,73,0,0,0,0,0,0,0,0,0,0,0,0,0,0,0,0,77,0,0,0,0,0
0,23,0,43,68,0,0,0,23,0,0,0,0,0,0,0,0,0,0,0,0,0,0,0,0,0,0,0,0,0,0
0,77,23,73,23,23,73,23,77,0,0,0,0,0,0,0,0,0,0,0,0,0,0,0,0,0,0,0,0,23,0
0,0,0,0,0,0,0,0,0,0,0,0,0,0,0,0,0,0,0,0,0,0,0,0,0,0,0,0,0,0,0
endlayer

layer
0,86,85,85,85,85,85,85,84,0,0,0,0,0,0,0,0,0,0,0,0,0,0,0,0,0,0,0,0,42,0
85,64,23,23,23,23,23,23,64,85,0,0,0,0,0,0,0,0,0,0,0,0,0,0,0,0,0,0,43,87,44
86,23,88,68,0,0,0,47,23,84,0,0,0,0,0,0,0,0,0,0,0,0,0,0,0,0,0,0,0,45,0
86,23,47,47,47,47,47,47,23,84,0,0,0,0,0,0,0,0,0,0,0,0,0,0,0,0,0,0,0,0,0
86,23,47,47,47,47,47,47,23,84,0,0,0,77,0,0,0,0,0,77,0,0,0,0,0,77,0,0,0,0,0
0,89,23,64,64,64,64,64,23,23,73,73,23,64,23,73,73,73,23,64,23,73,73,73,23,64,37,0,0,0,0
0,86,23,64,75,75,75,89,83,0,0,0,83,64,83,0,0,0,83,64,83,0,0,0,83,64,23,77,0,0,0
0,86,23,64,75,90,75,66,0,0,0,0,0,89,0,0,0,0,0,89,0,0,0,0,0,89,0,23,77,0,0
0,86,23,64,75,75,75,85,0,0,0,0,0,85,0,0,0,0,0,85,0,0,0,0,0,85,0,0,23,37,0
0,86,23,64,64,64,64,64,84,0,0,0,86,64,84,0,0,0,86,64,84,0,0,0,86,64,0,0,86,64,77
0,86,23,64,75,75,75,72,0,0,0,0,0,0,0,0,0,0,0,0,0,0,0,0,0,89,0,0,83,23,0
0,86,23,64,75,90,75,77,0,0,0,0,0,0,0,0,0,0,0,0,0,0,0,0,0,0,0,0,0,73,0
0,86,23,64,75,75,75,69,0,0,0,0,0,0,0,0,0,0,0,0,0,0,0,0,0,0,0,0,0,73,0
0,86,23,64,64,64,64,64,0,0,0,74,83,0,0,0,0,0,0,0,0,0,0,0,0,85,0,0,83,23,0
0,86,23,64,75,75,75,75,0,0,0,0,0,0,0,0,0,0,0,0,0,0,0,0,0,64,84,0,86,64,0
0,86,23,64,75,90,75,75,0,0,0,0,0,0,0,0,0,0,0,0,0,0,0,0,0,89,0,0,0,23,0
0,86,23,64,75,75,75,75,0,0,0,0,0,0,0,0,0,0,0,0,0,0,0,0,0,85,0,0,0,23,0
0,86,23,64,64,64,64,64,0,0,0,74,83,0,0,0,0,0,0,0,0,0,0,0,0,64,0,0,0,64,0
0,86,23,64,75,75,75,72,0,0,0,0,0,0,0,0,0,0,0,0,0,0,0,0,0,89,0,0,83,23,0
0,86,23,64,75,90,75,77,0,0,0,0,0,0,0,0,0,0,0,0,0,0,0,0,0,0,0,0,0,73,0
0,86,23,64,75,75,75,69,0,0,0,0,0,0,0,0,0,0,0,0,0,0,0,0,0,85,0,0,0,73,0
0,86,23,64,64,64,64,64,84,0,0,0,86,64,84,0,0,0,86,64,84,0,0,0,86,64,0,0,83,23,0
0,86,23,64,75,75,75,89,0,0,0,0,0,64,0,0,0,0,0,89,0,0,0,0,0,89,0,0,86,64,77
0,86,23,64,75,90,75,66,0,0,0,0,0,64,0,0,0,0,0,0,0,0,0,0,0,0,0,0,23,37,0
0,86,23,64,75,75,75,85,0,0,0,0,0,64,0,0,0,0,0,85,0,0,0,0,0,0,0,23,77,0,0
0,85,23,64,64,64,64,64,83,0,0,0,83,64,83,0,0,0,83,64,83,0,0,0,83,85,23,77,0,0,0
86,23,47,47,47,47,47,47,23,23,73,73,23,64,23,73,73,73,23,64,23,73,73,73,23,64,37,0,0,0,0
86,23,47,47,47,47,47,47,23,84,0,0,0,0,0,0,0,0,0,0,0,0,0,0,0,77,0,0,0,0,0
86,23,88,68,0,0,0,47,23,84,0,0,0,0,0,0,0,0,0,0,0,0,0,0,0,0,0,0,0,42,0
89,64,23,23,23,23,23,23,64,89,0,0,0,0,0,0,0,0,0,0,0,0,0,0,0,0,0,0,43,87,44
0,86,89,89,89,89,89,89,84,0,0,0,0,0,0,0,0,0,0,0,0,0,0,0,0,0,0,0,0,45,0
endlayer

layer
0,70,69,69,69,69,69,69,68,0,0,0,0,0,0,0,0,0,0,0,0,0,0,0,0,0,0,0,0,49,0
69,64,23,23,23,23,23,23,64,69,0,0,0,0,0,0,0,0,0,0,0,0,0,0,0,0,0,0,71,91,40
70,23,0,0,0,0,68,0,23,68,0,0,0,0,0,0,0,0,0,0,0,0,0,0,0,0,0,0,0,36,0
70,23,0,0,0,0,0,0,23,68,0,0,0,0,0,0,0,0,0,0,0,0,0,0,0,0,0,0,0,0,0
70,23,23,0,0,0,0,0,23,64,85,85,85,85,85,85,85,85,85,85,85,85,85,85,85,85,84,0,0,0,0
0,72,70,23,0,0,0,23,23,23,23,23,23,64,23,23,23,23,23,64,23,23,23,23,23,64,64,0,0,0,0
0,0,93,23,0,0,0,93,93,93,93,93,93,64,64,64,64,64,64,64,92,92,92,92,92,64,23,64,0,0,0
0,0,93,23,0,0,0,93,93,93,93,93,93,93,64,64,64,64,64,64,92,92,92,92,92,92,92,23,64,0,0
0,0,93,23,0,0,0,93,93,93,93,93,93,93,64,64,64,64,64,64,92,92,92,92,92,92,92,92,23,64,85
0,0,70,23,0,0,64,64,64,64,64,64,64,64,64,64,64,64,64,75,64,64,64,64,64,64,92,92,64,64,84
0,0,93,23,0,0,90,77,0,0,0,0,0,89,0,0,0,0,0,83,0,0,0,0,0,64,92,92,47,23,84
0,0,93,23,0,0,90,77,0,0,0,0,0,0,0,0,0,0,0,0,0,0,0,0,0,64,92,92,47,23,84
0,0,93,23,0,0,90,77,0,0,0,0,0,0,0,0,0,0,0,0,0,0,0,0,0,64,92,92,47,23,84
0,0,70,23,0,0,64,64,74,74,74,74,0,0,0,0,0,0,0,0,0,0,0,0,0,64,92,92,47,23,84
0,0,93,23,0,0,90,74,0,0,0,74,0,0,0,0,0,0,0,0,0,0,0,0,83,75,64,64,64,23,84
0,0,93,23,0,0,90,75,0,0,0,74,0,0,0,0,0,0,0,0,0,0,0,0,0,64,92,92,66,64,84
0,0,93,23,0,0,90,74,0,0,0,74,0,0,0,0,0,0,0,0,0,0,0,0,0,64,92,92,66,64,84
0,0,70,23,0,0,64,64,74,74,74,74,0,0,0,0,0,0,0,0,0,0,0,0,83,75,64,64,64,23,84
0,0,93,23,0,0,90,77,0,0,0,0,0,0,0,0,0,0,0,0,0,0,0,0,0,64,92,92,47,23,84
0,0,93,23,0,0,90,77,0,0,0,0,0,0,0,0,0,0,0,0,0,0,0,0,0,64,92,92,47,23,84
0,0,93,23,0,0,90,77,0,0,0,0,0,85,0,0,0,0,0,83,0,0,0,0,0,64,92,92,47,23,84
0,0,70,23,0,0,64,64,64,64,64,64,64,64,64,64,64,64,64,75,64,64,64,64,64,64,92,92,47,23,84
0,0,93,23,0,0,0,93,93,93,93,93,93,64,64,64,64,64,64,64,92,92,92,92,92,92,92,92,64,64,84
0,0,93,23,0,0,0,93,93,93,93,93,93,64,64,64,64,64,64,64,92,92,92,92,92,92,92,92,23,64,0
0,0,93,23,0,0,0,93,93,93,93,93,93,64,64,64,64,64,64,64,92,92,92,92,92,92,92,23,64,0,0
0,69,70,23,0,0,0,23,64,93,93,93,93,64,64,64,64,64,64,64,92,92,92,92,92,92,23,64,0,0,0
70,23,23,23,0,0,0,0,23,23,23,23,23,64,23,23,23,23,23,64,23,23,23,23,23,64,64,0,0,0,0
70,23,0,0,0,0,0,0,23,64,89,89,89,89,89,89,89,89,89,89,89,89,89,89,89,84,0,0,0,0,0
70,23,0,0,0,0,68,0,23,68,0,0,0,0,0,0,0,0,0,0,0,0,0,0,0,0,0,0,0,49,0
72,64,23,23,23,23,23,23,64,72,0,0,0,0,0,0,0,0,0,0,0,0,0,0,0,0,0,0,71,91,40
0,70,72,72,72,72,72,72,68,0,0,0,0,0,0,0,0,0,0,0,0,0,0,0,0,0,0,0,0,36,0
endlayer

layer
0,0,0,0,0,0,0,0,0,0,0,0,0,0,0,0,0,0,0,0,0,0,0,0,0,0,0,0,0,0,0
0,77,23,73,23,23,73,23,77,0,0,0,0,0,0,0,0,0,0,0,0,0,0,0,0,0,0,0,0,0,0
0,23,0,0,0,68,0,0,23,0,0,0,0,0,0,0,0,0,0,0,0,0,0,0,0,0,0,0,0,0,0
0,73,0,0,0,0,0,0,73,0,0,0,0,0,0,0,0,0,0,0,0,0,0,0,0,0,0,0,0,0,0
0,23,23,0,0,0,0,0,23,77,0,0,0,77,0,0,0,0,0,77,0,0,0,0,0,77,0,0,0,0,0
0,0,77,23,0,0,0,23,23,23,77,77,23,64,23,77,77,77,23,64,23,77,77,77,23,64,37,0,0,0,0
0,0,0,77,0,0,0,0,0,0,0,0,0,64,0,0,0,0,0,64,0,0,0,0,0,64,64,0,0,0,0
0,0,0,77,0,0,0,0,0,0,0,0,0,0,0,0,0,0,0,0,0,0,0,0,0,0,0,23,0,0,0
0,0,0,77,0,0,0,0,0,0,0,0,0,0,0,0,0,0,0,0,0,0,0,0,0,0,0,0,64,37,0
0,0,77,23,0,0,64,64,94,94,94,94,94,64,77,77,77,77,77,64,77,77,77,77,77,64,0,0,64,64,68
0,0,0,77,0,0,90,77,0,0,0,0,0,69,0,0,0,0,0,0,0,0,0,0,0,77,0,0,23,68,0
0,0,0,77,0,0,90,77,0,0,0,0,0,89,0,0,0,0,0,0,0,0,0,0,0,77,0,0,23,68,0
0,0,0,77,0,0,90,77,0,0,0,0,0,0,0,0,0,0,0,0,0,0,0,0,0,77,0,0,23,68,0
0,0,77,23,0,0,64,64,0,0,0,74,0,0,0,0,0,0,0,0,0,0,0,0,0,77,0,0,23,68,0
0,0,0,77,0,0,90,0,0,0,0,0,0,0,0,0,0,0,0,0,0,0,0,0,0,64,0,0,64,23,71
0,0,0,77,0,0,90,75,0,0,0,0,0,0,0,0,0,0,0,0,0,0,0,0,0,77,0,0,64,37,48
0,0,0,77,0,0,90,0,0,0,0,0,0,0,0,0,0,0,0,0,0,0,0,0,0,77,0,0,64,37,48
0,0,77,23,0,0,64,64,0,0,0,74,0,0,0,0,0,0,0,0,0,0,0,0,0,64,0,0,64,23,71
0,0,0,77,0,0,90,77,0,0,0,0,0,0,0,0,0,0,0,0,0,0,0,0,0,77,0,0,23,68,0
0,0,0,77,0,0,90,77,0,0,0,0,0,85,0,0,0,0,0,0,0,0,0,0,0,77,0,0,23,68,0
0,0,0,77,0,0,90,77,0,0,0,0,0,72,0,0,0,0,0,0,0,0,0,0,0,77,0,0,23,68,0
0,0,77,23,0,0,64,64,94,94,94,94,94,64,77,77,77,77,77,64,77,77,77,77,77,64,0,0,23,68,0
0,0,0,77,0,0,0,0,0,0,0,0,0,0,0,0,0,0,0,0,0,0,0,0,0,0,0,0,64,64,68
0,0,0,77,0,0,0,0,0,0,0,0,0,0,0,0,0,0,0,0,0,0,0,0,0,0,0,0,64,37,0
0,0,0,77,0,0,0,0,0,0,0,0,0,0,0,0,0,0,0,0,0,0,0,0,0,0,0,23,0,0,0
0,0,77,23,0,0,0,23,23,0,0,0,0,64,0,0,0,0,0,64,0,0,0,0,0,0,64,0,0,0,0
0,23,23,23,0,0,0,0,23,77,77,77,23,64,23,77,77,77,23,64,23,77,77,77,23,64,37,0,0,0,0
0,73,0,0,0,0,0,0,73,0,0,0,0,77,0,0,0,0,0,77,0,0,0,0,0,77,0,0,0,0,0
0,23,0,0,0,68,0,0,23,0,0,0,0,0,0,0,0,0,0,0,0,0,0,0,0,0,0,0,0,0,0
0,77,23,73,23,23,73,23,77,0,0,0,0,0,0,0,0,0,0,0,0,0,0,0,0,0,0,0,0,0,0
0,0,0,0,0,0,0,0,0,0,0,0,0,0,0,0,0,0,0,0,0,0,0,0,0,0,0,0,0,0,0
endlayer

layer
0,0,0,0,0,0,0,0,0,0,0,0,0,0,0,0,0,0,0,0,0,0,0,0,0,0,0,0,0,0,0
0,77,23,73,23,23,73,23,77,0,0,0,0,0,0,0,0,0,0,0,0,0,0,0,0,0,0,0,0,0,0
0,23,83,0,68,0,0,0,23,0,0,0,0,0,0,0,0,0,0,0,0,0,0,0,0,0,0,0,0,0,0
0,73,0,0,0,0,0,0,73,0,0,0,0,0,0,0,0,0,0,0,0,0,0,0,0,0,0,0,0,0,0
0,23,23,0,0,0,0,0,23,77,0,0,0,77,0,0,0,0,0,77,0,0,0,0,0,77,0,0,0,0,0
0,0,77,23,0,0,0,23,23,23,77,77,23,64,23,77,77,77,23,64,23,77,77,77,23,64,37,0,0,0,0
0,0,0,77,0,0,0,0,0,0,0,0,0,64,0,0,0,0,0,64,0,0,0,0,0,64,64,0,0,0,0
0,0,0,77,0,0,0,0,0,0,0,0,0,0,0,0,0,0,0,0,0,0,0,0,0,0,0,77,0,0,0
0,0,0,77,0,0,0,0,0,0,0,0,0,0,0,0,0,0,0,0,0,0,0,0,0,0,0,0,64,37,0
0,0,77,23,0,0,69,69,94,0,0,0,94,64,0,0,0,0,0,64,0,0,0,0,0,64,0,0,64,64,77
0,0,0,77,0,0,90,89,0,0,0,0,0,0,0,0,0,0,0,0,0,0,0,0,0,0,0,0,23,95,0
0,0,0,77,0,0,90,77,0,0,0,0,0,69,0,0,0,0,0,0,0,0,0,0,0,0,0,0,73,0,0
0,0,0,77,0,0,90,85,0,0,0,0,0,89,0,0,0,0,0,0,0,0,0,0,0,0,0,0,73,0,0
0,0,77,23,0,0,72,72,0,0,0,74,0,0,0,0,0,0,0,0,0,0,0,0,0,0,0,0,23,95,0
0,0,0,77,0,0,90,0,0,0,0,0,0,0,0,0,0,0,0,0,0,0,0,0,0,64,0,0,64,37,0
0,0,0,77,0,0,90,75,0,0,0,0,0,0,0,0,0,0,0,0,0,0,0,0,0,0,0,0,73,0,0
0,0,0,77,0,0,90,0,0,0,0,0,0,0,0,0,0,0,0,0,0,0,0,0,0,0,0,0,73,0,0
0,0,77,23,0,0,69,69,0,0,0,74,0,0,0,0,0,0,0,0,0,0,0,0,0,64,0,0,64,37,0
0,0,0,77,0,0,90,89,0,0,0,0,0,85,0,0,0,0,0,0,0,0,0,0,0,0,0,0,23,95,0
0,0,0,77,0,0,90,77,0,0,0,0,0,72,0,0,0,0,0,0,0,0,0,0,0,0,0,0,73,0,0
0,0,0,77,0,0,90,85,0,0,0,0,0,0,0,0,0,0,0,0,0,0,0,0,0,0,0,0,73,0,0
0,0,77,23,0,0,72,72,0,0,0,0,0,64,0,0,0,0,0,64,0,0,0,0,0,64,0,0,23,95,0
0,0,0,77,0,0,0,0,0,0,0,0,0,0,0,0,0,0,0,0,0,0,0,0,0,0,0,0,64,64,77
0,0,0,77,0,0,0,0,0,0,0,0,0,0,0,0,0,0,0,0,0,0,0,0,0,0,0,0,64,37,0
0,0,0,77,0,0,0,0,0,0,0,0,0,0,0,0,0,0,0,0,0,0,0,0,0,0,0,77,0,0,0
0,0,77,23,0,0,0,23,23,0,0,0,0,64,0,0,0,0,0,64,0,0,0,0,0,0,64,0,0,0,0
0,23,23,23,0,0,0,0,23,77,77,77,23,64,23,77,77,77,23,64,23,77,77,77,23,64,37,0,0,0,0
0,73,0,0,0,0,0,0,73,0,0,0,0,77,0,0,0,0,0,77,0,0,0,0,0,77,0,0,0,0,0
0,23,83,0,68,0,0,0,23,0,0,0,0,0,0,0,0,0,0,0,0,0,0,0,0,0,0,0,0,0,0
0,77,23,73,23,23,73,23,77,0,0,0,0,0,0,0,0,0,0,0,0,0,0,0,0,0,0,0,0,0,0
0,0,0,0,0,0,0,0,0,0,0,0,0,0,0,0,0,0,0,0,0,0,0,0,0,0,0,0,0,0,0
endlayer

layer
0,0,85,85,85,85,85,85,0,0,0,0,0,0,0,0,0,0,0,0,0,0,0,0,0,0,0,0,0,0,0
0,64,23,23,23,23,23,23,64,0,0,0,0,0,0,0,0,0,0,0,0,0,0,0,0,0,0,0,0,0,0
86,23,23,68,0,0,0,23,23,84,0,0,0,0,0,0,0,0,0,0,0,0,0,0,0,0,0,0,0,0,0
86,23,23,23,23,23,23,23,23,84,0,0,0,0,0,0,0,0,0,0,0,0,0,0,0,0,0,0,0,0,0
86,23,23,23,23,23,23,23,23,64,85,85,85,85,85,85,85,85,85,85,85,85,85,85,85,85,0,0,0,0,0
0,89,86,23,45,45,45,23,23,23,0,23,23,64,23,23,23,23,23,64,23,23,23,23,23,64,37,0,0,0,0
0,0,0,23,0,0,0,0,83,0,0,0,83,64,83,0,0,0,83,64,83,0,0,0,83,64,64,0,0,0,0
0,0,0,77,0,0,0,0,0,0,0,0,0,89,0,0,0,0,0,89,0,0,0,0,0,89,0,23,0,0,0
0,0,0,23,0,0,0,0,0,0,0,0,0,85,0,0,0,0,0,85,0,0,0,0,0,85,0,0,64,37,0
0,0,86,23,0,0,85,0,94,94,94,94,94,64,84,0,0,0,86,64,84,0,0,0,86,64,84,0,64,64,77
0,0,0,23,0,0,90,69,0,0,0,0,0,89,0,0,0,0,0,89,0,0,0,0,0,89,0,83,23,96,0
0,0,0,77,0,0,90,64,0,0,0,0,0,0,0,0,0,0,0,0,0,0,0,0,0,0,0,0,73,0,0
0,0,0,23,0,0,90,72,0,0,0,74,0,69,0,0,0,0,0,0,0,0,0,0,0,0,0,0,73,0,0
0,0,86,23,0,0,74,74,74,74,74,74,74,89,0,0,0,0,0,0,0,0,0,0,0,85,0,83,23,95,0
0,0,0,23,0,0,90,74,0,0,0,74,0,0,0,0,0,0,0,0,0,0,0,0,86,64,84,0,64,37,0
0,0,0,77,0,0,90,75,0,0,0,74,0,0,83,0,0,0,0,83,0,0,0,0,0,89,0,0,73,0,0
0,0,0,23,0,0,90,74,0,0,0,74,0,0,0,0,0,0,0,0,0,0,0,0,0,85,0,0,73,0,0
0,0,86,23,0,0,74,74,74,74,74,74,74,85,0,0,0,0,0,0,0,0,0,0,86,64,0,0,64,37,0
0,0,0,23,0,0,90,69,0,0,0,74,0,72,0,0,0,0,0,0,0,0,0,0,0,89,0,83,23,95,0
0,0,0,77,0,0,90,64,0,0,0,0,0,0,0,0,0,0,0,0,0,0,0,0,0,0,0,0,73,0,0
0,0,0,23,0,0,90,72,0,0,0,0,0,85,0,0,0,0,0,85,0,0,0,0,0,85,0,0,73,0,0
0,0,86,23,0,0,89,0,0,0,0,0,86,64,84,0,0,0,86,64,84,0,0,0,86,64,0,83,23,95,0
0,0,0,23,0,0,0,0,0,0,0,0,0,89,0,0,0,0,0,89,0,0,0,0,0,0,0,0,64,64,77
0,0,0,77,0,0,0,0,0,0,0,0,0,0,0,0,0,0,0,0,0,0,0,0,0,0,0,0,64,37,0
0,0,0,23,0,0,0,0,0,0,0,0,0,85,0,0,0,0,0,85,0,0,0,0,0,0,0,23,0,0,0
0,85,86,23,42,42,42,23,23,83,0,0,83,64,83,0,0,0,83,64,83,0,0,0,83,85,64,0,0,0,0
86,23,23,23,23,23,23,23,23,23,23,23,23,64,23,23,23,23,23,64,23,23,23,23,23,64,37,0,0,0,0
86,23,23,23,23,23,23,23,23,89,89,89,89,89,89,89,89,89,89,89,89,89,89,89,89,89,84,0,0,0,0
86,23,23,68,0,0,0,23,23,84,0,0,0,0,0,0,0,0,0,0,0,0,0,0,0,0,0,0,0,0,0
89,0,23,23,23,23,23,23,0,89,0,0,0,0,0,0,0,0,0,0,0,0,0,0,0,0,0,0,0,0,0
0,86,89,89,89,89,89,89,84,0,0,0,0,0,0,0,0,0,0,0,0,0,0,0,0,0,0,0,0,0,0
endlayer

layer
0,0,0,0,0,0,0,0,0,0,0,0,0,0,0,0,0,0,0,0,0,0,0,0,0,0,0,0,0,0,0
0,37,64,64,64,64,64,64,37,0,0,0,0,0,0,0,0,0,0,0,0,0,0,0,0,0,0,0,0,0,0
0,64,0,0,0,0,0,0,64,0,0,0,0,0,0,0,0,0,0,0,0,0,0,0,0,0,0,0,0,0,0
0,64,0,0,0,0,0,0,64,0,0,0,0,0,0,0,0,0,0,0,0,0,0,0,0,0,0,0,0,0,0
0,64,0,0,0,0,0,0,64,0,0,0,0,0,0,0,0,0,0,0,0,0,0,0,0,0,0,0,0,0,0
0,37,64,64,64,64,64,64,64,64,64,64,64,64,64,64,64,64,64,64,64,64,64,64,64,64,64,0,0,0,0
0,0,64,93,93,93,93,48,48,48,48,48,48,93,48,48,48,48,48,93,48,48,48,48,48,93,93,64,0,0,0
0,0,64,93,93,93,93,48,48,48,48,48,48,93,48,48,48,48,48,93,48,48,48,48,48,93,48,93,64,0,0
0,0,64,93,93,93,93,48,48,48,48,48,48,93,48,48,48,48,48,93,48,48,48,48,48,93,48,48,64,64,85
0,0,64,93,93,93,93,48,48,48,48,48,48,93,93,93,93,93,93,93,93,93,93,93,93,93,93,93,64,64,84
0,0,64,93,93,93,93,48,48,48,48,48,48,93,48,48,48,48,48,93,48,48,48,48,48,93,48,48,23,94,89
0,0,64,93,93,93,93,93,93,93,93,93,93,93,48,48,48,48,48,93,48,48,48,48,48,93,48,48,23,94,0
0,0,64,93,93,93,93,48,48,48,48,48,48,93,48,48,48,48,48,93,48,48,48,48,48,93,48,48,23,94,0
0,0,64,93,93,93,93,48,88,88,88,48,48,93,48,48,48,48,48,93,48,48,48,48,48,93,48,48,23,94,0
0,0,64,93,93,93,93,88,90,90,90,88,48,93,48,48,48,48,48,93,93,93,93,93,93,93,93,93,64,37,0
0,0,64,93,93,93,93,88,90,90,90,88,48,93,93,93,93,93,93,93,48,48,48,48,48,93,48,48,64,37,0
0,0,64,93,93,93,93,88,90,90,90,88,48,93,93,93,93,93,93,93,48,48,48,48,48,93,48,48,64,37,0
0,0,64,93,93,93,93,48,88,88,88,48,48,93,48,48,48,48,48,93,93,93,93,93,93,93,93,93,64,37,0
0,0,64,93,93,93,93,48,48,48,48,48,48,93,48,48,48,48,48,93,48,48,48,48,48,93,48,48,23,94,0
0,0,64,93,93,93,93,93,93,93,93,93,93,93,48,48,48,48,48,93,48,48,48,48,48,93,48,48,23,94,0
0,0,64,93,93,93,93,48,48,48,48,48,48,93,48,48,48,48,48,93,48,48,48,48,48,93,48,48,23,94,0
0,0,64,93,93,93,93,48,48,48,48,48,48,93,93,93,93,93,93,93,93,93,93,93,93,93,93,93,23,94,85
0,0,64,93,93,93,93,48,48,48,48,48,48,93,48,48,48,48,48,93,48,48,48,48,48,93,48,48,64,64,84
0,0,64,93,93,93,93,48,48,48,48,48,48,93,48,48,48,48,48,93,48,48,48,48,48,93,48,48,64,64,89
0,0,64,93,93,93,93,48,48,48,48,48,48,93,48,48,48,48,48,93,48,48,48,48,48,93,48,93,64,0,0
0,64,64,64,64,64,64,64,64,48,48,48,48,93,48,48,48,48,48,93,48,48,48,48,48,93,93,64,0,0,0
0,64,0,0,0,0,0,0,64,64,64,64,64,64,64,64,64,64,64,64,64,64,64,64,64,64,64,0,0,0,0
0,64,0,0,0,0,0,0,64,0,0,0,0,0,0,0,0,0,0,0,0,0,0,0,0,0,0,0,0,0,0
0,64,0,0,0,0,0,9,64,0,0,0,0,0,0,0,0,0,0,0,0,0,0,0,0,0,0,0,0,0,0
0,64,64,64,64,64,64,64,64,0,0,0,0,0,0,0,0,0,0,0,0,0,0,0,0,0,0,0,0,0,0
0,0,0,0,0,0,0,0,0,0,0,0,0,0,0,0,0,0,0,0,0,0,0,0,0,0,0,0,0,0,0
endlayer

layer
0,0,0,0,0,0,0,0,0,0,0,0,0,0,0,0,0,0,0,0,0,0,0,0,0,0,0,0,0,0,0
0,37,37,0,37,37,0,37,37,0,0,0,0,0,0,0,0,0,0,0,0,0,0,0,0,0,0,0,0,0,0
0,37,0,0,0,0,0,0,37,0,0,0,0,0,0,0,0,0,0,0,0,0,0,0,0,0,0,0,0,0,0
0,0,0,0,0,0,0,0,0,0,0,0,0,0,0,0,0,0,0,0,0,0,0,0,0,0,0,0,0,0,0
0,37,0,0,0,0,0,0,37,0,0,0,0,0,0,0,0,0,0,0,0,0,0,0,0,0,0,0,0,0,0
0,37,37,0,37,37,0,37,37,0,0,37,37,0,37,37,0,37,37,0,37,37,0,37,37,0,37,0,0,0,0
0,0,0,0,0,0,0,0,0,0,0,0,0,0,0,0,0,0,0,0,0,0,0,0,0,0,0,37,0,0,0
0,0,37,0,0,0,0,0,0,0,0,0,0,0,0,0,0,0,0,0,0,0,0,0,0,0,0,0,37,0,0
0,0,37,0,0,0,0,0,0,0,0,0,0,0,0,0,0,0,0,0,0,0,0,0,0,0,0,0,0,37,37
0,0,0,0,0,0,0,0,0,0,0,0,0,0,0,0,0,0,0,0,0,0,0,0,0,0,0,0,0,0,37
0,0,37,0,0,0,0,0,0,0,0,0,0,0,0,0,0,0,0,0,0,0,0,0,0,0,0,0,0,94,0
0,0,37,0,0,0,0,0,0,0,0,0,0,0,0,0,0,0,0,0,0,0,0,0,0,0,0,0,0,94,0
0,0,0,0,0,0,0,0,0,0,0,0,0,0,0,0,0,0,0,0,0,0,0,0,0,0,0,0,0,94,0
0,0,37,0,0,0,0,0,0,0,0,0,0,0,0,0,0,0,0,0,0,0,0,0,0,0,0,0,0,0,0
0,0,37,0,0,0,0,0,0,0,0,0,0,0,0,0,0,0,0,0,0,0,0,0,0,0,0,0,0,37,0
0,0,0,0,0,0,0,0,0,0,0,0,0,0,0,0,0,0,0,0,0,0,0,0,0,0,0,0,0,37,0
0,0,37,0,0,0,0,0,0,0,0,0,0,0,0,0,0,0,0,0,0,0,0,0,0,0,0,0,0,37,0
0,0,37,0,0,0,0,0,0,0,0,0,0,0,0,0,0,0,0,0,0,0,0,0,0,0,0,0,0,37,0
0,0,0,0,0,0,0,0,0,0,0,0,0,0,0,0,0,0,0,0,0,0,0,0,0,0,0,0,0,0,0
0,0,37,0,0,0,0,0,0,0,0,0,0,0,0,0,0,0,0,0,0,0,0,0,0,0,0,0,0,94,0
0,0,37,0,0,0,0,0,0,0,0,0,0,0,0,0,0,0,0,0,0,0,0,0,0,0,0,0,0,94,0
0,0,0,0,0,0,0,0,0,0,0,0,0,0,0,0,0,0,0,0,0,0,0,0,0,0,0,0,0,94,0
0,0,37,0,0,0,0,0,0,0,0,0,0,0,0,0,0,0,0,0,0,0,0,0,0,0,0,0,0,0,37
0,0,37,0,0,0,0,0,0,0,0,0,0,0,0,0,0,0,0,0,0,0,0,0,0,0,0,0,0,37,37
0,0,0,0,0,0,0,0,0,0,0,0,0,0,0,0,0,0,0,0,0,0,0,0,0,0,0,0,37,0,0
0,37,37,0,37,37,0,37,37,0,0,0,0,0,0,0,0,0,0,0,0,0,0,0,0,0,0,37,0,0,0
0,37,0,0,0,0,0,0,37,0,0,37,37,0,37,37,0,37,37,0,37,37,0,37,37,0,37,0,0,0,0
0,0,0,0,0,0,0,0,0,0,0,0,0,0,0,0,0,0,0,0,0,0,0,0,0,0,0,0,0,0,0
0,37,0,0,0,0,0,0,37,0,0,0,0,0,0,0,0,0,0,0,0,0,0,0,0,0,0,0,0,0,0
0,37,37,0,37,37,0,37,37,0,0,0,0,0,0,0,0,0,0,0,0,0,0,0,0,0,0,0,0,0,0
0,0,0,0,0,0,0,0,0,0,0,0,0,0,0,0,0,0,0,0,0,0,0,0,0,0,0,0,0,0,0
endlayer

layer
0,0,0,0,0,0,0,0,0,0,0,0,0,0,0,0,0,0,0,0,0,0,0,0,0,0,0,0,0,0,0
0,0,0,0,0,0,0,0,0,0,0,0,0,0,0,0,0,0,0,0,0,0,0,0,0,0,0,0,0,0,0
0,0,0,0,0,0,0,0,0,0,0,0,0,0,0,0,0,0,0,0,0,0,0,0,0,0,0,0,0,0,0
0,0,0,0,0,0,0,0,0,0,0,0,0,0,0,0,0,0,0,0,0,0,0,0,0,0,0,0,0,0,0
0,0,0,0,0,0,0,0,0,0,0,0,0,0,0,0,0,0,0,0,0,0,0,0,0,0,0,0,0,0,0
0,0,0,0,0,0,0,0,0,0,0,0,0,0,0,0,0,0,0,0,0,0,0,0,0,0,0,0,0,0,0
0,0,0,0,0,0,0,0,0,0,0,0,0,0,0,0,0,0,0,0,0,0,0,0,0,0,0,0,0,0,0
0,0,0,0,0,0,0,0,0,0,0,0,0,0,0,0,0,0,0,0,0,0,0,0,0,0,0,0,0,0,0
0,0,0,0,0,0,0,0,0,0,0,0,0,0,0,0,0,0,0,0,0,0,0,0,0,0,0,0,0,0,0
0,0,0,0,0,0,0,0,0,0,0,0,0,0,0,0,0,0,0,0,0,0,0,0,0,0,0,0,0,0,0
0,0,0,0,0,0,0,0,0,0,0,0,0,0,0,0,0,0,0,0,0,0,0,0,0,0,0,0,0,0,0
0,0,0,0,0,0,0,0,0,0,0,0,0,0,0,0,0,0,0,0,0,0,0,0,0,0,0,0,0,0,0
0,0,0,0,0,0,0,0,0,0,0,0,0,0,0,0,0,0,0,0,0,0,0,0,0,0,0,0,0,0,0
0,0,0,0,0,0,0,0,0,0,0,0,0,0,0,0,0,0,0,0,0,0,0,0,0,0,0,0,0,0,0
0,0,0,0,0,0,0,0,0,0,0,0,0,0,0,0,0,0,0,0,0,0,0,0,0,0,0,0,0,0,0
0,0,0,0,0,0,0,0,0,0,0,0,0,0,0,0,0,0,0,0,0,0,0,0,0,0,0,0,0,0,0
0,0,0,0,0,0,0,0,0,0,0,0,0,0,0,0,0,0,0,0,0,0,0,0,0,0,0,0,0,0,0
0,0,0,0,0,0,0,0,0,0,0,0,0,0,0,0,0,0,0,0,0,0,0,0,0,0,0,0,0,0,0
0,0,0,0,0,0,0,0,0,0,0,0,0,0,0,0,0,0,0,0,0,0,0,0,0,0,0,0,0,0,0
0,0,0,0,0,0,0,0,0,0,0,0,0,0,0,0,0,0,0,0,0,0,0,0,0,0,0,0,0,0,0
0,0,0,0,0,0,0,0,0,0,0,0,0,0,0,0,0,0,0,0,0,0,0,0,0,0,0,0,0,0,0
0,0,0,0,0,0,0,0,0,0,0,0,0,0,0,0,0,0,0,0,0,0,0,0,0,0,0,0,0,0,0
0,0,0,0,0,0,0,0,0,0,0,0,0,0,0,0,0,0,0,0,0,0,0,0,0,0,0,0,0,0,0
0,0,0,0,0,0,0,0,0,0,0,0,0,0,0,0,0,0,0,0,0,0,0,0,0,0,0,0,0,0,0
0,0,0,0,0,0,0,0,0,0,0,0,0,0,0,0,0,0,0,0,0,0,0,0,0,0,0,0,0,0,0
0,0,0,0,0,0,0,0,0,0,0,0,0,0,0,0,0,0,0,0,0,0,0,0,0,0,0,0,0,0,0
0,0,0,0,0,0,0,0,0,0,0,0,0,0,0,0,0,0,0,0,0,0,0,0,0,0,0,0,0,0,0
0,0,0,0,0,0,0,0,0,0,0,0,0,0,0,0,0,0,0,0,0,0,0,0,0,0,0,0,0,0,0
0,0,0,0,0,0,0,0,0,0,0,0,0,0,0,0,0,0,0,0,0,0,0,0,0,0,0,0,0,0,0
0,0,0,0,0,0,0,0,0,0,0,0,0,0,0,0,0,0,0,0,0,0,0,0,0,0,0,0,0,0,0
0,0,0,0,0,0,0,0,0,0,0,0,0,0,0,0,0,0,0,0,0,0,0,0,0,0,0,0,0,0,0
endlayer

layer
0,0,0,0,0,0,0,0,0,0,0,0,0,0,0,0,0,0,0,0,0,0,0,0,0,0,0,0,0,0,0
0,0,0,0,0,0,0,0,0,0,0,0,0,0,0,0,0,0,0,0,0,0,0,0,0,0,0,0,0,0,0
0,0,0,0,0,0,0,0,0,0,0,0,0,0,0,0,0,0,0,0,0,0,0,0,0,0,0,0,0,0,0
0,0,0,0,0,0,0,0,0,0,0,0,0,0,0,0,0,0,0,0,0,0,0,0,0,0,0,0,0,0,0
0,0,0,0,0,0,0,0,0,0,0,0,0,0,0,0,0,0,0,0,0,0,0,0,0,0,0,0,0,0,0
0,0,0,0,0,0,0,0,0,0,0,0,0,0,0,0,0,0,0,0,0,0,0,0,0,0,0,0,0,0,0
0,0,0,0,0,0,0,0,0,0,0,0,0,0,0,0,0,0,0,0,0,0,0,0,0,0,0,0,0,0,0
0,0,0,0,0,0,0,0,0,0,0,0,0,0,0,0,0,0,0,0,0,0,0,0,0,0,0,0,0,0,0
0,0,0,0,0,0,0,0,0,0,0,0,0,0,0,0,0,0,0,0,0,0,0,0,0,0,0,0,0,0,0
0,0,0,0,0,0,0,0,0,0,0,0,0,0,0,0,0,0,0,0,0,0,0,0,0,0,0,0,0,0,0
0,0,0,0,0,0,0,0,0,0,0,0,0,0,0,0,0,0,0,0,0,0,0,0,0,0,0,0,0,0,0
0,0,0,0,0,0,0,0,0,0,0,0,0,0,0,0,0,0,0,0,0,0,0,0,0,0,0,0,0,0,0
0,0,0,0,0,0,0,0,0,0,0,0,0,0,0,0,0,0,0,0,0,0,0,0,0,0,0,0,0,0,0
0,0,0,0,0,0,0,0,0,0,0,0,0,0,0,0,0,0,0,0,0,0,0,0,0,0,0,0,0,0,0
0,0,0,0,0,0,0,0,0,0,0,0,0,0,0,0,0,0,0,0,0,0,0,0,0,0,0,0,0,0,0
0,0,0,0,0,0,0,0,0,0,0,0,0,0,0,0,0,0,0,0,0,0,0,0,0,0,0,0,0,0,0
0,0,0,0,0,0,0,0,0,0,0,0,0,0,0,0,0,0,0,0,0,0,0,0,0,0,0,0,0,0,0
0,0,0,0,0,0,0,0,0,0,0,0,0,0,0,0,0,0,0,0,0,0,0,0,0,0,0,0,0,0,0
0,0,0,0,0,0,0,0,0,0,0,0,0,0,0,0,0,0,0,0,0,0,0,0,0,0,0,0,0,0,0
0,0,0,0,0,0,0,0,0,0,0,0,0,0,0,0,0,0,0,0,0,0,0,0,0,0,0,0,0,0,0
0,0,0,0,0,0,0,0,0,0,0,0,0,0,0,0,0,0,0,0,0,0,0,0,0,0,0,0,0,0,0
0,0,0,0,0,0,0,0,0,0,0,0,0,0,0,0,0,0,0,0,0,0,0,0,0,0,0,0,0,0,0
0,0,0,0,0,0,0,0,0,0,0,0,0,0,0,0,0,0,0,0,0,0,0,0,0,0,0,0,0,0,0
0,0,0,0,0,0,0,0,0,0,0,0,0,0,0,0,0,0,0,0,0,0,0,0,0,0,0,0,0,0,0
0,0,0,0,0,0,0,0,0,0,0,0,0,0,0,0,0,0,0,0,0,0,0,0,0,0,0,0,0,0,0
0,0,0,0,0,0,0,0,0,0,0,0,0,0,0,0,0,0,0,0,0,0,0,0,0,0,0,0,0,0,0
0,0,0,0,0,0,0,0,0,0,0,0,0,0,0,0,0,0,0,0,0,0,0,0,0,0,0,0,0,0,0
0,0,0,0,0,0,0,0,0,0,0,0,0,0,0,0,0,0,0,0,0,0,0,0,0,0,0,0,0,0,0
0,0,0,0,0,0,0,0,0,0,0,0,0,0,0,0,0,0,0,0,0,0,0,0,0,0,0,0,0,0,0
0,0,0,0,0,0,0,0,0,0,0,0,0,0,0,0,0,0,0,0,0,0,0,0,0,0,0,0,0,0,0
0,0,0,0,0,0,0,0,0,0,0,0,0,0,0,0,0,0,0,0,0,0,0,0,0,0,0,0,0,0,0
endlayer

layer
0,0,0,0,0,0,0,0,0,0,0,0,0,0,0,0,0,0,0,0,0,0,0,0,0,0,0,0,0,0,0
0,0,0,0,0,0,0,0,0,0,0,0,0,0,0,0,0,0,0,0,0,0,0,0,0,0,0,0,0,0,0
0,0,0,0,0,0,0,0,0,0,0,0,0,0,0,0,0,0,0,0,0,0,0,0,0,0,0,0,0,0,0
0,0,0,0,0,0,0,0,0,0,0,0,0,0,0,0,0,0,0,0,0,0,0,0,0,0,0,0,0,0,0
0,0,0,0,0,0,0,0,0,0,0,0,0,0,0,0,0,0,0,0,0,0,0,0,0,0,0,0,0,0,0
0,0,0,0,0,0,0,0,0,0,0,0,0,0,0,0,0,0,0,0,0,0,0,0,0,0,0,0,0,0,0
0,0,0,0,0,0,0,0,0,0,0,0,0,0,0,0,0,0,0,0,0,0,0,0,0,0,0,0,0,0,0
0,0,0,0,0,0,0,0,0,0,0,0,0,0,0,0,0,0,0,0,0,0,0,0,0,0,0,0,0,0,0
0,0,0,0,0,0,0,0,0,0,0,0,0,0,0,0,0,0,0,0,0,0,0,0,0,0,0,0,0,0,0
0,0,0,0,0,0,0,0,0,0,0,0,0,0,0,0,0,0,0,0,0,0,0,0,0,0,0,0,0,0,0
0,0,0,0,0,0,0,0,0,0,0,0,0,0,0,0,0,0,0,0,0,0,0,0,0,0,0,0,0,0,0
0,0,0,0,0,0,0,0,0,0,0,0,0,0,0,0,0,0,0,0,0,0,0,0,0,0,0,0,0,0,0
0,0,0,0,0,0,0,0,0,0,0,0,0,0,0,0,0,0,0,0,0,0,0,0,0,0,0,0,0,0,0
0,0,0,0,0,0,0,0,0,0,0,0,0,0,0,0,0,0,0,0,0,0,0,0,0,0,0,0,0,0,0
0,0,0,0,0,0,0,0,0,0,0,0,0,0,0,0,0,0,0,0,0,0,0,0,0,0,0,0,0,0,0
0,0,0,0,0,0,0,0,0,0,0,0,0,0,0,0,0,0,0,0,0,0,0,0,0,0,0,0,0,0,0
0,0,0,0,0,0,0,0,0,0,0,0,0,0,0,0,0,0,0,0,0,0,0,0,0,0,0,0,0,0,0
0,0,0,0,0,0,0,0,0,0,0,0,0,0,0,0,0,0,0,0,0,0,0,0,0,0,0,0,0,0,0
0,0,0,0,0,0,0,0,0,0,0,0,0,0,0,0,0,0,0,0,0,0,0,0,0,0,0,0,0,0,0
0,0,0,0,0,0,0,0,0,0,0,0,0,0,0,0,0,0,0,0,0,0,0,0,0,0,0,0,0,0,0
0,0,0,0,0,0,0,0,0,0,0,0,0,0,0,0,0,0,0,0,0,0,0,0,0,0,0,0,0,0,0
0,0,0,0,0,0,0,0,0,0,0,0,0,0,0,0,0,0,0,0,0,0,0,0,0,0,0,0,0,0,0
0,0,0,0,0,0,0,0,0,0,0,0,0,0,0,0,0,0,0,0,0,0,0,0,0,0,0,0,0,0,0
0,0,0,0,0,0,0,0,0,0,0,0,0,0,0,0,0,0,0,0,0,0,0,0,0,0,0,0,0,0,0
0,0,0,0,0,0,0,0,0,0,0,0,0,0,0,0,0,0,0,0,0,0,0,0,0,0,0,0,0,0,0
0,0,0,0,0,0,0,0,0,0,0,0,0,0,0,0,0,0,0,0,0,0,0,0,0,0,0,0,0,0,0
0,0,0,0,0,0,0,0,0,0,0,0,0,0,0,0,0,0,0,0,0,0,0,0,0,0,0,0,0,0,0
0,0,0,0,0,0,0,0,0,0,0,0,0,0,0,0,0,0,0,0,0,0,0,0,0,0,0,0,0,0,0
0,0,0,0,0,0,0,0,0,0,0,0,0,0,0,0,0,0,0,0,0,0,0,0,0,0,0,0,0,0,0
0,0,0,0,0,0,0,0,0,0,0,0,0,0,0,0,0,0,0,0,0,0,0,0,0,0,0,0,0,0,0
0,0,0,0,0,0,0,0,0,0,0,0,0,0,0,0,0,0,0,0,0,0,0,0,0,0,0,0,0,0,0
endlayer

layer
0,0,0,0,0,0,0,0,0,0,0,0,0,0,0,0,0,0,0,0,0,0,0,0,0,0,0,0,0,0,0
0,0,0,0,0,0,0,0,0,0,0,0,0,0,0,0,0,0,0,0,0,0,0,0,0,0,0,0,0,0,0
