
# Created by Ruins mod version 14.7 Ingame Parser
# authoring Player: Barlock_James

weight=1
embed_into_distance=0
acceptable_target_blocks=
unacceptable_target_blocks=flowing_water,water,flowing_lava,lava
dimensions=11,13,13
allowable_overhang=0
max_leveling=2
leveling_buffer=0
preserve_water=0
preserve_lava=0

rule1=0,100,DCsAppleMilk:defeatedcrow.yuzuFence-0
rule2=0,100,erebus:umberPaver-1
rule3=0,100,minecraft:dirt-0
rule4=0,100,chisel:factoryblock-13
rule5=0,100,chisel:factoryblock-15
rule6=0,100,chisel:factoryblock-1
rule7=0,100,chisel:iron_block-14
rule8=0,100,Railcraft:tile.railcraft.wall.beta-8
rule9=0,100,EnderIO:blockDarkSteelLadder-5
rule10=0,100,DCsAppleMilk:defeatedcrow.mobDropBox-1
rule11=0,100,EnderIO:blockDarkSteelLadder-3
rule12=0,100,GraveStone:GSPileOfBones-0
rule13=0,100,EnderIO:blockDarkSteelLadder-2
rule14=0,100,GraveStone:GSPileOfBones-1
rule15=0,100,EnderIO:blockDarkSteelLadder-4
rule16=0,100,malisisdoors:factory_door-2
rule17=0,100,erebus:wallErebus-6
rule18=0,100,chisel:iron_bars-9
rule19=0,100,chisel:glass-10
rule20=0,100,BiblioCraft:BiblioFancySign-0
rule21=0,100,chisel:iron_bars-2
rule22=0,100,malisisdoors:factory_door-8
rule23=0,100,GraveStone:GSBoneBlock-3
rule24=0,100,ExtraUtilities:color_redstoneLight-12
rule25=0,100,Thaumcraft:blockCosmeticSlabStone-9
rule26=0,100,chisel:glass-15
rule27=0,100,chisel:technical-15
rule28=0,100,Railcraft:tile.railcraft.lantern.stone-1
rule29=0,100,Thaumcraft:blockCosmeticOpaque-2
rule30=0,100,minecraft:trapdoor-0
rule31=0,100,minecraft:trapdoor-1
rule32=0,100,minecraft:trapdoor-2
rule33=0,100,chisel:iron_block-13
rule34=0,100,minecraft:trapdoor-3
rule35=0,100,chisel:iron_bars-4
rule36=0,100,chisel:warningSign-4

layer
1,2,2,2,2,2,2,2,2,2,2,2,1
2,3,3,3,3,3,3,3,3,3,3,3,2
2,3,4,4,4,4,5,4,4,4,4,3,2
2,3,4,4,4,4,5,4,4,4,4,3,2
2,3,4,4,4,4,5,4,4,4,4,3,2
2,3,4,4,4,4,5,4,4,4,4,3,2
2,3,5,5,5,5,5,5,5,5,5,3,2
2,3,4,4,4,4,5,4,4,4,4,3,2
2,3,4,4,4,4,5,4,4,4,4,3,2
2,3,4,4,4,4,5,4,4,4,4,3,2
2,3,4,4,4,4,5,4,4,4,4,3,2
2,3,3,3,3,3,5,3,3,3,3,3,2
1,2,2,2,2,2,2,2,2,2,2,2,1
endlayer

layer
0,0,0,0,0,0,0,0,0,0,0,0,0
0,5,6,7,7,6,5,6,7,7,6,5,0
0,6,8,0,0,9,10,9,0,0,8,6,0
0,6,0,0,0,0,0,0,0,0,0,6,0
0,6,0,0,0,0,0,0,0,0,0,6,0
0,6,13,0,0,12,12,12,0,0,11,6,0
0,5,0,0,0,12,5,12,0,0,0,5,0
0,6,13,0,0,12,14,12,0,0,11,6,0
0,6,0,0,0,0,0,0,0,0,0,6,0
0,6,0,0,0,0,0,0,0,0,0,6,0
0,6,8,0,0,15,0,15,0,0,8,6,0
0,5,6,7,7,6,16,6,7,7,6,5,0
0,0,0,0,0,17,18,17,0,0,0,0,0
endlayer

layer
0,0,0,0,0,0,0,0,0,0,0,0,0
0,5,6,19,19,6,5,6,19,19,6,5,0
0,6,8,0,0,9,20,9,0,0,8,6,0
0,21,0,0,0,0,0,0,0,0,0,21,0
0,21,0,0,0,0,0,0,0,0,0,21,0
0,6,13,0,0,0,0,0,0,0,11,6,0
0,5,0,0,0,0,5,0,0,0,0,5,0
0,6,13,0,0,0,0,0,0,0,11,6,0
0,21,0,0,0,0,0,0,0,0,0,21,0
0,21,0,0,0,0,0,0,0,0,0,21,0
0,6,8,0,0,15,0,15,0,0,8,6,0
0,5,6,19,19,6,22,6,19,19,6,5,0
0,0,0,0,0,17,18,17,0,0,0,0,0
endlayer

layer
0,0,0,0,0,0,0,0,0,0,0,0,0
0,5,6,19,19,6,5,6,19,19,6,5,0
0,6,23,0,0,9,0,9,0,0,23,6,0
0,21,0,0,0,0,0,0,0,0,0,21,0
0,21,0,0,0,0,0,0,0,0,0,21,0
0,6,13,0,0,0,0,0,0,0,11,6,0
0,5,0,0,0,0,5,0,0,0,0,5,0
0,6,13,0,0,0,0,0,0,0,11,6,0
0,21,0,0,0,0,0,0,0,0,0,21,0
0,21,0,0,0,0,0,0,0,0,0,21,0
0,6,23,0,0,15,0,15,0,0,23,6,0
0,5,6,19,19,6,24,6,19,19,6,5,0
0,0,0,0,0,17,0,17,0,0,0,0,0
endlayer

layer
0,5,25,25,25,25,5,25,25,25,25,5,0
5,5,6,6,6,6,5,6,6,6,6,5,5
25,6,26,26,27,9,5,9,27,26,26,6,25
25,6,26,26,27,0,0,0,27,26,26,6,25
25,6,27,27,27,0,0,0,27,27,27,6,25
25,6,13,0,0,0,0,0,0,0,11,6,25
5,5,5,0,0,28,29,28,0,0,5,5,5
25,6,13,0,0,0,0,0,0,0,11,6,25
25,6,27,27,27,0,0,0,27,27,27,6,25
25,6,26,26,27,0,0,0,27,26,26,6,25
25,6,26,26,27,15,5,15,27,26,26,6,25
5,5,6,6,6,6,5,6,6,6,6,5,5
0,5,25,25,25,17,17,17,25,25,25,5,0
endlayer

layer
0,5,18,18,18,18,5,18,18,18,18,5,0
5,0,0,0,0,0,0,0,0,0,0,0,5
18,0,0,0,0,31,5,30,0,0,0,0,18
18,0,0,0,0,26,5,26,0,0,0,0,18
18,0,0,0,27,0,0,0,27,0,0,0,18
18,0,32,26,0,0,29,0,0,26,32,0,18
5,0,5,5,0,29,33,29,0,5,5,0,5
18,0,34,26,0,0,29,0,0,26,34,0,18
18,0,0,0,27,0,0,0,27,0,0,0,18
18,0,0,0,0,26,5,26,0,0,0,0,18
18,0,0,0,0,31,5,30,0,0,0,0,18
5,0,0,0,0,0,0,0,0,0,0,0,5
0,5,18,18,18,18,5,18,18,18,18,5,0
endlayer

layer
0,5,35,35,35,35,5,35,35,35,35,5,0
5,0,0,0,0,0,0,0,0,0,0,0,5
35,0,0,0,0,0,0,0,0,0,0,0,35
35,0,0,0,0,0,5,0,0,0,0,0,35
35,0,0,0,0,26,5,26,0,0,0,0,35
35,0,0,0,26,27,5,27,26,0,0,0,35
5,0,0,5,5,5,5,5,5,5,0,0,5
35,0,0,0,26,27,5,27,26,0,0,0,35
35,0,0,0,0,26,5,26,0,0,0,0,35
35,0,0,0,0,0,5,0,0,0,0,0,35
35,0,0,0,0,0,0,0,0,0,0,0,35
5,0,0,0,0,0,0,0,0,0,0,0,5
0,5,35,35,35,35,5,35,35,35,35,5,0
endlayer

layer
0,1,0,0,0,0,1,0,0,0,0,1,0
1,0,0,0,0,0,0,0,0,0,0,0,1
0,0,0,0,0,0,0,0,0,0,0,0,0
0,0,0,0,0,0,1,0,0,0,0,0,0
0,0,0,0,0,0,1,0,0,0,0,0,0
0,0,0,0,0,0,1,0,0,0,0,0,0
1,0,0,1,1,1,1,1,1,1,0,0,1
0,0,0,0,0,0,1,0,0,0,0,0,0
0,0,0,0,0,0,1,0,0,0,0,0,0
0,0,0,0,0,0,1,0,0,0,0,0,0
0,0,0,0,0,0,0,0,0,0,0,0,0
1,0,0,0,0,0,0,0,0,0,0,0,1
0,1,0,0,0,0,1,0,0,0,0,1,0
endlayer

layer
0,0,0,0,0,0,0,0,0,0,0,0,0
0,0,0,0,0,0,0,0,0,0,0,0,0
0,0,0,0,0,0,0,0,0,0,0,0,0
0,0,0,0,0,0,0,0,0,0,0,0,0
0,0,0,0,0,0,0,0,0,0,0,0,0
0,0,0,0,0,0,0,0,0,0,0,0,0
0,0,0,0,0,0,1,0,0,0,0,0,0
0,0,0,0,0,0,0,0,0,0,0,0,0
0,0,0,0,0,0,0,0,0,0,0,0,0
0,0,0,0,0,0,0,0,0,0,0,0,0
0,0,0,0,0,0,0,0,0,0,0,0,0
0,0,0,0,0,0,0,0,0,0,0,0,0
0,0,0,0,0,0,0,0,0,0,0,0,0
endlayer

layer
0,0,0,0,0,0,0,0,0,0,0,0,0
0,0,0,0,0,0,0,0,0,0,0,0,0
0,0,0,0,0,0,0,0,0,0,0,0,0
0,0,0,0,0,0,0,0,0,0,0,0,0
0,0,0,0,0,0,0,0,0,0,0,0,0
0,0,0,0,0,0,0,0,0,0,0,0,0
0,0,0,0,0,0,1,0,0,0,0,0,0
0,0,0,0,0,0,0,0,0,0,0,0,0
0,0,0,0,0,0,0,0,0,0,0,0,0
0,0,0,0,0,0,0,0,0,0,0,0,0
0,0,0,0,0,0,0,0,0,0,0,0,0
0,0,0,0,0,0,0,0,0,0,0,0,0
0,0,0,0,0,0,0,0,0,0,0,0,0
endlayer

layer
0,0,0,0,0,0,0,0,0,0,0,0,0
0,0,0,0,0,0,0,0,0,0,0,0,0
0,0,0,0,0,0,0,0,0,0,0,0,0
0,0,0,0,0,0,0,0,0,0,0,0,0
0,0,0,0,0,0,0,0,0,0,0,0,0
0,0,0,0,0,0,0,0,0,0,0,0,0
0,0,0,0,0,0,36,0,0,0,0,0,0
0,0,0,0,0,0,0,0,0,0,0,0,0
0,0,0,0,0,0,0,0,0,0,0,0,0
0,0,0,0,0,0,0,0,0,0,0,0,0
0,0,0,0,0,0,0,0,0,0,0,0,0
0,0,0,0,0,0,0,0,0,0,0,0,0
0,0,0,0,0,0,0,0,0,0,0,0,0
endlayer

