
# Created by Ruins mod version 14.7 Ingame Parser
# authoring Player: Barlock_James

weight=1
embed_into_distance=0
acceptable_target_blocks=
unacceptable_target_blocks=flowing_water,water,flowing_lava,lava
dimensions=8,31,29
allowable_overhang=0
max_leveling=2
leveling_buffer=0
preserve_water=0
preserve_lava=0

rule1=0,100,minecraft:grass-0
rule2=0,100,minecraft:dirt-0
rule3=0,100,chisel:dirt-2
rule4=0,100,ExtraUtilities:color_brick-8
rule5=0,100,chisel:birch_planks-13
rule6=0,100,ExtraUtilities:decorativeBlock1-4
rule7=0,100,chisel:spruce_planks-13
rule8=0,100,minecraft:brick_block-0
rule9=0,100,ExtraUtilities:color_brick-7
rule10=0,100,betterstorage:reinforcedChest-0
rule11=0,100,harvestcraft:presser-0
rule12=0,100,chisel:scorching-0
rule13=0,100,Thaumcraft:blockTable-1
rule14=0,100,chisel:iron_bars-3
rule15=0,100,malisisdoors:curtain-7
rule16=0,100,cfm:chairwood-1
rule17=0,100,cfm:tablewood-1
rule18=0,100,harvestcraft:sink-0
rule19=0,100,minecraft:crafting_table-0
rule20=0,100,cfm:chairwood-3
rule21=0,100,erebus:dooreucalyptus-6
rule22=0,100,cfm:cabinet-1
rule23=0,100,cfm:toilet-1
rule24=0,100,cfm:bedsidecabinet-1
rule25=0,100,chisel:carpet-11
rule26=0,100,cfm:basin-2
rule27=0,100,erebus:dooreucalyptus-3
rule28=0,100,cfm:coffetablestone-2
rule29=0,100,cfm:bath1-0
rule30=0,100,cfm:bath2-0
rule31=0,100,BiblioCraft:BiblioClock-0
rule32=0,100,erebus:dooreucalyptus-0
rule33=0,100,cfm:couch-1
rule34=0,100,chisel:carpet-5
rule35=0,100,BiblioCraft:Armor Stand-2
rule36=0,100,BiblioCraft:BiblioSwordPedestal-0
rule37=0,100,IInventory;BiblioCraft:BiblioSeats;minecraft:carpet#1#12#0+BiblioCraft:item.seatBack5#1#0#1-0
rule38=0,100,BiblioCraft:BiblioTable-0
rule39=0,100,cfm:couch-2
rule40=0,100,cfm:bedsidecabinet-0
rule41=0,100,IInventory;BiblioCraft:BiblioSeats;minecraft:carpet#1#12#0-0
rule42=0,100,Automagy:blockGolemWorkbench-0
rule43=0,100,CarpentersBlocks:blockCarpentersBed-0
rule44=0,100,IInventory;BiblioCraft:BiblioDesk;minecraft:writable_book#1#0#0+minecraft:writable_book#1#0#4+minecraft:writable_book#1#0#8-0
rule45=0,100,cfm:chairstone-0
rule46=0,100,chisel:carpet-12
rule47=0,100,cfm:couch-0
rule48=0,100,CarpentersBlocks:blockCarpentersDoor-5
rule49=0,100,minecraft:planks-5
rule50=0,100,ChestGenHook:dungeonChest:5-4
rule51=0,100,BiblioCraft:Bibliotheca-0
rule52=0,100,IInventory;BiblioCraft:BookcaseFilled;minecraft:written_book#1#0#2+minecraft:written_book#1#0#3+minecraft:written_book#1#0#4+minecraft:written_book#1#0#5+minecraft:written_book#1#0#6+minecraft:written_book#1#0#7+minecraft:written_book#1#0#10+minecraft:written_book#1#0#12+minecraft:written_book#1#0#13+minecraft:written_book#1#0#15-0
rule53=0,100,Thaumcraft:blockAiry-1
rule54=0,100,DCsAppleMilk:defeatedcrow.WoodBox-1
rule55=0,100,IInventory;BiblioCraft:BiblioShelf;minecraft:bucket#1#0#0-0
rule56=0,100,IInventory;BiblioCraft:BiblioShelf;harvestcraft:bakewareItem#1#0#0+harvestcraft:mortarandpestleItem#1#0#1+harvestcraft:mixingbowlItem#1#0#2+harvestcraft:juicerItem#1#0#3-0
rule57=0,100,IInventory;BiblioCraft:BiblioShelf;harvestcraft:cuttingboardItem#1#0#0+harvestcraft:potItem#1#0#1+harvestcraft:skilletItem#1#0#2+harvestcraft:saucepanItem#1#0#3-0
rule58=0,100,harvestcraft:oven-5
rule59=0,100,harvestcraft:cuttingboard-0
rule60=0,100,chisel:glass-3
rule61=0,100,cfm:curtainon-2
rule62=0,100,malisisdoors:curtain-8
rule63=0,100,cfm:curtainon-0
rule64=0,100,malisisdoors:curtain-9
rule65=0,100,BiblioCraft:BiblioStuffs-0
rule66=0,100,erebus:dooreucalyptus-8
rule67=0,100,BiblioCraft:BiblioCase-0
rule68=0,100,BiblioCraft:BiblioRack-0
rule69=0,100,Railcraft:tile.railcraft.slab-0
rule70=0,100,cfm:blindon-2
rule71=0,100,BiblioCraft:Armor Stand-6
rule72=0,100,cfm:plate-1
rule73=0,100,BiblioCraft:BiblioIronLantern-0
rule74=0,100,cfm:curtainoff-2
rule75=0,100,BiblioCraft:BiblioBorderlessPainting-0
rule76=0,100,GardenTrees:thin_log-1
rule77=0,100,IInventory;BiblioCraft:Bibliotheca;BiblioCraft:item.BiblioClipboard#1#0#0+BiblioCraft:item.BiblioClipboard#1#0#4+BiblioCraft:item.BiblioClipboard#1#0#10+BiblioCraft:item.BiblioClipboard#1#0#14-0
rule78=0,100,IInventory;BiblioCraft:BookcaseFilled;minecraft:written_book#1#0#1+minecraft:written_book#1#0#2+minecraft:written_book#1#0#3+minecraft:written_book#1#0#4+minecraft:written_book#1#0#5+minecraft:written_book#1#0#6+minecraft:written_book#1#0#8+minecraft:written_book#1#0#9+minecraft:written_book#1#0#10+minecraft:written_book#1#0#11+minecraft:written_book#1#0#13+minecraft:written_book#1#0#14+minecraft:written_book#1#0#15-0
rule79=0,100,minecraft:brick_stairs-2
rule80=0,100,minecraft:brick_stairs-5
rule81=0,100,minecraft:brick_stairs-3
rule82=0,100,BiblioCraft:BiblioShelf-0
rule83=0,100,IInventory;BiblioCraft:BiblioShelf;cfm:ItemRecipeBook#1#0#0+BiblioCraft:item.RecipeBook#1#0#2-0
rule84=0,100,headcrumbs:betterSkull-3
rule85=0,100,minecraft:dark_oak_stairs-5
rule86=0,100,chisel:carpet_block-5

layer
1,1,1,1,1,1,1,1,1,1,1,1,1,1,1,1,1,1,1,1,1,1,1,1,1,1,1,1,1
1,1,1,1,1,1,1,1,2,2,2,2,2,2,2,2,2,2,2,2,2,1,1,1,1,1,1,1,1
1,1,1,1,1,1,1,2,2,2,2,2,2,2,2,2,2,2,2,2,2,2,1,1,1,1,1,1,1
1,1,1,1,1,1,2,2,2,2,2,2,2,2,2,2,2,2,2,2,2,2,2,1,1,1,1,1,1
1,1,1,1,1,2,2,2,2,2,2,2,2,2,2,2,2,2,2,2,2,2,2,2,1,1,1,1,1
1,1,1,1,2,2,2,3,3,3,3,3,3,3,3,3,3,3,3,3,3,3,3,2,2,1,1,1,1
1,1,1,2,2,2,3,4,4,4,4,4,4,4,4,3,4,4,4,4,4,4,3,2,2,2,1,1,1
1,1,1,1,2,2,3,4,4,4,4,4,4,4,4,3,4,4,4,4,4,4,3,2,2,2,1,1,1
1,1,1,1,1,2,3,4,4,4,4,4,4,4,4,4,4,4,4,4,4,4,3,2,2,2,1,1,1
1,1,1,1,1,2,3,4,4,4,4,4,4,4,4,4,4,4,4,4,4,4,3,2,2,2,1,1,1
1,1,1,1,1,2,3,4,4,4,4,4,4,4,4,3,4,4,4,4,4,4,3,2,2,2,1,1,1
1,1,1,1,1,2,3,4,4,4,4,4,4,4,4,3,4,4,4,4,4,4,3,2,2,2,2,1,1
1,1,1,1,1,2,3,3,3,3,5,5,5,3,3,3,3,3,3,4,3,3,3,3,3,3,2,2,1
1,1,1,1,1,2,3,5,5,5,5,5,5,5,5,3,5,5,5,5,5,5,3,6,6,6,3,2,2
1,1,1,1,1,1,3,5,5,5,5,5,5,5,5,3,5,5,5,5,5,5,3,6,6,6,3,2,2
1,1,1,1,1,1,3,5,5,5,5,5,5,5,5,5,5,5,5,5,5,5,6,6,6,6,3,2,2
1,1,1,1,1,1,3,5,5,5,5,5,5,5,5,3,5,5,5,5,5,5,3,6,6,6,3,2,2
1,1,1,1,1,2,3,5,5,5,5,5,5,5,5,3,5,5,5,5,5,5,3,6,6,6,3,2,2
1,1,1,1,1,2,3,3,3,3,5,5,5,3,3,3,3,3,3,7,3,3,3,3,3,3,2,2,2
1,1,1,1,1,2,3,7,7,7,7,7,7,7,7,3,7,7,7,7,7,7,7,3,2,2,2,2,2
1,1,1,1,1,2,3,7,7,7,7,7,7,7,7,3,7,7,7,7,7,7,7,3,2,2,2,2,1
1,1,1,1,1,2,3,7,7,7,7,7,7,7,7,7,7,7,7,7,7,7,7,3,2,2,2,2,1
1,1,1,1,1,2,3,7,7,7,7,7,7,7,7,7,7,7,7,7,7,7,7,3,2,2,2,2,1
1,1,1,1,1,2,3,7,7,8,8,8,7,7,7,3,7,7,7,7,7,7,7,3,2,2,2,2,1
1,1,1,1,2,2,3,7,7,8,9,8,7,7,7,3,7,7,7,7,7,7,7,3,2,2,2,2,1
1,1,1,1,1,2,2,3,3,3,8,3,3,3,3,3,3,3,3,3,3,3,3,2,2,2,2,1,1
1,1,1,1,1,2,2,2,2,2,2,2,2,2,2,2,2,2,2,2,2,2,2,2,2,2,1,1,1
1,1,1,1,1,1,2,2,2,2,2,2,2,2,2,2,2,2,2,2,2,2,2,2,2,1,1,1,1
1,1,1,1,1,1,1,2,2,2,2,2,2,2,2,2,2,2,2,2,2,2,2,2,1,1,1,1,1
1,1,1,1,1,1,1,1,2,2,2,2,2,2,2,2,2,2,2,2,2,2,2,1,1,1,1,1,1
1,1,1,1,1,1,1,1,1,1,1,1,1,1,1,1,1,1,1,1,1,1,1,1,1,1,1,1,1
endlayer

layer
0,0,0,0,0,0,0,0,0,0,0,0,0,0,0,0,0,0,0,0,0,0,0,0,0,0,0,0,0
0,0,0,0,0,0,0,0,1,1,1,1,1,1,1,1,1,1,1,1,1,0,0,0,0,0,0,0,0
0,0,0,0,0,0,0,1,2,2,2,2,2,2,2,2,2,2,2,2,2,1,0,0,0,0,0,0,0
0,0,0,0,0,0,1,2,2,2,2,2,2,2,2,2,2,2,2,2,2,2,1,0,0,0,0,0,0
0,0,0,0,0,1,2,2,2,2,2,2,2,2,2,2,2,2,2,2,2,2,2,1,0,0,0,0,0
0,0,0,0,1,2,2,3,3,3,3,3,3,3,3,3,3,3,3,3,3,3,3,2,1,0,0,0,0
0,0,0,1,2,2,3,13,13,9,12,9,10,11,10,3,0,0,0,0,0,0,3,2,2,1,0,0,0
0,0,0,0,1,2,3,0,0,14,14,14,0,0,0,3,0,0,0,0,0,0,3,2,2,1,0,0,0
0,0,0,0,0,1,3,0,0,0,0,0,0,0,0,15,0,0,0,0,0,0,3,1,1,1,0,0,0
0,0,0,0,0,1,3,16,16,0,0,0,0,0,0,15,0,0,0,0,0,0,3,1,1,1,0,0,0
0,0,0,0,0,2,3,17,17,0,0,0,0,0,0,3,0,0,0,0,0,0,3,2,2,1,0,0,0
0,0,0,0,0,2,3,20,20,0,0,0,0,19,18,3,0,0,0,0,0,0,3,2,2,2,1,0,0
0,0,0,0,0,2,3,3,3,3,0,0,0,3,3,3,3,3,3,21,3,3,3,3,3,3,2,1,0
0,0,0,0,0,1,3,0,0,0,0,0,0,0,0,3,0,0,0,0,0,0,3,24,23,22,3,2,1
0,0,0,0,0,0,3,25,25,25,25,25,25,25,25,3,0,0,0,0,0,0,3,0,0,0,3,2,2
0,0,0,0,0,0,27,25,25,25,25,25,25,25,25,27,0,0,0,0,0,0,27,0,0,26,3,1,1
0,0,0,0,0,0,3,25,25,25,25,25,25,25,25,3,0,0,0,0,0,0,3,28,28,28,3,2,2
0,0,0,0,0,1,3,0,0,0,0,0,0,0,31,3,0,0,0,0,0,0,3,30,29,28,3,2,2
0,0,0,0,0,2,3,3,3,3,0,0,0,3,3,3,3,3,3,32,3,3,3,3,3,3,2,2,2
0,0,0,0,0,2,3,38,37,0,0,0,0,36,35,3,10,34,34,0,0,33,0,3,2,2,2,2,1
0,0,0,0,0,1,3,0,41,0,0,0,0,0,0,3,40,34,34,0,0,0,39,3,2,2,2,1,0
0,0,0,0,0,1,3,47,46,46,46,46,0,45,44,3,43,43,42,34,34,0,0,3,1,1,1,1,0
0,0,0,0,0,1,3,47,46,46,46,46,39,0,0,3,43,43,42,34,34,0,0,3,1,1,1,1,0
0,0,0,0,0,1,3,0,0,0,0,0,0,0,0,3,40,34,34,0,48,48,0,3,2,2,2,1,0
0,0,0,0,1,2,3,28,54,8,53,8,52,51,51,3,10,34,34,49,50,50,49,3,2,2,2,1,0
0,0,0,0,0,1,2,3,3,3,8,3,3,3,3,3,3,3,3,3,3,3,3,2,2,2,1,0,0
0,0,0,0,0,1,2,2,2,2,2,2,2,2,2,2,2,2,2,2,2,2,2,2,2,1,0,0,0
0,0,0,0,0,0,1,2,2,2,2,2,2,2,2,2,2,2,2,2,2,2,2,2,1,0,0,0,0
0,0,0,0,0,0,0,1,2,2,2,2,2,2,2,2,2,2,2,2,2,2,2,1,0,0,0,0,0
0,0,0,0,0,0,0,0,1,1,1,1,1,1,1,1,1,1,1,1,1,1,1,0,0,0,0,0,0
0,0,0,0,0,0,0,0,0,0,0,0,0,0,0,0,0,0,0,0,0,0,0,0,0,0,0,0,0
endlayer

layer
0,0,0,0,0,0,0,0,0,0,0,0,0,0,0,0,0,0,0,0,0,0,0,0,0,0,0,0,0
0,0,0,0,0,0,0,0,0,0,0,0,0,0,0,0,0,0,0,0,0,0,0,0,0,0,0,0,0
0,0,0,0,0,0,0,0,1,1,1,1,1,1,1,1,1,1,1,1,1,0,0,0,0,0,0,0,0
0,0,0,0,0,0,0,1,2,2,2,2,2,2,2,2,2,2,2,2,2,1,0,0,0,0,0,0,0
0,0,0,0,0,0,1,2,2,2,2,2,2,2,2,2,2,2,2,2,2,2,1,0,0,0,0,0,0
0,0,0,0,0,1,2,3,3,3,3,3,3,3,3,3,3,3,3,3,3,3,3,1,0,0,0,0,0
0,0,0,0,1,2,3,59,0,9,58,9,57,56,55,3,0,0,0,0,0,0,3,2,1,0,0,0,0
0,0,0,0,0,1,3,0,0,0,0,0,0,0,0,3,0,0,0,0,0,0,3,2,1,0,0,0,0
0,0,0,0,0,0,60,63,0,0,0,0,0,0,0,62,0,0,0,0,0,61,60,0,0,0,0,0,0
0,0,0,0,0,0,60,63,0,0,0,0,0,0,0,64,0,0,0,0,0,61,60,0,0,0,0,0,0
0,0,0,0,0,1,3,0,0,0,0,0,0,0,0,3,0,0,0,0,0,0,3,2,1,0,0,0,0
0,0,0,0,0,2,3,0,0,0,0,0,0,65,0,3,0,0,0,0,0,0,3,2,2,1,0,0,0
0,0,0,0,0,1,2,3,3,3,0,0,0,3,3,3,3,3,3,66,3,3,3,3,3,3,1,0,0
0,0,0,0,0,69,3,68,0,0,0,0,0,0,67,3,0,0,0,0,0,0,3,24,0,22,3,1,0
0,0,0,0,0,69,3,0,0,0,0,0,0,0,67,3,0,0,0,0,0,0,3,0,0,0,3,2,1
0,0,0,0,0,0,66,0,0,0,0,0,0,0,0,66,0,0,0,0,0,0,66,0,0,70,60,0,0
0,0,0,0,0,69,3,0,0,0,0,0,0,0,0,3,0,0,0,0,0,0,3,0,0,0,3,2,1
0,0,0,0,0,69,3,68,0,0,0,0,0,0,31,3,0,0,0,0,0,0,3,0,0,0,3,2,1
0,0,0,0,0,1,2,3,3,3,0,0,0,3,3,3,3,3,3,66,3,3,3,3,3,3,2,2,1
0,0,0,0,0,1,3,72,0,0,0,0,0,0,71,3,0,0,0,0,0,0,0,3,2,2,2,1,0
0,0,0,0,0,0,3,0,0,0,0,0,0,0,0,3,73,0,0,0,0,0,0,3,2,2,1,0,0
0,0,0,0,0,0,60,63,0,0,0,0,0,0,0,3,75,0,0,0,0,0,74,60,0,0,0,0,0
0,0,0,0,0,0,60,63,0,0,0,0,0,0,0,3,75,0,0,0,0,0,74,60,0,0,0,0,0
0,0,0,0,0,0,3,0,0,76,76,76,0,0,0,3,73,0,0,0,48,48,0,3,2,2,1,0,0
0,0,0,0,0,1,3,0,0,81,80,79,78,77,51,3,0,0,0,49,50,50,49,3,2,2,1,0,0
0,0,0,0,0,0,1,3,3,3,8,3,3,3,3,3,3,3,3,3,3,3,3,2,2,1,0,0,0
0,0,0,0,0,0,1,2,2,2,2,2,2,2,2,2,2,2,2,2,2,2,2,2,1,0,0,0,0
0,0,0,0,0,0,0,1,2,2,2,2,2,2,2,2,2,2,2,2,2,2,2,1,0,0,0,0,0
0,0,0,0,0,0,0,0,1,1,1,1,1,1,1,1,1,1,1,1,1,1,1,0,0,0,0,0,0
0,0,0,0,0,0,0,0,0,0,0,0,0,0,0,0,0,0,0,0,0,0,0,0,0,0,0,0,0
0,0,0,0,0,0,0,0,0,0,0,0,0,0,0,0,0,0,0,0,0,0,0,0,0,0,0,0,0
endlayer

layer
0,0,0,0,0,0,0,0,0,0,0,0,0,0,0,0,0,0,0,0,0,0,0,0,0,0,0,0,0
0,0,0,0,0,0,0,0,0,0,0,0,0,0,0,0,0,0,0,0,0,0,0,0,0,0,0,0,0
0,0,0,0,0,0,0,0,0,0,0,0,0,0,0,0,0,0,0,0,0,0,0,0,0,0,0,0,0
0,0,0,0,0,0,0,0,1,1,1,1,1,1,1,1,1,1,1,1,1,0,0,0,0,0,0,0,0
0,0,0,0,0,0,0,1,2,2,2,2,2,2,2,2,2,2,2,2,2,1,0,0,0,0,0,0,0
0,0,0,0,0,0,1,2,2,2,2,2,2,2,2,2,2,2,2,2,2,2,1,0,0,0,0,0,0
0,0,0,0,0,1,2,3,3,9,9,9,3,3,3,3,3,3,3,3,3,3,3,1,0,0,0,0,0
0,0,0,0,0,0,3,83,82,0,0,0,0,0,73,3,73,0,0,0,0,73,3,2,0,0,0,0,0
0,0,0,0,0,0,3,0,0,0,0,0,0,0,0,3,0,0,0,0,0,0,3,0,0,0,0,0,0
0,0,0,0,0,0,3,0,0,0,0,0,0,0,0,3,0,0,0,0,0,0,3,0,0,0,0,0,0
0,0,0,0,0,0,3,73,73,0,0,0,0,0,73,3,73,0,0,0,0,73,3,2,0,0,0,0,0
0,0,0,0,0,1,2,3,3,3,0,0,0,3,3,3,0,0,0,73,0,0,3,2,1,0,0,0,0
0,0,0,0,0,0,2,2,2,3,3,60,3,3,2,2,3,3,3,3,3,3,2,2,2,1,0,0,0
0,0,0,0,0,0,2,3,3,3,0,0,0,3,3,3,0,0,0,73,0,0,3,3,3,3,1,0,0
0,0,0,0,0,0,3,0,0,0,0,0,0,0,67,3,0,0,0,0,0,0,3,0,0,0,3,1,0
0,0,0,0,0,69,3,0,0,0,0,0,0,0,0,3,0,0,0,0,0,0,3,0,0,0,3,2,0
0,0,0,0,0,0,3,0,0,0,0,0,0,0,0,3,0,0,0,0,0,0,3,0,0,0,3,1,0
0,0,0,0,0,0,2,3,3,3,0,0,0,3,3,3,0,0,0,73,0,0,3,3,3,3,2,1,0
0,0,0,0,0,0,2,2,2,2,3,60,3,2,2,2,3,3,3,3,3,3,3,2,2,2,2,1,0
0,0,0,0,0,0,2,3,3,3,0,0,0,3,3,3,0,0,0,0,0,0,73,3,2,2,1,0,0
0,0,0,0,0,0,3,73,0,0,0,0,0,0,73,3,0,0,0,0,0,0,0,3,2,1,0,0,0
0,0,0,0,0,0,3,0,0,0,0,0,0,0,84,3,75,0,0,0,0,0,0,3,0,0,0,0,0
0,0,0,0,0,0,3,0,0,0,0,0,0,0,84,3,75,0,0,0,0,0,0,3,0,0,0,0,0
0,0,0,0,0,0,3,73,0,0,0,0,0,0,73,3,0,0,0,0,0,0,73,3,2,1,0,0,0
0,0,0,0,0,0,1,3,3,3,8,3,3,3,3,3,3,3,3,3,85,85,3,3,2,1,0,0,0
0,0,0,0,0,0,0,1,2,2,2,2,2,2,2,2,2,2,2,2,2,2,2,2,1,0,0,0,0
0,0,0,0,0,0,0,1,2,2,2,2,2,2,2,2,2,2,2,2,2,2,2,1,0,0,0,0,0
0,0,0,0,0,0,0,0,1,1,1,1,1,1,1,1,1,1,1,1,1,1,1,0,0,0,0,0,0
0,0,0,0,0,0,0,0,0,0,0,0,0,0,0,0,0,0,0,0,0,0,0,0,0,0,0,0,0
0,0,0,0,0,0,0,0,0,0,0,0,0,0,0,0,0,0,0,0,0,0,0,0,0,0,0,0,0
0,0,0,0,0,0,0,0,0,0,0,0,0,0,0,0,0,0,0,0,0,0,0,0,0,0,0,0,0
endlayer

layer
0,0,0,0,0,0,0,0,0,0,0,0,0,0,0,0,0,0,0,0,0,0,0,0,0,0,0,0,0
0,0,0,0,0,0,0,0,0,0,0,0,0,0,0,0,0,0,0,0,0,0,0,0,0,0,0,0,0
0,0,0,0,0,0,0,0,0,0,0,0,0,0,0,0,0,0,0,0,0,0,0,0,0,0,0,0,0
0,0,0,0,0,0,0,0,0,0,0,0,0,0,0,0,0,0,0,0,0,0,0,0,0,0,0,0,0
0,0,0,0,0,0,0,0,1,1,1,1,1,1,1,1,1,1,1,1,1,0,0,0,0,0,0,0,0
0,0,0,0,0,0,0,1,1,1,1,1,1,1,1,1,1,1,1,1,1,1,0,0,0,0,0,0,0
0,0,0,0,0,0,1,2,2,2,9,2,2,2,2,2,2,2,2,2,2,2,1,0,0,0,0,0,0
0,0,0,0,0,0,1,3,3,3,3,3,3,3,3,3,3,3,3,3,3,3,3,1,0,0,0,0,0
0,0,0,0,0,0,3,0,0,0,0,0,0,0,0,3,0,0,0,0,0,0,3,2,0,0,0,0,0
0,0,0,0,0,0,3,0,0,0,0,0,0,0,0,3,0,0,0,0,0,0,3,2,0,0,0,0,0
0,0,0,0,0,0,1,3,3,3,0,0,0,3,3,3,3,3,3,3,3,3,3,2,0,0,0,0,0
0,0,0,0,0,0,1,2,2,2,3,73,3,2,2,2,3,3,3,3,3,3,2,2,0,0,0,0,0
0,0,0,0,0,0,1,2,2,2,3,3,3,2,2,2,2,2,2,2,2,2,2,2,1,0,0,0,0
0,0,0,0,0,0,1,2,2,2,3,73,3,2,2,2,3,3,3,3,3,3,2,2,1,1,0,0,0
0,0,0,0,0,0,1,3,3,3,3,0,3,3,3,3,3,3,3,3,3,3,3,3,3,3,1,0,0
0,0,0,0,0,73,3,73,0,0,0,0,0,0,73,3,73,0,0,0,0,73,3,73,0,73,3,1,0
0,0,0,0,0,0,1,3,3,3,3,0,3,3,3,3,3,3,3,3,3,3,3,3,3,3,1,0,0
0,0,0,0,0,0,1,2,2,2,3,73,3,2,2,2,3,3,3,3,3,3,2,2,2,2,1,0,0
0,0,0,0,0,0,1,2,2,2,3,3,3,2,2,2,2,2,2,2,2,2,2,2,2,2,1,0,0
0,0,0,0,0,0,1,2,2,2,3,3,3,2,2,2,3,3,3,3,3,3,3,2,2,1,0,0,0
0,0,0,0,0,0,1,3,3,3,3,3,3,3,3,3,3,3,3,3,3,3,3,3,2,0,0,0,0
0,0,0,0,0,0,3,0,0,0,0,0,0,0,0,3,86,86,0,0,0,0,0,3,2,0,0,0,0
0,0,0,0,0,0,3,0,0,0,0,0,0,0,0,3,86,86,0,0,0,0,0,3,2,0,0,0,0
0,0,0,0,0,0,1,3,3,3,3,3,3,3,3,3,3,3,3,3,3,3,3,3,1,0,0,0,0
0,0,0,0,0,0,0,1,2,2,8,2,2,2,2,2,2,2,2,2,2,2,2,2,1,0,0,0,0
0,0,0,0,0,0,0,0,1,1,1,1,1,1,1,1,1,1,1,1,1,1,1,1,0,0,0,0,0
0,0,0,0,0,0,0,0,1,1,1,1,1,1,1,1,1,1,1,1,1,1,1,0,0,0,0,0,0
0,0,0,0,0,0,0,0,0,0,0,0,0,0,0,0,0,0,0,0,0,0,0,0,0,0,0,0,0
0,0,0,0,0,0,0,0,0,0,0,0,0,0,0,0,0,0,0,0,0,0,0,0,0,0,0,0,0
0,0,0,0,0,0,0,0,0,0,0,0,0,0,0,0,0,0,0,0,0,0,0,0,0,0,0,0,0
0,0,0,0,0,0,0,0,0,0,0,0,0,0,0,0,0,0,0,0,0,0,0,0,0,0,0,0,0
endlayer

layer
0,0,0,0,0,0,0,0,0,0,0,0,0,0,0,0,0,0,0,0,0,0,0,0,0,0,0,0,0
0,0,0,0,0,0,0,0,0,0,0,0,0,0,0,0,0,0,0,0,0,0,0,0,0,0,0,0,0
0,0,0,0,0,0,0,0,0,0,0,0,0,0,0,0,0,0,0,0,0,0,0,0,0,0,0,0,0
0,0,0,0,0,0,0,0,0,0,0,0,0,0,0,0,0,0,0,0,0,0,0,0,0,0,0,0,0
0,0,0,0,0,0,0,0,0,0,0,0,0,0,0,0,0,0,0,0,0,0,0,0,0,0,0,0,0
0,0,0,0,0,0,0,0,0,0,0,0,0,0,0,0,0,0,0,0,0,0,0,0,0,0,0,0,0
0,0,0,0,0,0,0,1,1,1,9,1,1,1,1,1,1,1,1,1,1,1,0,0,0,0,0,0,0
0,0,0,0,0,0,0,1,1,1,1,1,1,1,1,1,1,1,1,1,1,1,1,0,0,0,0,0,0
0,0,0,0,0,0,1,3,3,3,3,3,3,3,3,3,3,3,3,3,3,3,3,1,0,0,0,0,0
0,0,0,0,0,0,1,3,3,3,3,3,3,3,3,3,3,3,3,3,3,3,3,1,0,0,0,0,0
0,0,0,0,0,0,0,1,2,2,2,3,2,2,2,2,2,2,2,2,2,2,2,1,0,0,0,0,0
0,0,0,0,0,0,0,1,2,2,2,3,2,2,2,2,2,2,2,2,2,2,2,1,0,0,0,0,0
0,0,0,0,0,0,0,1,2,2,2,3,2,2,2,2,2,2,2,2,2,2,2,1,0,0,0,0,0
0,0,0,0,0,0,0,1,2,2,2,3,2,2,2,2,2,2,2,2,2,2,2,1,0,0,0,0,0
0,0,0,0,0,0,0,1,2,2,2,3,2,2,2,2,2,2,2,2,2,2,2,2,1,1,0,0,0
0,0,0,0,0,0,1,3,3,3,3,0,3,3,3,3,3,3,3,3,3,3,3,3,3,3,1,0,0
0,0,0,0,0,0,0,1,2,2,2,3,2,2,2,2,2,2,2,2,2,2,2,2,2,1,0,0,0
0,0,0,0,0,0,0,1,2,2,2,3,2,2,2,2,2,2,2,2,2,2,2,2,2,1,0,0,0
0,0,0,0,0,0,0,1,2,2,2,3,2,2,2,2,2,2,2,2,2,2,2,2,2,1,0,0,0
0,0,0,0,0,0,0,1,2,2,2,3,2,2,2,2,2,2,2,2,2,2,2,2,1,0,0,0,0
0,0,0,0,0,0,0,1,2,2,2,3,2,2,2,2,2,2,2,2,2,2,2,2,1,0,0,0,0
0,0,0,0,0,0,1,3,3,3,3,3,3,3,3,3,3,3,3,3,3,3,3,3,1,0,0,0,0
0,0,0,0,0,0,1,3,3,3,3,3,3,3,3,3,3,3,3,3,3,3,3,3,1,0,0,0,0
0,0,0,0,0,0,0,1,1,1,1,1,1,1,1,1,1,1,1,1,1,1,1,1,0,0,0,0,0
0,0,0,0,0,0,0,0,1,1,8,1,1,1,1,1,1,1,1,1,1,1,1,1,0,0,0,0,0
0,0,0,0,0,0,0,0,0,0,0,0,0,0,0,0,0,0,0,0,0,0,0,0,0,0,0,0,0
0,0,0,0,0,0,0,0,0,0,0,0,0,0,0,0,0,0,0,0,0,0,0,0,0,0,0,0,0
0,0,0,0,0,0,0,0,0,0,0,0,0,0,0,0,0,0,0,0,0,0,0,0,0,0,0,0,0
0,0,0,0,0,0,0,0,0,0,0,0,0,0,0,0,0,0,0,0,0,0,0,0,0,0,0,0,0
0,0,0,0,0,0,0,0,0,0,0,0,0,0,0,0,0,0,0,0,0,0,0,0,0,0,0,0,0
0,0,0,0,0,0,0,0,0,0,0,0,0,0,0,0,0,0,0,0,0,0,0,0,0,0,0,0,0
endlayer

layer
0,0,0,0,0,0,0,0,0,0,0,0,0,0,0,0,0,0,0,0,0,0,0,0,0,0,0,0,0
0,0,0,0,0,0,0,0,0,0,0,0,0,0,0,0,0,0,0,0,0,0,0,0,0,0,0,0,0
0,0,0,0,0,0,0,0,0,0,0,0,0,0,0,0,0,0,0,0,0,0,0,0,0,0,0,0,0
0,0,0,0,0,0,0,0,0,0,0,0,0,0,0,0,0,0,0,0,0,0,0,0,0,0,0,0,0
0,0,0,0,0,0,0,0,0,0,0,0,0,0,0,0,0,0,0,0,0,0,0,0,0,0,0,0,0
0,0,0,0,0,0,0,0,0,0,0,0,0,0,0,0,0,0,0,0,0,0,0,0,0,0,0,0,0
0,0,0,0,0,0,0,0,0,0,9,0,0,0,0,0,0,0,0,0,0,0,0,0,0,0,0,0,0
0,0,0,0,0,0,0,0,0,0,0,0,0,0,0,0,0,0,0,0,0,0,0,0,0,0,0,0,0
0,0,0,0,0,0,0,1,1,1,1,1,1,1,1,1,1,1,1,1,1,1,1,0,0,0,0,0,0
0,0,0,0,0,0,0,1,1,1,1,1,1,1,1,1,1,1,1,1,1,1,1,0,0,0,0,0,0
0,0,0,0,0,0,0,0,1,1,1,1,1,1,1,1,1,1,1,1,1,1,1,0,0,0,0,0,0
0,0,0,0,0,0,0,0,1,1,1,1,1,1,1,1,1,1,1,1,1,1,1,0,0,0,0,0,0
0,0,0,0,0,0,0,0,1,1,1,1,1,1,1,1,1,1,1,1,1,1,1,0,0,0,0,0,0
0,0,0,0,0,0,0,0,1,1,1,1,1,1,1,1,1,1,1,1,1,1,1,0,0,0,0,0,0
0,0,0,0,0,0,0,0,1,1,1,1,1,1,1,1,1,1,1,1,1,1,1,1,0,0,0,0,0
0,0,0,0,0,0,0,1,1,1,1,0,1,1,1,1,1,1,1,1,1,1,1,1,1,1,0,0,0
0,0,0,0,0,0,0,0,1,1,1,1,1,1,1,1,1,1,1,1,1,1,1,1,1,0,0,0,0
0,0,0,0,0,0,0,0,1,1,1,1,1,1,1,1,1,1,1,1,1,1,1,1,1,0,0,0,0
0,0,0,0,0,0,0,0,1,1,1,1,1,1,1,1,1,1,1,1,1,1,1,1,1,0,0,0,0
0,0,0,0,0,0,0,0,1,1,1,1,1,1,1,1,1,1,1,1,1,1,1,1,0,0,0,0,0
0,0,0,0,0,0,0,0,1,1,1,1,1,1,1,1,1,1,1,1,1,1,1,1,0,0,0,0,0
0,0,0,0,0,0,0,1,1,1,1,1,1,1,1,1,1,1,1,1,1,1,1,1,0,0,0,0,0
0,0,0,0,0,0,0,1,1,1,1,1,1,1,1,1,1,1,1,1,1,1,1,1,0,0,0,0,0
0,0,0,0,0,0,0,0,0,0,0,0,0,0,0,0,0,0,0,0,0,0,0,0,0,0,0,0,0
0,0,0,0,0,0,0,0,0,0,8,0,0,0,0,0,0,0,0,0,0,0,0,0,0,0,0,0,0
0,0,0,0,0,0,0,0,0,0,0,0,0,0,0,0,0,0,0,0,0,0,0,0,0,0,0,0,0
0,0,0,0,0,0,0,0,0,0,0,0,0,0,0,0,0,0,0,0,0,0,0,0,0,0,0,0,0
0,0,0,0,0,0,0,0,0,0,0,0,0,0,0,0,0,0,0,0,0,0,0,0,0,0,0,0,0
0,0,0,0,0,0,0,0,0,0,0,0,0,0,0,0,0,0,0,0,0,0,0,0,0,0,0,0,0
0,0,0,0,0,0,0,0,0,0,0,0,0,0,0,0,0,0,0,0,0,0,0,0,0,0,0,0,0
0,0,0,0,0,0,0,0,0,0,0,0,0,0,0,0,0,0,0,0,0,0,0,0,0,0,0,0,0
endlayer

layer
0,0,0,0,0,0,0,0,0,0,0,0,0,0,0,0,0,0,0,0,0,0,0,0,0,0,0,0,0
0,0,0,0,0,0,0,0,0,0,0,0,0,0,0,0,0,0,0,0,0,0,0,0,0,0,0,0,0
0,0,0,0,0,0,0,0,0,0,0,0,0,0,0,0,0,0,0,0,0,0,0,0,0,0,0,0,0
0,0,0,0,0,0,0,0,0,0,0,0,0,0,0,0,0,0,0,0,0,0,0,0,0,0,0,0,0
0,0,0,0,0,0,0,0,0,0,0,0,0,0,0,0,0,0,0,0,0,0,0,0,0,0,0,0,0
0,0,0,0,0,0,0,0,0,0,0,0,0,0,0,0,0,0,0,0,0,0,0,0,0,0,0,0,0
0,0,0,0,0,0,0,0,0,0,9,0,0,0,0,0,0,0,0,0,0,0,0,0,0,0,0,0,0
0,0,0,0,0,0,0,0,0,0,0,0,0,0,0,0,0,0,0,0,0,0,0,0,0,0,0,0,0
0,0,0,0,0,0,0,0,0,0,0,0,0,0,0,0,0,0,0,0,0,0,0,0,0,0,0,0,0
0,0,0,0,0,0,0,0,0,0,0,0,0,0,0,0,0,0,0,0,0,0,0,0,0,0,0,0,0
0,0,0,0,0,0,0,0,0,0,0,0,0,0,0,0,0,0,0,0,0,0,0,0,0,0,0,0,0
0,0,0,0,0,0,0,0,0,0,0,0,0,0,0,0,0,0,0,0,0,0,0,0,0,0,0,0,0
0,0,0,0,0,0,0,0,0,0,0,0,0,0,0,0,0,0,0,0,0,0,0,0,0,0,0,0,0
0,0,0,0,0,0,0,0,0,0,0,0,0,0,0,0,0,0,0,0,0,0,0,0,0,0,0,0,0
0,0,0,0,0,0,0,0,0,0,0,0,0,0,0,0,0,0,0,0,0,0,0,0,0,0,0,0,0
0,0,0,0,0,0,0,0,0,0,0,0,0,0,0,0,0,0,0,0,0,0,0,0,0,0,0,0,0
0,0,0,0,0,0,0,0,0,0,0,0,0,0,0,0,0,0,0,0,0,0,0,0,0,0,0,0,0
0,0,0,0,0,0,0,0,0,0,0,0,0,0,0,0,0,0,0,0,0,0,0,0,0,0,0,0,0
0,0,0,0,0,0,0,0,0,0,0,0,0,0,0,0,0,0,0,0,0,0,0,0,0,0,0,0,0
0,0,0,0,0,0,0,0,0,0,0,0,0,0,0,0,0,0,0,0,0,0,0,0,0,0,0,0,0
0,0,0,0,0,0,0,0,0,0,0,0,0,0,0,0,0,0,0,0,0,0,0,0,0,0,0,0,0
0,0,0,0,0,0,0,0,0,0,0,0,0,0,0,0,0,0,0,0,0,0,0,0,0,0,0,0,0
0,0,0,0,0,0,0,0,0,0,0,0,0,0,0,0,0,0,0,0,0,0,0,0,0,0,0,0,0
0,0,0,0,0,0,0,0,0,0,0,0,0,0,0,0,0,0,0,0,0,0,0,0,0,0,0,0,0
0,0,0,0,0,0,0,0,0,0,8,0,0,0,0,0,0,0,0,0,0,0,0,0,0,0,0,0,0
0,0,0,0,0,0,0,0,0,0,0,0,0,0,0,0,0,0,0,0,0,0,0,0,0,0,0,0,0
0,0,0,0,0,0,0,0,0,0,0,0,0,0,0,0,0,0,0,0,0,0,0,0,0,0,0,0,0
0,0,0,0,0,0,0,0,0,0,0,0,0,0,0,0,0,0,0,0,0,0,0,0,0,0,0,0,0
0,0,0,0,0,0,0,0,0,0,0,0,0,0,0,0,0,0,0,0,0,0,0,0,0,0,0,0,0
0,0,0,0,0,0,0,0,0,0,0,0,0,0,0,0,0,0,0,0,0,0,0,0,0,0,0,0,0
0,0,0,0,0,0,0,0,0,0,0,0,0,0,0,0,0,0,0,0,0,0,0,0,0,0,0,0,0
endlayer

