
# Created by Ruins mod version 14.7 Ingame Parser
# authoring Player: Barlock_James

weight=1
embed_into_distance=0
acceptable_target_blocks=
unacceptable_target_blocks=flowing_water,water,flowing_lava,lava
dimensions=10,7,7
allowable_overhang=0
max_leveling=2
leveling_buffer=0
preserve_water=0
preserve_lava=0

rule1=0,100,minecraft:snow-0
rule2=0,100,minecraft:packed_ice-0
rule3=0,100,chisel:ice_stairs.1-8
rule4=0,100,chisel:ice_stairs.1-10
rule5=0,100,chisel:ice-4
rule6=0,100,chisel:ice_stairs.1-11
rule7=0,100,chisel:ice-3
rule8=0,100,chisel:ice_stairs.1-9
rule9=0,100,chisel:ice_pillar-14
rule10=0,100,chisel:ice_pillar-6
rule11=0,100,chisel:ice_pillar-12
rule12=0,100,chisel:ice_pillar-3
rule13=0,100,chisel:ice-13
rule14=0,100,chisel:ice_pillar-5
rule15=0,100,ExtraUtilities:decorativeBlock1-3
rule16=0,100,chisel:ice_pillar-4
rule17=0,100,witchery:icefence-0
rule18=0,100,witchery:iceslab-0

layer
1,1,1,1,1,1,1
1,1,1,1,1,1,1
1,1,1,1,1,1,1
1,1,1,1,1,1,1
1,1,1,1,1,1,1
1,1,1,1,1,1,1
1,1,1,1,1,1,1
endlayer

layer
2,3,3,3,3,3,2
6,5,5,5,5,5,4
6,5,7,7,7,5,4
6,5,7,7,7,5,4
6,5,7,7,7,5,4
6,5,5,5,5,5,4
2,8,8,8,8,8,2
endlayer

layer
2,0,0,0,0,0,2
0,0,0,0,0,0,0
0,0,9,0,9,0,0
0,0,0,0,0,0,0
0,0,9,0,9,0,0
0,0,0,0,0,0,0
2,0,0,0,0,0,2
endlayer

layer
2,0,0,0,0,0,2
0,0,0,0,0,0,0
0,0,10,0,10,0,0
0,0,0,0,0,0,0
0,0,10,0,10,0,0
0,0,0,0,0,0,0
2,0,0,0,0,0,2
endlayer

layer
2,0,0,0,0,0,2
0,0,0,0,0,0,0
0,0,11,0,11,0,0
0,0,0,0,0,0,0
0,0,11,0,11,0,0
0,0,0,0,0,0,0
2,0,0,0,0,0,2
endlayer

layer
2,2,12,12,12,2,2
2,2,12,13,12,2,2
12,12,14,14,14,12,12
12,13,14,15,14,13,12
12,12,14,14,14,12,12
2,2,12,13,12,2,2
2,2,12,12,12,2,2
endlayer

layer
0,0,0,0,0,0,0
0,3,3,3,3,4,0
0,6,16,16,16,4,0
0,6,16,0,16,4,0
0,6,16,16,16,4,0
0,6,8,8,8,4,0
0,0,0,0,0,0,0
endlayer

layer
0,0,0,0,0,0,0
0,0,0,0,0,0,0
0,0,16,17,16,0,0
0,0,17,0,17,0,0
0,0,16,17,16,0,0
0,0,0,0,0,0,0
0,0,0,0,0,0,0
endlayer

layer
0,0,0,0,0,0,0
0,0,18,18,18,0,0
0,18,18,18,18,18,0
0,18,18,17,18,18,0
0,18,18,18,18,18,0
0,0,18,18,18,0,0
0,0,0,0,0,0,0
endlayer

layer
0,0,0,0,0,0,0
0,0,0,0,0,0,0
0,0,0,0,0,0,0
0,0,0,17,0,0,0
0,0,0,0,0,0,0
0,0,0,0,0,0,0
0,0,0,0,0,0,0
endlayer

