
# Created by Ruins mod version 14.7 Ingame Parser
# authoring Player: Barlock_James

weight=1
embed_into_distance=0
acceptable_target_blocks=
unacceptable_target_blocks=flowing_water,water,flowing_lava,lava
dimensions=11,7,7
allowable_overhang=0
max_leveling=2
leveling_buffer=0
preserve_water=0
preserve_lava=0

rule1=0,100,chisel:technical2-0
rule2=0,100,witchery:spanishmoss-1
rule3=0,100,LLadders:tile.lladders.block.sturdyladder-3
rule4=0,100,witchery:spanishmoss-4
rule5=0,100,witchery:spanishmoss-2
rule6=0,100,chisel:factoryblock-1
rule7=0,100,chisel:factoryblock-14
rule8=0,100,IInventory;Automagy:blockGolemWorkbench;DCsAppleMilk:defeatedcrow.foodPlate#1#0#0+DCsAppleMilk:defeatedcrow.foodPlate#1#0#1+harvestcraft:blueberrysmoothieItem#1#0#2+harvestcraft:cherrysodaItem#1#0#3-0
rule9=0,100,minecraft:nether_brick_fence-0
rule10=0,100,minecraft:stone_slab-6
rule11=0,100,minecraft:stone_slab-14
rule12=0,100,chisel:glowstone-8

layer
0,0,0,0,0,0,0
0,1,0,0,0,1,0
0,0,0,0,0,0,0
4,0,0,3,0,0,2
4,0,0,0,0,0,2
0,1,0,0,0,1,0
0,0,0,0,0,0,0
endlayer

layer
0,0,0,0,0,0,0
0,1,0,0,0,1,0
0,0,0,0,0,0,0
4,0,0,3,0,0,2
4,0,0,0,0,0,2
0,1,0,0,0,1,0
0,0,0,0,0,0,0
endlayer

layer
0,0,0,0,0,0,0
0,1,0,0,0,1,0
0,0,1,0,1,0,0
4,0,0,3,0,0,2
4,0,1,0,1,0,2
0,1,0,0,0,1,0
0,0,0,0,0,0,0
endlayer

layer
0,0,0,0,0,0,0
0,4,0,0,0,2,0
0,0,1,0,1,0,0
4,0,0,3,0,0,2
4,0,1,0,1,0,2
0,5,0,0,0,5,0
0,0,0,0,0,0,0
endlayer

layer
0,0,0,0,0,0,0
0,4,0,0,0,2,0
0,0,1,1,1,0,0
4,0,1,3,1,0,2
4,0,1,1,1,0,2
0,5,0,0,0,5,0
0,0,0,0,0,0,0
endlayer

layer
0,0,0,0,0,0,0
0,4,6,6,6,2,0
0,6,6,6,6,6,0
4,6,6,3,6,6,2
4,6,6,6,6,6,2
0,5,6,6,6,5,0
0,0,0,0,0,0,0
endlayer

layer
0,0,0,0,0,0,0
0,0,7,7,7,0,0
0,7,0,0,0,7,0
0,7,0,0,0,7,0
0,7,8,0,0,7,0
0,0,7,7,7,0,0
0,0,0,0,0,0,0
endlayer

layer
0,0,0,0,0,0,0
0,0,9,0,9,0,0
0,9,0,0,0,9,0
0,0,0,0,0,0,0
0,9,0,0,0,9,0
0,0,9,0,9,0,0
0,0,0,0,0,0,0
endlayer

layer
0,0,0,0,0,0,0
0,0,9,0,9,0,0
0,9,0,0,0,9,0
0,0,0,0,0,0,0
0,9,0,0,0,9,0
0,0,9,0,9,0,0
0,0,0,0,0,0,0
endlayer

layer
0,0,0,0,0,0,0
0,0,10,10,10,0,0
0,10,11,11,11,10,0
0,10,11,12,11,10,0
0,10,11,11,11,10,0
0,0,10,10,10,0,0
0,0,0,0,0,0,0
endlayer

layer
0,0,0,0,0,0,0
0,0,0,0,0,0,0
0,0,0,0,0,0,0
0,0,0,10,0,0,0
0,0,0,0,0,0,0
0,0,0,0,0,0,0
0,0,0,0,0,0,0
endlayer

