
# Created by Ruins mod version 14.7 Ingame Parser
# authoring Player: Barlock_James

weight=1
embed_into_distance=0
acceptable_target_blocks=
unacceptable_target_blocks=flowing_water,water,flowing_lava,lava
dimensions=8,21,17
allowable_overhang=0
max_leveling=2
leveling_buffer=0
preserve_water=0
preserve_lava=0

rule1=0,100,minecraft:hardened_clay-0
rule2=0,100,minecraft:dirt-0
rule3=0,100,minecraft:stained_hardened_clay-7
rule4=0,100,minecraft:wool-12
rule5=0,100,minecraft:wool-1
rule6=0,100,minecraft:wool-4
rule7=0,100,minecraft:wool-0
rule8=0,100,IInventory;Thaumcraft:blockStoneDevice;lootplusplus:custom_spawn_egg#1#35#0-1
rule9=0,100,minecraft:log-0
rule10=0,100,minecraft:stained_hardened_clay-1
rule11=0,100,erebus:dooramber-0
rule12=0,100,ExtraUtilities:color_lightgem-1
rule13=0,100,witchery:altar-1
rule14=0,100,minecraft:leaves-0
rule15=0,100,witchery:wolfaltar-4
rule16=0,100,minecraft:stained_hardened_clay-4
rule17=0,100,erebus:dooramber-8
rule18=0,100,headcrumbs:betterSkull-4
rule19=0,100,minecraft:stained_hardened_clay-0
rule20=0,100,minecraft:stained_hardened_clay-14
rule21=0,100,erebus:amber-1

layer
1,1,1,1,1,1,1,1,1,1,1,1,1,1,1,1,1
1,1,1,1,1,1,1,1,1,1,1,1,1,1,1,1,1
1,1,2,3,3,3,3,3,3,3,3,3,3,3,2,1,1
1,1,3,3,3,3,3,3,3,3,3,3,3,3,3,1,1
1,1,3,3,4,4,4,4,4,4,4,4,4,3,3,1,1
1,1,3,3,4,4,4,4,4,4,4,4,4,3,3,1,1
1,1,3,3,4,4,5,5,5,5,5,4,4,3,3,1,1
1,1,3,3,4,4,5,6,6,6,5,4,4,3,3,1,1
1,1,3,3,4,4,5,6,7,6,5,4,4,3,3,1,1
1,1,3,3,4,4,5,6,7,6,5,4,4,3,3,1,1
1,1,3,3,4,4,5,6,8,6,5,4,4,3,3,1,1
1,1,3,3,4,4,5,6,7,6,5,4,4,3,3,1,1
1,1,3,3,4,4,5,6,7,6,5,4,4,3,3,1,1
1,1,3,3,4,4,5,6,6,6,5,4,4,3,3,1,1
1,1,3,3,4,4,5,5,5,5,5,4,4,3,3,1,1
1,1,3,3,4,4,4,4,4,4,4,4,4,3,3,1,1
1,1,3,3,4,4,4,4,4,4,4,4,4,3,3,1,1
1,1,3,3,3,3,3,3,3,3,3,3,3,3,3,1,1
1,1,2,3,3,3,3,3,3,3,3,3,3,3,2,1,1
1,1,1,1,1,1,1,1,1,1,1,1,1,1,1,1,1
1,1,1,1,1,1,1,1,1,1,1,1,1,1,1,1,1
endlayer

layer
0,0,0,0,0,0,0,0,0,0,0,0,0,0,0,0,0
0,0,0,0,0,0,0,0,0,0,0,0,0,0,0,0,0
0,0,9,0,0,0,0,10,0,10,0,0,0,0,9,0,0
0,0,0,0,10,10,10,10,0,10,10,10,10,0,0,0,0
0,0,0,10,10,10,10,10,11,10,10,10,10,10,0,0,0
0,0,0,10,10,12,0,0,0,0,0,12,10,10,0,0,0
0,0,0,10,10,0,0,0,0,0,0,0,10,10,0,0,0
0,0,0,10,10,0,0,0,0,0,0,0,10,10,0,0,0
0,0,0,10,10,0,0,0,0,0,0,0,10,10,0,0,0
0,0,0,10,10,0,0,0,0,0,0,0,10,10,0,0,0
0,0,0,10,10,0,0,0,0,0,0,0,10,10,0,0,0
0,0,0,10,10,0,0,13,13,13,0,0,10,10,0,0,0
0,0,0,10,10,0,0,13,13,13,0,0,10,10,0,0,0
0,0,0,10,10,0,0,0,0,0,0,0,10,10,0,0,0
0,0,0,10,10,0,0,0,0,0,0,0,10,10,0,0,0
0,0,0,10,10,12,0,0,0,0,0,12,10,10,0,0,0
0,0,0,10,10,10,10,10,10,10,10,10,10,10,0,0,0
0,0,0,0,10,10,10,10,10,10,10,10,10,0,0,0,0
0,0,9,0,0,0,0,0,0,0,0,0,0,0,9,0,0
0,0,0,0,0,0,0,0,0,0,0,0,0,0,0,0,0
0,0,0,0,0,0,0,0,0,0,0,0,0,0,0,0,0
endlayer

layer
0,0,0,0,0,0,0,0,0,0,0,0,14,14,14,14,0
0,0,0,0,0,0,0,0,0,0,0,0,14,14,14,14,14
0,0,9,0,0,0,0,15,0,15,0,0,14,14,9,14,14
0,0,0,0,0,0,0,16,0,16,0,0,14,14,14,14,14
0,0,0,0,0,16,16,16,17,16,16,16,14,14,14,14,0
0,0,0,0,16,16,16,16,0,16,16,16,16,0,0,0,0
0,0,0,0,16,16,0,0,0,0,0,16,16,0,0,0,0
0,0,0,0,16,16,0,0,0,0,0,16,16,0,0,0,0
0,0,0,0,16,16,0,0,0,0,0,16,16,0,0,0,0
0,0,0,0,16,16,0,0,0,0,0,16,16,0,0,0,0
0,0,0,0,16,16,0,0,0,0,0,16,16,0,0,0,0
0,0,0,0,16,16,0,0,0,0,0,16,16,0,0,0,0
0,0,0,0,16,16,0,0,0,0,0,16,16,0,0,0,0
0,0,0,0,16,16,0,0,0,0,0,16,16,0,0,0,0
0,0,0,0,16,16,0,0,0,0,0,16,16,0,0,0,0
0,0,0,0,16,16,16,16,16,16,16,16,16,0,0,0,0
0,0,0,0,0,16,16,16,16,16,16,16,0,0,0,0,0
0,0,0,0,0,0,0,0,0,0,0,0,0,0,0,0,0
0,0,9,0,0,0,0,0,0,0,0,0,0,0,9,0,0
0,0,0,0,0,0,0,0,0,0,0,0,0,0,0,0,0
0,0,0,0,0,0,0,0,0,0,0,0,0,0,0,0,0
endlayer

layer
0,0,0,0,0,0,0,0,0,0,0,0,14,14,14,14,0
0,0,0,0,0,0,0,0,0,0,0,0,14,14,14,14,14
0,0,9,0,0,0,0,0,0,0,0,0,14,14,9,14,14
0,0,0,0,0,0,0,0,18,0,0,0,14,14,14,14,14
0,0,0,0,0,0,0,19,19,19,0,0,14,14,14,14,14
0,0,0,0,0,0,19,19,19,19,19,0,0,0,0,0,0
0,0,0,0,0,19,19,19,19,19,19,19,0,0,0,0,0
0,0,0,0,0,19,19,0,0,0,19,19,0,0,0,0,0
0,0,0,0,0,19,19,0,0,0,19,19,0,0,0,0,0
0,0,0,0,0,19,19,0,0,0,19,19,0,0,0,0,0
0,0,0,0,0,19,19,0,0,0,19,19,0,0,0,0,0
0,0,0,0,0,19,19,0,0,0,19,19,0,0,0,0,0
0,0,0,0,0,19,19,0,0,0,19,19,0,0,0,0,0
0,0,0,0,0,19,19,0,0,0,19,19,0,0,0,0,0
0,0,0,0,0,19,19,19,19,19,19,19,0,0,0,0,0
0,0,0,0,0,0,19,19,19,19,19,0,0,0,0,0,0
0,14,14,14,14,0,0,0,0,0,0,0,14,14,14,14,14
14,14,14,14,14,0,0,0,0,0,0,0,14,14,14,14,14
14,14,9,14,14,0,0,0,0,0,0,0,14,14,9,14,14
14,14,14,14,14,0,0,0,0,0,0,0,14,14,14,14,14
0,14,14,14,0,0,0,0,0,0,0,0,14,14,14,14,0
endlayer

layer
0,14,14,14,0,0,0,0,0,0,0,0,0,0,0,0,0
14,14,14,14,14,0,0,0,0,0,0,0,0,14,14,14,0
14,14,9,14,14,0,0,0,0,0,0,0,0,14,9,14,0
14,14,14,14,14,0,0,0,0,0,0,0,0,14,14,14,0
0,14,14,14,0,0,0,0,0,0,0,0,0,0,0,0,0
0,0,0,0,0,0,0,0,20,0,0,0,0,0,0,0,0
0,0,0,0,0,0,0,20,20,20,0,0,0,0,0,0,0
0,0,0,0,0,0,20,20,20,20,20,0,0,0,0,0,0
0,0,0,0,0,0,20,20,21,20,20,0,0,0,0,0,0
0,0,0,0,0,0,20,20,21,20,20,0,0,0,0,0,0
0,0,0,0,0,0,20,20,21,20,20,0,0,0,0,0,0
0,0,0,0,0,0,20,20,21,20,20,0,0,0,0,0,0
0,0,0,0,0,0,20,20,21,20,20,0,0,0,0,0,0
0,0,0,0,0,0,20,20,20,20,20,0,0,0,0,0,0
0,0,0,0,0,0,0,20,20,20,0,0,0,0,0,0,0
0,0,0,0,0,0,0,0,0,0,0,0,0,0,0,0,0
14,14,14,14,14,0,0,0,0,0,0,0,14,14,14,14,14
14,14,14,14,14,0,0,0,0,0,0,0,14,14,14,14,14
14,14,9,14,14,0,0,0,0,0,0,0,14,14,9,14,14
14,14,14,14,14,0,0,0,0,0,0,0,14,14,14,14,14
14,14,14,14,14,0,0,0,0,0,0,0,0,14,14,14,0
endlayer

layer
14,14,14,14,0,0,0,0,0,0,0,0,0,0,0,0,0
14,14,14,14,14,0,0,0,0,0,0,0,0,0,14,0,0
14,14,9,14,14,0,0,0,0,0,0,0,0,14,14,14,0
14,14,14,14,14,0,0,0,0,0,0,0,0,0,14,0,0
14,14,14,14,0,0,0,0,0,0,0,0,0,0,0,0,0
0,0,0,0,0,0,0,0,0,0,0,0,0,0,0,0,0
0,0,0,0,0,0,0,0,0,0,0,0,0,0,0,0,0
0,0,0,0,0,0,0,0,0,0,0,0,0,0,0,0,0
0,0,0,0,0,0,0,0,21,0,0,0,0,0,0,0,0
0,0,0,0,0,0,0,0,21,0,0,0,0,0,0,0,0
0,0,0,0,0,0,0,0,21,0,0,0,0,0,0,0,0
0,0,0,0,0,0,0,0,21,0,0,0,0,0,0,0,0
0,0,0,0,0,0,0,0,21,0,0,0,0,0,0,0,0
0,0,0,0,0,0,0,0,0,0,0,0,0,0,0,0,0
0,0,0,0,0,0,0,0,0,0,0,0,0,0,0,0,0
0,0,0,0,0,0,0,0,0,0,0,0,0,0,0,0,0
0,0,0,0,0,0,0,0,0,0,0,0,0,0,0,0,0
0,14,14,0,0,0,0,0,0,0,0,0,0,14,14,0,0
0,14,9,14,0,0,0,0,0,0,0,0,0,14,9,14,0
0,0,14,14,0,0,0,0,0,0,0,0,0,0,14,0,0
0,0,0,0,0,0,0,0,0,0,0,0,0,0,0,0,0
endlayer

layer
0,0,0,0,0,0,0,0,0,0,0,0,0,0,0,0,0
0,14,14,14,0,0,0,0,0,0,0,0,0,0,0,0,0
0,14,9,14,0,0,0,0,0,0,0,0,0,0,0,0,0
0,14,14,0,0,0,0,0,0,0,0,0,0,0,0,0,0
0,0,0,0,0,0,0,0,0,0,0,0,0,0,0,0,0
0,0,0,0,0,0,0,0,0,0,0,0,0,0,0,0,0
0,0,0,0,0,0,0,0,0,0,0,0,0,0,0,0,0
0,0,0,0,0,0,0,0,0,0,0,0,0,0,0,0,0
0,0,0,0,0,0,0,0,0,0,0,0,0,0,0,0,0
0,0,0,0,0,0,0,0,0,0,0,0,0,0,0,0,0
0,0,0,0,0,0,0,0,0,0,0,0,0,0,0,0,0
0,0,0,0,0,0,0,0,0,0,0,0,0,0,0,0,0
0,0,0,0,0,0,0,0,0,0,0,0,0,0,0,0,0
0,0,0,0,0,0,0,0,0,0,0,0,0,0,0,0,0
0,0,0,0,0,0,0,0,0,0,0,0,0,0,0,0,0
0,0,0,0,0,0,0,0,0,0,0,0,0,0,0,0,0
0,0,0,0,0,0,0,0,0,0,0,0,0,0,0,0,0
0,0,14,0,0,0,0,0,0,0,0,0,0,0,14,0,0
0,14,14,14,0,0,0,0,0,0,0,0,0,14,14,14,0
0,0,14,0,0,0,0,0,0,0,0,0,0,0,14,0,0
0,0,0,0,0,0,0,0,0,0,0,0,0,0,0,0,0
endlayer

layer
0,0,0,0,0,0,0,0,0,0,0,0,0,0,0,0,0
0,0,14,0,0,0,0,0,0,0,0,0,0,0,0,0,0
0,14,14,14,0,0,0,0,0,0,0,0,0,0,0,0,0
0,0,14,0,0,0,0,0,0,0,0,0,0,0,0,0,0
0,0,0,0,0,0,0,0,0,0,0,0,0,0,0,0,0
0,0,0,0,0,0,0,0,0,0,0,0,0,0,0,0,0
0,0,0,0,0,0,0,0,0,0,0,0,0,0,0,0,0
0,0,0,0,0,0,0,0,0,0,0,0,0,0,0,0,0
0,0,0,0,0,0,0,0,0,0,0,0,0,0,0,0,0
0,0,0,0,0,0,0,0,0,0,0,0,0,0,0,0,0
0,0,0,0,0,0,0,0,0,0,0,0,0,0,0,0,0
0,0,0,0,0,0,0,0,0,0,0,0,0,0,0,0,0
0,0,0,0,0,0,0,0,0,0,0,0,0,0,0,0,0
0,0,0,0,0,0,0,0,0,0,0,0,0,0,0,0,0
0,0,0,0,0,0,0,0,0,0,0,0,0,0,0,0,0
0,0,0,0,0,0,0,0,0,0,0,0,0,0,0,0,0
0,0,0,0,0,0,0,0,0,0,0,0,0,0,0,0,0
0,0,0,0,0,0,0,0,0,0,0,0,0,0,0,0,0
0,0,0,0,0,0,0,0,0,0,0,0,0,0,0,0,0
0,0,0,0,0,0,0,0,0,0,0,0,0,0,0,0,0
0,0,0,0,0,0,0,0,0,0,0,0,0,0,0,0,0
endlayer

