
# Created by Ruins mod version 14.7 Ingame Parser
# authoring Player: Barlock_James

weight=1
embed_into_distance=0
acceptable_target_blocks=
unacceptable_target_blocks=flowing_water,water,flowing_lava,lava
dimensions=10,11,11
allowable_overhang=0
max_leveling=2
leveling_buffer=0
preserve_water=0
preserve_lava=0

rule1=0,100,minecraft:sand-0
rule2=0,100,minecraft:water-0
rule3=0,100,minecraft:log-3
rule4=0,100,cfm:hedge-3
rule5=0,100,IInventory;minecraft:chest;minecraft:fishing_rod#1#0#0+Aquaculture:item.IronFishingRod#1#0#1-5
rule6=0,100,minecraft:leaves-7
rule7=0,100,minecraft:leaves-15

layer
1,1,1,1,1,1,1,1,1,1,1
1,1,1,1,1,1,1,1,1,1,1
1,1,1,1,1,1,1,1,1,1,1
1,1,1,1,1,1,1,1,1,1,1
1,1,1,1,1,1,1,1,1,1,1
1,1,1,1,1,1,1,1,1,1,1
1,1,1,1,1,1,1,1,1,1,1
1,1,1,1,1,1,1,1,1,1,1
1,1,1,1,1,1,1,1,1,1,1
1,1,1,1,1,1,1,1,1,1,1
1,1,1,1,1,1,1,1,1,1,1
endlayer

layer
1,1,1,1,1,1,1,1,1,1,1
1,1,1,1,1,1,1,1,1,1,1
1,1,1,1,1,1,1,1,1,1,1
1,1,1,2,2,2,2,2,1,1,1
1,1,1,2,2,2,2,2,1,1,1
1,1,1,2,2,2,2,2,1,1,1
1,1,1,2,2,2,2,2,1,1,1
1,1,1,2,2,2,2,2,1,1,1
1,1,1,1,1,1,1,1,1,1,1
1,1,1,1,1,1,1,1,1,1,1
1,1,1,1,1,1,1,1,1,1,1
endlayer

layer
1,1,1,1,1,1,1,1,1,1,1
1,1,1,1,1,1,1,1,1,1,1
1,1,2,2,2,2,2,2,2,1,1
1,1,2,2,2,2,2,2,2,1,1
1,1,2,2,2,2,2,2,2,1,1
1,1,2,2,2,2,2,2,2,1,1
1,1,2,2,2,2,2,2,2,1,1
1,1,2,2,2,2,2,2,2,1,1
1,1,3,2,2,2,2,2,2,1,1
1,1,1,1,1,1,1,1,1,1,1
1,1,1,1,1,1,1,1,1,1,1
endlayer

layer
1,1,1,1,1,1,1,1,1,1,1
1,2,2,2,2,2,2,2,2,3,1
1,2,2,2,2,2,2,2,2,2,1
1,2,2,2,2,2,2,2,2,2,1
1,2,2,2,2,2,2,2,2,2,1
1,2,2,2,2,2,2,2,2,2,1
1,2,2,2,2,2,2,2,2,2,1
1,2,2,2,2,2,2,2,2,2,1
1,2,3,2,2,2,2,2,2,2,1
1,2,2,2,2,2,2,2,2,2,1
1,1,1,1,1,1,1,1,1,1,1
endlayer

layer
0,0,0,0,0,0,0,0,0,0,0
0,0,0,0,0,0,0,0,0,3,0
0,0,0,0,0,0,0,0,0,0,0
0,0,0,0,0,0,0,0,0,0,0
0,0,0,0,0,0,0,0,0,0,0
0,0,0,0,0,0,0,0,0,0,0
0,0,0,0,0,0,0,0,0,0,0
0,0,0,0,0,0,0,0,0,0,0
0,0,3,0,0,0,0,0,4,4,4
0,0,0,0,0,0,0,0,4,5,4
0,0,0,0,0,0,0,0,4,4,4
endlayer

layer
0,0,0,0,0,0,0,0,0,0,0
0,0,0,0,0,0,0,0,0,3,0
0,0,0,0,0,0,0,0,0,0,0
0,0,0,0,0,0,0,0,0,0,0
0,0,0,0,0,0,0,0,0,0,0
0,0,0,0,0,0,0,0,0,0,0
0,0,0,0,0,0,0,0,0,0,0
0,0,0,0,0,0,0,0,0,0,0
0,0,3,0,0,0,0,0,0,0,0
0,0,0,0,0,0,0,0,0,0,0
0,0,0,0,0,0,0,0,0,0,0
endlayer

layer
0,0,0,0,0,0,0,0,0,0,0
0,0,0,0,0,0,0,6,0,0,0
0,0,0,0,0,0,0,0,3,0,0
0,0,0,0,0,6,0,0,0,6,0
0,0,0,0,0,0,0,0,0,0,0
0,0,0,0,0,0,0,6,0,0,0
0,0,0,0,0,0,0,0,0,0,0
0,0,0,0,0,0,0,0,0,0,0
0,0,3,0,0,0,0,0,0,0,0
0,0,0,0,0,0,0,0,0,0,0
0,0,0,0,0,0,0,0,0,0,0
endlayer

layer
0,0,0,0,0,0,0,0,0,0,0
0,0,0,0,0,0,0,6,0,0,0
0,0,0,0,0,0,0,6,0,0,0
0,0,0,0,0,6,6,3,6,6,0
0,0,0,0,0,0,0,6,0,0,0
0,0,0,0,0,0,0,6,0,0,0
0,0,6,0,0,0,0,0,0,0,0
0,0,0,0,0,0,0,0,0,0,0
6,0,3,0,6,0,0,0,0,0,0
0,0,0,0,0,0,0,0,0,0,0
0,0,6,0,0,0,0,0,0,0,0
endlayer

layer
0,0,0,0,0,0,0,0,0,0,0
0,0,0,0,0,0,0,0,0,0,0
0,0,0,0,0,0,0,0,0,0,0
0,0,0,0,0,0,0,6,0,0,0
0,0,0,0,0,0,0,0,0,0,0
0,0,0,0,0,0,0,0,0,0,0
0,0,6,0,0,0,0,0,0,0,0
0,0,6,0,0,0,0,0,0,0,0
6,6,3,6,6,0,0,0,0,0,0
0,0,7,0,0,0,0,0,0,0,0
0,0,7,0,0,0,0,0,0,0,0
endlayer

layer
0,0,0,0,0,0,0,0,0,0,0
0,0,0,0,0,0,0,0,0,0,0
0,0,0,0,0,0,0,0,0,0,0
0,0,0,0,0,0,0,0,0,0,0
0,0,0,0,0,0,0,0,0,0,0
0,0,0,0,0,0,0,0,0,0,0
0,0,0,0,0,0,0,0,0,0,0
0,0,0,0,0,0,0,0,0,0,0
0,0,6,0,0,0,0,0,0,0,0
0,0,0,0,0,0,0,0,0,0,0
0,0,0,0,0,0,0,0,0,0,0
endlayer

