
# Created by Ruins mod version 14.7 Ingame Parser
# authoring Player: Barlock_James

weight=1
embed_into_distance=1
acceptable_target_blocks=
unacceptable_target_blocks=flowing_water,water,flowing_lava,lava
dimensions=6,14,18
allowable_overhang=0
max_leveling=2
leveling_buffer=0
preserve_water=0
preserve_lava=0

rule1=0,100,chisel:dirt-0
rule2=0,100,minecraft:grass-0
rule3=0,100,minecraft:dirt-0
rule4=0,100,minecraft:farmland-7
rule5=0,100,Botania:thatch-0
rule6=0,100,ExtraUtilities:color_stonebrick-7
rule7=0,100,Thaumcraft:blockAiry-1
rule8=0,100,minecraft:water-0
rule9=0,100,chisel:jungle_planks-13
rule10=0,100,minecraft:fence-0
rule11=0,100,minecraft:tallgrass-1
rule12=0,100,minecraft:log-3
rule13=0,100,Natura:N Crops-0
rule14=0,100,Natura:N Crops-1
rule15=0,100,witchery:wickerbundle-0
rule16=0,100,witchery:kettle-3
rule17=0,100,harvestcraft:pamonionCrop-0
rule18=0,100,minecraft:potatoes-1
rule19=0,100,minecraft:carrots-0
rule20=0,100,harvestcraft:pamstrawberryCrop-1
rule21=0,100,minecraft:fence_gate-1
rule22=0,100,minecraft:crafting_table-0
rule23=0,100,harvestcraft:pamonionCrop-2
rule24=0,100,minecraft:potatoes-0
rule25=0,100,minecraft:carrots-3
rule26=0,100,harvestcraft:pamstrawberryCrop-0
rule27=0,100,minecraft:double_plant-5
rule28=0,100,harvestcraft:pamstrawberryCrop-3
rule29=0,100,minecraft:double_plant-4
rule30=0,100,malisisdoors:shoji_door-2
rule31=0,100,harvestcraft:pamonionCrop-1
rule32=0,100,minecraft:fence_gate-3
rule33=0,100,minecraft:double_plant-11
rule34=0,100,malisisdoors:shoji_door-8
rule35=0,100,minecraft:double_plant-9
rule36=0,100,minecraft:double_plant-10
rule37=0,100,Botania:thatch0Stairs-2
rule38=0,100,Botania:thatch0Stairs-0
rule39=0,100,Botania:thatch0Stairs-3
rule40=0,100,Botania:thatch0Stairs-1
rule41=0,100,Botania:thatch0Slab-0
rule42=0,100,Botania:thatch0Slab-8

layer
1,1,1,1,1,1,1,1,1,1,1,1,1,1,1,1,1,1
1,4,4,4,4,2,2,2,3,3,3,2,2,2,2,2,2,1
1,4,4,4,4,2,2,3,5,5,5,3,2,2,2,2,2,1
1,4,4,4,4,2,3,5,5,5,5,5,3,2,2,2,2,1
1,4,4,4,4,3,5,5,6,6,6,5,5,3,2,2,2,1
1,4,4,4,8,3,5,5,6,7,6,5,5,3,2,2,2,1
1,4,4,4,4,3,5,5,6,6,6,5,5,3,2,2,2,1
1,4,4,4,4,2,3,5,5,5,5,5,3,2,2,2,2,1
1,4,4,4,4,2,2,3,5,5,5,3,2,2,2,2,2,1
1,4,4,4,4,2,2,2,3,9,3,2,2,2,2,2,2,1
1,2,2,2,2,2,2,2,2,2,2,2,2,2,2,2,2,1
1,2,2,2,2,2,2,2,2,2,2,2,2,2,2,2,2,1
1,2,2,2,2,2,2,2,2,2,2,2,2,2,2,2,2,1
1,1,1,1,1,1,1,1,1,1,1,1,1,1,1,1,1,1
endlayer

layer
10,10,10,10,10,10,10,10,10,10,10,10,10,10,10,10,10,10
10,13,14,13,13,0,0,11,12,9,12,11,0,0,0,0,0,10
10,13,14,14,14,0,11,15,0,0,0,15,11,0,0,0,0,10
10,13,13,14,13,11,15,0,0,0,0,0,15,0,0,0,0,10
10,13,13,13,13,12,0,0,0,0,0,0,0,12,0,0,0,10
10,13,14,13,0,9,0,0,0,16,0,0,0,9,0,0,0,10
10,20,19,18,17,12,0,0,0,0,0,0,0,12,0,0,0,10
10,26,25,24,23,0,15,22,0,0,0,0,15,10,10,21,10,10
10,28,19,24,17,0,10,15,0,0,0,15,0,0,0,0,27,10
10,20,25,24,31,0,10,29,12,30,12,29,0,0,0,0,0,10
10,10,10,10,10,21,10,0,0,0,0,0,0,0,0,0,0,10
10,0,0,0,0,0,0,0,0,0,0,0,0,0,0,0,0,10
10,27,0,0,0,0,0,0,0,0,0,0,0,0,0,0,27,10
10,10,10,10,10,10,10,10,10,32,10,10,10,10,10,10,10,10
endlayer

layer
0,0,0,0,0,0,0,0,0,0,0,0,0,0,0,0,0,0
0,0,0,0,0,0,0,0,12,0,12,0,0,0,0,0,0,0
0,0,0,0,0,0,0,15,0,0,0,15,0,0,0,0,0,0
0,0,0,0,0,0,15,0,0,0,0,0,15,0,0,0,0,0
0,0,0,0,0,12,0,0,0,0,0,0,0,12,0,0,0,0
0,0,0,0,0,0,0,0,0,10,0,0,0,0,0,0,0,0
0,0,0,0,0,12,0,0,0,0,0,0,0,12,0,0,0,0
0,0,0,0,0,0,15,0,0,0,0,0,15,0,0,0,0,0
0,0,0,0,0,0,0,15,0,0,0,15,0,0,0,0,33,0
0,0,0,0,0,0,0,33,12,34,12,33,0,0,0,0,0,0
0,0,0,0,0,0,0,0,0,0,0,0,0,0,0,0,0,0
0,0,0,0,0,0,0,0,0,0,0,0,0,0,0,0,0,0
0,36,0,0,0,0,0,0,0,0,0,0,0,0,0,0,35,0
0,0,0,0,0,0,0,0,10,0,10,0,0,0,0,0,0,0
endlayer

layer
0,0,0,0,0,0,0,39,38,38,38,37,0,0,0,0,0,0
0,0,0,0,0,0,39,38,12,9,12,37,38,0,0,0,0,0
0,0,0,0,0,39,38,15,0,0,0,15,37,38,0,0,0,0
0,0,0,0,38,38,15,0,0,0,0,0,15,37,38,0,0,0
0,0,0,0,39,12,0,0,0,0,0,0,0,12,37,0,0,0
0,0,0,0,39,9,0,0,0,10,0,0,0,9,37,0,0,0
0,0,0,0,39,12,0,0,0,0,0,0,0,12,37,0,0,0
0,0,0,0,40,39,15,0,0,0,0,0,15,40,40,0,0,0
0,0,0,0,0,40,39,15,0,0,0,15,40,37,0,0,0,0
0,0,0,0,0,0,40,39,12,9,12,40,37,0,0,0,0,0
0,0,0,0,0,0,0,39,40,40,40,37,0,0,0,0,0,0
0,0,0,0,0,0,0,0,0,0,0,0,0,0,0,0,0,0
0,0,0,0,0,0,0,0,0,0,0,0,0,0,0,0,0,0
0,0,0,0,0,0,0,0,10,10,10,0,0,0,0,0,0,0
endlayer

layer
0,0,0,0,0,0,0,0,0,0,0,0,0,0,0,0,0,0
0,0,0,0,0,0,0,0,41,41,41,0,0,0,0,0,0,0
0,0,0,0,0,0,0,41,42,42,42,41,0,0,0,0,0,0
0,0,0,0,0,0,41,42,42,42,42,42,41,0,0,0,0,0
0,0,0,0,0,41,42,42,0,0,0,42,42,41,0,0,0,0
0,0,0,0,0,41,42,42,0,10,0,42,42,41,0,0,0,0
0,0,0,0,0,41,42,42,0,0,0,42,42,41,0,0,0,0
0,0,0,0,0,0,41,42,42,42,42,42,41,0,0,0,0,0
0,0,0,0,0,0,0,41,42,42,42,41,0,0,0,0,0,0
0,0,0,0,0,0,0,0,41,41,41,0,0,0,0,0,0,0
0,0,0,0,0,0,0,0,0,0,0,0,0,0,0,0,0,0
0,0,0,0,0,0,0,0,0,0,0,0,0,0,0,0,0,0
0,0,0,0,0,0,0,0,0,0,0,0,0,0,0,0,0,0
0,0,0,0,0,0,0,0,0,0,0,0,0,0,0,0,0,0
endlayer

layer
0,0,0,0,0,0,0,0,0,0,0,0,0,0,0,0,0,0
0,0,0,0,0,0,0,0,0,0,0,0,0,0,0,0,0,0
0,0,0,0,0,0,0,0,0,0,0,0,0,0,0,0,0,0
0,0,0,0,0,0,0,0,0,0,0,0,0,0,0,0,0,0
0,0,0,0,0,0,0,0,41,41,41,0,0,0,0,0,0,0
0,0,0,0,0,0,0,0,41,10,41,0,0,0,0,0,0,0
0,0,0,0,0,0,0,0,41,41,41,0,0,0,0,0,0,0
0,0,0,0,0,0,0,0,0,0,0,0,0,0,0,0,0,0
0,0,0,0,0,0,0,0,0,0,0,0,0,0,0,0,0,0
0,0,0,0,0,0,0,0,0,0,0,0,0,0,0,0,0,0
0,0,0,0,0,0,0,0,0,0,0,0,0,0,0,0,0,0
0,0,0,0,0,0,0,0,0,0,0,0,0,0,0,0,0,0
0,0,0,0,0,0,0,0,0,0,0,0,0,0,0,0,0,0
0,0,0,0,0,0,0,0,0,0,0,0,0,0,0,0,0,0
endlayer

