
# Created by Ruins mod version 14.7 Ingame Parser
# authoring Player: Barlock_James

weight=1
embed_into_distance=0
acceptable_target_blocks=
unacceptable_target_blocks=flowing_water,water,flowing_lava,lava
dimensions=8,7,7
allowable_overhang=0
max_leveling=2
leveling_buffer=0
preserve_water=0
preserve_lava=0

rule1=0,100,minecraft:stonebrick-2
rule2=0,100,minecraft:stone_slab-5
rule3=0,100,IInventory;minecraft:chest;adventurebackpack:backpackComponent#1#1#0-5
rule4=0,100,minecraft:stone_brick_stairs-7
rule5=0,100,minecraft:stone_brick_stairs-6
rule6=0,100,minecraft:stone_brick_stairs-5
rule7=0,100,minecraft:stone_brick_stairs-4
rule8=0,100,minecraft:stone_brick_stairs-2
rule9=0,100,minecraft:stone_brick_stairs-3
rule10=0,100,minecraft:stone_brick_stairs-0
rule11=0,100,minecraft:stone_brick_stairs-1
rule12=0,100,Thaumcraft:blockCosmeticOpaque-2
rule13=0,100,ExtraUtilities:magnumTorch-0

layer
1,2,2,2,2,2,1
2,0,0,0,0,3,2
2,0,0,0,0,0,2
2,0,0,0,0,0,2
2,0,0,0,0,0,2
2,0,0,0,0,0,2
1,2,2,2,2,2,1
endlayer

layer
1,0,0,0,0,0,1
0,0,0,0,0,0,0
0,0,0,0,0,0,0
0,0,0,0,0,0,0
0,0,0,0,0,0,0
0,0,0,0,0,0,0
1,0,0,0,0,0,1
endlayer

layer
1,5,0,0,0,4,1
6,0,0,0,0,0,6
0,0,0,0,0,0,0
0,0,0,0,0,0,0
0,0,0,0,0,0,0
7,0,0,0,0,0,7
1,5,0,0,0,4,1
endlayer

layer
0,9,5,0,4,8,0
10,0,0,0,0,0,10
6,0,0,0,0,0,6
0,0,0,0,0,0,0
7,0,0,0,0,0,7
11,0,0,0,0,0,11
0,9,5,0,4,8,0
endlayer

layer
0,0,9,7,8,0,0
0,0,0,6,0,0,0
10,0,0,0,0,0,10
4,5,0,0,0,4,5
11,0,0,0,0,0,11
0,0,0,7,0,0,0
0,0,9,6,8,0,0
endlayer

layer
0,0,0,0,0,0,0
0,0,0,10,0,0,0
0,0,12,12,12,0,0
0,9,12,12,12,8,0
0,0,12,12,12,0,0
0,0,0,11,0,0,0
0,0,0,0,0,0,0
endlayer

layer
0,0,0,0,0,0,0
0,0,0,0,0,0,0
0,0,12,12,12,0,0
0,0,12,13,12,0,0
0,0,12,12,12,0,0
0,0,0,0,0,0,0
0,0,0,0,0,0,0
endlayer

layer
0,0,0,0,0,0,0
0,0,0,0,0,0,0
0,0,12,12,12,0,0
0,0,12,12,12,0,0
0,0,12,12,12,0,0
0,0,0,0,0,0,0
0,0,0,0,0,0,0
endlayer

