
# Created by Ruins mod version 14.7 Ingame Parser
# authoring Player: Barlock_James

weight=1
embed_into_distance=6
acceptable_target_blocks=
unacceptable_target_blocks=flowing_water,water,flowing_lava,lava
dimensions=9,24,18
allowable_overhang=0
max_leveling=2
leveling_buffer=0
preserve_water=0
preserve_lava=0

rule1=0,100,minecraft:dirt-0
rule2=0,100,minecraft:stone-0
rule3=0,100,minecraft:coal_ore-0
rule4=0,100,Steamcraft:steamcraftOre-0
rule5=0,100,harvestcraft:salt-0
rule6=0,100,Steamcraft:steamcraftOre-1
rule7=0,100,Thaumcraft:blockCustomOre-7
rule8=0,100,chisel:limestone-7
rule9=0,100,minecraft:grass-0
rule10=0,100,chisel:limestone-15
rule11=0,100,chisel:scorching-0
rule12=0,100,Thaumcraft:blockCustomOre-1
rule13=0,100,chisel:limestone-6
rule14=0,100,chisel:limestone-9
rule15=0,100,chisel:limestone-11
rule16=0,100,chisel:limestone_stairs.4-9
rule17=0,100,chisel:limestone_stairs.4-11
rule18=0,100,minecraft:tallgrass-1
rule19=0,100,IInventory;Thaumcraft:blockStoneDevice;Thaumcraft:blockCrystal#1#6#0-1
rule20=0,100,Thaumcraft:blockAiry-1
rule21=0,100,Thaumcraft:blockTable-1
rule22=0,100,minecraft:cauldron-0
rule23=0,100,minecraft:yellow_flower-0
rule24=0,100,ChestGenHook:dungeonChest:5-4
rule25=0,100,Botania:flower-15
rule26=0,100,minecraft:double_plant-2
rule27=0,100,chisel:torch5-5
rule28=0,100,chisel:torch5-2
rule29=0,100,minecraft:double_plant-8
rule30=0,100,chisel:limestone_stairs.4-13
rule31=0,100,chisel:limestone_stairs.4-12
rule32=0,100,chisel:limestone_slab-9
rule33=0,100,chisel:torch5-4
rule34=0,100,Botania:flower-13
rule35=0,100,minecraft:red_flower-3
rule36=0,100,Thaumcraft:blockMetalDevice-6
rule37=0,100,Botania:flower-8
rule38=0,100,DCsAppleMilk:defeatedcrow.teaTree-1
rule39=0,100,chisel:iron_bars-5

layer
1,2,2,2,2,2,0,2,2,2,2,2,2,2,2,1,1,1
1,2,2,2,2,2,2,2,2,2,2,2,2,2,1,1,1,1
1,2,2,2,2,2,2,2,2,2,2,2,2,2,1,1,1,1
2,2,2,2,2,2,2,2,2,2,2,2,2,2,1,1,1,1
3,2,2,2,2,2,2,2,2,2,2,2,2,2,1,1,1,1
3,3,2,2,2,2,2,2,2,2,2,2,2,2,1,1,1,1
3,3,2,2,2,2,2,2,2,2,2,2,2,2,2,2,1,1
3,3,2,2,2,2,2,2,2,2,4,2,2,2,2,2,1,1
3,3,2,2,2,2,2,2,2,2,5,2,2,2,2,2,1,1
2,3,2,2,2,2,2,2,2,2,2,5,2,2,6,2,1,1
2,2,2,2,2,2,0,2,2,2,2,2,2,2,6,6,1,1
2,2,2,2,0,2,2,2,2,2,2,5,5,2,2,2,1,1
2,2,8,8,2,2,2,2,2,2,2,2,2,7,2,2,1,1
0,8,10,10,10,10,10,10,10,2,2,2,2,2,9,1,1,2
0,8,10,10,8,8,8,10,10,2,2,2,2,2,2,2,2,0
0,8,10,8,10,8,10,8,10,2,2,2,2,2,2,2,2,1
2,2,10,8,8,11,8,8,10,2,2,2,2,2,2,2,1,1
2,2,10,8,10,8,10,8,10,2,2,2,2,2,7,1,1,1
2,2,10,10,8,8,8,10,10,2,2,2,2,2,2,1,1,1
2,12,10,10,10,10,10,10,10,2,2,2,2,2,2,1,1,1
2,12,12,2,2,2,1,1,2,2,2,2,2,2,2,2,1,1
2,2,2,2,2,2,1,1,2,2,2,2,2,2,2,2,1,1
2,2,2,2,2,1,1,1,1,2,2,2,2,2,2,2,1,1
2,2,2,2,2,1,0,1,1,2,2,2,2,1,1,2,2,1
endlayer

layer
1,1,1,1,2,2,0,2,2,2,2,2,2,2,2,1,1,1
1,1,2,2,2,1,1,2,2,2,2,2,2,2,2,1,1,1
1,2,2,2,2,1,13,13,2,2,2,2,2,2,2,1,1,1
2,2,2,2,2,2,13,13,2,2,2,2,2,2,1,1,1,1
3,2,2,2,2,2,2,13,13,13,2,2,2,1,1,1,1,1
3,3,2,2,2,2,13,13,13,13,2,2,2,1,1,1,1,1
3,3,2,2,2,2,13,13,13,13,2,2,1,1,1,1,1,1
3,3,2,2,2,2,13,13,13,13,2,1,1,1,1,1,1,1
3,3,2,2,2,2,2,13,13,2,2,1,1,1,1,1,1,1
2,3,2,2,2,2,13,13,13,13,2,1,1,1,1,1,1,9
2,2,2,2,2,13,13,13,13,13,2,1,1,1,1,1,1,9
2,2,15,15,14,13,13,13,13,13,2,2,1,1,1,1,1,9
2,14,0,0,17,16,16,14,15,2,2,5,1,1,1,1,1,9
0,0,0,0,0,0,0,0,19,14,2,2,2,1,18,1,9,9
0,0,0,0,0,0,0,0,0,15,2,2,2,9,1,1,1,0
0,0,0,0,0,0,0,0,0,15,2,2,2,1,1,1,1,9
2,14,0,0,0,20,0,0,0,15,2,2,2,1,1,1,1,9
2,15,0,0,0,0,0,0,0,15,2,2,2,1,1,1,1,1
2,15,0,0,0,0,0,0,0,15,2,2,2,1,1,1,1,1
2,14,22,0,0,0,0,21,21,14,2,2,2,1,1,1,1,1
2,2,15,15,15,15,15,15,15,2,2,2,2,1,1,1,1,1
2,2,2,2,2,1,9,1,1,2,2,2,2,1,1,1,1,1
2,2,2,2,2,1,1,1,1,2,2,2,2,1,1,1,1,1
2,2,2,2,2,1,0,1,1,2,2,2,2,1,1,1,1,1
endlayer

layer
1,1,1,9,9,9,0,9,9,9,9,9,9,9,9,9,9,9
1,1,1,1,1,1,9,9,1,1,1,1,9,9,9,9,9,9
1,1,1,1,1,1,0,0,1,1,1,1,1,1,1,1,1,1
1,1,1,1,1,1,0,0,14,15,1,1,1,1,1,1,1,1
1,1,1,2,2,2,14,0,0,0,15,1,1,1,1,1,1,1
2,2,2,2,2,15,0,0,0,0,15,2,1,1,1,1,1,9
2,2,2,2,2,15,0,0,0,0,15,1,1,1,1,1,1,9
2,2,2,2,2,15,0,0,0,0,15,1,1,1,1,1,1,9
2,2,2,2,2,0,14,0,0,14,2,1,1,1,1,1,1,1
3,2,2,2,0,15,0,0,0,0,15,1,1,1,1,1,1,23
3,2,2,2,15,0,0,0,0,0,15,1,1,1,1,1,1,18
3,2,15,15,14,0,0,0,0,0,15,1,1,1,1,1,1,18
2,14,0,0,0,0,0,14,15,15,2,1,1,1,1,9,9,0
0,0,0,0,0,0,0,0,0,14,2,2,1,1,1,9,0,0
0,0,0,0,0,0,0,0,0,15,2,2,1,0,1,1,9,0
0,0,0,0,0,0,0,0,0,15,2,2,1,1,1,1,9,0
2,14,0,0,0,0,0,0,0,15,2,2,1,1,1,1,1,18
2,15,0,0,0,0,0,0,0,15,2,2,1,1,1,1,1,9
1,15,0,0,0,0,0,0,0,15,2,2,1,1,1,1,1,9
1,14,0,0,0,0,0,0,0,14,2,2,1,1,1,1,1,9
1,1,15,15,15,24,15,15,15,2,2,1,1,1,1,1,1,9
1,1,1,1,1,15,0,1,1,2,2,1,1,1,1,1,1,9
1,1,1,1,1,1,1,1,1,1,1,1,1,1,1,1,1,9
2,2,2,2,2,1,0,1,1,2,2,2,1,1,1,1,1,1
endlayer

layer
1,1,1,0,0,0,0,0,0,0,0,0,0,0,0,0,0,0
1,1,1,9,9,9,0,0,1,1,1,9,18,26,0,0,0,25
1,1,1,1,1,1,0,0,1,15,1,1,1,9,1,1,1,1
1,1,1,1,1,1,0,0,14,27,15,1,1,1,1,1,1,1
1,1,1,1,1,1,14,0,0,0,15,1,1,1,1,1,9,9
1,1,1,1,1,15,0,0,0,0,15,1,1,1,1,1,9,0
1,1,1,1,1,15,0,0,0,0,15,1,1,1,1,1,1,0
1,1,1,1,1,15,0,0,0,0,15,1,1,1,1,1,1,0
1,1,1,1,1,0,14,0,0,14,1,1,1,1,1,1,1,9
1,1,1,1,0,15,0,0,0,0,15,1,1,1,1,1,1,0
1,1,1,1,15,0,0,0,0,0,15,1,1,1,1,1,1,0
1,1,15,15,14,0,0,0,0,0,15,1,1,1,1,1,9,0
1,14,0,0,0,0,0,14,27,15,1,1,1,1,1,0,0,0
0,0,0,0,0,0,0,0,0,14,1,1,1,1,9,0,0,0
0,0,0,0,0,0,0,0,0,15,1,1,1,1,1,9,0,0
0,0,0,0,0,0,0,0,0,15,1,1,1,1,1,1,0,0
1,14,0,0,0,0,0,0,0,15,1,1,1,1,1,1,9,0
1,15,0,0,0,0,0,0,0,15,1,1,1,1,1,9,9,18
1,15,0,0,0,0,0,0,0,15,1,1,1,1,1,9,9,18
1,14,0,0,0,0,0,0,0,14,1,1,1,1,1,9,9,0
1,1,15,15,15,28,15,15,15,1,1,1,1,1,1,1,9,0
1,1,1,1,1,15,0,1,1,1,1,1,1,1,1,1,9,0
1,1,1,1,1,1,1,1,1,1,1,1,1,1,1,9,9,0
1,1,1,1,1,1,0,1,1,1,1,1,1,1,1,9,9,9
endlayer

layer
9,9,9,0,0,0,0,0,0,0,0,0,0,0,0,0,0,0
9,9,1,0,0,0,0,0,9,9,9,0,0,29,0,0,0,0
1,1,1,1,1,1,0,0,1,1,1,9,9,0,1,1,9,9
1,1,1,1,1,1,0,14,14,15,1,1,1,1,1,1,9,9
1,1,1,1,1,1,14,0,0,0,15,1,1,1,1,1,0,0
1,1,1,1,1,15,0,0,0,0,15,1,1,1,1,1,0,0
1,1,1,1,1,15,0,0,0,0,15,1,1,1,1,1,9,0
1,1,1,1,1,15,0,0,0,0,15,1,1,1,1,1,9,0
1,1,1,1,1,0,14,0,0,14,1,1,1,1,1,1,9,0
1,1,1,1,0,15,0,0,0,0,15,1,1,1,1,1,9,0
1,1,1,1,15,0,0,0,0,0,15,1,1,1,1,1,9,0
1,1,15,15,14,0,0,0,0,0,15,1,1,1,1,1,0,0
1,14,0,0,0,0,0,14,15,15,1,1,1,1,9,0,0,0
0,30,0,0,0,0,0,0,0,14,1,1,1,9,0,0,0,0
0,0,0,0,0,0,0,0,0,15,1,1,1,9,9,0,0,0
0,31,0,0,0,0,0,0,0,15,1,1,1,9,9,9,0,0
1,14,0,0,0,0,0,0,0,15,1,1,1,9,9,9,0,0
1,15,0,0,0,0,0,0,0,15,1,1,1,9,9,0,0,0
1,15,0,0,0,0,0,0,0,15,1,1,1,9,9,18,0,0
1,14,0,0,0,0,0,0,0,14,1,1,1,1,9,0,18,0
1,1,15,15,15,15,15,15,15,1,1,1,1,1,9,9,0,0
1,1,1,1,1,1,1,1,9,1,1,1,1,1,1,9,0,0
1,1,1,1,1,1,1,9,9,9,9,9,9,9,9,0,18,0
1,1,1,1,1,1,0,1,9,9,9,9,9,9,9,0,0,0
endlayer

layer
18,0,0,0,0,0,0,0,0,0,0,0,0,0,0,0,0,0
18,0,9,0,0,0,0,0,0,0,0,0,0,0,0,0,0,0
9,9,9,9,9,9,9,9,9,9,9,0,0,0,9,9,0,0
9,9,9,9,9,9,9,9,9,9,9,9,9,9,9,9,0,0
9,9,9,1,1,1,1,32,32,32,1,9,9,9,9,9,0,0
1,1,1,1,1,1,32,8,8,32,1,1,1,9,9,9,0,0
1,1,1,1,1,1,32,8,8,32,1,1,1,1,9,9,0,0
1,1,1,1,1,1,32,8,8,32,1,1,1,1,9,9,26,0
1,1,1,1,1,1,1,32,32,1,1,1,1,1,9,9,0,0
1,1,1,1,1,1,8,8,8,8,1,1,1,1,9,9,18,0
1,1,1,1,1,8,8,8,8,8,1,1,1,1,9,9,0,0
1,1,1,1,32,32,32,32,8,8,1,1,1,9,9,9,0,0
1,14,14,14,14,14,14,14,14,1,1,1,1,9,0,0,0,0
1,14,0,0,0,0,0,0,14,1,1,1,9,0,0,0,0,0
0,14,33,0,0,0,0,0,14,1,1,1,9,18,0,0,0,0
1,14,0,0,0,0,0,0,14,1,1,1,9,18,0,18,0,0
9,14,0,0,0,0,0,0,14,1,1,1,9,18,0,18,0,0
9,14,0,0,0,0,0,0,14,1,1,1,9,0,0,0,0,0
9,14,0,0,0,0,0,0,14,1,1,1,9,0,0,0,0,0
9,14,14,14,14,14,14,14,14,1,1,1,9,9,0,0,0,0
9,9,9,9,9,9,9,9,1,1,1,9,9,9,0,18,0,0
9,9,9,9,9,9,9,9,0,9,1,9,9,9,9,0,0,0
9,9,9,9,9,9,9,0,0,0,0,0,0,0,0,0,0,0
9,9,9,9,9,9,0,9,0,34,0,0,0,0,0,0,0,0
endlayer

layer
0,0,0,0,0,0,0,0,0,0,0,0,0,0,0,0,0,0
0,0,0,0,0,0,0,0,0,0,0,0,0,0,0,0,0,0
0,18,18,0,18,0,0,0,0,18,0,0,0,0,0,0,0,0
18,0,18,0,18,18,18,18,18,18,0,0,0,0,35,0,0,0
18,18,0,9,9,9,9,9,9,9,9,0,0,0,0,26,0,0
9,9,9,9,9,9,9,9,9,9,9,9,9,0,0,0,0,0
9,9,9,9,9,9,9,9,9,9,9,9,9,9,0,0,0,0
9,9,9,9,9,9,9,9,9,9,9,9,9,9,0,35,29,0
9,9,9,9,9,9,9,9,9,9,9,9,9,9,0,0,0,0
9,9,9,9,9,9,9,9,9,9,9,9,9,9,0,0,0,0
9,9,9,9,9,9,9,9,9,1,9,9,9,9,0,0,0,0
9,9,9,9,9,1,1,1,1,1,9,9,9,35,0,35,0,0
9,9,9,1,1,1,1,1,1,1,9,9,9,18,0,0,0,0
9,1,14,14,14,14,14,14,1,1,9,9,18,0,0,0,0,0
0,1,14,0,0,0,0,14,1,1,9,9,35,0,0,0,0,0
9,1,14,0,36,36,0,14,1,1,9,9,0,0,0,0,0,0
0,1,14,0,36,36,0,14,1,1,9,9,0,0,0,0,0,0
0,1,14,0,0,0,0,14,1,1,9,9,0,0,0,0,0,0
0,1,14,14,14,14,14,14,1,1,9,9,0,0,0,0,0,0
0,1,1,1,1,1,1,1,1,1,9,9,0,0,0,0,0,0
0,0,0,0,0,0,0,0,9,9,9,0,0,0,0,0,0,0
0,0,0,0,0,0,0,18,0,0,9,0,0,0,0,0,0,0
0,0,0,0,0,0,0,0,0,0,0,0,0,0,0,0,0,0
0,0,0,0,0,0,0,0,0,0,0,0,0,0,0,0,0,0
endlayer

layer
0,0,0,0,0,0,0,0,0,0,0,0,0,0,0,0,0,0
0,0,0,0,0,0,0,0,0,0,0,0,0,0,0,0,0,0
0,0,0,0,0,0,0,0,0,0,0,0,0,0,0,0,0,0
0,0,0,0,0,0,0,0,0,0,0,0,0,0,0,0,0,0
0,0,0,0,0,0,35,18,0,0,0,0,0,0,0,29,0,0
37,0,18,18,0,0,0,18,0,18,18,35,0,0,0,0,0,0
0,37,0,18,0,0,0,18,0,18,18,0,18,0,0,0,0,0
18,18,0,0,0,18,0,18,0,18,0,0,0,18,0,0,0,0
18,0,0,0,0,0,18,35,18,0,35,35,26,0,0,0,0,0
0,18,38,18,18,0,0,18,0,0,35,18,0,0,0,0,0,0
18,0,18,0,0,18,0,18,0,9,0,18,18,0,0,0,0,0
0,0,18,18,0,9,9,9,9,9,35,0,0,0,0,0,0,0
18,0,0,9,9,9,9,9,9,9,18,18,0,0,0,0,0,0
18,9,9,9,9,9,9,9,9,9,0,0,0,0,0,0,0,0
0,9,9,14,14,14,14,9,9,9,18,0,0,0,0,0,0,0
0,9,9,14,39,39,14,9,9,9,18,0,0,0,0,0,0,0
0,9,9,14,39,39,14,9,9,9,0,0,0,0,0,0,0,0
0,9,9,14,14,14,14,9,9,9,0,0,0,0,0,0,0,0
0,9,9,9,9,9,9,9,9,9,0,0,0,0,0,0,0,0
0,9,9,9,9,9,9,9,9,9,34,0,0,0,0,0,0,0
0,0,0,0,0,0,0,0,0,0,0,0,0,0,0,0,0,0
0,0,0,0,0,0,0,0,0,0,0,0,0,0,0,0,0,0
0,0,0,0,0,0,0,0,0,0,0,0,0,0,0,0,0,0
0,0,0,0,0,0,0,0,0,0,0,0,0,0,0,0,0,0
endlayer

layer
0,0,0,0,0,0,0,0,0,0,0,0,0,0,0,0,0,0
0,0,0,0,0,0,0,0,0,0,0,0,0,0,0,0,0,0
0,0,0,0,0,0,0,0,0,0,0,0,0,0,0,0,0,0
0,0,0,0,0,0,0,0,0,0,0,0,0,0,0,0,0,0
0,0,0,0,0,0,0,0,0,0,0,0,0,0,0,0,0,0
0,0,0,0,0,0,0,0,0,0,0,0,0,0,0,0,0,0
0,0,0,0,0,0,0,0,0,0,0,0,0,0,0,0,0,0
0,0,0,0,0,0,0,0,0,0,0,0,0,0,0,0,0,0
0,0,0,0,0,0,0,0,0,0,0,0,29,0,0,0,0,0
0,0,0,0,0,0,0,0,0,0,0,0,0,0,0,0,0,0
0,0,0,0,0,0,0,0,0,18,0,0,0,0,0,0,0,0
0,0,0,0,0,0,0,0,0,0,0,0,0,0,0,0,0,0
0,0,0,0,18,0,0,0,18,18,0,0,0,0,0,0,0,0
0,0,0,0,18,0,18,0,18,0,0,0,0,0,0,0,0,0
0,0,18,0,0,0,0,0,0,0,0,0,0,0,0,0,0,0
0,0,0,0,0,0,0,0,18,0,0,0,0,0,0,0,0,0
0,0,0,0,0,0,0,0,0,0,0,0,0,0,0,0,0,0
0,0,0,0,0,0,0,0,0,18,0,0,0,0,0,0,0,0
0,0,0,0,0,0,0,0,0,0,0,0,0,0,0,0,0,0
0,0,0,0,0,0,0,0,0,0,0,0,0,0,0,0,0,0
0,0,0,0,0,0,0,0,0,0,0,0,0,0,0,0,0,0
0,0,0,0,0,0,0,0,0,0,0,0,0,0,0,0,0,0
0,0,0,0,0,0,0,0,0,0,0,0,0,0,0,0,0,0
0,0,0,0,0,0,0,0,0,0,0,0,0,0,0,0,0,0
endlayer

