
# Created by Ruins mod version 14.7 Ingame Parser
# authoring Player: Barlock_James

weight=1
embed_into_distance=0
acceptable_target_blocks=
unacceptable_target_blocks=flowing_water,water,flowing_lava,lava
dimensions=4,13,15
allowable_overhang=0
max_leveling=2
leveling_buffer=0
preserve_water=0
preserve_lava=0

rule1=0,100,Railcraft:tile.railcraft.brick.quarried-0
rule2=0,100,Railcraft:tile.railcraft.brick.quarried-5
rule3=0,100,Railcraft:tile.railcraft.stair-2
rule4=0,100,Railcraft:tile.railcraft.stair-1
rule5=0,100,Railcraft:tile.railcraft.stair-3
rule6=0,100,Railcraft:tile.railcraft.wall.beta-6
rule7=0,100,Railcraft:tile.railcraft.brick.quarried-1
rule8=0,100,ChestGenHook:dungeonChest:5-4
rule9=0,100,erebus:doorcypress-0
rule10=0,100,erebus:doorcypress-8
rule11=0,100,Railcraft:tile.railcraft.slab-0

layer
0,0,0,0,0,0,0,0,0,0,0,0,0,0,0
0,0,0,0,0,0,0,0,0,0,0,0,0,0,0
0,0,0,0,0,0,0,0,0,0,0,0,0,0,0
0,0,0,1,1,1,1,1,1,1,0,0,0,0,0
0,0,0,1,2,2,2,2,2,1,0,0,0,0,0
0,0,0,1,2,2,2,2,2,1,0,0,0,0,0
0,0,0,1,2,2,2,2,2,1,0,0,0,0,0
0,0,0,1,2,2,2,2,2,1,0,0,0,0,0
0,0,0,1,2,2,2,2,2,1,0,0,0,0,0
0,0,0,1,1,1,1,1,1,1,0,0,0,0,0
0,0,0,0,0,5,4,3,0,0,0,0,0,0,0
0,0,0,0,0,0,0,0,0,0,0,0,0,0,0
0,0,0,0,0,0,0,0,0,0,0,0,0,0,0
endlayer

layer
0,0,0,0,0,0,0,0,0,0,0,0,0,0,0
0,0,0,0,0,0,0,0,0,0,0,0,0,0,0
0,0,0,0,0,0,0,0,0,0,0,0,0,0,0
0,0,0,6,7,6,7,6,7,6,0,0,0,0,0
0,0,0,7,0,0,0,0,0,7,0,0,0,0,0
0,0,0,6,0,0,0,0,0,6,0,0,0,0,0
0,0,0,7,0,0,0,0,0,7,0,0,0,0,0
0,0,0,6,0,0,0,0,0,6,0,0,0,0,0
0,0,0,7,8,6,0,6,0,7,0,0,0,0,0
0,0,0,6,7,6,9,6,7,6,0,0,0,0,0
0,0,0,0,0,0,0,0,0,0,0,0,0,0,0
0,0,0,0,0,0,0,0,0,0,0,0,0,0,0
0,0,0,0,0,0,0,0,0,0,0,0,0,0,0
endlayer

layer
0,0,0,0,0,0,0,0,0,0,0,0,0,0,0
0,0,0,0,0,0,0,0,0,0,0,0,0,0,0
0,0,0,0,0,0,0,0,0,0,0,0,0,0,0
0,0,0,6,7,6,7,6,7,6,0,0,0,0,0
0,0,0,7,0,0,0,0,0,7,0,0,0,0,0
0,0,0,6,0,0,0,0,0,6,0,0,0,0,0
0,0,0,7,0,0,0,0,0,7,0,0,0,0,0
0,0,0,6,0,0,0,0,0,6,0,0,0,0,0
0,0,0,7,0,6,0,6,0,7,0,0,0,0,0
0,0,0,6,7,6,10,6,7,6,0,0,0,0,0
0,0,0,0,0,0,0,0,0,0,0,0,0,0,0
0,0,0,0,0,0,0,0,0,0,0,0,0,0,0
0,0,0,0,0,0,0,0,0,0,0,0,0,0,0
endlayer

layer
0,0,0,0,0,0,0,0,0,0,0,0,0,0,0
0,0,0,0,0,0,0,0,0,0,0,0,0,0,0
0,0,0,0,0,0,0,0,0,0,0,0,0,0,0
0,0,0,11,0,11,0,11,0,11,0,0,0,0,0
0,0,0,0,11,11,11,11,11,0,0,0,0,0,0
0,0,0,11,11,11,11,11,11,11,0,0,0,0,0
0,0,0,0,11,11,11,11,11,0,0,0,0,0,0
0,0,0,11,11,11,11,11,11,11,0,0,0,0,0
0,0,0,0,11,11,11,11,11,0,0,0,0,0,0
0,0,0,11,0,11,11,11,0,11,0,0,0,0,0
0,0,0,0,0,0,0,0,0,0,0,0,0,0,0
0,0,0,0,0,0,0,0,0,0,0,0,0,0,0
0,0,0,0,0,0,0,0,0,0,0,0,0,0,0
endlayer

