
# Created by Ruins mod version 14.7 Ingame Parser
# authoring Player: Barlock_James

weight=1
embed_into_distance=15
acceptable_target_blocks=flowing_water,water
unacceptable_target_blocks=flowing_lava,lava
dimensions=25,9,10
allowable_overhang=0
max_leveling=2
leveling_buffer=0
preserve_water=0
preserve_lava=0

rule1=0,100,minecraft:log-1
rule2=0,100,minecraft:water-0
rule3=0,100,minecraft:glowstone-0
rule4=0,100,minecraft:log-9
rule5=0,100,minecraft:log-5
rule6=0,100,minecraft:planks-5
rule7=0,100,minecraft:nether_brick_fence-0
rule8=0,100,minecraft:dark_oak_stairs-6
rule9=0,100,minecraft:dark_oak_stairs-3
rule10=0,100,minecraft:crafting_table-0
rule11=0,100,minecraft:furnace-3
rule12=0,100,minecraft:wooden_door-2
rule13=0,100,minecraft:glass_pane-0
rule14=0,100,BiblioCraft:BiblioIronLantern-0
rule15=0,100,minecraft:wooden_door-8
rule16=0,100,Railcraft:tile.railcraft.stair-2
rule17=0,100,Railcraft:tile.railcraft.stair-7
rule18=0,100,Railcraft:tile.railcraft.stair-6
rule19=0,100,Railcraft:tile.railcraft.stair-3
rule20=0,100,minecraft:wooden_slab-13
rule21=0,100,ChestGenHook:dungeonChest:5-2
rule22=0,100,minecraft:bed-0
rule23=0,100,minecraft:bed-8

layer
1,2,2,2,2,2,2,2,2,1
2,3,2,2,2,2,2,2,3,2
2,2,2,2,2,2,2,2,2,2
2,2,2,2,2,2,2,2,2,2
2,2,2,2,2,2,2,2,2,2
2,2,2,2,2,2,2,2,2,2
2,2,2,2,2,2,2,2,2,2
2,3,2,2,2,2,2,2,3,2
1,2,2,2,2,2,2,2,2,1
endlayer

layer
1,2,2,2,2,2,2,2,2,1
2,2,2,2,2,2,2,2,2,2
2,2,2,2,2,2,2,2,2,2
2,2,2,2,2,2,2,2,2,2
2,2,2,2,2,2,2,2,2,2
2,2,2,2,2,2,2,2,2,2
2,2,2,2,2,2,2,2,2,2
2,2,2,2,2,2,2,2,2,2
1,2,2,2,2,2,2,2,2,1
endlayer

layer
1,2,2,2,2,2,2,2,2,1
2,2,2,2,2,2,2,2,2,2
2,2,2,2,2,2,2,2,2,2
2,2,2,2,2,2,2,2,2,2
2,2,2,2,2,2,2,2,2,2
2,2,2,2,2,2,2,2,2,2
2,2,2,2,2,2,2,2,2,2
2,2,2,2,2,2,2,2,2,2
1,2,2,2,2,2,2,2,2,1
endlayer

layer
1,2,2,2,2,2,2,2,2,1
2,2,2,2,2,2,2,2,2,2
2,2,2,2,2,2,2,2,2,2
2,2,2,2,2,2,2,2,2,2
2,2,2,2,2,2,2,2,2,2
2,2,2,2,2,2,2,2,2,2
2,2,2,2,2,2,2,2,2,2
2,2,2,2,2,2,2,2,2,2
1,2,2,2,2,2,2,2,2,1
endlayer

layer
1,2,2,2,2,2,2,2,2,1
2,2,2,2,2,2,2,2,2,2
2,2,2,2,2,2,2,2,2,2
2,2,2,2,2,2,2,2,2,2
2,2,2,2,2,2,2,2,2,2
2,2,2,2,2,2,2,2,2,2
2,2,2,2,2,2,2,2,2,2
2,2,2,2,2,2,2,2,2,2
1,2,2,2,2,2,2,2,2,1
endlayer

layer
1,2,2,2,2,2,2,2,2,1
2,2,2,2,2,2,2,2,2,2
2,2,2,2,2,2,2,2,2,2
2,2,2,2,2,2,2,2,2,2
2,2,2,2,2,2,2,2,2,2
2,2,2,2,2,2,2,2,2,2
2,2,2,2,2,2,2,2,2,2
2,2,2,2,2,2,2,2,2,2
1,2,2,2,2,2,2,2,2,1
endlayer

layer
1,2,2,2,2,2,2,2,2,1
2,2,2,2,2,2,2,2,2,2
2,2,2,2,2,2,2,2,2,2
2,2,2,2,2,2,2,2,2,2
2,2,2,2,2,2,2,2,2,2
2,2,2,2,2,2,2,2,2,2
2,2,2,2,2,2,2,2,2,2
2,2,2,2,2,2,2,2,2,2
1,2,2,2,2,2,2,2,2,1
endlayer

layer
1,2,2,2,2,2,2,2,2,1
2,2,2,2,2,2,2,2,2,2
2,2,2,2,2,2,2,2,2,2
2,2,2,2,2,2,2,2,2,2
2,2,2,2,2,2,2,2,2,2
2,2,2,2,2,2,2,2,2,2
2,2,2,2,2,2,2,2,2,2
2,2,2,2,2,2,2,2,2,2
1,2,2,2,2,2,2,2,2,1
endlayer

layer
1,2,2,2,2,2,2,2,2,1
2,2,2,2,2,2,2,2,2,2
2,2,2,2,2,2,2,2,2,2
2,2,2,2,2,2,2,2,2,2
2,2,2,2,2,2,2,2,2,2
2,2,2,2,2,2,2,2,2,2
2,2,2,2,2,2,2,2,2,2
2,2,2,2,2,2,2,2,2,2
1,2,2,2,2,2,2,2,2,1
endlayer

layer
1,2,2,2,2,2,2,2,2,1
2,2,2,2,2,2,2,2,2,2
2,2,2,2,2,2,2,2,2,2
2,2,2,2,2,2,2,2,2,2
2,2,2,2,2,2,2,2,2,2
2,2,2,2,2,2,2,2,2,2
2,2,2,2,2,2,2,2,2,2
2,2,2,2,2,2,2,2,2,2
1,2,2,2,2,2,2,2,2,1
endlayer

layer
1,2,2,2,2,2,2,2,2,1
2,2,2,2,2,2,2,2,2,2
2,2,2,2,2,2,2,2,2,2
2,2,2,2,2,2,2,2,2,2
2,2,2,2,2,2,2,2,2,2
2,2,2,2,2,2,2,2,2,2
2,2,2,2,2,2,2,2,2,2
2,2,2,2,2,2,2,2,2,2
1,2,2,2,2,2,2,2,2,1
endlayer

layer
1,2,2,2,2,2,2,2,2,1
2,2,2,2,2,2,2,2,2,2
2,2,2,2,2,2,2,2,2,2
2,2,2,2,2,2,2,2,2,2
2,2,2,2,2,2,2,2,2,2
2,2,2,2,2,2,2,2,2,2
2,2,2,2,2,2,2,2,2,2
2,2,2,2,2,2,2,2,2,2
1,2,2,2,2,2,2,2,2,1
endlayer

layer
1,2,2,2,2,2,2,2,2,1
2,2,2,2,2,2,2,2,2,2
2,2,2,2,2,2,2,2,2,2
2,2,2,2,2,2,2,2,2,2
2,2,2,2,2,2,2,2,2,2
2,2,2,2,2,2,2,2,2,2
2,2,2,2,2,2,2,2,2,2
2,2,2,2,2,2,2,2,2,2
1,2,2,2,2,2,2,2,2,1
endlayer

layer
1,2,2,2,2,2,2,2,2,1
2,2,2,2,2,2,2,2,2,2
2,2,2,2,2,2,2,2,2,2
2,2,2,2,2,2,2,2,2,2
2,2,2,2,2,2,2,2,2,2
2,2,2,2,2,2,2,2,2,2
2,2,2,2,2,2,2,2,2,2
2,2,2,2,2,2,2,2,2,2
1,2,2,2,2,2,2,2,2,1
endlayer

layer
1,2,2,2,2,2,2,2,2,1
2,2,2,2,2,2,2,2,2,2
2,2,2,2,2,2,2,2,2,2
2,2,2,2,2,2,2,2,2,2
2,2,2,2,2,2,2,2,2,2
2,2,2,2,2,2,2,2,2,2
2,2,2,2,2,2,2,2,2,2
2,2,2,2,2,2,2,2,2,2
1,2,2,2,2,2,2,2,2,1
endlayer

layer
1,0,0,0,0,0,0,0,0,1
0,0,0,0,0,0,0,0,0,0
0,0,0,0,0,0,0,0,0,0
0,0,0,0,0,0,0,0,0,0
0,0,0,0,0,0,0,0,0,0
0,0,0,0,0,0,0,0,0,0
0,0,0,0,0,0,0,0,0,0
0,0,0,0,0,0,0,0,0,0
1,0,0,0,0,0,0,0,0,1
endlayer

layer
1,0,0,0,0,0,0,0,0,1
0,0,0,0,0,0,0,0,0,0
0,0,0,0,0,0,0,0,0,0
0,0,0,0,0,0,0,0,0,0
0,0,0,0,0,0,0,0,0,0
0,0,0,0,0,0,0,0,0,0
0,0,0,0,0,0,0,0,0,0
0,0,0,0,0,0,0,0,0,0
1,0,0,0,0,0,0,0,0,1
endlayer

layer
1,4,4,4,4,4,4,4,4,1
5,6,6,6,6,6,6,6,6,5
5,6,6,6,6,6,6,6,6,5
5,6,6,6,6,6,6,6,6,5
5,6,6,6,6,6,6,6,6,5
5,6,6,6,6,6,6,6,6,5
5,6,6,6,6,6,6,6,6,5
5,6,6,6,6,6,6,6,6,5
1,4,4,4,4,4,4,4,4,1
endlayer

layer
0,0,0,0,0,0,0,0,0,0
0,1,6,6,6,6,6,6,1,0
0,6,0,9,8,0,0,7,6,0
0,6,0,0,0,0,0,10,6,0
0,6,0,0,0,0,0,11,6,0
0,1,12,1,6,6,6,6,1,0
7,0,0,0,0,0,0,0,0,7
7,0,0,0,0,0,0,0,0,7
0,7,7,7,7,7,7,7,7,7
endlayer

layer
0,0,0,0,0,0,0,0,0,0
0,1,6,13,6,6,13,6,1,0
0,6,0,0,9,8,0,14,6,0
0,13,0,0,0,0,0,0,13,0
0,6,0,0,0,0,0,0,6,0
0,1,15,1,6,13,13,6,1,0
0,0,0,0,0,0,0,0,0,0
0,0,0,0,0,0,0,0,0,0
0,0,0,0,0,0,0,0,0,0
endlayer

layer
19,18,0,0,0,0,0,0,17,16
19,1,6,6,6,6,6,6,1,16
19,6,0,0,0,9,20,20,6,16
19,6,20,20,20,20,20,20,6,16
19,6,20,20,20,20,20,20,6,16
19,1,4,1,6,6,6,6,1,16
19,5,20,20,20,20,20,20,5,16
19,5,20,20,20,20,20,20,5,16
0,0,0,0,0,0,0,0,0,0
endlayer

layer
0,19,18,0,0,0,0,17,16,0
0,19,1,6,6,6,6,1,16,0
0,19,0,0,0,0,0,6,16,0
0,19,6,0,0,0,0,6,16,0
0,19,6,21,0,0,0,6,16,0
0,19,6,23,22,0,0,6,16,0
0,19,6,6,1,12,1,6,16,0
0,19,18,7,7,7,7,17,16,0
0,0,0,0,0,0,0,0,0,0
endlayer

layer
0,0,19,18,0,0,17,16,0,0
0,0,19,1,13,13,1,16,0,0
0,0,19,0,0,0,0,16,0,0
0,0,19,0,0,0,0,16,0,0
0,0,19,0,0,0,0,16,0,0
0,0,19,0,0,0,0,16,0,0
0,0,19,13,1,15,1,16,0,0
0,0,19,0,0,0,17,16,0,0
0,0,0,0,0,0,0,0,0,0
endlayer

layer
0,0,0,19,18,17,16,0,0,0
0,0,0,19,1,1,16,0,0,0
0,0,0,19,0,0,16,0,0,0
0,0,0,19,0,0,16,0,0,0
0,0,0,19,0,0,16,0,0,0
0,0,0,19,0,14,16,0,0,0
0,0,0,19,1,4,16,0,0,0
0,0,0,19,18,17,16,0,0,0
0,0,0,0,0,0,0,0,0,0
endlayer

layer
0,0,0,0,19,16,0,0,0,0
0,0,0,0,19,16,0,0,0,0
0,0,0,0,19,16,0,0,0,0
0,0,0,0,19,16,0,0,0,0
0,0,0,0,19,16,0,0,0,0
0,0,0,0,19,16,0,0,0,0
0,0,0,0,19,16,0,0,0,0
0,0,0,0,19,16,0,0,0,0
0,0,0,0,0,0,0,0,0,0
endlayer

