
# Created by Ruins mod version 14.7 Ingame Parser
# authoring Player: Barlock_James

weight=1
embed_into_distance=0
acceptable_target_blocks=
unacceptable_target_blocks=flowing_water,water,flowing_lava,lava
dimensions=23,23,23
allowable_overhang=0
max_leveling=2
leveling_buffer=0
preserve_water=0
preserve_lava=0

rule1=0,100,minecraft:dirt-0
rule2=0,100,minecraft:grass-0
rule3=0,100,chisel:carpet_block-5
rule4=0,100,minecraft:stonebrick-1
rule5=0,100,minecraft:water-0
rule6=0,100,Railcraft:tile.railcraft.wall.alpha-5
rule7=0,100,minecraft:stone_slab-5
rule8=0,100,Thaumcraft:blockEldritch-4
rule9=0,100,dendrology:logs1-3
rule10=0,100,minecraft:stonebrick-0
rule11=0,100,minecraft:stone_brick_stairs-0
rule12=0,100,minecraft:stone_brick_stairs-2
rule13=0,100,minecraft:stone_brick_stairs-3
rule14=0,100,minecraft:stone_brick_stairs-1
rule15=0,100,dendrology:leaves1-3
rule16=0,100,dendrology:logs1-11
rule17=0,100,dendrology:logs1-7
rule18=0,100,minecraft:stonebrick-2
rule19=0,100,minecraft:stone_brick_stairs-4
rule20=0,100,minecraft:stone_brick_stairs-7
rule21=0,100,minecraft:stone_brick_stairs-6
rule22=0,100,minecraft:stone_brick_stairs-5
rule23=0,100,dendrology:leaves1-7
rule24=0,100,minecraft:snow_layer-0
rule25=0,100,dendrology:leaves1-15
rule26=0,100,minecraft:stone_slab-13

layer
1,1,1,2,2,2,2,2,2,2,1,1,0,2,2,2,2,2,2,2,1,1,1
1,1,1,1,1,1,1,1,1,1,1,1,1,1,1,1,1,1,1,1,1,1,1
1,1,1,3,3,3,2,2,2,2,1,1,1,2,2,2,3,3,3,3,1,1,1
2,1,3,3,3,3,2,2,2,2,2,2,2,2,2,2,3,3,3,3,3,1,2
2,1,3,3,3,2,2,2,2,2,2,2,2,2,2,2,2,3,3,3,3,1,2
2,1,3,3,2,2,2,2,2,2,2,2,2,2,2,2,2,2,3,3,3,1,2
2,1,2,2,2,2,2,2,2,2,2,2,2,2,2,2,2,2,2,3,3,1,2
2,1,2,2,2,2,2,2,2,2,2,2,2,2,2,2,2,2,2,2,2,1,2
2,1,2,2,2,2,2,2,2,2,2,2,2,2,2,2,2,2,2,2,2,1,2
2,1,2,2,2,2,2,2,2,2,2,2,2,2,2,2,2,2,2,2,2,1,2
0,1,1,2,2,2,2,2,2,2,2,2,2,2,2,2,2,2,2,2,1,1,1
1,1,1,2,2,2,2,2,2,2,2,1,2,2,2,2,2,2,2,2,1,1,1
1,1,1,2,2,2,2,2,2,2,2,2,2,2,2,2,2,2,2,2,1,1,1
2,1,2,2,2,2,2,2,2,2,2,2,2,2,2,2,2,2,2,2,2,1,2
2,1,2,2,2,2,2,2,2,2,2,2,2,2,2,2,2,2,2,2,2,1,2
2,1,2,2,2,2,2,2,2,2,2,2,2,2,2,2,2,2,2,2,2,1,2
2,1,2,2,2,2,2,2,2,2,2,2,2,2,2,2,2,2,2,2,2,1,2
2,1,2,2,2,2,2,2,2,2,2,2,2,2,2,2,2,2,2,2,2,1,2
2,1,2,2,2,2,2,2,2,2,2,2,2,2,2,2,2,2,2,2,2,1,2
2,1,2,2,2,2,2,2,2,2,2,2,2,2,2,2,2,2,2,2,2,1,2
1,1,1,2,2,2,2,2,2,2,1,1,1,2,2,2,2,2,2,2,1,1,1
1,1,1,1,1,2,2,2,1,1,1,1,1,1,1,2,2,2,1,1,1,1,1
1,1,1,2,2,2,2,2,2,2,1,1,1,2,2,2,2,2,2,2,1,1,1
endlayer

layer
4,4,4,0,0,0,0,0,0,0,4,4,4,0,0,0,0,0,0,0,4,4,4
4,4,4,4,4,4,4,4,4,4,4,4,4,4,4,4,4,4,4,4,4,4,4
4,4,4,5,5,5,6,0,0,0,4,4,4,0,0,6,5,5,5,5,4,4,4
0,4,5,5,5,5,6,0,0,0,0,0,0,0,0,6,5,5,5,5,5,4,0
0,4,5,5,5,6,6,0,0,0,0,0,0,0,0,6,6,5,5,5,5,4,0
0,4,5,5,6,6,0,0,0,0,0,0,0,0,0,0,6,6,5,5,5,4,0
0,4,6,6,6,0,0,0,0,0,0,0,0,0,0,0,0,6,6,5,5,4,0
0,4,0,0,0,0,0,0,0,0,0,0,0,0,0,0,0,0,6,6,6,4,0
0,4,0,0,0,0,0,0,0,0,7,7,7,0,0,0,0,0,0,0,0,4,0
0,4,0,0,0,0,0,0,0,7,0,0,0,7,0,0,0,0,0,0,0,4,0
4,4,4,0,0,0,0,0,7,0,0,8,0,0,7,0,0,0,0,0,4,4,4
4,4,4,0,0,0,0,0,7,0,8,9,8,0,7,0,0,0,0,0,4,4,4
4,4,4,0,0,0,0,0,7,0,0,8,0,0,7,0,0,0,0,0,4,4,4
0,4,0,0,0,0,0,0,0,7,0,0,0,7,0,0,0,0,0,0,0,4,0
0,4,0,0,0,0,0,0,0,0,7,7,7,0,0,0,0,0,0,0,0,4,0
0,4,0,0,0,0,0,0,0,0,0,0,0,0,0,0,0,0,0,0,0,4,0
0,4,0,0,0,0,0,0,0,0,0,0,0,0,0,0,0,0,0,0,0,4,0
0,4,0,0,0,0,0,0,0,0,0,0,0,0,0,0,0,0,0,0,0,4,0
0,4,0,0,0,0,0,0,0,0,0,0,0,0,0,0,0,0,0,0,0,4,0
0,4,0,0,0,0,0,0,0,0,0,0,0,0,0,0,0,0,0,0,0,4,0
4,4,4,0,0,0,0,0,0,0,4,4,4,0,0,0,0,0,0,0,4,4,4
4,4,4,4,4,0,0,0,4,4,4,4,4,4,4,0,0,0,4,4,4,4,4
4,4,4,0,0,0,0,0,0,0,4,4,4,0,0,0,0,0,0,0,4,4,4
endlayer

layer
10,11,10,0,0,0,0,0,0,0,13,10,12,0,0,0,0,0,0,0,10,11,10
13,10,6,6,6,6,6,6,6,6,6,6,6,6,6,6,6,6,6,6,6,10,12
10,6,10,0,0,0,0,0,0,0,13,10,12,0,0,0,0,0,0,0,10,6,10
0,6,0,0,0,0,0,0,0,0,0,0,0,0,0,0,0,0,0,0,0,6,0
0,6,0,0,0,0,0,0,0,0,0,0,0,0,0,0,0,0,0,0,0,6,0
0,6,0,0,0,0,0,0,0,0,0,0,0,0,0,0,0,0,0,0,0,6,0
0,6,0,0,0,0,0,0,0,0,0,0,0,0,0,0,0,0,0,0,0,6,0
0,6,0,0,0,0,0,0,0,0,0,0,0,0,0,0,0,0,0,0,0,6,0
0,6,0,0,0,0,0,0,0,0,0,0,0,0,0,0,0,0,0,0,0,6,0
0,6,0,0,0,0,0,0,0,0,0,0,0,0,0,0,0,0,0,0,0,6,0
11,6,11,0,0,0,0,0,0,0,0,0,0,0,0,0,0,0,0,0,11,6,11
10,6,10,0,0,0,0,0,0,0,0,9,0,0,0,0,0,0,0,0,10,6,10
14,6,14,0,0,0,0,0,0,0,0,0,0,0,0,0,0,0,0,0,14,6,14
0,6,0,0,0,0,0,0,0,0,0,0,0,0,0,0,0,0,0,0,0,6,0
0,6,0,0,0,0,0,0,0,0,0,0,0,0,0,0,0,0,0,0,0,6,0
0,6,0,0,0,0,0,0,0,0,0,0,0,0,0,0,0,0,0,0,0,6,0
0,6,0,0,0,0,0,0,0,0,0,0,0,0,0,0,0,0,0,0,0,6,0
0,6,0,0,0,0,0,0,0,0,0,0,0,0,0,0,0,0,0,0,0,6,0
0,6,0,0,0,0,0,0,0,0,0,0,0,0,0,0,0,0,0,0,0,6,0
0,6,0,0,0,0,0,0,0,0,0,0,0,0,0,0,0,0,0,0,0,6,0
10,6,10,0,0,0,0,0,0,0,13,10,12,0,0,0,0,0,0,0,10,6,10
13,10,6,6,6,0,0,0,6,6,6,6,6,6,6,0,0,0,6,6,6,10,12
10,14,10,0,0,0,0,0,0,0,13,10,12,0,0,0,0,0,0,0,10,14,10
endlayer

layer
10,0,10,0,0,0,0,0,0,0,0,10,0,0,0,0,0,0,0,0,10,0,10
0,10,0,0,0,0,0,0,0,0,0,0,0,0,0,0,0,0,0,0,0,10,0
10,0,10,0,0,0,0,0,0,0,0,10,0,0,0,0,0,0,0,0,10,0,10
0,0,0,0,0,0,0,0,0,0,0,0,0,0,0,0,0,0,0,0,0,0,0
0,0,0,0,0,0,0,0,0,0,0,0,0,0,0,0,0,0,0,0,0,0,0
0,0,0,0,0,0,0,0,0,0,0,0,0,0,0,0,0,0,0,0,0,0,0
0,0,0,0,0,0,0,0,0,0,0,0,0,0,0,0,0,0,0,0,0,0,0
0,0,0,0,0,0,0,0,0,0,0,0,0,0,0,0,0,0,0,0,0,0,0
0,0,0,0,0,0,0,0,0,0,0,0,0,0,0,0,0,0,0,0,0,0,0
0,0,0,0,0,0,0,0,0,0,0,0,0,0,0,0,0,0,0,0,0,0,0
0,0,0,0,0,0,0,0,0,0,0,0,0,0,0,0,0,0,0,0,0,0,0
10,0,10,0,0,0,0,0,0,0,0,9,0,0,0,0,0,0,0,0,10,0,10
0,0,0,0,0,0,0,0,0,0,0,0,0,0,0,0,0,0,0,0,0,0,0
0,0,0,0,0,0,0,0,0,0,0,0,0,0,0,0,0,0,0,0,0,0,0
0,0,0,0,0,0,0,0,0,0,0,0,0,0,0,0,0,0,0,0,0,6,0
0,0,0,0,0,0,0,0,0,0,0,0,0,0,0,0,0,0,0,0,0,0,0
0,0,0,0,0,0,0,0,0,0,0,0,0,0,0,0,0,0,0,0,0,0,0
0,0,0,0,0,0,0,0,0,0,0,0,0,0,0,0,0,0,0,0,0,0,0
0,0,0,0,0,0,0,0,0,0,0,0,0,0,0,0,0,0,0,0,0,6,0
0,0,0,0,0,0,0,0,0,0,0,0,0,0,0,0,0,0,0,0,0,0,0
10,0,10,0,0,0,0,0,0,0,0,10,0,0,0,0,0,0,0,0,10,0,10
0,10,0,0,6,0,0,0,6,0,0,0,0,0,6,0,0,0,6,0,0,10,0
10,0,10,0,0,0,0,0,0,0,0,10,0,0,0,0,0,0,0,0,10,0,10
endlayer

layer
10,0,10,0,0,0,0,0,0,0,0,10,0,0,0,0,0,0,0,0,10,0,10
0,10,0,0,0,0,0,0,0,0,0,0,0,0,0,0,0,0,0,0,0,10,0
10,0,10,0,0,0,0,0,0,0,0,10,0,0,0,0,0,0,0,0,10,0,10
0,0,0,0,0,0,0,0,0,0,0,0,0,0,0,0,0,0,0,0,0,0,0
0,0,0,0,0,0,0,0,0,0,0,0,0,0,0,0,0,0,0,0,0,0,0
0,0,0,0,0,0,0,0,0,0,0,0,0,0,0,0,0,0,0,0,0,0,0
0,0,0,0,0,0,0,0,0,0,0,0,0,0,0,0,0,0,0,0,0,0,0
0,0,0,0,0,0,0,0,0,0,0,0,0,0,0,0,0,0,0,0,0,0,0
0,0,0,0,0,0,0,0,0,0,0,0,0,0,0,0,0,0,0,0,0,0,0
0,0,0,0,0,0,0,0,0,0,0,0,0,0,0,0,0,0,0,0,0,0,0
0,0,0,0,0,0,0,0,0,0,0,0,0,0,0,0,0,0,0,0,0,0,0
10,0,10,0,0,0,0,0,0,0,0,9,0,0,0,0,0,0,0,0,10,0,10
0,0,0,0,0,0,0,0,0,0,0,0,0,0,0,0,0,0,0,0,0,0,0
0,0,0,0,0,0,0,0,0,0,0,0,0,0,0,0,0,0,0,0,0,0,0
0,0,0,0,0,0,0,0,0,0,0,0,0,0,0,0,0,0,0,0,0,6,0
0,0,0,0,0,0,0,0,0,0,0,0,0,0,0,0,0,0,0,0,0,0,0
0,0,0,0,0,0,0,0,0,0,0,0,0,0,0,0,0,0,0,0,0,0,0
0,0,0,0,0,0,0,0,0,0,0,0,0,0,0,0,0,0,0,0,0,0,0
0,0,0,0,0,0,0,0,0,0,0,0,0,0,0,0,0,0,0,0,0,6,0
0,0,0,0,0,0,0,0,0,0,0,0,0,0,0,0,0,0,0,0,0,0,0
10,0,10,0,0,0,0,0,0,0,0,10,0,0,0,0,0,0,0,0,10,0,10
0,10,0,0,6,6,0,6,6,0,0,0,0,0,6,6,0,6,6,0,0,10,0
10,0,10,0,0,0,0,0,0,0,0,10,0,0,0,0,0,0,0,0,10,0,10
endlayer

layer
10,0,10,0,0,0,0,0,0,0,0,10,0,0,0,0,0,0,0,0,10,0,10
0,10,0,0,0,0,0,0,0,0,0,0,0,0,0,0,0,0,0,0,0,10,0
10,0,10,0,0,0,0,0,0,0,0,10,0,0,0,0,0,0,0,0,10,0,10
0,0,0,0,0,15,0,0,0,0,0,0,0,0,0,0,0,0,0,0,0,0,0
0,0,0,0,15,15,15,0,0,0,0,0,0,0,0,0,0,0,0,0,0,0,0
0,0,0,0,0,15,0,0,0,0,0,0,0,0,0,0,0,0,0,0,0,0,0
0,0,0,0,0,0,0,0,0,0,0,0,0,0,0,0,0,0,0,0,0,0,0
0,0,0,0,0,0,0,0,0,0,0,0,0,0,0,0,0,0,0,0,0,0,0
0,0,0,0,0,0,0,0,0,0,0,0,0,0,0,0,0,0,0,0,0,0,0
0,0,0,0,0,0,0,0,0,0,0,0,0,0,0,0,0,0,0,0,0,0,0
0,0,0,0,0,0,0,0,0,0,16,0,0,0,0,0,0,0,0,0,0,0,0
10,0,10,0,0,0,0,0,0,0,16,9,0,0,0,0,0,0,0,0,10,0,10
0,0,0,0,0,0,0,0,0,0,0,0,0,0,0,0,0,0,0,0,0,0,0
0,0,0,0,0,0,0,0,0,0,0,0,0,0,0,0,0,0,0,0,0,0,0
0,0,0,0,0,0,0,0,0,0,0,0,0,0,0,0,0,0,0,0,0,6,0
0,0,0,0,0,0,0,0,0,0,0,0,0,0,0,0,0,0,0,0,0,6,0
0,0,0,0,0,0,0,0,0,0,0,0,0,0,0,0,0,0,0,0,0,0,0
0,0,0,0,0,0,0,0,0,0,0,0,0,0,0,0,0,0,0,0,0,6,0
0,0,0,0,0,0,0,0,0,0,0,0,0,0,0,0,0,0,0,0,0,6,0
0,0,0,0,0,0,0,0,0,0,0,0,0,0,0,0,0,0,0,0,0,0,0
10,0,10,0,0,0,0,0,0,0,0,10,0,0,0,0,0,0,0,0,10,0,10
0,10,0,0,0,6,6,6,0,0,0,0,0,0,0,6,6,6,0,0,0,10,0
10,0,10,0,0,0,0,0,0,0,0,10,0,0,0,0,0,0,0,0,10,0,10
endlayer

layer
10,0,10,0,0,0,0,0,0,0,0,10,0,0,0,0,0,0,0,0,10,0,10
0,10,0,0,0,0,0,0,0,0,0,0,0,0,0,0,0,0,0,0,0,10,0
10,0,10,0,15,15,15,0,0,0,0,10,0,0,0,0,0,0,0,0,10,0,10
0,0,0,15,15,15,15,15,0,0,0,0,0,0,0,0,0,0,0,0,0,0,0
0,0,0,15,15,15,15,15,0,0,0,0,0,0,0,0,0,0,0,0,0,0,0
0,0,0,15,15,15,15,15,0,0,0,0,0,0,0,0,0,0,0,0,0,0,0
0,0,0,0,15,15,15,0,0,0,0,0,0,0,0,0,0,0,0,0,0,0,0
0,0,0,0,0,0,0,0,0,0,0,0,0,0,0,0,0,0,0,0,0,0,0
0,0,0,0,0,0,0,0,0,0,0,0,0,0,0,0,0,0,0,0,0,0,0
0,0,0,0,0,0,0,0,17,0,0,0,0,0,0,0,0,0,0,0,0,0,0
0,0,0,0,0,0,0,0,16,16,0,17,16,16,0,0,0,0,0,0,0,0,0
10,0,10,0,0,0,0,0,0,0,0,9,0,0,0,0,0,0,0,0,10,0,10
0,0,0,0,0,0,0,0,0,16,16,0,0,0,0,0,0,0,0,0,0,0,0
0,0,0,0,0,0,0,0,0,16,0,0,0,0,0,0,0,0,0,0,0,0,0
0,0,0,0,0,0,0,0,0,17,0,0,0,0,0,0,0,0,0,0,0,0,0
0,0,0,0,0,0,0,0,0,0,0,0,0,0,0,0,0,0,0,0,0,6,0
0,0,0,0,0,0,0,0,0,0,0,0,0,0,0,0,0,0,0,0,0,6,0
0,0,0,0,0,0,0,0,0,0,0,0,0,0,0,0,0,0,0,0,0,6,0
0,0,0,0,0,0,0,0,0,0,0,0,0,0,0,0,0,0,0,0,0,0,0
0,0,0,0,0,0,0,0,0,0,0,0,0,0,0,0,0,0,0,0,0,0,0
10,0,10,0,0,0,0,0,0,0,0,10,0,0,0,0,0,0,0,0,10,0,10
0,10,0,0,6,6,0,6,6,0,0,0,0,0,6,6,0,6,6,0,0,10,0
10,0,10,0,0,0,0,0,0,0,0,10,0,0,0,0,0,0,0,0,10,0,10
endlayer

layer
10,0,10,0,0,0,0,0,0,0,0,10,0,0,0,0,0,0,0,0,10,0,10
0,10,0,0,15,15,15,0,0,0,0,0,0,0,0,0,0,0,0,0,0,10,0
10,0,10,15,15,15,15,15,0,0,0,10,0,0,0,0,0,0,0,0,10,0,10
0,0,15,15,15,15,15,15,15,0,0,0,0,0,0,0,0,0,0,0,0,0,0
0,0,15,15,15,16,15,15,15,0,0,0,0,0,0,0,0,0,0,0,0,0,0
0,0,15,15,15,15,16,15,15,0,0,0,0,0,0,0,0,0,0,0,0,0,0
0,0,0,15,15,15,15,16,17,0,0,0,0,0,0,0,0,0,0,0,0,0,0
0,0,0,0,15,15,15,0,17,0,0,0,0,0,0,0,0,0,0,0,0,0,0
0,0,0,0,0,0,0,0,17,0,0,0,0,0,17,0,0,0,0,0,0,0,0
0,0,0,0,0,0,0,0,0,0,17,0,0,0,16,0,0,0,0,0,0,0,0
0,0,0,0,0,0,0,0,0,0,0,9,0,17,0,0,0,0,0,0,0,0,0
10,0,10,0,0,0,0,0,0,0,0,9,16,16,0,0,0,0,0,0,10,0,10
0,0,0,0,0,0,0,0,0,0,0,0,0,0,0,0,0,0,0,0,0,0,0
0,0,0,0,0,0,0,0,16,0,0,0,0,0,0,0,0,0,0,0,0,0,0
0,0,0,0,0,0,0,0,0,9,0,0,0,0,0,0,0,0,0,0,0,6,0
0,0,0,0,0,0,0,0,0,0,0,0,0,0,0,0,0,0,0,0,0,6,0
0,0,0,0,0,0,0,0,0,0,0,0,0,0,0,0,0,0,0,0,0,0,0
0,0,0,0,0,0,0,0,0,0,0,0,0,0,0,0,0,0,0,0,0,6,0
0,0,0,0,0,0,0,0,0,0,0,0,0,0,0,0,0,0,0,0,0,6,0
0,0,0,0,0,0,0,0,0,0,0,0,0,0,0,0,0,0,0,0,0,0,0
10,0,10,0,0,0,0,0,0,0,0,10,0,0,0,0,0,0,0,0,10,0,10
0,10,0,0,6,0,0,0,6,0,0,0,0,0,6,0,0,0,6,0,0,10,0
10,0,10,0,0,0,0,0,0,0,0,10,0,0,0,0,0,0,0,0,10,0,10
endlayer

layer
10,0,10,0,0,0,0,0,0,0,0,10,0,0,0,0,0,0,0,0,10,0,10
0,10,0,0,0,0,0,0,0,0,0,6,0,0,0,0,0,0,0,0,0,10,0
10,0,10,0,15,15,15,0,0,0,0,10,0,0,0,0,0,0,0,0,10,0,10
0,0,0,15,15,15,15,15,0,0,0,0,0,0,0,0,0,0,0,0,0,0,0
0,0,0,15,15,15,15,15,0,0,0,0,0,0,0,0,15,0,0,0,0,0,0
0,0,0,15,15,15,15,15,0,0,0,0,0,0,0,15,15,15,0,0,0,0,0
0,0,0,0,15,15,15,0,0,0,0,0,0,0,0,0,16,0,0,0,0,0,0
0,0,0,0,0,0,0,0,0,0,0,15,0,0,0,16,0,0,0,0,0,0,0
0,0,0,0,0,0,0,0,0,0,17,15,15,0,16,0,0,0,0,0,0,0,0
0,0,0,0,0,0,0,0,0,0,8,15,0,17,0,0,0,0,0,0,0,0,0
0,0,0,0,0,0,0,0,0,0,16,9,0,0,0,0,0,0,0,0,0,0,0
10,6,10,0,0,0,0,0,0,0,0,9,8,9,0,0,0,15,0,0,10,6,10
0,0,0,0,0,0,0,0,0,0,0,17,16,16,16,0,15,15,15,0,0,6,0
0,0,0,0,0,0,0,0,9,0,0,17,0,0,0,0,0,15,0,0,0,6,0
0,0,0,0,0,0,0,0,0,0,0,17,0,0,0,0,0,0,0,0,0,6,0
0,0,0,0,0,0,0,0,16,0,0,17,0,0,0,0,0,0,0,0,0,0,0
0,0,0,0,0,0,0,0,0,0,0,0,0,0,0,0,0,0,0,0,0,0,0
0,0,0,0,0,0,0,0,0,0,0,0,0,0,0,0,0,0,0,0,0,0,0
0,0,0,0,15,0,0,0,0,0,0,0,0,0,0,0,0,0,0,0,0,6,0
0,0,0,15,15,15,0,0,0,0,0,0,0,0,0,0,0,0,0,0,0,6,0
10,0,10,0,15,0,0,0,0,0,0,10,0,0,0,0,0,0,0,0,10,6,10
0,10,6,6,6,0,0,0,6,6,6,6,6,6,6,0,0,0,6,6,6,10,0
10,0,10,0,0,0,0,0,0,0,0,10,0,0,0,0,0,0,0,0,10,0,10
endlayer

layer
10,0,10,0,0,0,0,0,0,0,0,10,0,0,0,0,0,0,0,0,10,0,10
0,10,0,0,0,0,0,0,0,0,0,0,0,0,0,0,0,0,0,0,0,10,0
10,0,10,0,0,0,0,0,0,0,0,10,0,0,0,0,0,0,0,0,10,0,10
0,0,0,0,0,15,0,0,0,0,0,0,0,0,0,15,15,15,0,0,0,0,0
0,0,0,0,15,15,15,0,0,0,0,0,0,0,15,15,15,15,15,0,0,0,0
0,0,0,0,0,15,0,0,0,0,0,0,0,0,15,15,17,16,15,15,0,0,0
0,0,0,0,0,0,0,0,0,0,15,15,15,0,15,15,16,15,15,0,0,0,0
0,0,0,0,0,0,0,0,0,15,15,15,15,15,0,15,15,15,0,0,0,0,0
0,0,0,0,0,0,0,0,0,15,9,17,15,15,0,0,0,0,0,0,0,0,0
0,0,0,0,0,0,0,0,0,16,15,17,15,15,0,0,0,0,0,0,0,0,0
0,0,0,0,0,0,0,0,0,0,15,9,15,0,0,0,15,15,15,0,0,0,0
10,0,10,0,0,0,0,0,0,0,0,9,0,0,16,16,15,15,15,15,10,0,10
0,0,0,0,0,0,0,0,0,0,0,17,0,0,0,16,16,15,15,15,0,0,0
0,0,0,0,0,0,0,0,9,0,0,0,0,0,0,15,15,15,15,15,0,0,0
0,0,0,0,0,0,0,0,0,0,0,0,0,0,0,0,15,15,15,0,0,0,0
0,0,0,0,0,0,0,0,0,0,0,15,0,0,0,0,0,0,0,0,0,0,0
0,0,0,0,0,0,0,16,0,0,15,17,15,0,0,0,0,0,0,0,0,0,0
0,0,0,15,15,15,16,0,0,0,0,15,0,0,0,0,0,0,0,0,0,0,0
0,0,15,15,15,15,15,0,0,0,0,0,0,0,0,0,0,0,0,0,0,0,0
0,0,15,15,15,15,15,0,0,0,0,0,0,0,0,0,0,0,0,0,0,0,0
10,0,15,15,15,15,15,0,0,0,0,10,0,0,0,0,0,0,0,0,10,0,10
0,10,0,15,15,15,0,0,0,0,0,0,0,0,0,0,0,0,0,0,0,10,0
10,0,10,0,0,0,0,0,0,0,0,10,0,0,0,0,0,0,0,0,10,0,10
endlayer

layer
10,0,10,0,0,0,0,0,0,0,0,10,0,0,0,0,0,0,0,0,10,0,10
0,10,0,0,0,0,0,0,0,0,0,0,0,0,0,0,0,0,0,0,0,10,0
10,0,10,0,0,0,0,0,0,0,0,10,0,0,0,15,15,15,0,0,10,0,10
0,0,0,0,0,0,0,0,0,0,0,0,0,0,15,15,15,15,15,15,0,0,0
0,0,0,0,0,0,0,0,0,0,0,0,0,15,15,15,15,15,15,15,15,0,0
0,0,0,0,0,0,0,0,0,0,15,15,15,15,15,15,9,15,16,15,15,0,0
0,0,0,0,0,0,0,0,0,15,15,15,15,15,15,15,15,15,15,15,15,0,0
0,0,0,0,0,0,0,0,15,15,17,15,15,15,15,15,15,15,15,15,0,0,0
0,0,0,0,0,0,15,0,15,15,15,9,15,15,15,15,15,15,0,0,0,0,0
0,0,0,0,0,15,15,15,15,9,15,17,15,15,15,0,15,15,15,0,0,0,0
0,0,0,0,0,0,15,0,0,15,16,15,15,15,0,15,16,15,15,15,0,0,0
10,0,10,0,0,0,0,0,0,0,15,9,16,0,15,15,15,15,15,15,15,0,10
0,0,0,0,0,0,0,0,0,0,0,0,0,0,15,15,15,16,15,15,15,0,0
0,0,0,0,0,0,0,0,0,0,15,0,16,0,15,15,15,15,15,15,15,0,0
0,0,0,0,0,0,0,0,17,15,15,15,15,0,0,15,15,15,15,15,0,0,0
0,0,0,0,0,0,0,0,0,15,15,15,15,15,0,0,15,15,15,0,0,0,0
0,0,0,15,15,15,0,0,0,15,15,9,15,15,0,0,0,0,0,0,0,0,0
0,0,15,15,15,15,15,0,0,15,15,15,15,15,0,0,0,0,0,0,0,0,0
0,15,15,15,15,16,15,15,0,0,15,15,15,0,0,0,0,0,0,0,0,0,0
0,15,15,15,16,15,15,15,0,0,0,0,0,0,0,0,0,0,0,0,0,0,0
10,15,15,15,15,15,15,15,0,0,0,10,0,0,0,0,0,0,0,0,10,0,10
0,10,15,15,15,15,15,0,0,0,0,0,0,0,0,0,0,0,0,0,0,10,0
10,0,10,15,15,15,0,0,0,0,0,10,0,0,0,0,0,0,0,0,10,0,10
endlayer

layer
10,0,10,0,0,0,0,0,0,0,0,10,0,0,0,0,0,0,0,0,10,0,10
0,18,0,0,0,0,0,0,0,0,0,0,0,0,0,0,0,0,0,0,0,10,0
10,0,10,0,0,0,0,0,0,0,0,10,0,0,0,0,0,15,15,15,10,0,10
0,0,0,0,0,0,0,0,0,0,0,0,0,0,0,15,15,15,15,15,15,0,0
0,0,0,0,0,0,0,0,0,15,15,15,0,0,15,15,15,15,15,15,15,15,0
0,0,0,0,0,0,0,0,15,15,15,15,15,0,15,15,15,15,9,15,15,15,0
0,0,0,0,0,15,0,0,15,15,17,15,15,0,15,15,15,15,15,15,15,15,0
0,0,0,0,15,15,15,15,15,15,9,17,15,15,0,15,15,15,15,15,15,0,0
0,0,0,0,15,15,15,15,15,15,15,17,15,15,0,15,15,15,15,15,0,0,0
0,0,0,0,15,15,15,15,16,16,15,15,15,15,15,15,15,15,15,0,0,0,0
0,0,0,0,15,15,15,15,15,0,15,15,15,15,15,15,9,15,15,0,0,0,0
10,0,10,0,0,15,15,15,0,0,8,9,9,0,15,15,15,15,15,15,0,0,10
0,0,0,0,0,0,0,0,0,15,15,17,0,16,15,15,15,15,15,15,0,0,0
0,0,0,0,0,0,0,0,15,15,15,17,15,8,0,15,15,15,15,15,0,0,0
0,0,0,0,0,0,0,16,15,15,17,15,15,16,0,0,15,15,15,0,0,0,0
0,0,0,0,15,0,0,0,15,15,15,15,15,15,16,0,0,0,0,0,0,0,0
0,0,0,15,15,15,0,0,15,15,15,9,15,15,15,0,0,0,0,0,0,0,0
0,0,0,15,15,15,0,0,15,15,15,15,15,15,15,0,0,0,0,0,0,0,0
0,0,15,15,15,15,15,0,0,15,15,15,15,15,0,0,0,0,0,0,0,0,0
0,0,15,15,15,15,15,0,0,0,15,15,15,0,0,0,0,0,0,0,0,0,0
18,0,15,15,15,15,15,0,0,0,0,18,0,0,0,0,0,0,0,0,10,0,10
0,18,0,15,15,15,0,0,0,0,0,0,0,0,0,0,0,0,0,0,0,10,0
18,0,18,0,0,0,0,0,0,0,0,10,0,0,0,0,0,0,0,0,10,0,10
endlayer

layer
18,0,18,0,0,0,0,0,0,0,0,18,0,0,0,0,0,0,0,0,18,0,18
0,18,0,0,0,0,0,0,0,0,0,0,0,0,0,0,0,0,0,0,0,18,0
18,0,18,0,0,0,0,0,0,0,0,18,0,0,0,0,0,0,0,0,18,0,18
0,0,0,0,0,0,0,0,0,15,15,15,15,0,0,0,0,15,15,15,0,0,0
0,0,0,0,0,0,0,0,15,15,15,15,15,15,0,0,15,15,15,15,15,0,0
0,0,0,0,15,15,15,15,15,15,15,17,15,15,0,15,15,15,15,15,15,0,0
0,0,0,15,15,15,15,15,15,15,9,17,15,15,0,0,15,15,15,15,15,0,0
0,0,0,15,15,15,15,15,15,15,17,15,15,15,15,15,15,15,15,15,0,0,0
0,0,0,15,15,15,16,15,15,15,15,15,15,15,15,15,15,15,15,0,0,0,0
0,0,0,15,15,15,16,16,16,15,15,15,15,15,15,15,15,15,15,15,0,0,0
0,0,0,15,15,15,15,15,15,15,0,15,16,15,15,15,9,15,15,15,0,0,0
18,0,18,0,15,15,15,15,15,15,16,9,9,15,15,15,15,15,15,15,0,0,18
0,0,0,0,0,15,15,15,15,15,16,15,16,15,16,16,15,15,15,0,0,0,0
0,0,0,0,0,0,0,15,15,15,15,15,15,15,15,15,15,15,0,0,0,0,0
0,0,0,15,15,15,0,15,15,15,9,15,15,15,15,15,15,0,0,0,0,0,0
0,0,15,15,15,16,16,15,15,15,15,15,15,15,0,16,15,15,0,0,0,0,0
0,0,15,15,16,15,15,0,15,15,15,15,15,15,0,0,15,0,0,0,0,0,0
0,0,15,15,15,15,15,0,0,15,15,15,15,15,0,0,0,0,0,0,0,0,0
0,0,0,15,15,15,0,0,0,0,15,15,15,0,0,0,0,0,0,0,0,0,0
0,0,0,15,15,15,0,0,0,0,0,0,0,0,0,0,0,0,0,0,0,0,0
18,0,18,0,15,0,0,0,0,0,0,18,0,0,0,0,0,0,0,0,18,0,18
0,18,0,0,0,0,0,0,0,0,0,0,0,0,0,0,0,0,0,0,0,18,0
18,0,18,0,0,0,0,0,0,0,0,18,0,0,0,0,0,0,0,0,18,0,10
endlayer

layer
18,0,18,0,0,0,0,0,0,0,0,18,0,0,0,0,0,0,0,0,18,0,18
0,18,0,0,0,0,0,0,0,0,0,0,0,0,0,0,0,0,0,0,0,18,0
18,0,18,0,0,0,0,0,0,0,15,15,15,0,0,0,0,0,0,0,18,0,18
0,0,0,0,0,0,0,0,0,15,15,15,15,15,0,0,0,0,0,0,0,0,0
0,0,0,0,15,15,15,0,15,15,15,15,15,15,15,0,0,0,15,0,0,0,0
0,0,0,15,15,15,15,15,15,15,15,9,15,15,15,0,0,15,15,15,0,0,0
0,0,15,15,15,15,15,15,15,15,17,15,15,15,15,0,0,0,15,0,0,0,0
0,0,15,15,15,16,15,15,15,15,15,15,15,15,15,15,0,0,0,0,0,0,0
0,0,15,15,15,15,15,15,15,15,15,15,15,15,15,15,15,15,0,0,0,0,0
0,0,0,15,15,15,15,15,15,15,15,15,15,17,15,15,15,15,15,0,0,0,0
0,0,0,0,15,15,15,15,15,16,16,17,15,16,15,15,15,15,15,0,0,0,0
18,0,18,0,0,15,15,15,15,15,15,9,9,15,15,15,15,15,15,0,0,0,18
0,0,0,0,0,0,0,15,15,15,17,15,9,15,15,9,15,15,15,0,0,0,0
0,0,0,15,15,15,0,15,15,16,17,15,15,15,15,15,15,15,15,0,0,0,0
0,0,15,15,15,15,15,15,15,15,15,15,15,15,15,15,15,15,15,0,0,0,0
0,15,15,15,15,15,15,15,15,15,15,15,15,0,15,15,16,15,15,0,0,0,0
0,15,15,15,9,15,15,15,0,15,15,15,15,0,15,15,15,15,15,0,0,0,0
0,15,15,15,15,15,15,15,0,0,0,15,0,0,0,15,15,15,0,0,0,0,0
0,0,15,15,15,15,15,0,0,0,0,0,0,0,0,0,0,0,0,0,0,0,0
0,0,0,15,15,15,0,0,0,0,0,0,0,0,0,0,0,0,0,0,0,0,0
18,0,18,0,0,0,0,0,0,0,0,18,0,0,0,0,0,0,0,0,18,0,18
0,18,0,0,0,0,0,0,0,0,0,0,0,0,0,0,0,0,0,0,0,18,0
18,0,18,0,0,0,0,0,0,0,0,18,0,0,0,0,0,0,0,0,18,0,18
endlayer

layer
18,19,18,21,0,0,0,0,0,0,20,18,21,0,0,0,0,0,0,20,18,19,18
20,18,21,0,0,0,0,0,0,0,0,6,0,0,0,0,0,0,0,0,20,18,21
18,22,18,21,0,0,0,0,0,0,20,18,21,0,0,0,0,0,0,20,18,22,18
22,0,22,0,0,0,0,0,0,0,15,15,15,0,0,0,0,0,0,0,0,0,22
0,0,0,0,0,0,0,0,0,15,15,15,15,15,0,0,0,0,0,0,0,0,0
0,0,0,0,15,15,15,0,15,15,15,15,15,15,0,0,0,0,0,0,0,0,0
0,0,0,15,15,15,15,15,15,15,15,15,15,15,0,0,0,0,0,0,0,0,0
0,0,0,15,15,15,15,15,15,15,15,15,15,15,15,0,0,0,0,0,0,0,0
0,0,0,15,15,15,15,15,15,15,15,15,15,15,15,15,0,0,0,0,0,0,0
0,0,0,0,15,15,15,15,15,16,15,17,15,15,15,15,15,0,0,0,0,0,0
19,0,19,0,0,0,15,15,15,9,15,15,15,15,16,15,15,15,0,0,0,0,19
18,6,18,0,0,0,0,15,15,15,15,9,9,15,15,15,15,15,0,0,0,6,18
22,0,22,0,0,0,15,15,15,15,9,15,15,15,15,15,15,15,0,0,0,0,22
0,0,0,0,0,0,15,15,15,9,15,15,15,16,15,15,15,15,15,0,0,0,0
0,0,0,15,15,15,15,15,15,15,15,15,15,15,15,15,15,15,15,15,0,0,0
0,0,15,15,15,15,15,15,15,15,15,15,15,15,15,15,9,15,15,15,0,0,0
0,0,15,15,15,15,15,0,15,15,15,0,0,15,15,15,15,15,15,15,0,0,0
0,0,15,15,15,15,15,0,0,0,0,0,0,0,15,15,15,15,15,0,0,0,0
0,0,0,15,15,15,0,0,0,0,0,0,0,0,0,15,15,15,0,0,0,0,0
19,0,19,0,0,0,0,0,0,0,0,19,0,0,0,0,0,0,0,0,19,0,19
18,19,18,21,0,0,0,0,0,0,20,18,21,0,0,0,0,0,0,20,18,19,18
20,18,21,0,0,0,0,0,0,0,0,6,0,0,0,0,0,0,0,0,20,18,21
18,22,18,21,0,0,0,0,0,0,20,18,21,0,0,0,0,0,0,20,18,22,18
endlayer

layer
18,6,18,18,21,0,0,0,0,20,18,18,18,21,0,0,0,0,20,18,18,6,18
6,18,6,0,0,0,0,0,0,0,6,18,6,0,0,0,0,0,0,0,6,18,6
18,6,18,18,21,0,0,0,0,20,18,18,18,21,0,0,0,0,20,18,18,6,18
18,0,18,0,0,0,0,0,0,0,0,18,0,0,0,0,0,0,0,0,0,0,18
22,0,22,0,0,0,0,0,0,0,0,15,0,0,0,0,0,0,0,0,0,0,22
0,0,0,0,0,0,0,0,0,0,15,15,15,0,0,0,0,0,0,0,0,0,0
0,0,0,0,0,15,0,0,15,15,15,23,23,0,0,0,0,0,0,0,0,0,0
0,0,0,0,15,15,15,15,15,15,15,15,15,15,15,15,0,0,0,0,0,0,0
0,0,0,0,0,15,15,15,15,15,15,15,15,15,15,15,15,0,0,0,0,0,0
19,0,19,0,0,0,15,15,15,9,15,9,15,15,15,15,15,15,0,0,0,0,19
18,6,18,0,0,0,15,15,15,9,15,15,15,15,9,15,15,15,0,0,0,6,18
18,18,18,21,0,0,15,15,15,15,15,15,15,15,15,15,15,15,0,20,18,18,18
18,6,18,0,0,0,0,15,15,15,15,15,15,15,15,15,15,0,0,0,0,6,18
22,0,22,0,0,0,0,15,15,15,15,15,15,9,15,15,15,15,0,0,0,0,22
0,0,0,0,0,0,0,15,15,15,15,15,15,15,15,15,15,15,15,0,0,0,0
0,0,0,0,15,0,0,0,15,15,15,15,15,15,15,15,15,15,15,0,0,0,0
0,0,0,15,15,15,0,0,0,0,0,0,15,15,15,15,15,15,15,0,0,0,0
0,0,0,0,15,0,0,0,0,0,0,0,0,0,0,15,15,15,0,0,0,0,0
19,0,19,0,0,0,0,0,0,0,0,19,0,0,0,0,0,0,0,0,19,0,19
18,0,18,0,0,0,0,0,0,0,0,18,0,0,0,0,0,0,0,0,18,0,18
18,6,18,18,21,0,0,0,0,20,18,18,18,21,0,0,0,0,20,18,18,6,18
6,18,6,0,0,0,0,0,0,0,6,18,6,0,0,0,0,0,0,0,6,18,6
18,6,18,18,21,0,0,0,0,20,18,18,18,21,0,0,0,0,20,18,18,6,18
endlayer

layer
0,6,24,24,18,21,0,0,20,18,0,6,0,18,21,0,0,20,18,0,0,6,0
6,0,6,0,0,0,0,0,0,0,6,0,6,0,0,0,0,0,0,0,6,0,6
0,6,0,0,18,21,0,0,20,18,0,6,0,18,21,0,0,20,18,0,0,6,0
0,0,0,0,0,0,0,0,0,0,0,0,0,0,0,0,0,0,0,0,0,0,0
18,0,18,0,0,0,0,0,0,0,0,18,0,0,0,0,0,0,0,0,0,0,18
22,0,22,0,0,0,0,0,0,0,0,22,0,0,0,0,0,0,0,0,0,0,22
0,0,0,0,0,0,0,0,0,0,0,0,0,0,0,0,0,0,0,0,0,0,0
0,0,0,0,0,0,0,0,15,15,15,25,25,0,0,0,0,0,0,0,0,0,0
19,0,19,0,0,0,0,15,15,15,15,15,15,15,15,15,0,0,0,0,0,0,19
18,0,18,0,0,0,0,15,15,15,15,15,15,15,15,15,15,0,0,0,0,0,18
0,6,0,0,0,0,24,15,15,15,15,15,15,15,15,15,15,0,0,0,0,6,0
6,0,6,18,21,0,24,15,15,15,15,15,15,15,15,15,15,0,20,18,6,0,6
0,6,0,0,0,0,0,0,15,15,15,15,15,15,15,15,0,0,0,0,0,6,0
18,0,18,0,0,0,0,0,15,15,15,15,15,15,15,15,0,0,0,0,0,0,18
22,0,22,0,0,0,0,0,0,15,0,15,15,15,15,15,15,0,0,0,0,0,22
0,0,0,0,0,0,0,0,0,0,0,0,15,15,15,15,15,15,0,0,0,0,0
0,0,0,24,0,0,0,0,0,0,0,0,0,0,0,0,15,0,0,0,0,0,0
19,0,19,0,0,0,0,0,0,0,0,19,0,0,0,0,0,0,0,0,19,0,19
18,0,18,0,0,0,0,0,0,0,0,18,0,0,0,0,0,0,0,0,18,0,18
0,0,0,0,0,0,0,0,0,0,0,0,0,0,0,0,0,0,0,0,0,0,0
0,6,0,0,18,21,0,0,20,18,0,6,0,18,21,0,0,20,18,0,0,6,0
6,0,6,0,0,0,0,0,0,0,6,0,6,0,0,0,0,0,0,0,6,0,6
0,6,0,0,18,21,0,0,20,18,0,6,0,18,21,0,0,20,18,0,0,6,0
endlayer

layer
0,7,0,0,0,18,21,20,18,0,0,7,0,0,18,21,20,18,0,0,0,7,0
7,0,7,0,0,0,0,0,0,0,7,0,7,0,0,0,0,0,0,0,7,0,7
0,7,0,0,0,18,21,20,18,0,0,7,0,0,18,21,20,18,0,0,0,7,0
0,0,0,0,0,0,0,0,0,0,0,0,0,0,0,0,0,0,0,0,0,0,0
0,0,24,0,0,0,0,0,0,0,0,0,0,0,0,0,0,0,0,0,0,0,0
18,0,18,0,0,0,0,0,0,0,0,18,0,0,0,0,0,0,0,0,0,0,18
22,0,22,0,0,0,0,0,0,0,0,22,0,0,0,0,0,0,0,0,0,0,22
19,0,19,0,0,0,0,0,0,0,0,0,0,0,0,0,0,0,0,0,0,0,19
18,0,18,0,0,0,0,0,0,15,0,15,0,0,0,0,0,0,0,0,0,0,18
0,0,0,0,0,0,0,0,15,15,15,15,15,24,15,0,0,0,0,0,0,0,0
0,7,0,0,0,0,0,0,15,15,15,15,0,15,15,15,0,0,0,0,0,7,0
7,0,7,0,18,21,0,0,0,15,0,0,0,0,15,0,0,20,18,0,7,0,7
0,7,0,0,0,0,0,0,0,0,0,0,0,15,0,0,0,0,0,0,0,7,0
0,0,0,0,0,0,0,0,0,0,0,0,15,15,15,0,0,0,0,0,0,0,0
18,0,18,0,0,0,0,0,0,0,0,0,0,15,0,0,0,0,0,0,0,0,18
22,0,22,0,0,0,0,0,0,0,0,0,0,0,24,0,24,0,0,0,0,0,22
19,0,19,0,0,0,0,0,0,0,0,19,0,0,0,0,0,0,0,0,19,0,19
18,0,18,0,0,0,0,0,0,0,0,18,0,0,0,0,0,0,0,0,18,0,18
0,0,0,0,0,0,0,0,0,0,0,0,0,0,0,0,0,0,0,0,0,0,0
0,0,0,0,0,0,0,0,0,0,0,0,0,0,0,0,0,0,0,0,0,0,0
0,7,0,0,0,18,21,20,18,0,0,7,0,0,18,21,20,18,0,0,0,7,0
7,0,7,0,0,0,0,0,0,0,7,0,7,0,0,0,0,0,0,0,7,0,7
0,7,0,0,0,18,21,20,18,0,0,7,0,0,18,21,20,18,0,0,0,7,0
endlayer

layer
0,0,0,0,0,0,0,0,0,0,0,0,0,0,0,0,0,0,0,0,0,0,0
0,0,0,0,0,0,0,0,0,0,0,0,0,0,0,0,0,0,0,0,0,0,0
0,0,0,0,0,0,0,0,0,0,0,0,0,0,0,0,0,0,0,0,0,0,0
0,0,0,0,0,0,0,0,0,0,0,0,0,0,0,0,0,0,0,0,0,0,0
0,0,0,0,0,0,0,0,0,0,0,0,0,0,0,0,0,0,0,0,0,0,0
0,0,0,0,0,0,0,0,0,0,0,0,0,0,0,0,0,0,0,0,0,0,0
0,0,0,0,0,0,0,0,0,18,18,18,18,18,0,0,0,0,0,0,0,0,0
0,0,0,0,0,0,0,0,18,0,0,22,0,0,18,0,0,0,0,0,0,0,0
0,0,0,0,0,0,0,18,0,0,0,0,0,0,0,18,0,0,0,0,0,0,0
0,0,0,0,0,0,18,0,0,0,0,0,24,0,0,0,18,0,0,0,0,0,0
0,0,0,0,0,18,0,0,0,0,0,0,0,0,0,24,0,18,0,0,0,0,0
0,0,0,0,0,18,21,0,0,0,0,0,0,0,24,0,20,18,0,0,0,0,0
0,0,0,0,0,18,0,0,0,0,0,0,0,0,0,0,0,18,0,0,0,0,0
0,0,0,0,0,0,18,0,0,0,0,0,0,0,0,0,18,0,0,0,0,0,0
0,0,24,0,0,0,0,18,0,0,0,0,0,0,0,18,0,0,0,0,0,0,24
0,0,0,0,0,0,0,0,18,0,0,19,0,0,18,0,0,0,0,0,0,0,0
0,0,0,0,0,0,0,0,0,18,18,18,18,18,0,0,0,0,0,0,0,0,0
0,0,0,0,0,0,0,0,0,0,0,0,0,0,0,0,0,0,0,0,0,0,0
0,0,0,0,0,0,0,0,0,0,0,0,0,0,0,0,0,0,0,0,0,0,0
0,0,0,0,0,0,0,0,0,0,0,0,0,0,0,0,0,0,0,0,0,0,0
0,0,0,0,0,0,0,0,0,0,0,0,0,0,0,0,0,0,0,0,0,0,0
0,0,0,0,0,0,0,0,0,0,0,0,0,0,0,0,0,0,0,0,0,0,0
0,0,0,0,0,0,0,0,0,0,0,0,0,0,0,0,0,0,0,0,0,0,0
endlayer

layer
0,0,0,0,0,0,0,0,0,0,0,0,0,0,0,0,0,0,0,0,0,0,0
0,0,0,0,0,0,0,0,0,0,0,0,0,0,0,0,0,0,0,0,0,0,0
0,0,0,0,0,0,0,0,0,0,0,0,0,0,0,0,0,0,0,0,0,0,0
0,0,0,0,0,0,0,0,0,0,0,0,0,0,0,0,0,0,0,0,0,0,0
0,0,0,0,0,0,0,0,0,0,0,0,0,0,0,0,0,0,0,0,0,0,0
0,0,0,0,0,0,0,0,0,0,0,0,0,0,0,0,0,0,0,0,0,0,0
0,0,0,0,0,0,0,0,0,0,0,0,0,0,0,0,0,0,0,0,0,0,0
0,0,0,0,0,0,0,0,0,0,0,18,0,0,0,0,0,0,0,0,0,0,0
0,0,0,0,0,0,0,0,0,0,0,22,0,0,0,0,0,0,0,0,0,0,0
0,0,0,0,0,0,0,0,0,0,0,0,0,0,0,0,0,0,0,0,0,0,0
0,0,0,0,0,0,0,0,0,0,0,0,0,0,0,0,0,0,0,0,0,0,0
0,0,0,0,0,0,18,21,0,0,0,0,0,0,0,20,18,0,0,0,0,0,0
0,0,0,0,0,0,0,0,0,0,0,0,0,0,0,0,0,0,0,0,0,0,0
0,0,0,0,0,0,0,0,0,0,0,0,0,0,0,0,0,0,0,0,0,0,0
0,0,0,0,0,0,0,0,0,0,0,19,0,0,0,0,0,0,0,0,0,0,0
0,0,0,0,0,0,0,0,0,0,0,18,0,0,0,0,0,0,0,0,0,0,0
0,0,0,0,0,0,0,0,0,0,0,0,0,0,0,0,0,0,0,0,0,0,0
0,0,0,0,0,0,0,0,0,0,0,0,0,0,0,0,0,0,0,0,0,0,0
0,0,0,0,0,0,0,0,0,0,0,0,0,0,0,0,0,0,0,0,0,0,0
0,0,0,0,0,0,0,0,0,0,0,0,0,0,0,0,0,0,0,0,0,0,0
0,0,0,0,0,0,0,0,0,0,0,0,0,0,0,0,0,0,0,0,0,0,0
0,0,0,0,0,0,0,0,0,0,0,0,0,0,0,0,0,0,0,0,0,0,0
0,0,0,0,0,0,0,0,0,0,0,0,0,0,0,0,0,0,0,0,0,0,0
endlayer

layer
0,0,0,0,0,0,0,0,0,0,0,0,0,0,0,0,0,0,0,0,0,0,0
0,0,0,0,0,0,0,0,0,0,0,0,0,0,0,0,0,0,0,0,0,0,0
0,0,0,0,0,0,0,0,0,0,0,0,0,0,0,0,0,0,0,0,0,0,0
0,0,0,0,0,0,0,0,0,0,0,0,0,0,0,0,0,0,0,0,0,0,0
0,0,0,0,0,0,0,0,0,0,0,0,0,0,0,0,0,0,0,0,0,0,0
0,0,0,0,0,0,0,0,0,0,0,0,0,0,0,0,0,0,0,0,0,0,0
0,0,0,0,0,0,0,0,0,0,0,0,0,0,0,0,0,0,0,0,0,0,0
0,0,0,0,0,0,0,0,0,0,0,0,0,0,0,0,0,0,0,0,0,0,0
0,0,0,0,0,0,0,0,0,0,0,18,0,0,0,0,0,0,0,0,0,0,0
0,0,0,0,0,0,0,0,0,0,0,22,0,0,0,0,0,0,0,0,0,0,0
0,0,0,0,0,0,0,0,0,0,0,26,0,0,0,0,0,0,0,0,0,0,0
0,0,0,0,0,0,0,18,21,26,26,26,26,26,20,18,0,0,0,0,0,0,0
0,0,0,0,0,0,0,0,0,0,0,26,0,0,0,0,0,0,0,0,0,0,0
0,0,0,0,0,0,0,0,0,0,0,19,0,0,0,0,0,0,0,0,0,0,0
0,0,0,0,0,0,0,0,0,0,0,18,0,0,0,0,0,0,0,0,0,0,0
0,0,0,0,0,0,0,0,0,0,0,0,0,0,0,0,0,0,0,0,0,0,0
0,0,0,0,0,0,0,0,0,0,0,0,0,0,0,0,0,0,0,0,0,0,0
0,0,0,0,0,0,0,0,0,0,0,0,0,0,0,0,0,0,0,0,0,0,0
0,0,0,0,0,0,0,0,0,0,0,0,0,0,0,0,0,0,0,0,0,0,0
0,0,0,0,0,0,0,0,0,0,0,0,0,0,0,0,0,0,0,0,0,0,0
0,0,0,0,0,0,0,0,0,0,0,0,0,0,0,0,0,0,0,0,0,0,0
0,0,0,0,0,0,0,0,0,0,0,0,0,0,0,0,0,0,0,0,0,0,0
0,0,0,0,0,0,0,0,0,0,0,0,0,0,0,0,0,0,0,0,0,0,0
endlayer

layer
0,0,0,0,0,0,0,0,0,0,0,0,0,0,0,0,0,0,0,0,0,0,0
0,0,0,0,0,0,0,0,0,0,0,0,0,0,0,0,0,0,0,0,0,0,0
0,0,0,0,0,0,0,0,0,0,0,0,0,0,0,0,0,0,0,0,0,0,0
0,0,0,0,0,0,0,0,0,0,0,0,0,0,0,0,0,0,0,0,0,0,0
0,0,0,0,0,0,0,0,0,0,0,0,0,0,0,0,0,0,0,0,0,0,0
0,0,0,0,0,0,0,0,0,0,0,0,0,0,0,0,0,0,0,0,0,0,0
0,0,0,0,0,0,0,0,0,0,0,0,0,0,0,0,0,0,0,0,0,0,0
0,0,0,0,0,0,0,0,0,0,0,0,0,0,0,0,0,0,0,0,0,0,0
0,0,0,0,0,0,0,0,0,0,0,0,0,0,0,0,0,0,0,0,0,0,0
0,0,0,0,0,0,0,0,0,0,0,0,0,0,0,0,0,0,0,0,0,0,0
0,0,0,0,0,0,0,0,0,0,0,6,0,0,0,0,0,0,0,0,0,0,0
0,0,0,0,0,0,0,0,0,0,6,0,6,0,0,0,0,0,0,0,0,0,0
0,0,0,0,0,0,0,0,0,0,0,6,0,0,0,0,0,0,0,0,0,0,0
0,0,0,0,0,0,0,0,0,0,0,0,0,0,0,0,0,0,0,0,0,0,0
0,0,0,0,0,0,0,0,0,0,0,0,0,0,0,0,0,0,0,0,0,0,0
0,0,0,0,0,0,0,0,0,0,0,0,0,0,0,0,0,0,0,0,0,0,0
0,0,0,0,0,0,0,0,0,0,0,0,0,0,0,0,0,0,0,0,0,0,0
0,0,0,0,0,0,0,0,0,0,0,0,0,0,0,0,0,0,0,0,0,0,0
0,0,0,0,0,0,0,0,0,0,0,0,0,0,0,0,0,0,0,0,0,0,0
0,0,0,0,0,0,0,0,0,0,0,0,0,0,0,0,0,0,0,0,0,0,0
0,0,0,0,0,0,0,0,0,0,0,0,0,0,0,0,0,0,0,0,0,0,0
0,0,0,0,0,0,0,0,0,0,0,0,0,0,0,0,0,0,0,0,0,0,0
0,0,0,0,0,0,0,0,0,0,0,0,0,0,0,0,0,0,0,0,0,0,0
endlayer

layer
0,0,0,0,0,0,0,0,0,0,0,0,0,0,0,0,0,0,0,0,0,0,0
0,0,0,0,0,0,0,0,0,0,0,0,0,0,0,0,0,0,0,0,0,0,0
0,0,0,0,0,0,0,0,0,0,0,0,0,0,0,0,0,0,0,0,0,0,0
0,0,0,0,0,0,0,0,0,0,0,0,0,0,0,0,0,0,0,0,0,0,0
0,0,0,0,0,0,0,0,0,0,0,0,0,0,0,0,0,0,0,0,0,0,0
0,0,0,0,0,0,0,0,0,0,0,0,0,0,0,0,0,0,0,0,0,0,0
0,0,0,0,0,0,0,0,0,0,0,0,0,0,0,0,0,0,0,0,0,0,0
0,0,0,0,0,0,0,0,0,0,0,0,0,0,0,0,0,0,0,0,0,0,0
0,0,0,0,0,0,0,0,0,0,0,0,0,0,0,0,0,0,0,0,0,0,0
0,0,0,0,0,0,0,0,0,0,0,0,0,0,0,0,0,0,0,0,0,0,0
0,0,0,0,0,0,0,0,0,0,0,7,0,0,0,0,0,0,0,0,0,0,0
0,0,0,0,0,0,0,0,0,0,7,0,7,0,0,0,0,0,0,0,0,0,0
0,0,0,0,0,0,0,0,0,0,0,7,0,0,0,0,0,0,0,0,0,0,0
0,0,0,0,0,0,0,0,0,0,0,0,0,0,0,0,0,0,0,0,0,0,0
0,0,0,0,0,0,0,0,0,0,0,0,0,0,0,0,0,0,0,0,0,0,0
0,0,0,0,0,0,0,0,0,0,0,0,0,0,0,0,0,0,0,0,0,0,0
0,0,0,0,0,0,0,0,0,0,0,0,0,0,0,0,0,0,0,0,0,0,0
0,0,0,0,0,0,0,0,0,0,0,0,0,0,0,0,0,0,0,0,0,0,0
0,0,0,0,0,0,0,0,0,0,0,0,0,0,0,0,0,0,0,0,0,0,0
0,0,0,0,0,0,0,0,0,0,0,0,0,0,0,0,0,0,0,0,0,0,0
0,0,0,0,0,0,0,0,0,0,0,0,0,0,0,0,0,0,0,0,0,0,0
0,0,0,0,0,0,0,0,0,0,0,0,0,0,0,0,0,0,0,0,0,0,0
0,0,0,0,0,0,0,0,0,0,0,0,0,0,0,0,0,0,0,0,0,0,0
endlayer

