
# Created by Ruins mod version 14.7 Ingame Parser
# authoring Player: Barlock_James

weight=1
embed_into_distance=0
acceptable_target_blocks=
unacceptable_target_blocks=flowing_water,water,flowing_lava,lava
dimensions=11,13,13
allowable_overhang=0
max_leveling=2
leveling_buffer=0
preserve_water=0
preserve_lava=0

rule1=0,100,DCsAppleMilk:defeatedcrow.yuzuFence-0
rule2=0,100,erebus:umberPaver-1
rule3=0,100,minecraft:dirt-0
rule4=0,100,chisel:factoryblock-13
rule5=0,100,chisel:factoryblock-15
rule6=0,100,chisel:technical-10
rule7=0,100,chisel:factoryblock-1
rule8=0,100,chisel:iron_block-14
rule9=0,100,EnderIO:blockDarkSteelLadder-5
rule10=0,100,EnderIO:blockDarkSteelLadder-3
rule11=0,100,EnderIO:blockDarkSteelLadder-2
rule12=0,100,EnderIO:blockDarkSteelLadder-4
rule13=0,100,malisisdoors:factory_door-2
rule14=0,100,erebus:wallErebus-6
rule15=0,100,chisel:iron_bars-9
rule16=0,100,chisel:glass-10
rule17=0,100,chisel:iron_bars-2
rule18=0,100,malisisdoors:factory_door-8
rule19=0,100,Thaumcraft:blockCosmeticOpaque-2
rule20=0,100,ExtraUtilities:color_redstoneLight-12
rule21=0,100,Thaumcraft:blockCosmeticSlabStone-9
rule22=0,100,chisel:glass-15
rule23=0,100,chisel:technical-15
rule24=0,100,IInventory;Thaumcraft:blockStoneDevice;clockworkphase:gearDiamond#1#0#0-1
rule25=0,100,minecraft:trapdoor-0
rule26=0,100,minecraft:trapdoor-1
rule27=0,100,minecraft:trapdoor-2
rule28=0,100,minecraft:trapdoor-3
rule29=0,100,minecraft:trapdoor-4
rule30=0,100,chisel:iron_bars-4
rule31=0,100,chisel:warningSign-4

layer
1,2,2,2,2,2,2,2,2,2,2,2,1
2,3,3,3,3,3,3,3,3,3,3,3,2
2,3,4,4,4,4,5,4,4,4,4,3,2
2,3,4,4,4,4,5,4,4,4,4,3,2
2,3,4,4,4,4,5,4,4,4,4,3,2
2,3,4,4,4,4,5,4,4,4,4,3,2
2,3,5,5,5,5,6,5,5,5,5,3,2
2,3,4,4,4,4,5,4,4,4,4,3,2
2,3,4,4,4,4,5,4,4,4,4,3,2
2,3,4,4,4,4,5,4,4,4,4,3,2
2,3,4,4,4,4,5,4,4,4,4,3,2
2,3,3,3,3,3,5,3,3,3,3,3,2
1,2,2,2,2,2,2,2,2,2,2,2,1
endlayer

layer
0,0,0,0,0,0,0,0,0,0,0,0,0
0,5,7,8,8,7,5,7,8,8,7,5,0
0,7,0,0,0,9,0,9,0,0,0,7,0
0,7,0,0,0,0,0,0,0,0,0,7,0
0,7,0,0,0,0,0,0,0,0,0,7,0
0,7,11,0,0,0,0,0,0,0,10,7,0
0,5,0,0,0,0,0,0,0,0,0,5,0
0,7,11,0,0,0,0,0,0,0,10,7,0
0,7,0,0,0,0,0,0,0,0,0,7,0
0,7,0,0,0,0,0,0,0,0,0,7,0
0,7,0,0,0,12,0,12,0,0,0,7,0
0,5,7,8,8,7,13,7,8,8,7,5,0
0,0,0,0,0,14,15,14,0,0,0,0,0
endlayer

layer
0,0,0,0,0,0,0,0,0,0,0,0,0
0,5,7,16,16,7,5,7,16,16,7,5,0
0,7,0,0,0,9,0,9,0,0,0,7,0
0,17,0,0,0,0,0,0,0,0,0,17,0
0,17,0,0,0,0,0,0,0,0,0,17,0
0,7,11,0,0,0,0,0,0,0,10,7,0
0,5,0,0,0,0,0,0,0,0,0,5,0
0,7,11,0,0,0,0,0,0,0,10,7,0
0,17,0,0,0,0,0,0,0,0,0,17,0
0,17,0,0,0,0,0,0,0,0,0,17,0
0,7,0,0,0,12,0,12,0,0,0,7,0
0,5,7,16,16,7,18,7,16,16,7,5,0
0,0,0,0,0,14,15,14,0,0,0,0,0
endlayer

layer
0,0,0,0,0,0,0,0,0,0,0,0,0
0,5,7,16,16,7,5,7,16,16,7,5,0
0,7,0,0,0,9,0,9,0,0,0,7,0
0,17,0,0,0,0,0,0,0,0,0,17,0
0,17,0,0,0,0,0,0,0,0,0,17,0
0,7,11,0,0,0,0,0,0,0,10,7,0
0,5,0,0,0,0,19,0,0,0,0,5,0
0,7,11,0,0,0,0,0,0,0,10,7,0
0,17,0,0,0,0,0,0,0,0,0,17,0
0,17,0,0,0,0,0,0,0,0,0,17,0
0,7,0,0,0,12,0,12,0,0,0,7,0
0,5,7,16,16,7,20,7,16,16,7,5,0
0,0,0,0,0,14,0,14,0,0,0,0,0
endlayer

layer
0,5,21,21,21,21,5,21,21,21,21,5,0
5,5,7,7,7,7,5,7,7,7,7,5,5
21,7,22,22,23,9,5,9,23,22,22,7,21
21,7,22,22,23,0,0,0,23,22,22,7,21
21,7,23,23,23,0,0,0,23,23,23,7,21
21,7,11,0,0,0,19,0,0,0,10,7,21
5,5,5,0,0,19,24,19,0,0,5,5,5
21,7,11,0,0,0,19,0,0,0,10,7,21
21,7,23,23,23,0,0,0,23,23,23,7,21
21,7,22,22,23,0,0,0,23,22,22,7,21
21,7,22,22,23,12,5,12,23,22,22,7,21
5,5,7,7,7,7,5,7,7,7,7,5,5
0,5,21,21,21,14,14,14,21,21,21,5,0
endlayer

layer
0,5,15,15,15,15,5,15,15,15,15,5,0
5,0,0,0,0,0,0,0,0,0,0,0,5
15,0,0,0,0,26,5,25,0,0,0,0,15
15,0,0,0,0,22,5,22,0,0,0,0,15
15,0,0,0,23,0,0,0,23,0,0,0,15
15,0,27,22,0,0,19,0,0,22,27,0,15
5,0,5,5,0,19,0,19,0,5,5,0,5
15,0,28,22,0,0,19,0,0,22,28,0,15
15,0,0,0,23,0,0,0,23,0,0,0,15
15,0,0,0,0,22,5,22,0,0,0,0,15
15,0,0,0,0,26,5,29,0,0,0,0,15
5,0,0,0,0,0,0,0,0,0,0,0,5
0,5,15,15,15,15,5,15,15,15,15,5,0
endlayer

layer
0,5,30,30,30,30,5,30,30,30,30,5,0
5,0,0,0,0,0,0,0,0,0,0,0,5
30,0,0,0,0,0,0,0,0,0,0,0,30
30,0,0,0,0,0,5,0,0,0,0,0,30
30,0,0,0,0,22,5,22,0,0,0,0,30
30,0,0,0,22,23,5,23,22,0,0,0,30
5,0,0,5,5,5,19,5,5,5,0,0,5
30,0,0,0,22,23,5,23,22,0,0,0,30
30,0,0,0,0,22,5,22,0,0,0,0,30
30,0,0,0,0,0,5,0,0,0,0,0,30
30,0,0,0,0,0,0,0,0,0,0,0,30
5,0,0,0,0,0,0,0,0,0,0,0,5
0,5,30,30,30,30,5,30,30,30,30,5,0
endlayer

layer
0,1,0,0,0,0,1,0,0,0,0,1,0
1,0,0,0,0,0,0,0,0,0,0,0,1
0,0,0,0,0,0,0,0,0,0,0,0,0
0,0,0,0,0,0,1,0,0,0,0,0,0
0,0,0,0,0,0,1,0,0,0,0,0,0
0,0,0,0,0,0,1,0,0,0,0,0,0
1,0,0,1,1,1,1,1,1,1,0,0,1
0,0,0,0,0,0,1,0,0,0,0,0,0
0,0,0,0,0,0,1,0,0,0,0,0,0
0,0,0,0,0,0,1,0,0,0,0,0,0
0,0,0,0,0,0,0,0,0,0,0,0,0
1,0,0,0,0,0,0,0,0,0,0,0,1
0,1,0,0,0,0,1,0,0,0,0,1,0
endlayer

layer
0,0,0,0,0,0,0,0,0,0,0,0,0
0,0,0,0,0,0,0,0,0,0,0,0,0
0,0,0,0,0,0,0,0,0,0,0,0,0
0,0,0,0,0,0,0,0,0,0,0,0,0
0,0,0,0,0,0,0,0,0,0,0,0,0
0,0,0,0,0,0,0,0,0,0,0,0,0
0,0,0,0,0,0,1,0,0,0,0,0,0
0,0,0,0,0,0,0,0,0,0,0,0,0
0,0,0,0,0,0,0,0,0,0,0,0,0
0,0,0,0,0,0,0,0,0,0,0,0,0
0,0,0,0,0,0,0,0,0,0,0,0,0
0,0,0,0,0,0,0,0,0,0,0,0,0
0,0,0,0,0,0,0,0,0,0,0,0,0
endlayer

layer
0,0,0,0,0,0,0,0,0,0,0,0,0
0,0,0,0,0,0,0,0,0,0,0,0,0
0,0,0,0,0,0,0,0,0,0,0,0,0
0,0,0,0,0,0,0,0,0,0,0,0,0
0,0,0,0,0,0,0,0,0,0,0,0,0
0,0,0,0,0,0,0,0,0,0,0,0,0
0,0,0,0,0,0,1,0,0,0,0,0,0
0,0,0,0,0,0,0,0,0,0,0,0,0
0,0,0,0,0,0,0,0,0,0,0,0,0
0,0,0,0,0,0,0,0,0,0,0,0,0
0,0,0,0,0,0,0,0,0,0,0,0,0
0,0,0,0,0,0,0,0,0,0,0,0,0
0,0,0,0,0,0,0,0,0,0,0,0,0
endlayer

layer
0,0,0,0,0,0,0,0,0,0,0,0,0
0,0,0,0,0,0,0,0,0,0,0,0,0
0,0,0,0,0,0,0,0,0,0,0,0,0
0,0,0,0,0,0,0,0,0,0,0,0,0
0,0,0,0,0,0,0,0,0,0,0,0,0
0,0,0,0,0,0,0,0,0,0,0,0,0
0,0,0,0,0,0,31,0,0,0,0,0,0
0,0,0,0,0,0,0,0,0,0,0,0,0
0,0,0,0,0,0,0,0,0,0,0,0,0
0,0,0,0,0,0,0,0,0,0,0,0,0
0,0,0,0,0,0,0,0,0,0,0,0,0
0,0,0,0,0,0,0,0,0,0,0,0,0
0,0,0,0,0,0,0,0,0,0,0,0,0
endlayer

