
# Created by Ruins mod version 14.7 Ingame Parser
# authoring Player: Barlock_James

weight=1
embed_into_distance=0
acceptable_target_blocks=
unacceptable_target_blocks=flowing_water,water,flowing_lava,lava
dimensions=6,7,7
allowable_overhang=0
max_leveling=2
leveling_buffer=0
preserve_water=0
preserve_lava=0

rule1=0,100,ExtraUtilities:decorativeBlock1-10
rule2=0,100,ChestGenHook:dungeonChest:5-3
rule3=0,100,chisel:technical-15
rule4=0,100,chisel:factoryblock-1
rule5=0,100,chisel:iron_block-14
rule6=0,100,chisel:factoryblock-13

layer
1,1,1,1,1,1,1
1,1,1,1,1,1,1
1,1,1,1,1,1,1
1,1,1,2,1,1,1
1,1,1,1,1,1,1
1,1,1,1,1,1,1
1,1,1,1,1,1,1
endlayer

layer
0,0,0,3,0,0,0
0,0,0,4,0,0,0
0,0,0,0,0,0,0
3,4,0,5,0,4,3
0,0,0,0,0,0,0
0,0,0,4,0,0,0
0,0,0,3,0,0,0
endlayer

layer
0,0,0,3,0,0,0
0,0,0,0,0,0,0
0,0,0,4,0,0,0
3,0,4,4,4,0,3
0,0,0,4,0,0,0
0,0,0,0,0,0,0
0,0,0,3,0,0,0
endlayer

layer
0,0,0,0,0,0,0
0,0,0,3,0,0,0
0,0,0,0,0,0,0
0,3,0,4,0,3,0
0,0,0,0,0,0,0
0,0,0,3,0,0,0
0,0,0,0,0,0,0
endlayer

layer
0,0,0,0,0,0,0
0,0,0,0,0,0,0
0,0,0,3,0,0,0
0,0,3,3,3,0,0
0,0,0,3,0,0,0
0,0,0,0,0,0,0
0,0,0,0,0,0,0
endlayer

layer
0,0,0,0,0,0,0
0,0,0,0,0,0,0
0,0,0,0,0,0,0
0,0,0,6,0,0,0
0,0,0,0,0,0,0
0,0,0,0,0,0,0
0,0,0,0,0,0,0
endlayer

