
# Created by Ruins mod version 14.7 Ingame Parser
# authoring Player: Barlock_James

weight=1
embed_into_distance=0
acceptable_target_blocks=
unacceptable_target_blocks=flowing_water,water,flowing_lava,lava
dimensions=10,19,19
allowable_overhang=0
max_leveling=2
leveling_buffer=0
preserve_water=0
preserve_lava=0

rule1=0,100,minecraft:stone_slab-5
rule2=0,100,minecraft:stone_brick_stairs-0
rule3=0,100,minecraft:stone_brick_stairs-2
rule4=0,100,minecraft:stone_brick_stairs-3
rule5=0,100,minecraft:dirt-2
rule6=0,100,minecraft:stonebrick-1
rule7=0,100,minecraft:dirt-0
rule8=0,100,minecraft:stone_brick_stairs-1
rule9=0,100,minecraft:brown_mushroom_block-10
rule10=0,100,minecraft:log-3
rule11=0,100,DCsAppleMilk:defeatedcrow.logYuzu-0
rule12=0,100,minecraft:red_mushroom_block-10
rule13=0,100,harvestcraft:pamLime-2
rule14=0,100,harvestcraft:pamLime-1
rule15=0,100,DCsAppleMilk:defeatedcrow.leavesYuzu-3
rule16=0,100,harvestcraft:pamLemon-2
rule17=0,100,minecraft:red_mushroom_block-1
rule18=0,100,minecraft:red_mushroom_block-4
rule19=0,100,minecraft:red_mushroom_block-7
rule20=0,100,harvestcraft:pamLemon-1
rule21=0,100,harvestcraft:pamLemon-0
rule22=0,100,minecraft:red_mushroom_block-2
rule23=0,100,minecraft:red_mushroom_block-8
rule24=0,100,minecraft:red_mushroom_block-3
rule25=0,100,minecraft:red_mushroom_block-9
rule26=0,100,minecraft:red_mushroom_block-6
rule27=0,100,minecraft:leaves-3
rule28=0,100,minecraft:stone_brick_stairs-6
rule29=0,100,minecraft:stone_brick_stairs-7
rule30=0,100,minecraft:stone_brick_stairs-5
rule31=0,100,minecraft:stone_brick_stairs-4
rule32=0,100,minecraft:brown_mushroom_block-5
rule33=0,100,minecraft:red_mushroom_block-5
rule34=0,100,BiblioCraft:BiblioLantern-0
rule35=0,100,ExtraUtilities:decorativeBlock2-7

layer
0,0,0,0,0,0,0,0,0,0,0,0,0,0,0,0,0,0,0
0,1,2,1,0,0,0,0,4,2,3,0,0,0,0,1,2,1,0
0,4,7,3,0,0,0,0,4,6,3,0,0,0,0,4,5,3,0
0,1,8,1,0,0,0,0,8,8,3,0,0,0,0,1,8,1,0
0,0,0,0,0,0,0,0,0,0,0,0,0,0,0,0,0,0,0
0,0,0,0,0,0,0,0,0,0,0,0,0,0,0,0,0,0,0
0,0,0,0,0,0,0,0,0,0,0,0,0,0,0,0,0,0,0
0,0,0,0,0,0,0,0,0,0,0,0,0,0,0,0,0,0,0
0,4,2,2,0,0,0,0,2,2,3,0,0,0,0,2,2,2,0
0,4,6,3,0,0,0,0,4,7,3,0,0,0,0,4,6,3,0
0,8,8,8,0,0,0,0,4,8,8,0,0,0,0,8,8,3,0
0,0,0,0,0,0,0,0,0,0,0,0,0,0,0,0,0,0,0
0,0,0,0,0,0,0,0,0,0,0,0,0,0,0,0,0,0,0
0,0,0,0,0,0,0,0,0,0,0,0,0,0,0,0,0,0,0
0,0,0,0,0,0,0,0,0,0,0,0,0,0,0,0,0,0,0
0,1,2,1,0,0,0,0,2,2,2,0,0,0,0,1,2,1,0
0,4,5,3,0,0,0,0,4,6,3,0,0,0,0,4,7,3,0
0,1,8,1,0,0,0,0,8,8,3,0,0,0,0,1,8,1,0
0,0,0,0,0,0,0,0,0,0,0,0,0,0,0,0,0,0,0
endlayer

layer
0,0,0,0,0,0,0,0,0,0,0,0,0,0,0,0,0,0,0
0,0,0,0,0,0,0,0,0,0,0,0,0,0,0,0,0,0,0
0,0,10,0,0,0,0,0,0,6,0,0,0,0,0,0,9,0,0
0,0,0,0,0,0,0,0,0,0,0,0,0,0,0,0,0,0,0
0,0,0,0,0,0,0,0,0,0,0,0,0,0,0,0,0,0,0
0,0,0,0,0,0,0,0,0,0,0,0,0,0,0,0,0,0,0
0,0,0,0,0,0,0,0,0,0,0,0,0,0,0,0,0,0,0
0,0,0,0,0,0,0,0,0,0,0,0,0,0,0,0,0,0,0
0,0,0,0,0,0,0,0,0,0,0,0,0,0,0,0,0,0,0
0,0,6,0,0,0,0,0,0,11,0,0,0,0,0,0,6,0,0
0,0,0,0,0,0,0,0,0,0,0,0,0,0,0,0,0,0,0
0,0,0,0,0,0,0,0,0,0,0,0,0,0,0,0,0,0,0
0,0,0,0,0,0,0,0,0,0,0,0,0,0,0,0,0,0,0
0,0,0,0,0,0,0,0,0,0,0,0,0,0,0,0,0,0,0
0,0,0,0,0,0,0,0,0,0,0,0,0,0,0,0,0,0,0
0,0,0,0,0,0,0,0,0,0,0,0,0,0,0,0,0,0,0
0,0,12,0,0,0,0,0,0,6,0,0,0,0,0,0,10,0,0
0,0,0,0,0,0,0,0,0,0,0,0,0,0,0,0,0,0,0
0,0,0,0,0,0,0,0,0,0,0,0,0,0,0,0,0,0,0
endlayer

layer
0,0,13,0,0,0,0,0,0,0,0,0,0,0,0,0,0,0,0
0,0,0,0,0,0,0,0,0,0,0,0,0,0,0,0,0,0,0
0,13,10,13,0,0,0,0,0,6,0,0,0,0,0,0,9,0,0
0,0,0,0,0,0,0,0,0,0,0,0,0,0,0,0,0,0,0
13,14,13,0,0,0,0,0,0,0,0,0,0,0,0,0,0,0,0
0,0,0,0,0,0,0,0,0,0,0,0,0,0,0,0,0,0,0
0,0,0,0,0,0,0,0,0,0,0,0,0,0,0,0,0,0,0
0,0,0,0,0,0,0,15,15,15,15,15,0,0,0,0,0,0,0
0,0,0,0,0,0,0,15,15,15,15,15,0,0,0,0,0,0,0
0,0,6,0,0,0,0,15,15,11,15,15,0,0,0,0,6,0,0
0,0,0,0,0,0,0,15,15,15,15,15,0,0,0,0,0,0,0
0,0,0,0,0,0,0,15,15,15,15,0,0,0,0,0,0,0,0
0,0,0,0,0,0,0,0,0,0,0,0,0,0,0,0,0,0,0
0,0,0,0,0,0,0,0,0,0,0,0,0,0,0,0,0,0,0
0,19,18,17,0,0,0,0,0,0,0,0,0,0,0,16,0,0,0
19,0,0,0,17,0,0,0,0,0,0,0,0,0,21,0,20,0,0
23,0,12,0,22,0,0,0,0,6,0,0,0,0,0,0,10,0,0
25,0,0,0,24,0,0,0,0,0,0,0,0,0,16,16,16,0,16
0,25,26,24,0,0,0,0,0,0,0,0,0,0,0,0,0,0,0
endlayer

layer
0,27,27,27,27,0,0,0,0,0,0,0,0,0,0,0,0,0,0
27,27,27,27,27,0,0,0,0,0,0,0,0,0,0,0,0,0,0
27,27,10,27,27,0,0,0,0,6,0,0,0,0,0,0,9,0,0
27,27,27,27,27,0,0,0,0,0,0,0,0,0,0,0,0,0,0
27,27,27,27,0,0,0,0,0,0,0,0,0,0,0,0,0,0,0
0,0,0,0,0,0,0,0,0,0,0,0,0,0,0,0,0,0,0
0,0,0,0,0,0,0,0,0,0,0,0,0,0,0,0,0,0,0
0,0,0,0,0,0,0,0,15,15,15,0,0,0,0,0,0,0,0
0,0,0,0,0,0,0,15,15,15,15,15,0,0,0,0,0,0,0
0,0,6,0,0,0,0,15,15,11,15,15,0,0,0,0,6,0,0
0,0,0,0,0,0,0,15,15,15,15,15,0,0,0,0,0,0,0
0,0,0,0,0,0,0,0,15,15,15,0,0,0,0,0,0,0,0
0,0,0,0,0,0,0,0,0,0,0,0,0,0,0,0,0,0,0
0,0,0,0,0,0,0,0,0,0,0,0,0,0,0,0,0,0,0
0,19,18,17,0,0,0,0,0,0,0,0,0,0,0,27,27,27,27
19,0,0,0,17,0,0,0,0,0,0,0,0,0,27,27,27,27,27
23,0,12,0,22,0,0,0,0,6,0,0,0,0,27,27,10,27,27
25,0,0,0,24,0,0,0,0,0,0,0,0,0,27,27,27,27,27
0,25,26,24,0,0,0,0,0,0,0,0,0,0,0,27,27,27,0
endlayer

layer
0,27,27,27,0,0,0,0,0,0,0,0,0,0,0,0,0,0,0
27,27,27,27,27,0,0,0,0,0,0,0,0,0,0,0,0,0,0
27,27,10,27,27,0,0,0,29,6,28,0,0,0,0,0,9,0,0
27,27,27,27,27,0,0,0,0,30,0,0,0,0,0,0,0,0,0
0,27,27,27,0,0,0,0,0,0,0,0,0,0,0,0,0,0,0
0,0,0,0,0,0,0,0,0,0,0,0,0,0,0,0,0,0,0
0,0,0,0,0,0,0,0,0,0,0,0,0,0,0,0,0,0,0
0,0,0,0,0,0,0,0,0,0,0,0,0,0,0,0,0,0,0
0,0,31,0,0,0,0,0,0,15,15,0,0,0,0,0,31,0,0
0,0,6,28,0,0,0,0,15,11,15,0,0,0,0,29,6,0,0
0,0,30,0,0,0,0,0,15,15,0,0,0,0,0,0,30,0,0
0,0,0,0,0,0,0,0,0,0,0,0,0,0,0,0,0,0,0
0,0,0,0,0,0,0,0,0,0,0,0,0,0,0,0,0,0,0
0,0,0,0,0,0,0,0,0,0,0,0,0,0,0,0,0,0,0
0,19,18,17,0,0,0,0,0,0,0,0,0,0,0,27,27,27,27
19,0,0,0,17,0,0,0,0,31,0,0,0,0,27,27,27,27,27
23,0,12,0,22,0,0,0,29,6,28,0,0,0,27,27,10,27,27
25,0,0,0,24,0,0,0,0,0,0,0,0,0,27,27,27,27,27
0,25,26,24,0,0,0,0,0,0,0,0,0,0,0,27,27,27,27
endlayer

layer
0,0,0,0,0,0,0,0,0,0,0,0,0,0,0,32,32,32,0
0,0,27,27,0,0,0,0,0,0,0,0,0,0,32,32,32,32,32
0,27,10,27,0,0,0,29,6,0,6,28,0,0,32,32,32,32,32
0,0,27,0,0,0,0,0,0,6,0,0,0,0,32,32,32,32,32
0,0,0,0,0,0,0,0,0,30,0,0,0,0,0,32,32,32,0
0,0,0,0,0,0,0,0,0,0,0,0,0,0,0,0,0,0,0
0,0,0,0,0,0,0,0,0,0,0,0,0,0,0,0,0,0,0
0,0,31,0,0,0,0,0,0,0,0,0,0,0,0,0,31,0,0
0,0,6,0,0,0,0,0,0,15,0,0,0,0,0,0,6,0,0
0,0,0,6,28,0,0,0,15,15,15,0,0,0,29,6,0,0,0
0,0,6,0,0,0,0,0,0,15,0,0,0,0,0,0,6,0,0
0,0,30,0,0,0,0,0,0,0,0,0,0,0,0,0,30,0,0
0,0,0,0,0,0,0,0,0,0,0,0,0,0,0,0,0,0,0
0,0,0,0,0,0,0,0,0,0,0,0,0,0,0,0,0,0,0
0,0,0,0,0,0,0,0,0,31,0,0,0,0,0,0,0,0,0
0,19,18,17,0,0,0,0,0,6,0,0,0,0,0,0,27,27,0
0,23,33,22,0,0,0,29,6,0,6,28,0,0,0,27,10,27,0
0,25,26,24,0,0,0,0,0,0,0,0,0,0,0,0,27,0,0
0,0,0,0,0,0,0,0,0,0,0,0,0,0,0,0,0,0,0
endlayer

layer
0,0,0,0,0,0,0,0,0,0,0,0,0,0,0,0,0,0,0
0,0,27,0,0,0,0,0,0,0,0,0,0,0,0,0,0,0,0
0,27,27,27,0,0,29,6,0,0,0,6,28,0,0,0,0,0,0
0,0,27,0,0,0,0,0,0,0,0,0,0,0,0,0,0,0,0
0,0,0,0,0,0,0,0,0,6,0,0,0,0,0,0,0,0,0
0,0,0,0,0,0,0,0,0,30,0,0,0,0,0,0,0,0,0
0,0,31,0,0,0,0,0,0,0,0,0,0,0,0,0,31,0,0
0,0,6,0,0,0,0,0,0,0,0,0,0,0,0,0,6,0,0
0,0,0,0,0,0,0,0,0,0,0,0,0,0,0,0,0,0,0
0,0,0,0,6,28,0,0,0,0,0,0,0,29,6,0,0,0,0
0,0,0,0,0,0,0,0,0,0,0,0,0,0,0,0,0,0,0
0,0,6,0,0,0,0,0,0,0,0,0,0,0,0,0,6,0,0
0,0,30,0,0,0,0,0,0,0,0,0,0,0,0,0,30,0,0
0,0,0,0,0,0,0,0,0,31,0,0,0,0,0,0,0,0,0
0,0,0,0,0,0,0,0,0,6,0,0,0,0,0,0,0,0,0
0,0,0,0,0,0,0,0,0,0,0,0,0,0,0,0,27,0,0
0,0,0,0,0,0,29,6,0,0,0,6,28,0,0,27,27,27,0
0,0,0,0,0,0,0,0,0,0,0,0,0,0,0,0,27,0,0
0,0,0,0,0,0,0,0,0,0,0,0,0,0,0,0,0,0,0
endlayer

layer
0,0,0,0,0,0,0,0,0,0,0,0,0,0,0,0,0,0,0
0,0,0,0,0,0,0,0,0,0,0,0,0,0,0,0,0,0,0
0,0,0,0,0,29,6,0,0,0,0,0,6,28,0,0,0,0,0
0,0,0,0,0,0,0,0,0,0,0,0,0,0,0,0,0,0,0
0,0,0,0,0,0,0,0,0,0,0,0,0,0,0,0,0,0,0
0,0,31,0,0,0,0,0,0,6,0,0,0,0,0,0,31,0,0
0,0,6,0,0,0,0,0,0,30,0,0,0,0,0,0,6,0,0
0,0,0,0,0,0,0,0,0,0,0,0,0,0,0,0,0,0,0
0,0,0,0,0,0,0,0,0,0,0,0,0,0,0,0,0,0,0
0,0,0,0,0,6,28,0,0,0,0,0,29,6,0,0,0,0,0
0,0,0,0,0,0,0,0,0,0,0,0,0,0,0,0,0,0,0
0,0,0,0,0,0,0,0,0,0,0,0,0,0,0,0,0,0,0
0,0,6,0,0,0,0,0,0,31,0,0,0,0,0,0,6,0,0
0,0,30,0,0,0,0,0,0,6,0,0,0,0,0,0,30,0,0
0,0,0,0,0,0,0,0,0,0,0,0,0,0,0,0,0,0,0
0,0,0,0,0,0,0,0,0,0,0,0,0,0,0,0,0,0,0
0,0,0,0,0,29,6,0,0,0,0,0,6,28,0,0,0,0,0
0,0,0,0,0,0,0,0,0,0,0,0,0,0,0,0,0,0,0
0,0,0,0,0,0,0,0,0,0,0,0,0,0,0,0,0,0,0
endlayer

layer
0,0,0,0,0,0,0,0,0,0,0,0,0,0,0,0,0,0,0
0,0,0,0,0,0,0,0,0,0,0,0,0,0,0,0,0,0,0
0,0,34,0,29,6,0,0,0,0,0,0,0,6,28,0,34,0,0
0,0,0,0,0,0,0,0,0,0,0,0,0,0,0,0,0,0,0
0,0,31,0,0,0,0,0,0,0,0,0,0,0,0,0,31,0,0
0,0,6,0,0,0,0,0,0,0,0,0,0,0,0,0,6,0,0
0,0,0,0,0,0,0,0,0,6,0,0,0,0,0,0,0,0,0
0,0,0,0,0,0,0,0,0,30,0,0,0,0,0,0,0,0,0
0,0,0,0,0,0,0,0,0,0,0,0,0,0,0,0,0,0,0
0,0,0,0,0,0,6,28,0,0,0,29,6,0,0,0,0,0,0
0,0,0,0,0,0,0,0,0,0,0,0,0,0,0,0,0,0,0
0,0,0,0,0,0,0,0,0,31,0,0,0,0,0,0,0,0,0
0,0,0,0,0,0,0,0,0,6,0,0,0,0,0,0,0,0,0
0,0,6,0,0,0,0,0,0,0,0,0,0,0,0,0,6,0,0
0,0,30,0,0,0,0,0,0,0,0,0,0,0,0,0,30,0,0
0,0,0,0,0,0,0,0,0,0,0,0,0,0,0,0,0,0,0
0,0,34,0,29,6,0,0,0,0,0,0,0,6,28,0,34,0,0
0,0,0,0,0,0,0,0,0,0,0,0,0,0,0,0,0,0,0
0,0,0,0,0,0,0,0,0,0,0,0,0,0,0,0,0,0,0
endlayer

layer
0,0,0,0,0,0,0,0,0,0,0,0,0,0,0,0,0,0,0
0,0,0,0,0,0,0,0,0,0,0,0,0,0,0,0,0,0,0
0,0,6,29,6,0,0,0,0,0,0,0,0,0,6,28,6,0,0
0,0,31,0,0,0,0,0,0,0,0,0,0,0,0,0,31,0,0
0,0,6,0,0,0,0,0,0,0,0,0,0,0,0,0,6,0,0
0,0,0,0,0,0,0,0,0,0,0,0,0,0,0,0,0,0,0
0,0,0,0,0,0,0,0,0,0,0,0,0,0,0,0,0,0,0
0,0,0,0,0,0,0,0,0,6,0,0,0,0,0,0,0,0,0
0,0,0,0,0,0,0,0,0,30,0,0,0,0,0,0,0,0,0
0,0,0,0,0,0,0,6,28,35,29,6,0,0,0,0,0,0,0
0,0,0,0,0,0,0,0,0,31,0,0,0,0,0,0,0,0,0
0,0,0,0,0,0,0,0,0,6,0,0,0,0,0,0,0,0,0
0,0,0,0,0,0,0,0,0,0,0,0,0,0,0,0,0,0,0
0,0,0,0,0,0,0,0,0,0,0,0,0,0,0,0,0,0,0
0,0,6,0,0,0,0,0,0,0,0,0,0,0,0,0,6,0,0
0,0,30,0,0,0,0,0,0,0,0,0,0,0,0,0,30,0,0
0,0,6,29,6,0,0,0,0,0,0,0,0,0,6,28,6,0,0
0,0,0,0,0,0,0,0,0,0,0,0,0,0,0,0,0,0,0
0,0,0,0,0,0,0,0,0,0,0,0,0,0,0,0,0,0,0
endlayer

