
# Created by Ruins mod version 14.7 Ingame Parser
# authoring Player: Barlock_James

weight=1
embed_into_distance=0
acceptable_target_blocks=
unacceptable_target_blocks=flowing_water,water,flowing_lava,lava
dimensions=30,20,17
allowable_overhang=0
max_leveling=2
leveling_buffer=0
preserve_water=0
preserve_lava=0

rule1=0,100,Thaumcraft:blockStairsArcaneStone-2
rule2=0,100,Thaumcraft:blockStairsArcaneStone-0
rule3=0,100,Thaumcraft:blockStairsArcaneStone-3
rule4=0,100,Thaumcraft:blockCosmeticSlabStone-0
rule5=0,100,minecraft:log2-0
rule6=0,100,minecraft:stained_hardened_clay-11
rule7=0,100,lootplusplus:single_entity_spawner-0
rule8=0,100,Thaumcraft:blockStairsArcaneStone-1
rule9=0,100,Natura:Natura.fence-8
rule10=0,100,EnderIO:blockDarkSteelLadder-2
rule11=0,100,Thaumcraft:blockArcaneDoor-7
rule12=0,100,Natura:trapdoor.amaranth-14
rule13=0,100,Natura:trapdoor.amaranth-12
rule14=0,100,Natura:stair.amaranth-7
rule15=0,100,Thaumcraft:blockArcaneDoor-8
rule16=0,100,Natura:trapdoor.amaranth-15
rule17=0,100,Natura:plankSlab2-0
rule18=0,100,ExtraUtilities:color_redstoneLight-10
rule19=0,100,Natura:stair.amaranth-3
rule20=0,100,Natura:plankSlab2-8
rule21=0,100,Natura:planks-8
rule22=0,100,Thaumcraft:blockAiry-3
rule23=0,100,chisel:carpet_block-2
rule24=0,100,ChestGenHook:dungeonChest:5-5
rule25=0,100,ChestGenHook:dungeonChest:5-3
rule26=0,100,IInventory;Thaumcraft:blockStoneDevice;Thaumcraft:WandCasting#1#54#0-5
rule27=0,100,ChestGenHook:dungeonChest:5-2
rule28=0,100,ChestGenHook:dungeonChest:5-4
rule29=0,100,minecraft:stained_glass-10
rule30=0,100,minecraft:wool-10
rule31=0,100,Thaumcraft:blockCosmeticOpaque-2
rule32=0,100,IInventory;BiblioCraft:BiblioTable;Thaumcraft:ItemThaumonomicon#1#0#0-0
rule33=0,100,Thaumcraft:blockArcaneDoor-1
rule34=0,100,minecraft:bed-0
rule35=0,100,minecraft:bed-8
rule36=0,100,Thaumcraft:blockCosmeticSolid-7
rule37=0,100,IInventory;BiblioCraft:BiblioTable;Thaumcraft:ItemThaumometer#1#0#0-0
rule38=0,100,IInventory;BiblioCraft:BiblioSeats;BiblioCraft:item.seatBack5#1#0#1-0
rule39=0,100,cfm:couch-3
rule40=0,100,BiblioCraft:BiblioDesk-0
rule41=0,100,chisel:arcane-4
rule42=0,100,IInventory;BiblioCraft:BookcaseFilled;minecraft:written_book#1#0#1+minecraft:written_book#1#0#4+minecraft:written_book#1#0#5+minecraft:written_book#1#0#6+minecraft:written_book#1#0#7+minecraft:written_book#1#0#8+minecraft:written_book#1#0#9+minecraft:written_book#1#0#11+minecraft:written_book#1#0#13+minecraft:written_book#1#0#14+minecraft:written_book#1#0#15-0
rule43=0,100,BiblioCraft:BiblioIronLamp-12
rule44=0,100,chisel:arcane-1
rule45=0,100,Thaumcraft:blockCosmeticSlabStone-8
rule46=0,100,Natura:stair.amaranth-4
rule47=0,100,Natura:stair.amaranth-6
rule48=0,100,Natura:stair.amaranth-5
rule49=0,100,Thaumcraft:blockAiry-1
rule50=0,100,Thaumcraft:blockTable-15
rule51=0,100,BiblioCraft:BiblioPotionShelf-0
rule52=0,100,Thaumcraft:blockJar-0
rule53=0,100,Thaumcraft:blockMetalDevice-1
rule54=0,100,minecraft:bookshelf-0
rule55=0,100,minecraft:carpet-10
rule56=0,100,minecraft:enchanting_table-0
rule57=0,100,chisel:carpet-2
rule58=0,100,Thaumcraft:blockMetalDevice-0
rule59=0,100,IInventory;Thaumcraft:blockStoneDevice;Thaumcraft:blockCustomPlant#1#1#0-1
rule60=0,100,IInventory;Thaumcraft:blockStoneDevice;Thaumcraft:blockCrystal#1#6#0-1
rule61=0,100,Thaumcraft:blockTable-7
rule62=0,100,IInventory;Thaumcraft:blockTable;Thaumcraft:ItemInkwell#1#0#0-2
rule63=0,100,chisel:bookshelf-3
rule64=0,100,IInventory;BiblioCraft:BiblioPotionShelf;minecraft:glass_bottle#64#0#4-0
rule65=0,100,chisel:bookshelf-2
rule66=0,100,IInventory;BiblioCraft:BiblioPotionShelf;Thaumcraft:ItemEssence#64#0#7-0
rule67=0,100,chisel:bookshelf-8
rule68=0,100,Natura:trapdoor.amaranth-0
rule69=0,100,minecraft:log2-8
rule70=0,100,minecraft:log2-4
rule71=0,100,Thaumcraft:blockMetalDevice-7

layer
0,0,0,0,0,0,0,0,0,0,0,0,0,0,0,0,0
0,0,0,0,0,0,0,0,0,0,0,0,0,0,0,0,0
0,0,0,0,0,0,0,0,0,0,0,0,0,0,0,0,0
0,0,0,0,0,0,0,0,0,0,0,0,0,0,0,0,0
0,0,0,0,0,3,2,1,4,3,2,1,0,0,0,0,0
0,0,0,0,0,3,5,6,6,6,5,1,0,0,0,0,0
0,0,0,0,4,6,0,0,0,0,0,6,4,0,0,0,0
0,0,2,2,6,7,0,0,0,0,0,7,6,2,2,0,0
0,0,3,5,0,0,0,0,0,0,0,0,0,5,1,0,0
0,9,8,6,0,0,0,0,0,0,0,0,0,6,8,0,0
0,0,0,11,0,0,0,0,5,10,0,0,0,6,4,0,0
0,9,2,6,0,0,0,0,0,0,0,0,0,6,2,0,0
0,0,3,5,0,0,0,0,0,0,0,0,0,5,1,0,0
0,0,8,8,6,7,0,0,0,0,0,7,6,8,8,0,0
0,0,0,0,4,6,0,0,0,0,0,6,4,0,0,0,0
0,0,0,0,0,3,5,6,6,6,5,1,0,0,0,0,0
0,0,0,0,0,8,8,1,4,3,8,1,0,0,0,0,0
0,0,0,0,0,0,0,0,0,0,0,0,0,0,0,0,0
0,0,0,0,0,0,0,0,0,0,0,0,0,0,0,0,0
0,0,0,0,0,0,0,0,0,0,0,0,0,0,0,0,0
endlayer

layer
0,0,0,0,0,0,0,0,0,0,0,0,0,0,0,0,0
0,0,0,0,0,0,0,0,0,0,0,0,0,0,0,0,0
0,0,0,0,0,0,0,0,0,0,0,0,0,0,0,0,0
0,0,0,0,0,0,0,0,0,0,0,0,0,0,0,0,0
0,0,0,0,0,0,0,12,0,12,0,0,0,0,0,0,0
0,0,0,0,0,0,5,6,9,6,5,0,0,0,0,0,0
0,0,0,0,0,6,0,0,0,0,0,6,0,0,0,0,0
0,0,0,0,6,0,0,0,0,0,0,0,6,0,0,0,0
0,0,0,5,0,0,0,0,0,0,0,0,0,5,0,0,0
0,9,14,6,0,0,0,0,0,0,0,0,0,6,13,0,0
0,0,0,15,0,0,0,0,5,10,0,0,0,9,0,0,0
0,9,14,6,0,0,0,0,0,0,0,0,0,6,13,0,0
0,0,0,5,0,0,0,0,0,0,0,0,0,5,0,0,0
0,0,0,0,6,0,0,0,0,0,0,0,6,0,0,0,0
0,0,0,0,0,6,0,0,0,0,0,6,0,0,0,0,0
0,0,0,0,0,0,5,6,9,6,5,0,0,0,0,0,0
0,0,0,0,0,0,0,16,0,16,0,0,0,0,0,0,0
0,0,0,0,0,0,0,0,0,0,0,0,0,0,0,0,0
0,0,0,0,0,0,0,0,0,0,0,0,0,0,0,0,0
0,0,0,0,0,0,0,0,0,0,0,0,0,0,0,0,0
endlayer

layer
0,0,0,0,0,0,0,0,0,0,0,0,0,0,0,0,0
0,0,0,0,0,0,0,0,0,0,0,0,0,0,0,0,0
0,0,0,0,0,0,0,0,0,0,0,0,0,0,0,0,0
0,0,0,0,0,0,0,0,0,0,0,0,0,0,0,0,0
0,0,0,0,0,0,0,12,0,12,0,0,0,0,0,0,0
0,0,0,0,0,0,5,6,9,6,5,0,0,0,0,0,0
0,0,0,0,0,6,0,0,0,0,0,6,0,0,0,0,0
0,0,0,0,6,0,0,0,0,0,0,0,6,0,0,0,0
0,0,0,5,0,0,0,0,0,0,0,0,0,5,0,0,0
0,17,17,6,0,0,0,0,0,0,0,0,0,6,13,0,0
0,17,19,18,0,0,0,0,5,10,0,0,0,9,0,0,0
0,17,17,6,0,0,0,0,0,0,0,0,0,6,13,0,0
0,0,0,5,0,0,0,0,0,0,0,0,0,5,0,0,0
0,0,0,0,6,0,0,0,0,0,0,0,6,0,0,0,0
0,0,0,0,0,6,0,0,0,0,0,6,0,0,0,0,0
0,0,0,0,0,0,5,6,9,6,5,0,0,0,0,0,0
0,0,0,0,0,0,0,16,0,16,0,0,0,0,0,0,0
0,0,0,0,0,0,0,0,0,0,0,0,0,0,0,0,0
0,0,0,0,0,0,0,0,0,0,0,0,0,0,0,0,0
0,0,0,0,0,0,0,0,0,0,0,0,0,0,0,0,0
endlayer

layer
0,0,0,0,0,0,0,0,0,0,0,0,0,0,0,0,0
0,0,0,0,0,0,0,0,0,0,0,0,0,0,0,0,0
0,0,0,0,0,0,0,0,0,0,0,0,0,0,0,0,0
0,0,0,0,0,0,0,0,0,0,0,0,0,0,0,0,0
0,0,0,0,0,0,0,0,0,0,0,0,0,0,0,0,0
0,0,0,0,0,0,5,6,6,6,5,0,0,0,0,0,0
0,0,0,0,0,6,20,20,20,20,20,6,0,0,0,0,0
0,0,0,0,6,18,20,20,20,20,20,18,6,0,0,0,0
0,0,0,5,20,20,20,20,20,20,20,20,20,5,0,0,0
0,0,0,6,20,20,20,20,20,20,20,20,20,6,0,0,0
0,0,0,21,20,20,20,20,5,10,20,20,20,6,0,0,0
0,0,0,6,20,20,20,20,20,20,20,20,20,6,0,0,0
0,0,0,5,20,20,20,20,20,20,20,20,20,5,0,0,0
0,0,0,0,6,18,20,20,20,20,20,18,6,0,0,0,0
0,0,0,0,0,6,20,20,20,20,20,6,0,0,0,0,0
0,0,0,0,0,0,5,6,6,6,5,0,0,0,0,0,0
0,0,0,0,0,0,0,0,0,0,0,0,0,0,0,0,0
0,0,0,0,0,0,0,0,0,0,0,0,0,0,0,0,0
0,0,0,0,0,0,0,0,0,0,0,0,0,0,0,0,0
0,0,0,0,0,0,0,0,0,0,0,0,0,0,0,0,0
endlayer

layer
0,0,0,0,0,0,0,0,0,0,0,0,0,0,0,0,0
0,0,0,0,0,0,0,0,0,0,0,0,0,0,0,0,0
0,0,0,0,0,0,22,0,0,0,0,0,0,0,0,0,0
0,0,0,0,0,0,0,0,0,0,0,0,0,0,0,0,0
0,22,0,0,0,0,0,0,0,0,0,0,0,0,0,0,0
0,0,0,0,0,0,5,6,6,6,5,0,0,0,0,0,0
0,0,0,0,0,6,6,6,6,6,6,6,0,22,0,0,0
0,0,0,0,6,6,23,23,23,23,23,6,6,0,0,0,0
0,0,0,5,6,23,23,23,23,23,23,23,6,5,0,0,0
0,0,0,6,6,23,23,23,23,23,23,23,6,6,0,0,0
0,0,0,21,6,23,23,23,5,10,23,23,6,6,0,0,0
0,0,0,6,6,23,23,23,23,23,23,23,6,6,0,0,0
0,0,0,5,6,23,23,23,23,23,23,23,6,5,0,0,0
0,22,0,0,6,6,23,23,23,23,23,6,6,0,0,0,0
0,0,0,0,0,6,6,6,6,6,6,6,22,0,0,0,0
0,0,0,0,0,0,5,6,6,6,5,0,0,0,0,0,0
0,0,0,0,0,0,22,0,0,0,0,0,0,0,0,0,0
0,0,0,0,0,0,0,0,0,0,0,0,0,0,0,0,0
0,0,0,0,0,0,0,0,0,0,0,0,0,0,0,0,0
0,0,0,0,0,0,0,0,0,0,0,0,0,0,0,22,0
endlayer

layer
0,0,0,0,0,0,0,0,0,0,0,0,0,0,0,0,0
0,0,0,0,0,0,0,0,0,0,0,0,0,0,0,0,0
0,0,0,0,0,0,0,0,0,0,0,0,0,0,0,0,0
0,0,0,0,0,0,0,0,0,0,0,0,0,0,0,0,0
0,0,0,0,0,0,0,0,0,0,0,0,0,0,0,0,0
0,0,0,0,0,0,9,0,0,0,9,0,0,0,0,0,0
0,0,0,0,0,0,6,5,21,5,6,0,0,0,0,0,0
0,0,0,0,0,6,0,0,24,0,0,6,0,0,0,0,0
0,0,0,9,6,0,0,0,0,0,0,0,6,9,0,0,0
0,0,0,0,5,0,0,0,0,0,0,0,5,0,0,0,0
0,0,0,0,21,27,0,26,5,10,0,25,21,0,0,0,0
0,0,0,0,5,0,0,0,0,0,0,0,5,0,0,0,0
0,0,0,9,6,0,0,0,0,0,0,0,6,9,0,0,0
0,0,0,0,0,6,0,0,28,0,0,6,0,0,0,0,0
0,0,0,0,0,0,6,5,21,5,6,0,0,0,0,0,0
0,0,0,0,0,0,9,0,0,0,9,0,0,0,0,0,0
0,0,0,0,0,0,0,0,0,0,0,0,0,0,0,0,0
0,0,0,0,0,0,0,0,0,0,0,0,0,0,0,0,0
0,0,0,0,0,0,0,0,0,0,0,0,0,0,0,0,0
0,0,0,0,0,0,0,0,0,0,0,0,0,0,0,0,0
endlayer

layer
0,0,0,0,0,0,0,0,0,0,0,0,0,0,0,0,0
0,0,0,0,0,0,0,0,0,0,0,0,0,0,0,0,0
0,0,0,0,0,0,0,0,0,0,0,0,0,0,0,0,0
0,0,0,0,0,0,0,0,0,0,0,0,0,0,0,0,0
0,0,0,0,0,0,0,0,0,0,0,0,0,0,0,0,0
0,0,0,0,0,0,0,0,0,0,0,0,0,0,0,0,0
0,0,0,0,0,0,6,5,29,5,6,0,0,0,0,0,0
0,0,0,0,0,6,0,0,0,0,0,6,0,0,0,0,0
0,0,0,0,6,0,0,0,0,0,0,0,6,0,0,0,0
0,0,0,0,5,0,0,0,0,0,0,0,5,0,0,0,0
0,0,0,0,29,0,0,0,5,10,0,0,29,0,0,0,0
0,0,0,0,5,0,0,0,0,0,0,0,5,0,0,0,0
0,0,0,0,6,0,0,0,0,0,0,0,6,0,0,0,0
0,0,0,0,0,6,0,0,0,0,0,6,0,0,0,0,0
0,0,0,0,0,0,6,5,29,5,6,0,0,0,0,0,0
0,0,0,0,0,0,0,0,0,0,0,0,0,0,0,0,0
0,0,0,0,0,0,0,0,0,0,0,0,0,0,0,0,0
0,0,0,0,0,0,0,0,0,0,0,0,0,0,0,0,0
0,0,0,0,0,0,0,0,0,0,0,0,0,0,0,0,0
0,0,0,0,0,0,0,0,0,0,0,0,0,0,0,0,0
endlayer

layer
0,0,0,0,0,0,0,0,0,0,0,0,0,0,0,0,0
0,0,0,0,0,0,0,0,0,0,0,0,0,0,0,0,0
0,0,0,0,0,0,0,0,0,0,0,0,0,0,0,0,0
0,0,0,0,0,0,0,0,0,0,0,0,0,0,0,0,0
0,0,0,0,0,0,0,0,0,0,0,0,0,0,0,0,0
0,0,0,0,0,0,0,0,0,0,0,0,0,0,0,0,0
0,0,0,0,0,0,6,5,29,5,6,0,0,0,0,0,0
0,0,0,0,0,6,0,0,0,0,0,6,0,0,0,0,0
0,0,0,0,6,0,0,0,0,0,0,0,6,0,0,0,0
0,0,0,0,5,0,0,0,0,0,0,0,5,0,0,0,0
0,0,0,0,29,0,0,7,5,10,0,0,29,0,0,0,0
0,0,0,0,5,0,0,0,0,0,0,0,5,0,0,0,0
0,0,0,0,6,0,0,0,0,0,0,0,6,0,0,0,0
0,0,0,0,0,6,0,0,0,0,0,6,0,0,0,0,0
0,0,0,0,0,0,6,5,29,5,6,0,0,0,0,0,0
0,0,0,0,0,0,0,0,0,0,0,0,0,0,0,0,0
0,0,0,0,0,0,0,0,0,0,0,0,0,0,0,0,0
0,0,0,0,0,0,0,0,0,0,0,0,0,0,0,0,0
0,0,0,0,0,0,0,0,0,0,0,0,0,0,0,0,0
0,0,0,0,0,0,0,0,0,0,0,0,0,0,0,0,0
endlayer

layer
0,0,0,0,0,0,0,0,0,0,0,0,0,0,0,0,0
0,0,0,0,0,0,0,0,0,0,0,0,0,0,0,0,0
0,0,0,0,0,0,0,0,0,0,0,0,0,0,0,0,0
0,0,0,0,0,0,0,0,0,0,0,0,0,0,0,0,0
0,0,0,0,0,0,0,0,0,0,0,0,0,0,0,0,0
0,0,0,0,0,0,0,0,0,0,0,0,0,0,0,0,0
0,0,0,0,0,0,6,5,21,5,6,0,0,0,0,0,0
0,0,0,0,0,6,20,20,20,20,20,6,0,0,0,0,0
0,0,0,0,6,20,20,20,20,20,20,20,6,0,0,0,0
0,0,0,0,5,20,20,20,18,20,20,20,5,0,0,0,0
0,0,0,0,21,20,20,18,5,10,20,20,21,0,0,0,0
0,0,0,0,5,20,20,20,18,20,20,20,5,0,0,0,0
0,0,0,0,6,20,20,20,20,20,20,20,6,0,0,0,0
0,0,0,0,0,6,20,20,20,20,20,6,0,0,0,0,0
0,0,0,0,0,0,6,5,21,5,6,0,0,0,0,0,0
0,0,0,0,0,0,0,0,0,0,0,0,0,0,0,0,0
0,0,0,0,0,0,0,0,0,0,0,0,0,0,0,0,0
0,0,0,0,0,0,0,0,0,0,0,0,0,0,0,0,0
0,0,0,0,0,0,0,0,0,0,0,0,0,0,0,0,0
0,0,0,0,0,0,0,0,0,0,0,0,0,0,0,0,0
endlayer

layer
0,0,0,0,0,0,0,0,0,0,0,0,0,0,0,0,0
0,0,0,0,0,0,0,0,0,0,0,0,0,0,0,0,0
0,0,0,0,0,0,0,0,0,0,0,0,0,0,0,0,0
0,0,0,0,0,0,0,0,0,0,0,0,0,0,0,0,0
0,0,0,0,0,0,0,0,0,0,0,0,0,0,0,0,0
0,0,0,0,0,0,0,0,0,0,0,0,0,0,0,0,0
0,0,0,0,0,0,6,5,21,5,6,0,0,0,0,0,0
0,0,0,0,0,6,30,30,30,30,30,6,0,0,0,0,0
0,0,0,0,6,30,30,30,30,30,30,30,6,0,0,0,0
0,0,0,0,5,30,30,30,30,30,30,30,5,0,0,0,0
0,0,0,0,21,30,30,30,5,10,30,30,21,0,0,0,0
0,0,0,0,5,30,30,30,30,30,30,30,5,0,0,0,0
0,0,0,0,6,30,30,30,30,30,30,30,6,0,0,0,0
0,0,0,0,0,6,30,30,30,30,30,6,0,0,0,0,0
0,0,0,0,0,0,6,5,21,5,6,0,0,0,0,0,0
0,0,0,0,0,0,0,0,0,0,0,0,0,0,0,0,0
0,0,0,0,0,0,0,0,0,0,0,0,0,0,0,0,0
0,0,0,0,0,0,0,0,0,0,0,0,0,0,0,0,0
0,0,0,0,0,0,0,0,0,0,0,0,0,0,0,0,0
0,0,0,0,0,0,0,0,0,0,0,0,0,0,0,0,0
endlayer

layer
0,0,0,0,0,0,0,0,0,0,0,0,0,0,0,0,0
0,0,0,0,0,0,0,0,0,0,0,0,0,0,0,0,0
0,0,0,0,0,0,0,0,0,0,0,0,0,0,0,0,0
0,0,0,0,0,0,0,0,0,0,0,0,0,0,0,0,0
0,0,0,0,0,0,0,0,0,0,0,0,0,0,0,0,0
0,0,0,0,0,0,0,0,0,0,0,0,0,0,0,0,0
0,0,0,0,0,0,6,5,21,5,6,0,0,0,0,0,0
0,0,0,0,0,6,0,0,31,0,0,6,0,0,0,0,0
0,0,0,0,6,27,0,0,33,0,0,32,6,0,0,0,0
0,0,0,0,5,27,0,0,31,0,0,0,5,0,0,0,0
0,0,0,0,21,35,34,0,5,10,0,0,21,0,0,0,0
0,0,0,0,5,27,0,0,36,0,0,0,5,0,0,0,0
0,0,0,0,6,27,38,0,36,0,0,37,6,0,0,0,0
0,0,0,0,0,6,40,0,36,39,39,6,0,0,0,0,0
0,0,0,0,0,0,6,5,21,5,6,0,0,0,0,0,0
0,0,0,0,0,0,0,0,0,0,0,0,0,0,0,0,0
0,0,0,0,0,0,0,0,0,0,0,0,0,0,0,0,0
0,0,0,0,0,0,0,0,0,0,0,0,0,0,0,0,0
0,0,0,0,0,0,0,0,0,0,0,0,0,0,0,0,0
0,0,0,0,0,0,0,0,0,0,0,0,0,0,0,0,0
endlayer

layer
0,0,0,0,0,0,0,0,0,0,0,0,0,0,0,0,0
0,0,0,0,0,0,0,0,0,0,0,0,0,0,0,0,0
0,0,0,0,0,0,0,0,0,0,0,0,0,0,0,0,0
0,0,0,0,0,0,0,0,0,0,0,0,0,0,0,0,0
0,0,0,0,0,0,0,0,0,0,0,0,0,0,0,0,0
0,0,0,0,0,0,0,0,0,0,0,0,0,0,0,0,0
0,0,0,0,0,0,6,5,21,5,6,0,0,0,0,0,0
0,0,0,0,0,6,0,0,31,0,0,6,0,0,0,0,0
0,0,0,0,6,0,0,0,15,0,0,0,6,0,0,0,0
0,0,0,0,5,0,0,0,31,0,0,0,5,0,0,0,0
0,0,0,0,21,0,0,0,5,10,0,0,29,0,0,0,0
0,0,0,0,5,0,0,0,36,0,0,0,5,0,0,0,0
0,0,0,0,6,0,0,0,41,0,0,0,6,0,0,0,0
0,0,0,0,0,6,42,0,36,0,0,6,0,0,0,0,0
0,0,0,0,0,0,6,5,21,5,6,0,0,0,0,0,0
0,0,0,0,0,0,0,0,0,0,0,0,0,0,0,0,0
0,0,0,0,0,0,0,0,0,0,0,0,0,0,0,0,0
0,0,0,0,0,0,0,0,0,0,0,0,0,0,0,0,0
0,0,0,0,0,0,0,0,0,0,0,0,0,0,0,0,0
0,0,0,0,0,0,0,0,0,0,0,0,0,0,0,0,0
endlayer

layer
0,0,0,0,0,0,0,0,0,0,0,0,0,0,0,0,0
0,0,0,0,0,0,0,0,0,0,0,0,0,0,0,0,0
0,0,0,0,0,0,0,0,0,0,0,0,0,0,0,0,0
0,0,0,0,0,0,0,0,0,0,0,0,0,0,0,0,0
0,0,0,0,0,0,0,0,0,0,0,0,0,0,0,0,0
0,0,0,0,0,0,0,0,0,0,0,0,0,0,0,0,0
0,0,0,0,0,0,6,5,21,5,6,0,0,0,0,0,0
0,0,0,0,0,6,0,0,31,0,0,6,0,0,0,0,0
0,0,0,0,6,0,0,0,31,0,0,0,6,0,0,0,0
0,0,0,0,5,0,0,0,31,0,0,0,5,0,0,0,0
0,0,0,0,21,43,0,0,5,10,0,0,29,0,0,0,0
0,0,0,0,5,0,0,0,36,0,0,0,5,0,0,0,0
0,0,0,0,6,0,0,0,44,0,0,0,6,0,0,0,0
0,0,0,0,0,6,0,0,36,0,0,6,0,0,0,0,0
0,0,0,0,0,0,6,5,21,5,6,0,0,0,0,0,0
0,0,0,0,0,0,0,0,0,0,0,0,0,0,0,0,0
0,0,0,0,0,0,0,0,0,0,0,0,0,0,0,0,0
0,0,0,0,0,0,0,0,0,0,0,0,0,0,0,0,0
0,0,0,0,0,0,0,0,0,0,0,0,0,0,0,0,0
0,0,0,0,0,0,0,0,0,0,0,0,0,0,0,0,0
endlayer

layer
0,0,0,0,0,0,0,0,0,0,0,0,0,0,0,0,0
0,0,0,0,0,0,0,0,0,0,0,0,0,0,0,0,0
0,0,0,0,0,0,0,0,0,0,0,0,0,0,0,0,0
0,0,0,0,0,0,0,0,0,0,0,0,0,0,0,0,0
0,0,0,0,0,0,0,0,0,0,0,0,0,0,0,0,0
0,0,0,0,0,0,0,0,0,0,0,0,0,0,0,0,0
0,0,0,0,0,0,6,5,21,5,6,0,0,0,0,0,0
0,0,0,0,0,6,0,0,31,0,0,6,0,0,0,0,0
0,0,0,0,6,0,0,0,31,0,0,0,6,0,0,0,0
0,0,0,0,5,0,0,0,31,0,0,0,5,0,0,0,0
0,0,0,0,21,0,0,0,5,10,0,0,21,0,0,0,0
0,0,0,0,5,0,0,0,36,0,0,0,5,0,0,0,0
0,0,0,0,6,0,0,0,36,0,0,0,6,0,0,0,0
0,0,0,0,0,6,0,0,36,0,0,6,0,0,0,0,0
0,0,0,0,0,0,6,5,21,5,6,0,0,0,0,0,0
0,0,0,0,0,0,0,0,0,0,0,0,0,0,0,0,0
0,0,0,0,0,0,0,0,0,0,0,0,0,0,0,0,0
0,0,0,0,0,0,0,0,0,0,0,0,0,0,0,0,0
0,0,0,0,0,0,0,0,0,0,0,0,0,0,0,0,0
0,0,0,0,0,0,0,0,0,0,0,0,0,0,0,0,0
endlayer

layer
0,0,0,0,0,0,0,0,0,0,0,0,0,0,0,0,0
0,0,0,0,0,0,0,0,0,0,0,0,0,0,0,0,0
0,0,0,0,0,0,0,0,0,0,0,0,0,0,0,0,0
0,0,0,0,0,0,0,0,0,0,0,0,0,0,0,0,0
0,0,0,0,0,0,0,0,0,0,0,0,0,0,0,0,0
0,0,0,0,0,0,45,45,46,45,45,0,0,0,0,0,0
0,0,0,0,0,45,6,5,6,5,6,45,0,0,0,0,0
0,0,0,0,45,6,0,0,31,0,0,6,45,0,0,0,0
0,0,0,45,6,0,0,0,31,0,0,0,6,45,0,0,0
0,0,0,45,5,0,0,0,31,0,0,0,5,45,0,0,0
0,0,0,14,6,0,0,0,5,10,0,0,6,47,0,0,0
0,0,0,45,5,0,0,0,36,0,0,0,5,45,0,0,0
0,0,0,45,6,0,0,0,36,0,0,0,6,45,0,0,0
0,0,0,0,45,6,0,0,36,0,0,6,45,0,0,0,0
0,0,0,0,0,45,6,5,6,5,6,45,0,0,0,0,0
0,0,0,0,0,0,45,45,48,45,45,0,0,0,0,0,0
0,0,0,0,0,0,0,0,0,0,0,0,0,0,0,0,0
0,0,0,0,0,0,0,0,0,0,0,0,0,0,0,0,0
0,0,0,0,0,0,0,0,0,0,0,0,0,0,0,0,0
0,0,0,0,0,0,0,0,0,0,0,0,0,0,0,0,0
endlayer

layer
0,0,0,0,0,0,0,0,0,0,0,0,0,0,0,0,0
0,0,0,0,0,0,0,0,0,0,0,0,0,0,0,0,0
0,0,0,0,0,0,0,0,0,0,0,0,0,0,0,0,0
0,0,0,0,0,0,0,0,0,0,0,0,0,0,0,0,0
0,0,0,0,0,0,0,0,0,0,0,0,0,0,0,0,0
0,0,0,0,0,0,6,6,21,6,6,0,0,0,0,0,0
0,0,0,0,0,6,6,5,6,5,6,6,0,0,0,0,0
0,0,0,0,6,18,20,20,20,20,20,18,6,0,0,0,0
0,0,0,6,6,20,20,20,7,20,20,20,6,6,0,0,0
0,0,0,6,5,20,20,20,20,20,20,20,5,6,0,0,0
0,0,0,21,6,20,20,20,5,10,20,20,6,21,0,0,0
0,0,0,6,5,20,20,20,20,20,20,20,5,6,0,0,0
0,0,0,6,6,20,20,20,7,20,20,20,6,6,0,0,0
0,0,0,0,6,18,20,20,20,20,20,18,6,0,0,0,0
0,0,0,0,0,6,6,5,6,5,6,6,0,0,0,0,0
0,0,0,0,0,0,6,6,21,6,6,0,0,0,0,0,0
0,0,0,0,0,0,0,0,22,0,0,0,0,0,0,0,0
0,0,0,0,0,0,0,0,0,0,0,0,0,0,0,0,0
0,0,0,0,0,0,0,0,0,0,0,0,0,0,0,0,0
0,0,0,0,0,0,0,0,0,0,0,0,0,0,0,0,0
endlayer

layer
0,0,0,0,0,0,0,0,0,0,0,0,0,0,0,0,0
0,0,0,0,0,0,0,0,0,0,0,0,0,0,0,0,0
0,0,0,0,0,0,0,0,0,0,0,0,0,0,0,0,0
0,0,0,0,0,0,0,0,0,0,0,0,0,0,0,0,0
0,0,0,0,0,0,0,0,46,0,0,0,0,0,0,0,0
0,0,0,0,0,0,6,5,5,5,6,0,0,0,0,0,0
0,0,0,0,0,5,23,23,23,23,23,5,0,0,0,0,0
0,0,0,0,5,23,23,23,23,23,23,23,5,0,0,0,0
0,0,0,6,23,23,23,23,23,23,23,23,30,6,0,0,0
0,0,0,5,23,23,30,30,30,21,23,23,30,5,0,0,0
0,0,14,49,23,23,30,30,5,10,21,23,23,5,47,0,0
0,0,0,5,23,23,30,30,30,21,23,23,30,5,0,0,0
0,0,0,6,23,23,23,23,23,23,23,23,30,6,0,0,0
0,0,0,0,5,23,23,23,23,23,23,30,5,0,0,0,0
0,0,0,0,0,5,23,23,23,23,23,5,0,0,0,0,0
0,0,0,0,0,0,6,5,5,5,6,0,0,0,0,0,0
0,0,0,0,0,0,0,0,48,0,0,0,0,0,0,0,0
0,0,0,0,0,0,0,0,0,0,0,0,0,0,0,0,0
0,0,0,0,0,0,0,0,0,0,0,0,0,0,0,0,0
0,0,0,0,0,0,0,0,0,0,0,0,0,0,0,0,0
endlayer

layer
0,0,0,0,0,0,0,0,0,0,0,0,0,0,0,0,0
0,0,0,0,0,0,0,0,0,0,0,0,0,0,0,0,0
0,0,0,0,0,0,0,0,0,0,0,0,0,0,0,0,0
0,0,0,0,0,0,0,0,0,0,0,0,0,0,0,0,0
0,0,0,0,0,0,0,0,5,0,0,0,0,0,0,0,0
0,0,0,0,0,0,5,5,50,5,5,0,0,0,0,0,0
0,0,0,0,0,5,52,0,0,0,51,5,0,0,0,0,0
0,0,0,0,5,53,0,0,0,0,0,51,5,0,0,0,0
0,0,0,5,52,0,0,0,0,0,0,22,54,5,0,0,0
0,0,0,5,0,0,0,0,0,55,0,0,54,5,0,0,0
0,0,5,58,0,0,0,0,5,10,57,0,0,56,5,0,0
0,0,0,5,0,0,0,0,0,55,0,0,54,5,0,0,0
0,0,0,5,0,0,0,0,0,0,0,0,54,5,0,0,0
0,0,0,0,5,7,0,0,0,0,0,59,5,0,0,0,0
0,0,0,0,0,5,62,61,0,0,60,5,0,0,0,0,0
0,0,0,0,0,0,5,5,63,5,5,0,0,0,0,0,0
0,0,0,0,0,0,0,0,5,0,0,0,0,0,0,0,0
0,0,0,0,0,0,0,0,0,0,0,0,0,0,0,0,0
0,0,0,0,0,0,0,0,0,0,0,0,0,0,0,0,0
0,0,0,0,0,0,0,0,0,0,0,0,0,0,0,0,0
endlayer

layer
0,0,0,0,0,0,0,0,0,0,0,0,0,0,0,0,0
0,0,0,0,0,0,0,0,0,0,0,0,0,0,0,0,0
0,0,0,0,0,0,0,0,0,0,0,0,0,0,0,0,0
0,0,0,0,0,0,0,0,0,0,0,0,0,0,0,0,0
0,0,0,0,0,0,0,0,5,0,0,0,0,0,0,0,0
0,0,0,0,0,0,6,29,0,29,6,0,0,0,0,0,0
0,0,0,0,0,5,52,0,0,0,51,5,0,0,0,0,0
0,0,0,0,5,53,0,0,0,0,0,64,5,0,0,0,0
0,0,0,6,52,0,0,0,0,0,0,0,54,6,0,0,0
0,0,0,29,0,0,0,0,0,0,0,0,55,29,0,0,0
0,0,5,0,0,0,0,0,5,10,0,0,0,0,5,0,0
0,0,0,29,0,0,0,0,0,0,0,0,55,29,0,0,0
0,0,0,6,0,0,0,0,0,0,0,0,54,6,0,0,0
0,0,0,0,5,0,0,0,0,0,0,0,5,0,0,0,0
0,0,0,0,0,5,0,0,0,0,0,5,0,0,0,0,0
0,0,0,0,0,0,6,29,65,29,6,0,0,0,0,0,0
0,0,0,0,0,0,0,0,5,0,0,0,0,0,0,0,0
0,0,0,0,0,0,0,0,0,0,0,0,0,0,0,0,0
0,0,0,0,0,0,0,0,0,0,0,0,0,0,0,0,0
0,0,0,0,0,0,0,0,0,0,0,0,0,0,0,0,0
endlayer

layer
0,0,0,0,0,0,0,0,0,0,0,0,0,0,0,0,0
0,0,0,0,0,0,0,0,0,0,0,0,0,0,0,0,0
0,0,0,0,0,0,0,0,0,0,0,0,0,0,0,0,0
0,0,0,0,0,0,0,0,0,0,0,0,0,0,0,0,0
0,0,0,0,0,0,0,0,5,0,0,0,0,0,0,0,0
0,0,0,0,0,0,6,29,0,29,6,0,0,0,0,0,0
0,0,0,0,0,5,52,0,0,0,66,5,0,0,0,0,0
0,0,0,0,5,53,0,0,0,0,0,51,5,0,0,0,0
0,0,0,6,52,0,0,0,0,0,0,0,54,6,0,0,0
0,0,0,29,0,0,0,0,0,0,0,0,0,29,0,0,0
0,0,5,0,0,0,0,0,5,10,0,0,0,0,5,0,0
0,0,0,29,0,0,0,0,0,0,0,0,0,29,0,0,0
0,0,0,6,0,0,0,0,0,0,0,0,54,6,0,0,0
0,0,0,0,5,0,0,0,0,0,0,0,5,0,0,0,0
0,0,0,0,0,5,0,0,0,0,0,5,0,0,0,0,0
0,0,0,0,0,0,6,29,67,29,6,0,0,0,0,0,0
0,0,0,0,0,0,0,0,5,0,0,0,0,0,0,0,0
0,0,0,0,0,0,0,0,0,0,0,0,0,0,0,0,0
0,0,0,0,0,0,0,0,0,0,0,0,0,0,0,0,0
0,0,0,0,0,0,0,0,0,0,0,0,0,0,0,0,0
endlayer

layer
0,0,0,0,0,0,0,0,0,0,0,0,0,0,0,0,0
0,0,0,0,0,0,0,0,0,0,0,0,0,0,0,0,0
0,0,0,0,0,0,0,0,0,0,0,0,0,0,0,0,0
0,0,0,0,0,0,0,0,0,0,0,0,0,0,0,0,0
0,0,0,0,0,0,0,0,5,0,0,0,0,0,0,0,0
0,0,0,0,0,0,5,5,18,5,5,0,0,0,0,0,0
0,0,0,0,0,5,0,0,0,0,0,5,0,0,0,0,0
0,0,0,0,5,0,0,0,0,0,0,0,5,0,0,0,0
0,0,0,5,0,0,0,0,0,0,0,0,54,5,0,0,0
0,0,0,5,0,0,0,0,0,0,0,0,54,5,0,0,0
0,0,5,18,0,0,0,0,5,10,0,0,54,18,5,0,0
0,0,0,5,0,0,0,0,0,0,0,0,54,5,0,0,0
0,0,0,5,0,0,0,0,0,0,0,0,54,5,0,0,0
0,0,0,0,5,0,0,0,0,0,0,0,5,0,0,0,0
0,0,0,0,0,5,0,0,0,0,0,5,0,0,0,0,0
0,0,0,0,0,0,5,5,18,5,5,0,0,0,0,0,0
0,0,0,0,0,0,0,0,5,0,0,0,0,0,0,0,0
0,0,0,0,0,0,0,0,0,0,0,0,0,0,0,0,0
0,0,0,0,0,0,0,0,0,0,0,0,0,0,0,0,0
0,0,0,0,0,0,0,0,0,0,0,0,0,0,0,0,0
endlayer

layer
0,0,0,0,0,0,0,0,0,0,0,0,0,0,0,0,0
0,0,0,0,0,0,0,0,0,0,0,0,0,0,0,0,0
0,0,0,0,0,0,0,0,0,0,0,0,0,0,0,0,0
0,0,0,0,0,0,0,0,0,0,0,0,0,0,0,0,0
0,0,0,0,0,2,2,2,2,2,2,1,0,0,0,0,0
0,0,0,0,2,3,5,5,5,5,5,2,1,0,0,0,0
0,0,0,2,3,5,0,0,0,0,0,5,2,1,0,0,0
0,0,2,3,5,0,0,0,0,0,0,0,5,2,1,0,0
0,0,3,5,0,0,0,0,0,0,0,0,0,5,1,0,0
0,0,3,5,0,0,0,0,0,0,0,0,0,5,1,0,0
0,0,3,5,0,0,0,0,5,10,0,0,0,5,1,0,0
0,0,3,5,0,0,0,0,0,0,0,0,0,5,1,0,0
0,0,3,5,0,0,0,0,0,0,0,22,0,5,1,0,0
0,0,8,8,5,0,0,0,0,0,0,0,5,1,8,0,0
0,0,0,3,8,5,0,0,0,0,0,5,1,8,0,0,0
0,0,0,0,3,8,5,5,5,5,5,1,8,0,0,0,0
0,0,0,0,0,3,8,8,8,8,8,8,0,0,0,0,0
0,0,0,0,0,0,0,0,0,0,0,0,0,0,0,0,0
0,0,0,0,0,0,0,0,0,0,0,0,0,0,0,0,0
0,0,0,0,0,0,0,0,0,0,0,0,0,0,0,0,0
endlayer

layer
0,0,0,0,0,0,0,0,0,0,0,0,0,0,0,0,0
0,0,0,0,0,0,0,0,0,0,0,0,0,0,0,0,0
0,0,0,0,0,0,0,0,0,0,0,0,0,0,0,0,0
0,0,0,0,0,0,0,0,0,0,0,0,0,0,0,0,0
0,0,0,0,0,0,0,0,0,0,0,0,0,0,0,0,0
0,0,0,0,0,0,2,2,2,2,1,0,0,0,0,0,0
0,0,0,0,0,2,3,47,48,48,2,1,0,0,0,0,0
0,0,0,0,2,3,47,48,0,14,48,2,1,0,0,0,0
0,0,0,2,3,47,48,0,0,0,14,48,2,1,0,0,0
0,0,0,3,47,48,0,0,0,0,0,14,48,1,0,0,0
0,0,0,3,47,0,0,0,5,10,0,0,14,1,0,0,0
0,0,0,3,47,47,0,0,0,0,0,46,14,1,0,0,0
0,0,0,3,8,46,47,0,0,0,46,14,1,8,0,0,0
0,0,0,0,3,8,46,47,0,46,14,1,8,0,0,0,0
0,0,0,0,0,3,8,46,46,14,1,8,0,0,0,0,0
0,0,0,0,0,0,3,8,8,8,8,0,0,0,0,0,0
0,0,0,0,0,0,0,0,0,0,0,0,0,0,0,0,0
0,0,0,0,0,0,0,0,0,0,0,0,0,0,0,0,0
0,0,0,0,0,0,0,0,0,0,0,0,0,0,0,0,0
0,0,0,0,0,0,0,0,0,0,0,0,0,0,0,0,0
endlayer

layer
0,0,0,0,0,0,0,0,0,0,0,0,0,0,0,0,0
0,0,0,0,0,0,0,0,0,0,0,0,0,0,0,0,0
0,0,0,0,0,0,0,0,0,0,0,0,0,0,0,0,0
0,0,0,0,0,0,0,0,0,0,0,0,0,0,0,0,0
0,0,0,0,0,0,0,0,0,0,0,0,0,0,0,0,0
0,0,0,0,0,0,0,0,0,0,0,0,0,0,0,0,0
0,0,0,0,0,0,0,2,2,1,0,0,0,0,0,0,0
0,0,0,0,0,0,2,3,48,2,1,0,0,0,0,0,0
0,0,0,0,0,2,3,48,20,48,2,1,0,0,0,0,0
0,0,0,0,2,3,47,20,20,20,14,2,2,0,0,0,0
0,0,0,0,3,47,20,20,5,10,20,14,1,0,0,0,0
0,0,0,0,8,8,47,20,20,20,14,1,8,0,0,0,0
0,0,0,0,0,3,8,46,20,46,1,8,0,0,0,0,0
0,0,0,0,22,0,3,8,46,1,8,0,0,0,0,0,0
0,0,0,0,0,0,0,3,8,1,0,0,0,0,0,0,0
0,0,0,0,0,0,0,0,0,0,0,0,0,0,0,0,0
0,0,0,0,0,0,0,0,0,0,0,0,0,0,0,0,0
0,0,0,0,0,0,0,0,0,0,0,0,0,0,0,0,0
0,0,0,0,0,0,0,0,0,0,0,0,0,0,0,0,0
0,0,0,0,0,0,0,0,0,0,0,0,0,0,0,0,0
endlayer

layer
0,0,0,0,0,0,0,0,0,0,0,0,0,0,0,0,0
0,0,0,0,0,0,0,0,0,0,0,0,0,0,0,0,0
0,0,0,0,0,0,0,0,0,0,0,0,0,0,0,0,0
0,0,0,0,0,0,0,0,0,0,0,0,0,0,0,0,0
0,0,0,0,0,0,0,0,0,0,0,0,0,0,0,0,0
0,0,0,0,0,0,0,0,0,0,0,0,0,0,0,0,0
0,0,0,0,0,0,0,0,0,0,0,0,0,0,0,0,0
0,0,0,0,0,0,0,9,5,9,0,0,0,0,0,0,0
0,0,0,0,0,0,9,5,7,5,9,0,0,0,0,0,0
0,0,0,0,0,9,5,0,0,0,5,9,0,0,0,0,0
0,0,0,0,0,5,7,0,5,68,7,5,0,0,0,0,0
0,0,0,0,0,9,5,0,0,0,5,9,0,0,0,0,0
0,0,0,0,0,0,9,5,7,5,9,0,0,0,0,0,0
0,0,0,0,0,0,0,9,5,9,0,0,0,0,0,0,0
0,0,0,0,0,0,0,0,0,0,0,0,0,0,0,0,0
0,0,0,0,0,0,0,0,0,0,0,0,0,0,0,0,0
0,0,0,0,0,0,0,0,0,0,0,0,0,0,0,0,0
0,0,0,0,0,0,0,0,0,0,0,0,0,0,0,0,0
0,0,0,0,0,0,0,0,0,0,0,0,0,0,0,0,0
0,0,0,0,0,0,0,0,0,0,0,0,0,0,0,0,0
endlayer

layer
0,0,0,0,0,0,0,0,0,0,0,0,0,0,0,0,0
0,0,0,0,0,0,0,0,0,0,0,0,0,0,0,0,0
0,0,0,0,0,0,0,0,0,0,0,0,0,0,0,0,0
0,0,0,0,0,0,0,0,0,0,0,0,0,0,0,0,0
0,0,0,0,0,0,0,0,0,0,0,0,0,0,0,0,0
0,0,0,0,0,0,0,0,0,0,0,0,0,0,0,0,0
0,0,0,0,0,0,0,0,0,0,0,0,0,0,0,0,0
0,0,0,0,0,0,0,9,5,9,0,0,0,0,0,0,0
0,0,0,0,0,0,9,5,0,5,9,0,0,0,0,0,0
0,0,0,0,0,9,5,0,0,0,5,9,22,0,0,0,0
0,0,0,0,0,5,0,0,0,0,0,5,0,0,0,0,0
0,0,0,0,0,9,5,0,0,0,5,9,0,0,0,0,0
0,0,0,0,0,0,9,5,0,5,9,0,0,0,0,0,0
0,0,0,0,0,0,0,9,5,9,0,0,0,0,0,0,0
0,0,0,0,0,0,0,0,0,0,0,0,0,0,0,0,0
0,0,0,0,0,0,0,0,0,0,0,0,0,0,0,0,0
0,0,0,0,0,0,0,0,22,0,0,0,0,0,0,0,0
0,0,0,0,0,0,0,0,0,0,0,0,0,0,0,0,0
0,0,0,0,0,0,0,0,0,0,0,0,0,0,0,0,0
0,0,0,0,0,0,0,0,0,0,0,0,0,0,0,0,0
endlayer

layer
0,0,0,0,0,0,0,0,0,0,0,0,0,0,0,0,0
0,0,0,0,0,0,0,0,0,0,0,0,0,0,0,0,0
0,0,0,0,0,0,0,0,0,0,0,0,0,0,0,0,0
0,0,0,0,0,0,0,0,0,0,0,0,0,0,0,0,0
0,0,0,0,0,0,0,0,0,0,0,0,0,0,0,0,0
0,0,0,0,0,0,0,0,22,0,0,0,0,0,0,0,0
0,0,0,0,0,0,0,3,2,1,0,0,0,0,0,0,0
0,0,0,0,0,0,2,3,5,2,1,0,0,0,0,0,0
0,0,0,0,0,2,3,5,0,5,2,1,0,0,0,0,0
0,0,0,22,2,3,5,0,0,0,5,2,2,0,0,0,0
0,0,0,0,3,5,0,0,0,0,0,5,1,0,0,0,0
0,0,0,0,8,8,5,0,0,0,5,1,8,0,0,0,0
0,0,0,0,0,3,8,5,0,5,1,8,0,0,0,0,0
0,0,0,0,0,0,3,8,5,1,8,0,0,0,0,0,0
0,0,0,0,0,0,0,3,8,1,0,0,0,0,0,0,0
0,0,0,0,0,0,0,0,0,0,0,0,0,0,0,0,0
0,0,0,0,0,0,0,0,0,0,0,0,0,0,0,0,0
0,0,0,0,0,0,0,0,0,0,0,0,0,0,0,0,0
0,0,0,0,0,0,0,0,0,0,0,0,0,0,0,0,0
0,0,0,0,0,0,0,0,0,0,0,0,0,0,0,0,0
endlayer

layer
0,0,0,0,0,0,0,0,0,0,0,0,0,0,0,0,0
0,0,0,0,0,0,0,0,0,0,0,0,0,0,0,0,0
0,0,0,0,0,0,0,0,0,0,0,0,0,0,0,0,0
0,0,0,0,0,0,0,0,0,0,0,0,0,0,0,0,0
0,0,0,0,0,0,0,0,0,0,0,0,0,0,0,0,0
0,0,0,0,0,0,0,0,0,0,0,0,0,0,0,0,0
0,0,0,0,0,0,0,0,0,0,0,0,0,0,0,0,0
0,0,0,0,0,0,0,0,4,0,0,0,0,0,0,0,0
0,0,0,0,0,0,0,2,2,1,0,0,0,0,0,0,0
0,0,0,0,0,0,2,3,69,2,1,0,0,0,0,0,0
0,0,0,0,0,4,3,70,0,70,1,4,0,0,0,0,0
0,0,0,0,0,0,3,8,69,1,8,0,0,0,0,0,0
0,0,0,0,0,0,0,3,8,8,0,0,0,0,0,0,0
0,0,0,0,0,0,0,0,4,0,0,0,0,0,0,0,0
0,0,0,0,0,0,0,0,0,0,0,0,0,0,0,0,0
0,0,0,0,0,0,0,0,0,0,0,0,0,0,0,0,0
0,0,0,0,0,0,0,0,0,0,0,0,0,0,0,0,0
0,0,0,0,0,0,0,0,0,0,0,0,0,0,0,0,0
0,0,0,0,0,0,0,0,0,0,0,0,0,0,0,0,0
0,0,0,0,0,0,0,0,0,0,0,0,0,0,0,0,0
endlayer

layer
0,0,0,0,0,0,0,0,0,0,0,0,0,0,0,0,0
0,0,0,0,0,0,0,0,0,0,0,0,0,0,0,0,0
0,0,0,0,0,0,0,0,0,0,0,0,0,0,0,0,0
0,0,0,0,0,0,0,0,0,0,0,0,0,0,0,0,0
0,0,0,0,0,0,0,0,0,0,0,0,0,0,0,0,0
0,0,0,0,0,0,0,0,0,0,0,0,0,0,0,0,0
0,0,0,0,0,0,0,0,0,0,0,0,0,0,0,0,0
0,0,0,0,0,0,0,0,0,0,0,0,0,0,0,0,0
0,0,0,0,0,0,0,0,0,0,0,0,0,0,0,0,0
0,0,0,0,0,0,0,0,2,0,0,0,0,0,0,0,0
0,0,0,0,0,0,0,3,18,1,0,0,0,0,0,0,0
0,0,0,0,0,0,0,0,8,0,0,0,0,0,0,0,0
0,0,0,0,0,0,0,0,0,0,0,0,0,0,0,0,0
0,0,0,0,0,0,0,0,0,0,0,0,0,0,0,0,0
0,0,0,0,0,0,0,0,0,0,0,0,0,0,0,0,0
0,0,0,0,0,0,0,0,0,0,0,0,0,0,0,0,0
0,0,0,0,0,0,0,0,0,0,0,0,0,0,0,0,0
0,0,0,0,0,0,0,0,0,0,0,0,0,0,0,0,0
0,0,0,0,0,0,0,0,0,0,0,0,0,0,0,0,0
0,0,0,0,0,0,0,0,0,0,0,0,0,0,0,0,0
endlayer

layer
0,0,0,0,0,0,0,0,0,0,0,0,0,0,0,0,0
0,0,0,0,0,0,0,0,0,0,0,0,0,0,0,0,0
0,0,0,0,0,0,0,0,0,0,0,0,0,0,0,0,0
0,0,0,0,0,0,0,0,0,0,0,0,0,0,0,0,0
0,0,0,0,0,0,0,0,0,0,0,0,0,0,0,0,0
0,0,0,0,0,0,0,0,0,0,0,0,0,0,0,0,0
0,0,0,0,0,0,0,0,0,0,0,0,0,0,0,0,0
0,0,0,0,0,0,0,0,0,0,0,0,0,0,0,0,0
0,0,0,0,0,0,0,0,0,0,0,0,0,0,0,0,0
0,0,0,0,0,0,0,0,0,0,0,0,0,0,0,0,0
0,0,0,0,0,0,0,0,71,0,0,0,0,0,0,0,0
0,0,0,0,0,0,0,0,0,0,0,0,0,0,0,0,0
0,0,0,0,0,0,0,0,0,0,0,0,0,0,0,0,0
0,0,0,0,0,0,0,0,0,0,0,0,0,0,0,0,0
0,0,0,0,0,0,0,0,0,0,0,0,0,0,0,0,0
0,0,0,0,0,0,0,0,0,0,0,0,0,0,0,0,0
0,0,0,0,0,0,0,0,0,0,0,0,0,0,0,0,0
0,0,0,0,0,0,0,0,0,0,0,0,0,0,0,0,0
0,0,0,0,0,0,0,0,0,0,0,0,0,0,0,0,0
0,0,0,0,0,0,0,0,0,0,0,0,0,0,0,0,0
endlayer

