
# Created by Ruins mod version 14.7 Ingame Parser
# authoring Player: Barlock_James

weight=1
embed_into_distance=1
acceptable_target_blocks=
unacceptable_target_blocks=flowing_water,water,flowing_lava,lava
dimensions=30,17,26
allowable_overhang=0
max_leveling=2
leveling_buffer=0
preserve_water=0
preserve_lava=0

rule1=0,100,minecraft:grass-0
rule2=0,100,minecraft:dirt-0
rule3=0,100,minecraft:tallgrass-1
rule4=0,100,minecraft:double_plant-2
rule5=0,100,minecraft:red_flower-3
rule6=0,100,minecraft:yellow_flower-0
rule7=0,100,minecraft:log-3
rule8=0,100,minecraft:red_flower-7
rule9=0,100,minecraft:red_flower-8
rule10=0,100,minecraft:vine-8
rule11=0,100,minecraft:vine-1
rule12=0,100,minecraft:vine-4
rule13=0,100,minecraft:vine-2
rule14=0,100,minecraft:red_flower-0
rule15=0,100,minecraft:double_plant-8
rule16=0,100,minecraft:leaves-3
rule17=0,100,minecraft:red_flower-4
rule18=2,100,minecraft:torch-3
rule19=0,100,minecraft:wooden_slab-11
rule20=0,100,minecraft:jungle_stairs-4
rule21=0,100,minecraft:jungle_stairs-7
rule22=0,100,minecraft:leaves-7
rule23=0,100,minecraft:jungle_stairs-6
rule24=0,100,minecraft:jungle_stairs-5
rule25=0,100,minecraft:fence-0
rule26=1,100,minecraft:torch-5
rule27=0,100,minecraft:planks-3
rule28=0,100,minecraft:bed-10
rule29=0,100,minecraft:bed-2
rule30=0,100,minecraft:cauldron-3
rule31=0,100,minecraft:furnace-3
rule32=0,100,ChestGenHook:dungeonChest:5-3
rule33=0,100,minecraft:crafting_table-0
rule34=2,100,minecraft:torch-1

layer
1,1,1,1,1,1,1,1,1,1,1,1,1,1,1,1,1,1,1,1,0,0,0,0,0,0
1,1,1,1,1,1,1,1,1,1,1,1,1,1,1,1,1,1,1,1,2,2,2,2,2,0
1,1,1,1,1,1,1,1,1,1,1,1,1,1,1,1,1,1,1,1,2,2,2,2,2,0
1,1,1,1,1,1,1,2,1,1,1,1,1,1,1,2,1,1,1,1,2,2,2,2,2,0
1,1,2,1,1,1,1,1,1,1,1,1,1,1,1,1,1,1,1,2,2,2,2,2,2,0
1,1,1,1,1,1,1,1,1,1,1,1,1,1,1,1,1,2,2,2,2,2,2,2,2,0
1,1,1,1,1,1,1,1,1,1,1,1,1,1,1,1,2,2,2,2,2,2,2,2,2,0
1,1,1,1,1,1,2,2,1,1,1,1,1,1,1,1,2,2,2,2,2,2,2,2,2,0
1,1,1,1,1,1,2,2,1,1,1,1,1,1,1,1,2,2,2,2,2,2,2,2,2,0
1,1,1,1,1,1,1,1,1,1,1,1,1,1,1,1,2,2,2,2,2,2,2,2,2,0
1,1,1,1,1,1,1,1,1,1,1,1,1,1,1,1,2,2,2,2,2,2,2,2,2,0
1,1,1,1,1,1,1,1,1,1,1,1,2,1,1,1,2,2,2,2,2,2,2,2,2,0
1,1,1,1,2,1,1,1,1,1,1,1,1,1,1,1,2,2,2,2,2,2,2,2,2,0
1,1,1,1,1,1,1,1,1,1,1,1,1,1,1,1,2,2,2,2,2,2,2,2,2,0
1,1,1,1,1,1,1,1,1,1,1,1,1,1,1,1,2,2,2,2,2,2,2,2,2,0
1,1,1,1,1,1,1,1,1,1,1,1,1,1,1,1,2,2,2,2,2,2,2,2,2,0
1,1,1,1,1,1,1,1,1,1,1,1,1,1,1,1,0,0,0,0,0,0,0,0,0,0
endlayer

layer
4,0,3,0,4,3,0,0,3,3,3,3,3,3,3,3,3,3,3,3,1,0,0,0,0,0
0,4,4,6,4,3,4,3,0,5,3,3,3,0,3,3,3,3,3,3,1,2,2,2,2,0
0,0,0,3,3,3,0,3,3,3,3,3,3,5,3,3,3,3,3,3,1,1,2,2,2,0
0,0,3,3,3,3,0,7,3,3,3,3,3,8,3,7,3,3,3,3,1,1,2,2,2,0
0,0,7,9,4,3,0,3,3,3,3,3,3,3,3,3,3,3,3,1,1,1,2,2,2,0
0,0,0,3,3,3,0,3,3,3,3,3,3,3,3,0,0,1,1,1,1,2,2,2,2,0
3,3,3,3,0,3,10,10,3,3,3,3,3,3,3,3,1,1,1,1,1,2,2,2,2,0
3,3,3,3,9,12,7,7,11,3,3,3,3,3,3,3,1,1,1,1,1,2,2,2,2,0
0,3,3,3,3,12,7,7,3,3,3,0,0,3,3,3,1,2,2,1,1,2,2,2,2,0
0,3,14,3,3,3,0,13,3,3,6,3,3,3,3,3,1,2,2,1,1,2,2,2,2,0
3,3,3,3,3,3,3,0,3,3,3,3,3,0,0,3,1,1,1,1,2,2,2,2,2,0
0,3,4,9,3,0,3,3,0,3,3,0,7,0,3,3,1,2,2,2,2,2,2,2,2,0
3,3,3,3,7,0,3,3,3,3,3,0,0,3,0,0,1,2,2,2,2,2,2,2,2,0
3,3,5,5,3,3,3,3,9,0,6,3,0,3,0,3,1,2,2,2,2,2,2,2,2,0
9,3,4,3,3,6,3,3,6,3,0,3,0,3,3,3,1,2,2,2,2,2,2,2,2,0
0,0,3,3,3,3,3,9,3,3,3,3,3,3,0,3,1,2,2,2,2,2,2,2,2,0
0,0,3,3,0,3,0,9,3,3,3,3,3,3,3,3,1,0,0,0,0,0,0,0,0,0
endlayer

layer
15,0,0,0,15,0,0,0,0,0,0,0,0,0,0,0,0,0,0,0,0,1,1,1,1,1
0,15,15,0,15,0,15,0,0,0,0,0,0,0,16,16,16,0,0,0,0,1,1,1,1,1
0,0,0,0,0,0,0,0,0,0,0,0,0,16,16,16,16,16,0,0,4,3,1,1,1,1
0,0,0,0,0,0,0,7,0,0,0,0,0,16,16,7,16,16,0,0,0,3,2,1,1,1
0,0,7,0,15,0,0,0,0,0,0,0,0,16,16,16,16,16,0,3,3,0,1,1,1,1
0,0,0,0,0,0,0,0,0,0,0,0,0,16,16,16,16,16,0,4,0,1,1,1,1,1
0,0,0,0,0,0,10,10,0,0,0,0,0,0,0,0,3,3,0,3,9,1,1,1,1,1
0,0,0,0,0,12,7,7,11,0,0,0,0,0,0,0,3,3,10,3,3,1,1,1,1,1
0,0,0,0,0,12,7,7,11,0,0,0,0,0,0,0,3,7,7,11,3,1,1,2,1,1
0,0,0,0,0,0,0,13,0,0,0,0,0,0,0,0,14,7,7,6,3,1,1,1,1,1
0,0,0,0,0,0,0,0,0,0,0,0,0,0,0,0,3,13,13,3,1,1,1,1,1,1
0,0,15,0,0,0,0,0,0,0,0,0,7,0,0,0,3,1,1,1,1,1,1,1,1,1
0,0,0,0,7,0,0,0,0,0,0,0,0,0,0,0,0,1,1,1,1,1,1,1,1,1
0,0,0,0,0,0,0,0,0,0,0,0,0,0,0,0,3,1,1,1,1,2,1,1,1,1
0,0,15,0,0,0,0,0,0,0,0,0,0,0,0,0,3,1,2,1,1,1,1,1,1,1
0,0,0,0,0,0,0,0,0,0,0,0,0,0,0,0,0,1,1,1,1,1,1,1,1,1
0,0,0,0,0,0,0,0,0,0,0,0,0,0,0,0,0,1,1,1,1,1,1,1,1,1
endlayer

layer
0,0,0,0,0,0,0,0,0,0,0,0,0,0,0,0,0,0,0,0,0,5,6,6,3,3
0,0,0,0,0,0,0,0,0,0,0,0,0,16,16,16,16,0,0,0,0,3,3,3,3,0
0,0,0,0,0,0,0,0,0,0,0,0,0,16,16,16,16,16,0,0,15,0,6,3,3,3
0,0,0,0,0,0,0,7,0,0,0,0,0,16,16,7,16,16,0,0,0,0,7,0,3,3
0,0,7,0,0,0,0,0,0,0,0,0,0,16,16,16,16,16,0,0,0,0,3,3,3,3
0,0,0,0,0,0,0,0,0,0,0,0,0,0,16,16,16,0,0,15,0,3,3,3,3,0
0,0,0,0,0,0,10,10,0,0,0,0,0,0,0,0,0,0,0,0,0,0,4,3,6,3
0,0,0,0,0,12,7,7,11,0,0,0,0,0,0,0,0,10,10,0,0,3,3,3,3,3
0,0,0,0,0,12,7,7,11,0,0,0,0,0,0,0,12,7,7,11,0,0,0,7,9,3
0,0,0,0,0,0,13,13,0,0,0,16,16,16,16,0,12,7,7,0,0,14,4,9,3,0
0,0,0,0,0,0,0,0,0,0,16,16,16,16,16,0,0,13,13,0,3,17,3,3,3,3
0,0,0,0,0,0,0,0,0,0,16,16,7,16,16,0,0,0,3,3,3,3,4,3,3,3
0,0,0,0,7,0,0,0,0,0,16,16,16,16,16,0,0,3,3,3,4,3,6,14,3,3
0,0,0,0,0,0,0,0,0,0,0,16,16,16,16,0,0,3,3,3,6,7,3,0,3,3
0,0,0,0,0,0,0,0,0,0,0,0,0,0,0,0,0,3,7,3,3,3,0,3,3,3
0,0,0,0,0,0,0,0,0,0,0,0,0,0,0,0,0,3,3,3,3,3,3,3,0,6
0,0,0,0,0,0,0,0,0,0,0,0,0,0,0,0,0,3,3,3,3,3,3,3,0,0
endlayer

layer
0,0,0,0,0,0,0,0,0,0,0,0,0,0,0,0,0,0,0,0,0,0,0,0,0,0
0,0,0,0,0,0,0,0,0,0,0,0,0,0,0,0,0,0,0,0,0,0,0,0,0,0
0,0,0,0,0,0,0,0,0,0,0,0,0,0,16,16,16,0,0,0,0,0,0,0,0,0
0,0,0,0,0,0,0,7,0,0,0,0,0,0,16,7,16,0,0,0,0,0,7,0,0,0
0,0,7,0,0,0,0,0,0,0,0,0,0,0,0,16,0,0,0,0,0,0,0,0,0,0
0,0,0,0,0,0,0,0,0,0,0,0,0,0,0,0,0,0,0,0,0,0,0,0,0,0
0,0,0,0,0,0,10,10,0,0,0,0,0,0,0,0,0,0,0,0,0,0,15,0,0,0
0,0,0,0,0,12,7,7,11,0,0,0,0,0,0,0,0,10,10,0,0,0,0,0,0,0
0,0,0,0,0,12,7,7,0,0,0,0,0,0,0,0,12,7,7,11,0,0,0,7,0,0
0,0,0,0,0,0,13,0,0,0,16,16,16,16,0,0,0,7,7,0,0,0,15,0,0,0
0,0,16,16,16,16,16,0,0,0,16,16,16,16,16,0,0,13,13,0,0,0,0,0,0,0
0,0,16,16,16,16,16,0,0,12,16,16,7,16,16,0,0,0,0,0,0,0,15,0,0,0
0,0,16,16,7,16,16,0,0,12,16,16,16,16,16,0,0,0,0,0,15,0,0,0,0,0
0,0,16,16,16,16,16,0,0,0,16,16,16,16,16,0,0,0,0,0,0,7,0,0,0,0
0,0,0,16,16,16,0,0,0,0,0,0,0,0,0,0,0,0,7,0,0,0,0,0,0,0
0,0,0,0,0,0,0,0,0,0,0,0,0,0,0,0,0,0,0,0,0,0,0,0,0,0
0,0,0,0,0,0,0,0,0,0,0,0,0,0,0,0,0,0,0,0,0,0,0,0,0,0
endlayer

layer
0,0,0,0,0,0,0,0,0,0,0,0,0,0,0,0,0,0,0,0,0,0,0,0,0,0
0,0,0,0,0,0,0,0,0,0,0,0,0,0,0,0,0,0,0,0,0,0,0,0,0,0
0,0,0,0,0,0,0,0,0,0,0,0,0,0,0,16,0,0,0,0,0,0,0,0,0,0
0,0,0,0,0,0,0,7,0,0,0,0,0,0,16,16,16,0,0,0,0,0,7,0,0,0
0,0,7,0,0,0,0,0,0,0,0,0,0,0,0,16,0,0,0,0,0,0,0,0,0,0
0,0,0,0,0,0,0,0,0,0,0,0,0,0,0,0,0,0,0,0,0,0,0,0,0,0
0,0,0,0,0,0,10,10,0,0,0,0,0,0,0,0,0,0,0,0,0,0,0,0,0,0
0,0,0,0,0,12,7,7,11,0,0,0,0,0,0,0,0,10,10,0,0,0,0,0,0,0
0,0,0,0,0,12,7,7,0,0,0,0,0,0,0,0,12,7,7,11,0,0,0,7,0,0
0,0,0,0,0,0,13,13,0,0,0,0,0,0,0,0,12,7,7,0,0,0,0,0,0,0
0,0,0,16,16,16,0,0,0,0,0,0,16,16,0,0,0,0,13,0,0,0,0,0,0,0
0,0,16,16,16,16,16,0,0,0,0,16,7,16,0,0,0,0,0,0,0,0,0,0,0,0
0,0,16,16,7,16,16,0,0,0,0,16,16,16,0,0,0,0,0,0,0,0,0,0,0,0
0,0,16,16,16,16,16,0,0,0,0,0,0,0,0,0,0,0,0,0,0,7,0,0,0,0
0,0,16,16,16,16,0,0,0,0,0,0,0,0,0,0,0,0,7,0,0,0,0,0,0,0
0,0,13,13,13,0,0,0,0,0,0,0,0,0,0,0,0,0,0,0,0,0,0,0,0,0
0,0,0,0,0,0,0,0,0,0,0,0,0,0,0,0,0,0,0,0,0,0,0,0,0,0
endlayer

layer
0,0,0,0,0,0,0,0,0,0,0,0,0,0,0,0,0,0,0,0,0,0,0,0,0,0
0,0,0,0,0,0,0,0,0,0,0,0,0,0,0,0,0,0,0,0,0,0,0,0,0,0
0,0,0,0,0,0,0,0,0,0,0,0,0,0,0,0,0,0,0,0,0,0,0,0,0,0
0,0,10,0,0,0,0,7,0,0,0,0,0,0,0,0,0,0,0,0,0,0,7,0,0,0
0,0,7,0,0,0,0,0,0,0,0,0,0,0,0,0,0,0,0,0,0,0,0,0,0,0
0,0,0,0,0,0,0,0,0,0,0,0,0,0,0,0,0,0,0,0,0,0,0,0,0,0
0,0,0,0,0,0,10,10,0,0,0,0,0,0,0,0,0,0,0,0,0,0,0,0,0,0
0,0,0,0,0,12,7,7,11,0,0,0,0,0,0,0,0,10,10,0,0,0,0,0,0,0
0,0,0,0,0,12,7,7,11,0,0,0,0,0,0,0,12,7,7,11,0,0,0,7,0,0
0,0,0,0,0,0,13,13,0,0,0,0,0,0,0,0,12,7,7,11,0,0,0,0,0,0
0,0,0,0,0,0,0,0,0,0,0,0,16,0,0,0,0,0,13,0,0,0,0,0,0,0
0,0,0,0,16,0,0,0,0,0,0,16,16,16,0,0,0,0,10,0,0,0,0,0,0,0
0,0,0,16,7,16,0,0,0,0,0,0,16,0,0,0,16,16,16,16,0,0,0,0,0,0
0,0,0,0,16,16,0,0,0,0,0,0,0,0,0,0,16,16,16,16,16,7,0,0,0,0
0,0,0,0,0,0,0,0,0,0,0,0,0,0,0,0,16,16,7,16,16,0,0,0,0,0
0,0,0,0,0,0,0,0,0,0,0,0,0,0,0,0,16,16,16,16,16,0,0,0,0,0
0,0,0,0,0,0,0,0,0,0,0,0,0,0,0,0,0,16,16,16,16,0,0,0,0,0
endlayer

layer
0,0,0,0,0,0,0,0,0,0,0,0,0,0,0,0,0,0,0,0,0,0,0,0,0,0
0,0,0,0,0,0,0,0,0,0,0,0,0,0,0,0,0,0,0,0,0,0,0,0,0,0
0,0,0,0,0,0,0,0,0,0,0,0,0,0,0,0,0,0,0,0,0,0,0,0,0,0
0,0,10,0,0,0,0,7,0,0,0,0,0,0,0,0,0,0,0,0,0,0,7,0,0,0
0,0,7,0,0,0,0,0,0,0,0,0,0,0,0,0,0,0,0,0,0,0,0,0,0,0
0,0,0,0,0,0,0,0,0,0,0,0,0,0,0,0,0,0,0,0,0,0,0,0,0,0
0,0,0,0,0,0,10,10,0,0,0,0,0,0,0,0,0,0,0,0,0,0,0,0,0,0
0,0,0,0,0,12,7,7,11,0,0,0,0,0,0,0,0,10,10,0,0,0,0,0,0,0
0,0,0,0,0,12,7,7,0,0,0,0,0,0,0,0,12,7,7,11,0,0,0,7,0,0
0,0,0,0,0,0,13,13,0,0,0,0,0,0,0,0,12,7,7,0,0,0,0,0,0,0
0,0,0,0,0,0,0,0,0,0,0,0,0,0,0,0,0,13,13,0,0,0,0,0,0,0
0,0,0,0,16,0,0,0,0,0,0,0,0,0,0,0,0,0,0,0,0,0,0,0,0,0
0,0,0,16,16,16,0,0,0,0,0,0,0,0,0,0,16,16,16,16,16,0,0,0,0,0
0,0,0,0,16,0,0,0,0,0,0,0,0,0,0,12,16,16,16,16,16,7,0,0,0,0
0,0,0,0,0,0,0,0,0,0,0,0,0,0,0,12,16,16,7,16,16,0,0,0,0,0
0,0,0,0,0,0,0,0,0,0,0,0,0,0,0,12,16,16,16,16,16,0,0,0,0,0
0,0,0,0,0,0,0,0,0,0,0,0,0,0,0,0,0,16,16,16,16,0,0,0,0,0
endlayer

layer
0,0,0,0,0,0,0,0,0,0,0,0,0,0,0,0,0,0,0,0,0,0,0,0,0,0
0,0,0,0,0,0,0,0,0,0,0,0,0,0,0,0,0,0,0,0,0,0,0,0,0,0
0,16,16,16,16,0,0,0,0,0,0,0,0,0,0,0,0,0,0,0,0,0,0,0,0,0
16,16,16,16,16,0,0,7,0,0,0,0,0,0,0,0,0,0,0,0,0,12,7,0,0,0
16,16,7,16,16,0,0,0,0,0,0,0,0,0,0,0,0,0,0,0,0,0,0,0,0,0
16,16,16,16,16,0,0,0,0,0,0,0,0,0,0,0,0,0,0,0,0,0,0,0,0,0
0,16,16,16,0,0,10,10,0,0,0,0,0,0,0,0,0,0,0,0,0,0,0,0,0,0
0,0,0,0,0,12,7,7,11,0,0,0,0,0,0,0,0,10,10,0,0,0,0,0,0,0
0,0,0,0,0,12,7,7,0,0,0,0,0,0,0,0,12,7,7,11,0,0,0,7,0,0
0,0,0,0,0,0,13,13,0,0,0,0,0,0,0,0,12,7,7,11,0,0,0,0,0,0
0,0,0,0,0,0,0,0,0,0,0,0,0,0,0,0,0,13,13,0,0,0,0,0,0,0
0,0,0,0,0,0,0,0,0,0,0,0,0,0,0,0,0,0,0,0,0,0,0,0,0,0
0,0,0,0,0,0,0,0,0,0,0,0,0,0,0,0,0,0,0,0,0,0,0,0,0,0
0,0,0,0,0,0,0,0,0,0,0,0,0,0,0,0,0,0,16,16,0,7,0,0,0,0
0,0,0,0,0,0,0,0,0,0,0,0,0,0,0,0,0,16,7,16,0,0,0,0,0,0
0,0,0,0,0,0,0,0,0,0,0,0,0,0,0,0,0,0,16,0,0,0,0,0,0,0
0,0,0,0,0,0,0,0,0,0,0,0,0,0,0,0,0,0,0,0,0,0,0,0,0,0
endlayer

layer
0,0,0,0,0,0,0,0,0,0,0,0,0,0,0,0,0,0,0,0,0,0,0,0,0,0
0,0,0,0,0,0,16,16,16,0,0,0,0,0,0,0,0,0,0,0,16,16,16,16,0,0
16,16,16,16,16,16,16,16,16,16,11,0,0,0,0,0,0,0,0,0,16,16,16,16,16,0
16,16,16,16,16,16,16,7,16,16,0,0,0,0,0,0,0,0,0,0,16,16,7,16,16,0
16,16,7,16,16,16,16,16,16,16,11,0,0,0,0,0,0,0,0,0,16,16,16,16,16,0
16,16,16,16,16,0,16,16,16,16,0,0,0,0,0,0,0,0,0,0,16,16,16,16,0,0
0,16,16,16,16,0,10,10,0,0,0,0,0,0,0,0,0,0,0,0,0,16,16,16,16,0
0,0,0,0,0,12,7,7,11,0,0,0,0,0,0,0,0,10,10,0,0,16,16,16,16,16
0,0,0,0,0,0,7,7,11,0,0,0,0,0,0,0,12,7,7,11,0,16,16,7,16,16
0,0,0,0,0,0,13,0,0,0,0,0,0,0,0,0,12,7,7,11,0,16,16,16,16,16
0,0,0,0,0,0,0,0,0,0,0,0,0,0,0,0,0,13,13,0,0,0,16,16,16,0
0,0,0,0,0,0,0,0,0,0,0,0,0,0,0,0,0,0,0,0,0,0,0,13,13,0
0,0,0,0,0,0,0,0,0,0,0,0,0,0,0,0,0,0,0,0,0,0,0,0,0,0
0,0,0,0,0,0,0,0,0,0,0,0,0,0,0,0,0,0,16,0,0,7,0,0,0,0
0,0,0,0,0,0,0,0,0,0,0,0,0,0,0,0,0,16,16,16,0,0,0,0,0,0
0,0,0,0,0,0,0,0,0,0,0,0,0,0,0,0,0,0,16,0,0,0,0,0,0,0
0,0,0,0,0,0,0,0,0,0,0,0,0,0,0,0,0,0,0,0,0,0,0,0,0,0
endlayer

layer
0,0,0,0,0,0,0,0,0,0,0,0,0,0,0,0,0,0,0,0,0,0,0,0,0,0
0,0,0,0,0,0,16,16,16,0,0,0,0,0,0,0,0,0,0,0,0,16,16,16,16,0
0,0,0,0,0,16,16,16,16,16,0,0,0,0,0,0,0,0,0,0,16,16,16,16,16,0
0,16,16,16,0,16,16,7,16,16,11,0,0,0,0,0,0,0,0,0,16,16,7,16,16,0
0,16,7,16,0,16,16,16,16,16,0,0,0,0,0,0,0,0,0,0,16,16,16,16,16,0
0,0,16,16,0,0,16,16,16,0,0,0,0,0,0,0,0,0,0,0,0,16,16,16,16,0
0,0,0,0,0,0,10,10,0,0,0,0,0,0,0,0,0,0,0,0,0,16,16,16,16,16
0,0,0,0,0,12,7,7,11,0,0,0,0,0,0,0,0,10,10,0,0,16,16,16,16,16
0,0,0,0,0,12,7,7,11,0,0,0,0,0,0,0,12,7,7,11,0,16,16,7,16,16
0,0,0,0,0,0,13,13,0,0,0,0,0,0,0,0,12,7,7,11,0,16,16,16,16,16
0,0,0,0,0,0,0,0,0,0,0,0,0,0,0,0,0,13,13,0,0,16,16,16,16,0
0,0,0,0,0,0,0,0,0,0,0,0,0,0,0,0,0,0,0,0,0,0,0,0,0,0
0,0,0,0,0,0,0,0,0,0,0,0,0,0,0,0,0,0,0,0,0,0,0,0,0,0
0,0,0,0,0,0,0,0,0,0,0,0,0,0,0,0,0,0,0,0,0,7,0,0,0,0
0,0,0,0,0,0,0,0,0,0,0,0,0,0,0,0,0,0,0,0,0,13,0,0,0,0
0,0,0,0,0,0,0,0,0,0,0,0,0,0,0,0,0,0,0,0,0,0,0,0,0,0
0,0,0,0,0,0,0,0,0,0,0,0,0,0,0,0,0,0,0,0,0,0,0,0,0,0
endlayer

layer
0,0,0,0,0,0,0,0,0,0,0,0,0,0,0,0,0,0,0,0,0,0,0,0,0,0
0,0,0,0,0,0,0,0,0,0,0,0,0,0,0,0,0,0,0,0,0,0,0,0,0,0
0,0,0,0,0,0,0,16,0,0,0,0,0,0,0,0,0,0,0,0,0,0,16,0,0,0
0,0,16,0,0,0,16,7,16,0,0,0,0,0,0,0,0,0,0,0,0,16,7,16,0,0
0,16,16,16,0,0,16,16,16,0,0,0,0,0,0,0,0,0,0,0,0,0,16,0,0,0
0,0,16,0,0,0,0,0,0,0,0,0,0,0,0,0,0,0,0,0,0,0,0,0,0,0
0,0,0,0,0,0,10,10,0,0,0,0,0,0,0,0,0,0,0,0,0,0,0,0,0,0
0,0,0,0,0,12,7,7,11,0,0,0,0,0,0,0,0,10,10,0,0,0,16,16,16,0
0,0,0,0,0,12,7,7,11,0,0,0,0,0,0,0,12,7,7,11,0,0,16,7,16,0
0,0,0,0,0,0,7,13,0,0,0,0,0,0,0,0,12,7,7,11,0,0,0,16,16,0
0,0,0,0,0,0,0,0,0,0,0,0,0,0,0,0,0,13,13,0,0,0,0,0,0,0
0,0,0,0,0,0,0,0,0,0,0,0,0,0,0,0,0,0,0,16,16,16,16,0,0,0
0,0,0,0,0,0,0,0,0,0,0,0,0,0,0,0,0,0,0,16,16,16,16,16,0,0
0,0,0,0,0,0,0,0,0,0,0,0,0,0,0,0,0,0,0,16,16,7,16,16,0,0
0,0,0,0,0,0,0,0,0,0,0,0,0,0,0,0,0,0,0,16,16,16,16,16,0,0
0,0,0,0,0,0,0,0,0,0,0,0,0,0,0,0,0,0,0,0,16,16,16,0,0,0
0,0,0,0,0,0,0,0,0,0,0,0,0,0,0,0,0,0,0,0,0,0,0,0,0,0
endlayer

layer
0,0,0,0,0,0,0,0,0,0,0,0,0,0,0,0,0,0,0,0,0,0,0,0,0,0
0,0,0,0,0,0,0,0,0,0,0,0,0,0,0,0,0,0,0,0,0,0,0,0,0,0
0,0,0,0,0,0,0,16,0,0,0,0,0,0,0,0,0,0,0,0,0,0,16,0,0,0
0,0,0,0,0,0,16,16,16,0,0,0,0,0,0,0,0,0,0,0,0,16,16,16,0,0
0,0,0,0,0,0,0,16,0,0,0,0,0,0,0,0,0,0,0,0,0,0,16,0,0,0
0,0,0,0,0,0,0,0,0,0,0,0,0,0,0,0,0,0,0,0,0,0,0,0,0,0
0,0,0,0,0,0,10,10,0,0,0,0,0,0,0,0,0,0,0,0,0,0,0,0,0,0
0,0,0,0,0,12,7,7,11,0,0,0,0,0,0,0,0,10,10,0,0,0,0,16,0,0
0,0,0,0,0,12,7,7,11,0,0,0,0,0,0,0,12,7,7,11,0,0,16,16,16,0
0,0,0,0,0,0,13,16,0,0,0,0,0,0,0,0,0,7,7,11,0,0,0,16,0,0
0,0,0,0,0,16,16,7,16,16,0,0,0,0,0,0,0,0,13,0,0,0,0,0,0,0
0,0,0,0,0,16,16,7,16,16,0,0,0,0,0,0,0,0,0,16,16,16,16,0,0,0
0,0,0,0,16,16,16,16,16,16,16,0,0,0,0,0,0,0,0,16,16,16,16,16,0,0
0,0,0,0,0,16,16,16,16,16,0,0,0,0,0,0,0,0,0,16,16,7,16,16,0,0
0,0,0,0,0,16,16,16,16,16,0,0,0,0,0,0,0,0,0,16,16,16,16,16,0,0
0,0,0,0,0,0,0,16,0,0,0,0,0,0,0,0,0,0,0,16,16,16,16,16,0,0
0,0,0,0,0,0,0,0,0,0,0,0,0,0,0,0,0,0,0,0,0,0,0,0,0,0
endlayer

layer
0,0,0,0,0,0,0,0,0,0,0,0,0,0,0,0,0,0,0,0,0,0,0,0,0,0
0,0,0,0,0,0,0,0,0,0,0,0,0,0,0,0,0,0,0,0,0,0,0,0,0,0
0,0,0,0,0,0,0,0,0,0,0,0,0,0,0,0,0,0,0,0,0,0,0,0,0,0
0,0,0,0,0,0,0,0,0,0,0,0,0,0,0,0,0,0,0,0,0,0,0,0,0,0
0,0,0,0,0,0,0,0,0,0,0,0,0,0,0,0,0,0,0,0,0,0,0,0,0,0
0,0,0,0,0,0,0,0,0,0,0,0,0,0,0,0,0,0,0,0,0,0,0,0,0,0
0,0,0,0,0,0,10,10,0,0,0,0,0,0,0,0,0,0,0,0,0,0,0,0,0,0
0,0,0,0,0,12,7,7,11,0,0,0,0,0,0,0,0,10,0,0,0,0,0,0,0,0
0,0,0,0,0,0,7,7,11,0,0,0,0,0,0,0,12,7,7,11,0,0,0,0,0,0
0,0,0,0,0,0,13,13,0,0,0,0,0,0,0,0,0,7,7,11,0,0,0,0,0,0
0,0,0,0,0,0,0,16,0,0,0,0,0,0,0,0,0,0,13,0,0,0,0,0,0,0
0,0,0,0,0,0,16,16,16,0,0,0,0,0,0,0,0,0,0,0,0,0,0,0,0,0
0,0,0,0,0,16,16,7,16,16,0,0,0,0,0,0,0,0,0,0,0,16,0,0,0,0
0,0,0,0,0,0,16,16,16,0,0,0,0,0,0,0,0,0,0,0,16,7,16,0,0,0
0,0,0,0,0,0,0,16,0,0,0,0,0,0,0,0,0,0,0,0,0,16,0,0,0,0
0,0,0,0,0,0,0,0,0,0,0,0,0,0,0,0,0,0,0,0,0,0,0,0,0,0
0,0,0,0,0,0,0,0,0,0,0,0,0,0,0,0,0,0,0,0,0,0,0,0,0,0
endlayer

layer
0,0,0,0,0,0,0,0,0,0,0,0,0,0,0,0,0,0,0,0,0,0,0,0,0,0
0,0,0,0,0,0,0,0,0,0,0,0,0,0,0,0,0,0,0,0,0,0,0,0,0,0
0,0,0,0,0,0,0,0,0,0,0,0,0,0,0,0,0,0,0,0,0,0,0,0,0,0
0,0,0,0,0,0,0,0,0,0,0,0,0,0,0,0,0,0,0,0,0,0,0,0,0,0
0,0,0,0,0,0,0,0,0,0,0,0,0,0,0,0,0,0,0,0,0,0,0,0,0,0
0,0,0,0,0,0,0,0,0,0,0,0,0,0,0,0,0,0,0,0,0,0,0,0,0,0
0,0,0,0,0,0,0,10,0,0,0,0,0,0,0,0,0,0,0,0,0,0,0,0,0,0
0,0,0,0,0,12,7,7,11,0,0,0,0,0,0,0,0,0,0,0,0,0,0,0,0,0
0,0,0,0,0,12,7,7,11,0,0,0,0,0,0,0,7,7,7,11,0,0,0,0,0,0
0,0,0,0,0,0,13,13,0,0,0,0,0,0,0,0,0,7,7,11,0,0,0,0,0,0
0,0,0,0,0,0,0,0,0,0,0,0,0,0,0,0,0,13,0,0,0,0,0,0,0,0
0,0,0,0,0,0,0,16,0,0,0,0,0,0,0,0,0,0,0,0,0,0,0,0,0,0
0,0,0,0,0,0,16,16,16,0,0,0,0,0,0,0,0,0,0,0,0,16,0,0,0,0
0,0,0,0,0,0,0,16,0,0,0,0,0,0,0,0,0,0,0,0,16,16,16,0,0,0
0,0,0,0,0,0,0,0,0,0,0,0,0,0,0,0,0,0,0,0,0,16,0,0,0,0
0,0,0,0,0,0,0,0,0,0,0,0,0,0,0,0,0,0,0,0,0,0,0,0,0,0
0,0,0,0,0,0,0,0,0,0,0,0,0,0,0,0,0,0,0,0,0,0,0,0,0,0
endlayer

layer
0,0,0,0,0,0,0,0,0,0,0,0,0,0,0,0,0,0,0,0,0,0,0,0,0,0
0,0,0,0,0,0,0,0,0,0,0,0,0,0,0,0,0,0,0,0,0,0,0,0,0,0
0,0,0,0,0,0,0,0,0,0,0,0,0,0,0,0,0,0,0,0,0,0,0,0,0,0
0,0,0,0,0,0,0,0,0,0,0,0,0,0,0,0,0,0,0,0,0,0,0,0,0,0
0,0,0,0,0,0,0,0,0,0,0,0,0,0,16,0,0,0,0,0,0,0,0,0,0,0
0,0,0,0,0,0,0,0,0,0,0,0,16,16,16,16,16,0,0,0,0,0,0,0,0,0
0,0,0,0,0,0,7,10,0,0,0,0,16,16,16,16,16,0,0,0,0,0,0,0,0,0
0,0,0,0,0,12,7,7,11,0,0,16,16,16,16,16,16,16,10,0,0,0,0,0,0,0
0,0,0,0,0,12,7,7,11,0,0,0,16,16,16,7,7,7,7,11,0,0,0,0,0,0
0,0,0,0,0,0,13,13,0,0,0,0,16,16,16,16,16,7,7,0,0,0,0,0,0,0
0,0,0,0,0,0,0,0,0,0,0,0,0,0,16,0,0,13,13,0,0,0,0,0,0,0
0,0,0,0,0,0,0,0,0,0,0,0,0,0,0,0,0,0,0,0,0,0,0,0,0,0
0,0,0,0,0,0,0,0,0,0,0,0,0,0,0,0,0,0,0,0,0,0,0,0,0,0
0,0,0,0,0,0,0,0,0,0,0,0,0,0,0,0,0,0,0,0,0,0,0,0,0,0
0,0,0,0,0,0,0,0,0,0,0,0,0,0,0,0,0,0,0,0,0,0,0,0,0,0
0,0,0,0,0,0,0,0,0,0,0,0,0,0,0,0,0,0,0,0,0,0,0,0,0,0
0,0,0,0,0,0,0,0,0,0,0,0,0,0,0,0,0,0,0,0,0,0,0,0,0,0
endlayer

layer
0,0,0,0,0,0,0,0,0,0,0,0,0,0,0,0,0,0,0,0,0,0,0,0,0,0
0,0,0,0,0,0,0,0,0,0,0,0,0,0,0,0,0,0,0,0,0,0,0,0,0,0
0,0,0,0,0,0,0,0,0,0,0,0,0,0,0,0,0,0,0,0,0,0,0,0,0,0
0,0,0,0,0,0,16,0,0,0,0,0,0,0,0,0,0,0,0,0,0,0,0,0,0,0
0,0,0,0,0,16,16,16,0,0,0,0,0,0,0,0,0,0,0,0,0,0,0,0,0,0
0,0,0,0,16,16,7,16,16,0,0,0,0,0,16,0,0,0,0,0,0,0,0,0,0,0
0,0,0,0,0,16,16,16,0,0,0,0,0,16,16,16,0,0,0,0,0,0,0,0,0,0
0,0,0,0,0,12,7,7,11,0,0,0,16,16,7,16,16,10,10,0,0,0,0,0,0,0
0,0,0,0,0,18,7,7,0,0,0,0,0,16,16,16,12,7,7,11,0,0,0,0,0,0
0,0,0,0,0,0,0,13,0,0,0,0,0,0,16,0,12,7,7,11,0,0,0,0,0,0
0,0,0,0,0,0,0,0,0,0,0,0,0,0,0,0,0,13,13,0,0,0,0,0,0,0
0,0,0,0,0,0,0,0,0,0,0,0,0,0,0,0,0,0,0,0,0,0,0,0,0,0
0,0,0,0,0,0,0,0,0,0,0,0,0,0,0,0,0,0,0,0,0,0,0,0,0,0
0,0,0,0,0,0,0,0,0,0,0,0,0,0,0,0,0,0,0,0,0,0,0,0,0,0
0,0,0,0,0,0,0,0,0,0,0,0,0,0,0,0,0,0,0,0,0,0,0,0,0,0
0,0,0,0,0,0,0,0,0,0,0,0,0,0,0,0,0,0,0,0,0,0,0,0,0,0
0,0,0,0,0,0,0,0,0,0,0,0,0,0,0,0,0,0,0,0,0,0,0,0,0,0
endlayer

layer
0,0,0,0,0,0,0,0,0,0,0,0,0,0,0,0,0,0,0,0,0,0,0,0,0,0
0,0,0,0,0,0,0,0,0,0,0,0,0,0,0,0,0,0,0,0,0,0,0,0,0,0
0,0,0,0,0,0,0,0,0,0,0,0,0,0,0,0,0,0,0,0,0,0,0,0,0,0
0,0,0,0,0,0,0,0,0,0,0,0,0,0,0,0,0,0,0,0,0,0,0,0,0,0
0,0,0,0,19,19,19,19,19,19,0,0,0,0,0,0,0,0,0,0,0,0,0,0,0,0
0,0,0,19,19,19,19,19,19,19,19,0,0,0,0,0,0,0,0,0,0,0,0,0,0,0
0,0,0,19,19,21,20,20,20,19,19,0,0,0,16,0,0,0,0,0,0,0,0,0,0,0
0,0,0,19,19,12,7,7,23,19,19,0,0,0,22,0,0,10,10,0,0,0,0,0,0,0
0,0,0,19,19,21,7,7,23,19,19,19,19,19,19,19,21,7,7,11,0,0,0,0,0,0
0,0,0,19,19,24,24,24,23,19,19,19,19,19,19,19,21,7,7,0,0,0,0,0,0,0
0,0,0,19,19,19,19,19,19,19,19,0,0,0,0,0,0,13,13,0,0,0,0,0,0,0
0,0,0,0,19,19,19,19,19,19,0,0,0,0,0,0,0,0,0,0,0,0,0,0,0,0
0,0,0,0,0,0,0,0,0,0,0,0,0,0,0,0,0,0,0,0,0,0,0,0,0,0
0,0,0,0,0,0,0,0,0,0,0,0,0,0,0,0,0,0,0,0,0,0,0,0,0,0
0,0,0,0,0,0,0,0,0,0,0,0,0,0,0,0,0,0,0,0,0,0,0,0,0,0
0,0,0,0,0,0,0,0,0,0,0,0,0,0,0,0,0,0,0,0,0,0,0,0,0,0
0,0,0,0,0,0,0,0,0,0,0,0,0,0,0,0,0,0,0,0,0,0,0,0,0,0
endlayer

layer
0,0,0,0,0,0,0,0,0,0,0,0,0,0,0,0,0,0,0,0,0,0,0,0,0,0
0,0,0,0,0,0,0,0,0,0,0,0,0,0,0,0,0,0,0,0,0,0,0,0,0,0
0,0,0,0,0,0,0,0,0,0,0,0,0,0,0,0,0,0,0,0,0,0,0,0,0,0
0,0,0,0,0,0,0,0,0,0,0,0,0,0,0,0,0,0,0,0,0,0,0,0,0,0
0,0,0,25,25,0,25,25,0,25,25,0,0,0,0,0,0,0,0,0,0,0,0,0,0,0
0,0,0,25,0,0,0,0,0,0,25,0,0,0,0,0,0,0,0,0,0,0,0,0,0,0
0,0,0,0,0,0,10,10,0,0,25,0,0,0,0,0,0,0,0,0,0,0,0,0,0,0
0,0,0,25,0,12,7,7,11,0,25,0,0,0,0,0,0,10,10,0,0,0,0,0,0,0
0,0,0,25,0,12,7,7,11,0,0,0,0,0,0,0,12,7,7,11,0,0,0,0,0,0
0,0,0,0,0,0,13,7,0,0,0,0,0,0,0,0,12,7,7,0,0,0,0,0,0,0
0,0,0,25,0,0,0,0,0,0,25,0,0,0,0,0,0,13,0,0,0,0,0,0,0,0
0,0,0,25,25,0,25,25,0,25,25,0,0,0,0,0,0,0,0,0,0,0,0,0,0,0
0,0,0,0,0,0,0,0,0,0,0,0,0,0,0,0,0,0,0,0,0,0,0,0,0,0
0,0,0,0,0,0,0,0,0,0,0,0,0,0,0,0,0,0,0,0,0,0,0,0,0,0
0,0,0,0,0,0,0,0,0,0,0,0,0,0,0,0,0,0,0,0,0,0,0,0,0,0
0,0,0,0,0,0,0,0,0,0,0,0,0,0,0,0,0,0,0,0,0,0,0,0,0,0
0,0,0,0,0,0,0,0,0,0,0,0,0,0,0,0,0,0,0,0,0,0,0,0,0,0
endlayer

layer
0,0,0,0,0,0,0,0,0,0,0,0,0,0,0,0,0,0,0,0,0,0,0,0,0,0
0,0,0,0,0,0,0,0,0,0,0,0,0,0,0,0,0,0,0,0,0,0,0,0,0,0
0,0,0,0,0,0,0,0,0,0,0,0,0,0,0,0,0,0,0,0,0,0,0,0,0,0
0,0,0,0,0,0,0,0,0,0,0,0,0,0,0,0,0,0,0,0,0,0,0,0,0,0
0,0,0,26,25,0,0,0,0,25,26,0,0,0,0,0,0,0,0,0,0,0,0,0,0,0
0,0,0,25,0,0,0,0,0,0,25,0,0,0,0,0,0,0,0,0,0,0,0,0,0,0
0,0,0,0,0,0,10,10,0,0,0,0,0,0,0,0,0,0,0,0,0,0,0,0,0,0
0,0,0,0,0,12,7,7,11,0,0,0,0,0,0,0,0,10,10,0,0,0,0,0,0,0
0,0,0,0,0,12,7,7,11,0,0,0,0,0,0,0,12,7,7,11,0,0,0,0,0,0
0,0,0,0,0,0,13,13,0,0,0,0,0,0,0,0,12,7,7,0,0,0,0,0,0,0
0,0,0,25,0,0,0,7,0,0,25,0,0,0,0,0,0,13,0,7,0,0,0,0,0,0
0,0,0,26,25,0,0,7,0,25,26,0,0,0,0,0,0,0,0,0,0,0,0,0,0,0
0,0,0,0,0,0,0,0,0,0,0,0,0,0,0,0,0,0,0,0,0,0,0,0,0,0
0,0,0,0,0,0,0,0,0,0,0,0,0,0,0,0,0,0,0,0,0,0,0,0,0,0
0,0,0,0,0,0,0,0,0,0,0,0,0,0,0,0,0,0,0,0,0,0,0,0,0,0
0,0,0,0,0,0,0,0,0,0,0,0,0,0,0,0,0,0,0,0,0,0,0,0,0,0
0,0,0,0,0,0,0,0,0,0,0,0,0,0,0,0,0,0,0,0,0,0,0,0,0,0
endlayer

layer
0,0,0,0,0,0,0,0,0,0,0,0,0,0,0,0,0,0,0,0,0,0,0,0,0,0
0,0,0,0,0,0,0,0,0,0,0,0,0,0,0,0,0,0,0,0,0,0,0,0,0,0
0,0,0,0,0,0,0,0,0,0,0,0,0,0,0,0,0,0,0,0,0,0,0,0,0,0
0,0,0,0,0,0,0,0,0,0,0,0,0,0,0,0,0,0,0,0,0,0,0,0,0,0
0,0,0,0,25,0,0,0,0,25,0,0,0,0,0,0,0,0,0,0,0,0,0,0,0,0
0,0,0,25,0,0,0,0,0,0,25,0,0,0,0,0,0,0,0,0,0,0,0,0,0,0
0,0,0,0,0,0,10,0,0,0,0,0,0,0,0,0,0,0,0,0,0,0,0,0,0,0
0,0,0,0,0,12,7,7,11,0,0,0,0,0,0,0,0,10,0,0,0,0,0,0,0,0
0,0,0,0,0,12,7,7,0,0,0,0,0,0,0,0,12,7,7,11,16,0,0,0,0,0
0,0,0,0,0,0,13,16,0,0,0,0,0,0,0,0,12,7,7,16,16,16,0,0,0,0
0,0,0,25,0,0,16,16,16,0,25,0,0,0,0,0,0,13,16,16,7,16,16,0,0,0
0,0,0,0,25,16,16,7,16,16,0,0,0,0,0,0,0,0,0,16,16,16,0,0,0,0
0,0,0,0,0,0,16,16,16,0,0,0,0,0,0,0,0,0,0,0,16,0,0,0,0,0
0,0,0,0,0,0,0,16,0,0,0,0,0,0,0,0,0,0,0,0,0,0,0,0,0,0
0,0,0,0,0,0,0,0,0,0,0,0,0,0,0,0,0,0,0,0,0,0,0,0,0,0
0,0,0,0,0,0,0,0,0,0,0,0,0,0,0,0,0,0,0,0,0,0,0,0,0,0
0,0,0,0,0,0,0,0,0,0,0,0,0,0,0,0,0,0,0,0,0,0,0,0,0,0
endlayer

layer
0,0,0,0,0,0,0,0,0,0,0,0,0,0,0,0,0,0,0,0,0,0,0,0,0,0
0,0,0,0,0,0,0,0,0,0,0,0,0,0,0,0,0,0,0,0,0,0,0,0,0,0
0,0,0,0,0,0,16,16,0,0,0,0,0,0,0,0,0,0,0,0,0,0,0,0,0,0
0,0,0,16,16,16,16,16,16,16,16,0,0,0,0,0,0,0,0,0,0,0,0,0,0,0
0,0,16,16,16,16,16,16,16,16,16,16,0,0,0,0,0,0,0,0,0,0,0,0,0,0
0,0,16,16,16,16,16,16,16,16,16,16,0,0,0,0,0,0,0,0,0,0,0,0,0,0
0,0,16,16,16,16,16,16,16,16,16,16,0,0,0,0,0,0,0,0,0,0,0,0,0,0
0,16,16,16,16,16,7,7,16,16,16,16,16,0,0,0,0,10,10,0,0,0,0,0,0,0
0,16,16,16,16,16,7,7,16,16,16,16,16,0,0,0,12,7,7,11,0,0,0,0,0,0
0,0,16,16,16,16,16,16,16,16,16,16,0,0,0,0,12,7,7,11,16,0,0,0,0,0
0,0,16,16,16,16,16,16,16,16,16,16,0,0,0,0,0,13,13,16,16,16,0,0,0,0
0,0,16,16,16,16,16,16,16,16,16,16,0,0,0,0,0,0,0,0,16,0,0,0,0,0
0,0,0,16,16,16,16,16,16,16,16,0,0,0,0,0,0,0,0,0,0,0,0,0,0,0
0,0,0,0,0,0,16,16,0,0,0,0,0,0,0,0,0,0,0,0,0,0,0,0,0,0
0,0,0,0,0,0,0,0,0,0,0,0,0,0,0,0,0,0,0,0,0,0,0,0,0,0
0,0,0,0,0,0,0,0,0,0,0,0,0,0,0,0,0,0,0,0,0,0,0,0,0,0
0,0,0,0,0,0,0,0,0,0,0,0,0,0,0,0,0,0,0,0,0,0,0,0,0,0
endlayer

layer
0,0,0,0,0,0,0,0,0,0,0,0,0,0,0,0,0,0,0,0,0,0,0,0,0,0
0,0,0,0,0,0,0,0,0,0,0,0,0,0,0,0,0,0,0,0,0,0,0,0,0,0
0,0,0,0,0,0,0,0,0,0,0,0,0,0,0,0,0,0,0,0,0,0,0,0,0,0
0,0,0,0,0,0,16,16,0,0,0,0,0,0,0,0,0,0,0,0,0,0,0,0,0,0
0,0,0,0,16,16,16,16,16,16,0,0,0,0,0,0,0,0,0,0,0,0,0,0,0,0
0,0,0,16,16,16,16,16,16,16,16,0,0,0,0,0,0,0,0,0,0,0,0,0,0,0
0,0,0,16,16,16,16,16,16,16,16,0,0,0,0,0,0,0,0,0,0,0,0,0,0,0
0,0,16,16,16,16,16,7,16,16,16,16,0,0,0,0,0,10,10,0,0,0,0,0,0,0
0,0,16,16,16,16,16,16,16,16,16,16,0,0,0,0,12,7,7,11,0,0,0,0,0,0
0,0,0,16,16,16,16,16,16,16,16,0,0,0,0,0,12,7,7,11,0,0,0,0,0,0
0,0,0,16,16,16,16,16,16,16,16,0,0,0,0,0,0,13,13,0,0,0,0,0,0,0
0,0,0,0,16,16,16,16,16,16,0,0,0,0,0,0,0,0,0,0,0,0,0,0,0,0
0,0,0,0,0,0,16,16,0,0,0,0,0,0,0,0,0,0,0,0,0,0,0,0,0,0
0,0,0,0,0,0,0,0,0,0,0,0,0,0,0,0,0,0,0,0,0,0,0,0,0,0
0,0,0,0,0,0,0,0,0,0,0,0,0,0,0,0,0,0,0,0,0,0,0,0,0,0
0,0,0,0,0,0,0,0,0,0,0,0,0,0,0,0,0,0,0,0,0,0,0,0,0,0
0,0,0,0,0,0,0,0,0,0,0,0,0,0,0,0,0,0,0,0,0,0,0,0,0,0
endlayer

layer
0,0,0,0,0,0,0,0,0,0,0,0,0,0,0,0,0,0,0,0,0,0,0,0,0,0
0,0,0,0,0,0,0,0,0,0,0,0,0,0,0,0,0,0,0,0,0,0,0,0,0,0
0,0,0,0,0,0,0,0,0,0,0,0,0,0,0,0,0,0,0,0,0,0,0,0,0,0
0,0,0,0,0,0,0,0,0,0,0,0,0,0,0,0,0,0,0,0,0,0,0,0,0,0
0,0,0,0,0,0,16,16,0,0,0,0,0,0,0,0,0,0,0,0,0,0,0,0,0,0
0,0,0,0,16,16,16,16,16,16,0,0,0,0,0,0,0,0,0,0,0,0,0,0,0,0
0,0,0,0,16,16,16,16,16,16,0,0,0,0,0,0,0,0,0,0,0,0,0,0,0,0
0,0,0,16,16,16,16,16,16,16,16,0,0,0,0,0,0,10,0,0,0,0,0,0,0,0
0,0,0,16,16,16,16,16,16,16,16,0,0,0,0,0,12,7,7,11,0,0,0,0,0,0
0,0,0,0,16,16,16,16,16,16,0,0,0,0,0,0,12,7,7,11,0,0,0,0,0,0
0,0,0,0,16,16,16,16,16,16,0,0,0,0,0,0,0,7,0,0,0,0,0,0,0,0
0,0,0,0,0,0,16,16,0,0,0,0,0,0,0,0,0,0,0,0,0,0,0,0,0,0
0,0,0,0,0,0,0,0,0,0,0,0,0,0,0,0,0,0,0,0,0,0,0,0,0,0
0,0,0,0,0,0,0,0,0,0,0,0,0,0,0,0,0,0,0,0,0,0,0,0,0,0
0,0,0,0,0,0,0,0,0,0,0,0,0,0,0,0,0,0,0,0,0,0,0,0,0,0
0,0,0,0,0,0,0,0,0,0,0,0,0,0,0,0,0,0,0,0,0,0,0,0,0,0
0,0,0,0,0,0,0,0,0,0,0,0,0,0,0,0,0,0,0,0,0,0,0,0,0,0
endlayer

layer
0,0,0,0,0,0,0,0,0,0,0,0,0,0,0,0,0,0,0,0,0,0,0,0,0,0
0,0,0,0,0,0,0,0,0,0,0,0,0,0,0,0,0,0,0,0,0,0,0,0,0,0
0,0,0,0,0,0,0,0,0,0,0,0,0,0,0,0,0,0,0,0,0,0,0,0,0,0
0,0,0,0,0,0,0,0,0,0,0,0,0,0,0,0,0,0,0,0,0,0,0,0,0,0
0,0,0,0,0,0,0,0,0,0,0,0,0,0,0,0,0,0,0,0,0,0,0,0,0,0
0,0,0,0,0,0,0,0,0,0,0,0,0,0,0,19,19,19,19,19,19,19,0,0,0,0
0,0,0,0,0,0,0,0,0,0,0,0,0,0,19,19,19,19,19,19,19,19,19,0,0,0
0,0,0,0,0,0,0,0,0,0,0,0,0,0,19,19,21,20,20,23,19,19,19,0,0,0
0,0,0,0,0,0,0,0,0,0,0,0,0,0,19,19,12,7,7,23,19,19,19,0,0,0
0,0,0,0,0,0,0,0,0,0,0,0,0,0,19,19,21,7,7,23,19,19,19,0,0,0
0,0,0,0,0,0,0,0,0,0,0,0,0,0,19,19,21,24,24,23,19,19,19,0,0,0
0,0,0,0,0,0,0,0,0,0,0,0,0,0,19,0,7,19,19,19,19,19,19,0,0,0
0,0,0,0,0,0,0,0,0,0,0,0,0,0,0,0,7,19,19,19,19,19,19,0,0,0
0,0,0,0,0,0,0,0,0,0,0,0,0,0,0,0,0,0,0,0,0,0,0,0,0,0
0,0,0,0,0,0,0,0,0,0,0,0,0,0,0,0,0,0,0,0,0,0,0,0,0,0
0,0,0,0,0,0,0,0,0,0,0,0,0,0,0,0,0,0,0,0,0,0,0,0,0,0
0,0,0,0,0,0,0,0,0,0,0,0,0,0,0,0,0,0,0,0,0,0,0,0,0,0
endlayer

layer
0,0,0,0,0,0,0,0,0,0,0,0,0,0,0,0,0,0,0,0,0,0,0,0,0,0
0,0,0,0,0,0,0,0,0,0,0,0,0,0,0,0,0,0,0,0,0,0,0,0,0,0
0,0,0,0,0,0,0,0,0,0,0,0,0,0,0,0,0,0,0,0,0,0,0,0,0,0
0,0,0,0,0,0,0,0,0,0,0,0,0,0,0,0,0,0,0,0,0,0,0,0,0,0
0,0,0,0,0,0,0,0,0,0,0,0,0,0,0,0,0,0,0,0,0,0,0,0,0,0
0,0,0,0,0,0,0,0,0,0,0,0,0,0,0,27,27,27,27,27,27,27,0,0,0,0
0,0,0,0,0,0,0,0,0,0,0,0,0,0,27,0,0,0,0,0,29,28,27,0,0,0
0,0,0,0,0,0,0,0,0,0,0,0,0,0,27,0,0,10,10,0,0,0,27,0,0,0
0,0,0,0,0,0,0,0,0,0,0,0,0,0,27,0,12,7,7,11,0,30,27,0,0,0
0,0,0,0,0,0,0,0,0,0,0,0,0,0,27,0,12,7,7,11,0,31,27,0,0,0
0,0,0,0,0,0,0,0,0,0,0,0,0,0,27,0,0,13,13,0,0,32,27,0,0,0
0,0,0,0,0,0,0,0,0,0,0,0,0,0,27,16,26,0,0,0,0,33,27,0,0,0
0,0,0,0,0,0,0,0,0,0,0,0,0,0,16,16,16,27,27,27,27,27,27,0,0,0
0,0,0,0,0,0,0,0,0,0,0,0,0,16,16,7,16,16,0,0,0,0,0,0,0,0
0,0,0,0,0,0,0,0,0,0,0,0,0,0,16,16,16,0,0,0,0,0,0,0,0,0
0,0,0,0,0,0,0,0,0,0,0,0,0,0,0,16,0,0,0,0,0,0,0,0,0,0
0,0,0,0,0,0,0,0,0,0,0,0,0,0,0,0,0,0,0,0,0,0,0,0,0,0
endlayer

layer
0,0,0,0,0,0,0,0,0,0,0,0,0,0,0,0,0,0,0,0,0,0,0,0,0,0
0,0,0,0,0,0,0,0,0,0,0,0,0,0,0,0,0,0,0,0,0,0,0,0,0,0
0,0,0,0,0,0,0,0,0,0,0,0,0,0,0,0,0,0,0,0,0,0,0,0,0,0
0,0,0,0,0,0,0,0,0,0,0,0,0,0,0,0,0,0,0,0,0,0,0,0,0,0
0,0,0,0,0,0,0,0,0,0,0,0,0,0,0,0,0,0,0,0,0,0,0,0,0,0
0,0,0,0,0,0,0,0,0,0,0,0,0,0,0,27,25,25,27,25,25,27,0,0,0,0
0,0,0,0,0,0,0,0,0,0,0,0,0,0,27,34,0,0,0,0,0,34,27,0,0,0
0,0,0,0,0,0,0,0,0,0,0,0,0,0,25,0,0,10,10,0,0,0,25,0,0,0
0,0,0,0,0,0,0,0,0,0,0,0,0,0,25,0,12,7,7,11,0,0,25,0,0,0
0,0,0,0,0,0,0,0,0,0,0,0,0,0,27,0,12,7,7,11,0,0,27,0,0,0
0,0,0,0,0,0,0,0,0,0,0,0,0,0,25,0,0,13,13,0,0,0,25,0,0,0
0,0,0,0,0,0,0,0,0,0,0,0,0,0,25,0,0,0,0,0,0,0,25,0,0,0
0,0,0,0,0,0,0,0,0,0,0,0,0,0,0,16,0,25,25,27,25,25,27,0,0,0
0,0,0,0,0,0,0,0,0,0,0,0,0,0,16,16,16,0,0,0,0,0,0,0,0,0
0,0,0,0,0,0,0,0,0,0,0,0,0,0,0,16,0,0,0,0,0,0,0,0,0,0
0,0,0,0,0,0,0,0,0,0,0,0,0,0,0,0,0,0,0,0,0,0,0,0,0,0
0,0,0,0,0,0,0,0,0,0,0,0,0,0,0,0,0,0,0,0,0,0,0,0,0,0
endlayer

layer
0,0,0,0,0,0,0,0,0,0,0,0,0,0,0,0,0,0,0,0,0,0,0,0,0,0
0,0,0,0,0,0,0,0,0,0,0,0,0,0,0,0,0,0,0,0,0,0,0,0,0,0
0,0,0,0,0,0,0,0,0,0,0,0,0,0,0,0,0,0,0,0,0,0,0,0,0,0
0,0,0,0,0,0,0,0,0,0,0,0,0,0,0,0,0,16,16,0,0,0,0,0,0,0
0,0,0,0,0,0,0,0,0,0,0,0,0,0,16,16,16,16,16,16,16,16,0,0,0,0
0,0,0,0,0,0,0,0,0,0,0,0,0,16,16,16,16,16,16,16,16,16,16,0,0,0
0,0,0,0,0,0,0,0,0,0,0,0,0,16,16,16,16,16,16,16,16,16,16,0,0,0
0,0,0,0,0,0,0,0,0,0,0,0,0,16,16,16,16,16,16,16,16,16,16,0,0,0
0,0,0,0,0,0,0,0,0,0,0,0,16,16,16,16,16,7,7,16,16,16,16,16,0,0
0,0,0,0,0,0,0,0,0,0,0,0,16,16,16,16,16,7,7,16,16,16,16,16,0,0
0,0,0,0,0,0,0,0,0,0,0,0,0,16,16,16,16,16,16,16,16,16,16,0,0,0
0,0,0,0,0,0,0,0,0,0,0,0,0,16,16,16,16,16,16,16,16,16,16,0,0,0
0,0,0,0,0,0,0,0,0,0,0,0,0,16,16,16,16,16,16,16,16,16,16,0,0,0
0,0,0,0,0,0,0,0,0,0,0,0,0,0,16,16,16,16,16,16,16,16,0,0,0,0
0,0,0,0,0,0,0,0,0,0,0,0,0,0,0,0,0,16,16,0,0,0,0,0,0,0
0,0,0,0,0,0,0,0,0,0,0,0,0,0,0,0,0,0,0,0,0,0,0,0,0,0
0,0,0,0,0,0,0,0,0,0,0,0,0,0,0,0,0,0,0,0,0,0,0,0,0,0
endlayer

layer
0,0,0,0,0,0,0,0,0,0,0,0,0,0,0,0,0,0,0,0,0,0,0,0,0,0
0,0,0,0,0,0,0,0,0,0,0,0,0,0,0,0,0,0,0,0,0,0,0,0,0,0
0,0,0,0,0,0,0,0,0,0,0,0,0,0,0,0,0,0,0,0,0,0,0,0,0,0
0,0,0,0,0,0,0,0,0,0,0,0,0,0,0,0,0,0,0,0,0,0,0,0,0,0
0,0,0,0,0,0,0,0,0,0,0,0,0,0,0,0,0,16,16,0,0,0,0,0,0,0
0,0,0,0,0,0,0,0,0,0,0,0,0,0,0,16,16,16,16,16,16,0,0,0,0,0
0,0,0,0,0,0,0,0,0,0,0,0,0,0,16,16,16,16,16,16,16,16,0,0,0,0
0,0,0,0,0,0,0,0,0,0,0,0,0,0,16,16,16,16,16,16,16,16,0,0,0,0
0,0,0,0,0,0,0,0,0,0,0,0,0,16,16,16,16,16,7,16,16,16,16,0,0,0
0,0,0,0,0,0,0,0,0,0,0,0,0,16,16,16,16,16,16,16,16,16,16,0,0,0
0,0,0,0,0,0,0,0,0,0,0,0,0,0,16,16,16,16,16,16,16,16,0,0,0,0
0,0,0,0,0,0,0,0,0,0,0,0,0,0,16,16,16,16,16,16,16,16,0,0,0,0
0,0,0,0,0,0,0,0,0,0,0,0,0,0,0,16,16,16,16,16,16,0,0,0,0,0
0,0,0,0,0,0,0,0,0,0,0,0,0,0,0,0,0,16,16,0,0,0,0,0,0,0
0,0,0,0,0,0,0,0,0,0,0,0,0,0,0,0,0,0,0,0,0,0,0,0,0,0
0,0,0,0,0,0,0,0,0,0,0,0,0,0,0,0,0,0,0,0,0,0,0,0,0,0
0,0,0,0,0,0,0,0,0,0,0,0,0,0,0,0,0,0,0,0,0,0,0,0,0,0
endlayer

layer
0,0,0,0,0,0,0,0,0,0,0,0,0,0,0,0,0,0,0,0,0,0,0,0,0,0
0,0,0,0,0,0,0,0,0,0,0,0,0,0,0,0,0,0,0,0,0,0,0,0,0,0
0,0,0,0,0,0,0,0,0,0,0,0,0,0,0,0,0,0,0,0,0,0,0,0,0,0
0,0,0,0,0,0,0,0,0,0,0,0,0,0,0,0,0,0,0,0,0,0,0,0,0,0
0,0,0,0,0,0,0,0,0,0,0,0,0,0,0,0,0,0,0,0,0,0,0,0,0,0
0,0,0,0,0,0,0,0,0,0,0,0,0,0,0,0,0,16,16,0,0,0,0,0,0,0
0,0,0,0,0,0,0,0,0,0,0,0,0,0,0,16,16,16,16,16,16,0,0,0,0,0
0,0,0,0,0,0,0,0,0,0,0,0,0,0,0,16,16,16,16,16,16,0,0,0,0,0
0,0,0,0,0,0,0,0,0,0,0,0,0,0,16,16,16,16,16,16,16,16,0,0,0,0
0,0,0,0,0,0,0,0,0,0,0,0,0,0,16,16,16,16,16,16,16,16,0,0,0,0
0,0,0,0,0,0,0,0,0,0,0,0,0,0,0,16,16,16,16,16,16,0,0,0,0,0
0,0,0,0,0,0,0,0,0,0,0,0,0,0,0,16,16,16,16,16,16,0,0,0,0,0
0,0,0,0,0,0,0,0,0,0,0,0,0,0,0,0,0,16,16,0,0,0,0,0,0,0
0,0,0,0,0,0,0,0,0,0,0,0,0,0,0,0,0,0,0,0,0,0,0,0,0,0
0,0,0,0,0,0,0,0,0,0,0,0,0,0,0,0,0,0,0,0,0,0,0,0,0,0
0,0,0,0,0,0,0,0,0,0,0,0,0,0,0,0,0,0,0,0,0,0,0,0,0,0
0,0,0,0,0,0,0,0,0,0,0,0,0,0,0,0,0,0,0,0,0,0,0,0,0,0
endlayer

