
# Created by Ruins mod version 14.7 Ingame Parser
# authoring Player: Barlock_James

weight=1
embed_into_distance=5
acceptable_target_blocks=
unacceptable_target_blocks=flowing_water,water,flowing_lava,lava
dimensions=8,18,21
allowable_overhang=0
max_leveling=2
leveling_buffer=0
preserve_water=0
preserve_lava=0

rule1=0,100,minecraft:snow-0
rule2=0,100,chisel:cobblestone-2
rule3=0,100,minecraft:netherrack-0
rule4=0,100,minecraft:bed-0
rule5=0,100,minecraft:bed-8
rule6=0,100,minecraft:carpet-0
rule7=0,100,IInventory;GardenContainers:decorative_pot;Botania:flower#1#0#0-0
rule8=0,100,minecraft:furnace-3
rule9=0,100,ChestGenHook:dungeonChest:5-3
rule10=0,100,minecraft:planks-2
rule11=0,100,minecraft:farmland-7
rule12=0,100,BiblioCraft:BiblioSwordPedestal-0
rule13=0,100,minecraft:wooden_door-3
rule14=0,100,minecraft:fire-15
rule15=0,100,minecraft:water-0
rule16=0,100,IInventory;BiblioCraft:BiblioSwordPedestal;Natura:natura.sword.netherquartz#1#0#0-0
rule17=0,100,minecraft:crafting_table-0
rule18=0,100,BiblioCraft:BiblioRack-0
rule19=0,100,BiblioCraft:BiblioCase-0
rule20=0,100,IInventory;BiblioCraft:BiblioShelf;minecraft:bow#1#0#0+minecraft:arrow#64#0#1-0
rule21=0,100,GardenCore:garden_proxy-0
rule22=0,100,minecraft:potatoes-0
rule23=0,100,minecraft:carrots-0
rule24=0,100,minecraft:wooden_door-8
rule25=0,100,minecraft:wheat-0

layer
1,1,1,1,1,1,1,1,1,1,1,1,1,1,1,1,1,1,1,1,1
1,1,1,1,1,1,1,1,1,1,1,1,1,1,1,1,1,1,1,1,1
1,1,1,1,1,1,1,1,1,1,1,1,1,1,1,1,1,1,1,1,1
1,1,1,1,1,1,1,1,1,1,1,1,1,1,1,1,1,1,1,1,1
1,1,1,1,1,1,1,1,1,1,1,1,1,1,1,1,1,1,1,1,1
1,1,1,1,1,1,1,1,1,1,1,1,1,1,1,1,1,1,1,1,1
1,1,1,1,1,1,1,1,1,1,1,1,1,1,1,1,1,1,1,1,1
1,1,1,1,1,1,1,1,1,1,2,1,1,1,1,1,1,1,1,1,1
1,1,1,1,1,1,1,1,1,2,3,2,1,1,1,1,1,1,1,1,1
1,1,1,1,1,1,1,1,1,1,2,1,1,1,1,1,1,1,1,1,1
1,1,1,1,1,1,1,1,1,1,1,1,1,1,1,1,1,1,1,1,1
1,1,1,1,1,1,1,1,1,1,5,4,1,1,1,1,1,1,1,1,1
1,1,1,1,1,1,1,1,1,1,1,1,1,1,1,1,1,1,1,1,1
1,1,1,1,1,1,1,1,1,1,1,1,1,1,1,1,1,1,1,1,1
1,1,1,1,1,1,1,1,1,1,1,1,1,1,1,1,1,1,1,1,1
1,1,1,1,1,1,1,1,1,1,1,1,1,1,1,1,1,1,1,1,1
1,1,1,1,1,1,1,1,1,1,1,1,1,1,1,1,1,1,1,1,1
1,1,1,1,1,1,1,1,1,1,1,1,1,1,1,1,1,1,1,1,1
endlayer

layer
1,1,1,1,1,1,1,1,1,1,1,1,1,1,1,1,1,1,1,1,1
1,1,1,1,1,1,1,1,1,1,1,1,1,1,1,1,1,1,1,1,1
1,1,1,1,1,1,1,1,1,6,6,6,6,6,1,1,1,1,1,1,1
1,1,1,1,1,1,1,1,7,6,6,6,6,6,0,1,1,1,1,1,1
1,1,1,1,1,1,1,7,0,6,6,6,6,6,0,0,1,1,1,1,1
1,1,1,1,1,1,7,0,0,6,6,6,6,6,0,0,8,1,1,1,1
1,1,1,1,1,11,10,0,0,0,0,0,0,0,0,0,9,1,1,1,1
1,1,1,1,1,11,10,0,0,0,0,0,0,0,0,12,1,1,1,1,1
1,1,1,1,1,15,10,0,0,0,14,0,0,0,0,0,13,1,1,1,1
1,1,1,1,1,11,10,0,0,0,0,0,0,0,0,16,1,1,1,1,1
1,1,1,1,1,11,10,0,0,0,0,0,0,0,0,0,9,1,1,1,1
1,1,1,1,1,1,10,0,0,0,0,0,0,0,0,0,17,1,1,1,1
1,1,1,1,1,1,1,0,0,0,0,0,0,0,0,0,1,1,1,1,1
1,1,1,1,1,1,1,1,0,0,0,0,0,0,0,1,1,1,1,1,1
1,1,1,1,1,1,1,1,1,0,0,0,0,0,1,1,1,1,1,1,1
1,1,1,1,1,1,1,1,1,1,1,1,1,1,1,1,1,1,1,1,1
1,1,1,1,1,1,1,1,1,1,1,1,1,1,1,1,1,1,1,1,1
1,1,1,1,1,1,1,1,1,1,1,1,1,1,1,1,1,1,1,1,1
endlayer

layer
1,1,1,1,1,1,1,1,1,1,1,1,1,1,1,1,1,1,1,1,1
1,1,1,1,1,1,1,1,1,1,1,1,1,1,1,1,1,1,1,1,1
1,1,1,1,1,1,1,1,1,0,20,19,18,0,1,1,1,1,1,1,1
1,1,1,1,1,1,1,1,21,0,0,0,0,0,0,1,1,1,1,1,1
1,1,1,1,1,1,1,21,0,0,0,0,0,0,0,0,1,1,1,1,1
1,1,1,1,1,1,21,0,0,0,0,0,0,0,0,0,0,1,1,1,1
1,1,1,1,1,22,0,0,0,0,0,0,0,0,0,0,0,1,1,1,1
1,1,1,1,1,23,0,0,0,0,0,0,0,0,0,0,1,1,1,1,1
1,1,1,1,1,0,0,0,0,0,0,0,0,0,0,0,24,0,1,1,1
1,1,1,1,1,25,0,0,0,0,0,0,0,0,0,0,1,1,1,1,1
1,1,1,1,1,25,0,0,0,0,0,0,0,0,0,0,0,1,1,1,1
1,1,1,1,1,1,0,0,0,0,0,0,0,0,0,0,0,1,1,1,1
1,1,1,1,1,1,1,0,0,0,0,0,0,0,0,0,1,1,1,1,1
1,1,1,1,1,1,1,1,0,0,0,0,0,0,0,1,1,1,1,1,1
1,1,1,1,1,1,1,1,1,0,0,0,0,0,1,1,1,1,1,1,1
1,1,1,1,1,1,1,1,1,1,1,1,1,1,1,1,1,1,1,1,1
1,1,1,1,1,1,1,1,1,1,1,1,1,1,1,1,1,1,1,1,1
1,1,1,1,1,1,1,1,1,1,1,1,1,1,1,1,1,1,1,1,1
endlayer

layer
1,1,1,1,1,1,1,1,1,1,1,1,1,1,1,1,1,1,1,1,1
1,1,1,1,1,1,1,1,1,1,1,1,1,1,1,1,1,1,1,1,1
1,1,1,1,1,1,1,1,1,1,1,1,1,1,1,1,1,1,1,1,1
1,1,1,1,1,1,1,1,1,0,0,0,0,0,1,1,1,1,1,1,1
1,1,1,1,1,1,1,1,0,0,0,0,0,0,0,1,1,1,1,1,1
1,1,1,1,1,1,1,0,0,0,0,0,0,0,0,0,1,1,1,1,1
1,1,1,1,1,1,0,0,0,0,0,0,0,0,0,0,1,1,1,1,1
1,1,1,1,1,1,0,0,0,0,0,0,0,0,0,1,1,1,1,1,1
1,1,1,1,1,1,0,0,0,0,0,0,0,0,0,1,0,0,0,1,1
1,1,1,1,1,1,0,0,0,0,0,0,0,0,0,1,1,1,1,1,1
1,1,1,1,1,1,0,0,0,0,0,0,0,0,0,0,1,1,1,1,1
1,1,1,1,1,1,1,0,0,0,0,0,0,0,0,0,1,1,1,1,1
1,1,1,1,1,1,1,1,0,0,0,0,0,0,0,1,1,1,1,1,1
1,1,1,1,1,1,1,1,1,0,0,0,0,0,1,1,1,1,1,1,1
1,1,1,1,1,1,1,1,1,1,1,1,1,1,1,1,1,1,1,1,1
1,1,1,1,1,1,1,1,1,1,1,1,1,1,1,1,1,1,1,1,1
1,1,1,1,1,1,1,1,1,1,1,1,1,1,1,1,1,1,1,1,1
1,1,1,1,1,1,1,1,1,1,1,1,1,1,1,1,1,1,1,1,1
endlayer

layer
0,0,0,0,0,0,0,0,0,0,0,0,0,0,0,0,0,0,0,0,0
0,0,0,0,0,0,0,0,0,0,0,0,0,0,0,0,0,0,0,0,0
0,0,0,0,0,0,0,0,0,0,0,0,0,0,0,0,0,0,0,0,0
0,0,0,0,0,0,0,0,0,1,1,1,1,1,0,0,0,0,0,0,0
0,0,0,0,0,0,0,0,1,0,0,0,0,0,1,0,0,0,0,0,0
0,0,0,0,0,0,0,1,0,0,0,0,0,0,0,1,0,0,0,0,0
0,0,0,0,0,0,1,0,0,0,0,0,0,0,0,1,0,0,0,0,0
0,0,0,0,0,0,1,0,0,0,0,0,0,0,0,1,1,1,1,0,0
0,0,0,0,0,0,1,0,0,0,0,0,0,0,0,1,0,0,0,0,0
0,0,0,0,0,0,1,0,0,0,0,0,0,0,0,1,1,1,1,0,0
0,0,0,0,0,0,1,0,0,0,0,0,0,0,0,1,0,0,0,0,0
0,0,0,0,0,0,0,1,0,0,0,0,0,0,0,1,0,0,0,0,0
0,0,0,0,0,0,0,0,1,0,0,0,0,0,1,0,0,0,0,0,0
0,0,0,0,0,0,0,0,0,1,1,1,1,1,0,0,0,0,0,0,0
0,0,0,0,0,0,0,0,0,0,0,0,0,0,0,0,0,0,0,0,0
0,0,0,0,0,0,0,0,0,0,0,0,0,0,0,0,0,0,0,0,0
0,0,0,0,0,0,0,0,0,0,0,0,0,0,0,0,0,0,0,0,0
0,0,0,0,0,0,0,0,0,0,0,0,0,0,0,0,0,0,0,0,0
endlayer

layer
0,0,0,0,0,0,0,0,0,0,0,0,0,0,0,0,0,0,0,0,0
0,0,0,0,0,0,0,0,0,0,0,0,0,0,0,0,0,0,0,0,0
0,0,0,0,0,0,0,0,0,0,0,0,0,0,0,0,0,0,0,0,0
0,0,0,0,0,0,0,0,0,0,0,0,0,0,0,0,0,0,0,0,0
0,0,0,0,0,0,0,0,0,1,1,1,1,1,0,0,0,0,0,0,0
0,0,0,0,0,0,0,0,1,0,0,0,0,1,1,0,0,0,0,0,0
0,0,0,0,0,0,0,1,0,0,0,0,0,0,1,0,0,0,0,0,0
0,0,0,0,0,0,0,1,0,0,0,0,0,0,1,1,1,1,1,0,0
0,0,0,0,0,0,0,1,0,0,0,0,0,0,1,1,1,0,0,0,0
0,0,0,0,0,0,0,1,0,0,0,0,0,0,1,1,1,1,1,0,0
0,0,0,0,0,0,0,1,0,0,0,0,0,0,1,0,0,0,0,0,0
0,0,0,0,0,0,0,0,1,0,0,0,0,1,1,0,0,0,0,0,0
0,0,0,0,0,0,0,0,0,1,1,1,1,1,0,0,0,0,0,0,0
0,0,0,0,0,0,0,0,0,0,0,0,0,0,0,0,0,0,0,0,0
0,0,0,0,0,0,0,0,0,0,0,0,0,0,0,0,0,0,0,0,0
0,0,0,0,0,0,0,0,0,0,0,0,0,0,0,0,0,0,0,0,0
0,0,0,0,0,0,0,0,0,0,0,0,0,0,0,0,0,0,0,0,0
0,0,0,0,0,0,0,0,0,0,0,0,0,0,0,0,0,0,0,0,0
endlayer

layer
0,0,0,0,0,0,0,0,0,0,0,0,0,0,0,0,0,0,0,0,0
0,0,0,0,0,0,0,0,0,0,0,0,0,0,0,0,0,0,0,0,0
0,0,0,0,0,0,0,0,0,0,0,0,0,0,0,0,0,0,0,0,0
0,0,0,0,0,0,0,0,0,0,0,0,0,0,0,0,0,0,0,0,0
0,0,0,0,0,0,0,0,0,0,0,0,0,0,0,0,0,0,0,0,0
0,0,0,0,0,0,0,0,0,1,1,1,1,0,0,0,0,0,0,0,0
0,0,0,0,0,0,0,0,1,1,0,0,1,1,0,0,0,0,0,0,0
0,0,0,0,0,0,0,0,1,0,0,0,0,1,0,0,0,0,0,0,0
0,0,0,0,0,0,0,0,1,0,0,0,0,1,1,1,1,1,1,0,0
0,0,0,0,0,0,0,0,1,0,0,0,0,1,0,0,0,0,0,0,0
0,0,0,0,0,0,0,0,1,1,0,0,1,1,0,0,0,0,0,0,0
0,0,0,0,0,0,0,0,0,1,1,1,1,0,0,0,0,0,0,0,0
0,0,0,0,0,0,0,0,0,0,0,0,0,0,0,0,0,0,0,0,0
0,0,0,0,0,0,0,0,0,0,0,0,0,0,0,0,0,0,0,0,0
0,0,0,0,0,0,0,0,0,0,0,0,0,0,0,0,0,0,0,0,0
0,0,0,0,0,0,0,0,0,0,0,0,0,0,0,0,0,0,0,0,0
0,0,0,0,0,0,0,0,0,0,0,0,0,0,0,0,0,0,0,0,0
0,0,0,0,0,0,0,0,0,0,0,0,0,0,0,0,0,0,0,0,0
endlayer

layer
0,0,0,0,0,0,0,0,0,0,0,0,0,0,0,0,0,0,0,0,0
0,0,0,0,0,0,0,0,0,0,0,0,0,0,0,0,0,0,0,0,0
0,0,0,0,0,0,0,0,0,0,0,0,0,0,0,0,0,0,0,0,0
0,0,0,0,0,0,0,0,0,0,0,0,0,0,0,0,0,0,0,0,0
0,0,0,0,0,0,0,0,0,0,0,0,0,0,0,0,0,0,0,0,0
0,0,0,0,0,0,0,0,0,0,0,0,0,0,0,0,0,0,0,0,0
0,0,0,0,0,0,0,0,0,0,1,1,0,0,0,0,0,0,0,0,0
0,0,0,0,0,0,0,0,0,1,1,1,1,0,0,0,0,0,0,0,0
0,0,0,0,0,0,0,0,0,1,0,1,1,0,0,0,0,0,0,0,0
0,0,0,0,0,0,0,0,0,1,1,1,1,0,0,0,0,0,0,0,0
0,0,0,0,0,0,0,0,0,0,1,1,0,0,0,0,0,0,0,0,0
0,0,0,0,0,0,0,0,0,0,0,0,0,0,0,0,0,0,0,0,0
0,0,0,0,0,0,0,0,0,0,0,0,0,0,0,0,0,0,0,0,0
0,0,0,0,0,0,0,0,0,0,0,0,0,0,0,0,0,0,0,0,0
0,0,0,0,0,0,0,0,0,0,0,0,0,0,0,0,0,0,0,0,0
0,0,0,0,0,0,0,0,0,0,0,0,0,0,0,0,0,0,0,0,0
0,0,0,0,0,0,0,0,0,0,0,0,0,0,0,0,0,0,0,0,0
0,0,0,0,0,0,0,0,0,0,0,0,0,0,0,0,0,0,0,0,0
endlayer

