
# Created by Ruins mod version 14.7 Ingame Parser
# authoring Player: saphrym

weight=1
embed_into_distance=0
acceptable_target_blocks=
unacceptable_target_blocks=flowing_water,water,flowing_lava,lava
dimensions=10,7,5
allowable_overhang=0
max_leveling=2
leveling_buffer=0
preserve_water=0
preserve_lava=0

rule1=0,100,chisel:mossy_cobblestone-9
rule2=0,100,chisel:cobblestone-13
rule3=0,100,chisel:mossy_cobblestone-7
rule4=0,100,minecraft:water-1
rule5=0,100,minecraft:water-2
rule6=0,100,minecraft:water-9
rule7=0,100,chisel:mossy_cobblestone-3
rule8=0,100,minecraft:water-0
rule9=0,100,Railcraft:tile.railcraft.slab-0

layer
0,0,0,0,0
0,3,2,1,0
1,4,5,4,3
7,6,2,6,1
1,4,5,4,1
0,7,2,1,0
0,0,0,0,0
endlayer

layer
0,0,0,0,0
0,0,0,0,0
0,0,2,0,0
0,6,2,6,0
0,0,2,0,0
0,0,0,0,0
0,0,0,0,0
endlayer

layer
0,0,0,0,0
0,0,2,0,0
0,0,2,0,0
0,4,8,4,0
0,0,2,0,0
0,0,2,0,0
0,0,0,0,0
endlayer

layer
0,0,0,0,0
0,0,0,0,0
0,0,2,0,0
0,0,2,0,0
0,0,2,0,0
0,0,0,0,0
0,0,0,0,0
endlayer

layer
0,0,0,0,0
0,0,2,0,0
0,0,0,0,0
0,0,2,0,0
0,0,0,0,0
0,0,2,0,0
0,0,0,0,0
endlayer

layer
0,0,0,0,0
0,0,0,0,0
0,0,0,0,0
0,0,0,0,0
0,0,0,0,0
0,0,0,0,0
0,0,0,0,0
endlayer

layer
0,0,0,0,0
0,0,0,0,0
0,0,0,0,0
0,0,0,0,0
0,0,0,0,0
0,0,0,0,0
0,0,0,0,0
endlayer

layer
0,0,0,0,0
0,0,0,0,0
0,0,0,0,0
0,0,0,0,0
0,0,0,0,0
0,0,0,0,0
0,0,0,0,0
endlayer

layer
0,0,0,0,0
0,0,0,9,9
0,0,9,9,9
0,0,9,9,0
0,0,9,9,9
0,0,0,9,9
0,0,0,0,0
endlayer

layer
0,0,0,0,0
0,0,0,0,0
0,0,0,0,0
0,0,0,0,9
0,0,0,0,0
0,0,0,0,0
0,0,0,0,0
endlayer

