
# Created by Ruins mod version 14.7 Ingame Parser
# authoring Player: Barlock_James

weight=1
embed_into_distance=1
acceptable_target_blocks=
unacceptable_target_blocks=flowing_water,water,flowing_lava,lava
dimensions=7,10,4
allowable_overhang=0
max_leveling=2
leveling_buffer=0
preserve_water=0
preserve_lava=0

rule1=0,100,minecraft:grass-0
rule2=0,100,ChestGenHook:dungeonChest:5-4
rule3=0,100,minecraft:stained_glass-4
rule4=0,100,minecraft:double_plant-2
rule5=0,100,minecraft:yellow_flower-0
rule6=0,100,Natura:Natura.fence-7
rule7=0,100,minecraft:tallgrass-1
rule8=0,100,minecraft:stained_glass-0
rule9=0,100,minecraft:double_plant-8
rule10=0,100,ExtraUtilities:decorativeBlock2-7
rule11=0,100,minecraft:stained_glass-15
rule12=0,100,minecraft:stained_glass-10

layer
1,1,1,1
1,1,1,1
1,1,1,1
1,1,1,1
1,1,1,1
1,1,1,1
1,1,1,1
1,2,2,1
1,3,3,1
1,1,1,1
endlayer

layer
4,4,5,4
4,6,6,4
4,4,4,4
4,7,7,4
4,7,7,7
7,3,3,4
4,3,3,4
4,8,8,4
4,8,8,4
4,4,7,4
endlayer

layer
9,9,0,9
9,10,10,9
9,9,9,9
9,3,3,9
9,3,3,0
0,8,8,9
9,8,8,9
9,11,11,9
9,11,11,9
9,9,0,9
endlayer

layer
0,0,0,0
0,3,3,0
0,3,3,0
0,8,8,0
0,8,8,0
0,11,11,0
0,11,11,0
0,12,12,0
0,12,12,0
0,0,0,0
endlayer

layer
0,0,0,0
0,8,8,0
0,8,8,0
0,11,11,0
0,11,11,0
0,12,12,0
0,12,12,0
0,0,0,0
0,0,0,0
0,0,0,0
endlayer

layer
0,0,0,0
0,11,11,0
0,11,11,0
0,12,12,0
0,12,12,0
0,0,0,0
0,0,0,0
0,0,0,0
0,0,0,0
0,0,0,0
endlayer

layer
0,0,0,0
0,12,12,0
0,12,12,0
0,0,0,0
0,0,0,0
0,0,0,0
0,0,0,0
0,0,0,0
0,0,0,0
0,0,0,0
endlayer

