
# Created by Ruins mod version 14.7 Ingame Parser
# authoring Player: Barlock_James

weight=1
embed_into_distance=1
acceptable_target_blocks=
unacceptable_target_blocks=flowing_water,water,flowing_lava,lava
dimensions=8,31,31
allowable_overhang=0
max_leveling=2
leveling_buffer=0
preserve_water=0
preserve_lava=0

rule1=0,100,minecraft:grass-0
rule2=0,100,minecraft:stonebrick-2
rule3=0,100,minecraft:stonebrick-0
rule4=0,100,minecraft:dirt-0
rule5=0,100,minecraft:stonebrick-1
rule6=0,100,minecraft:tallgrass-1
rule7=0,100,minecraft:double_plant-2
rule8=0,100,minecraft:vine-8
rule9=0,100,minecraft:vine-1
rule10=0,100,Botania:flower-9
rule11=0,100,Botania:flower-1
rule12=0,100,minecraft:vine-9
rule13=0,100,minecraft:vine-2
rule14=0,100,Botania:flower-2
rule15=0,100,minecraft:vine-3
rule16=0,100,minecraft:yellow_flower-0
rule17=0,100,minecraft:vine-4
rule18=0,100,minecraft:stone_brick_stairs-5
rule19=0,100,minecraft:stone_slab-13
rule20=0,100,minecraft:stone_brick_stairs-4
rule21=0,100,Botania:flower-5
rule22=0,100,Botania:flower-12
rule23=0,100,Botania:flower-6
rule24=0,100,Botania:flower-15
rule25=0,100,minecraft:double_plant-8
rule26=0,100,ChestGenHook:dungeonChest:5-4
rule27=2,100,minecraft:torch-2
rule28=0,100,minecraft:stone_brick_stairs-7
rule29=0,100,minecraft:stone_brick_stairs-6
rule30=0,100,minecraft:stone_brick_stairs-0
rule31=0,100,minecraft:stone_brick_stairs-2
rule32=0,100,minecraft:stone_brick_stairs-3
rule33=0,100,minecraft:stone_brick_stairs-1
rule34=2,100,minecraft:torch-3
rule35=2,100,minecraft:torch-4

layer
0,0,0,0,0,0,0,0,0,0,1,1,0,0,2,3,2,1,1,1,1,1,1,1,1,1,1,1,1,1,0
0,0,0,0,0,0,0,0,0,0,1,1,1,0,3,3,3,1,1,1,1,1,1,1,1,1,1,1,1,1,1
0,0,0,0,0,0,0,0,1,1,1,1,1,1,3,3,3,1,1,1,1,1,1,1,1,1,1,1,1,1,1
0,0,0,0,0,0,0,1,1,1,1,1,1,1,3,3,3,1,1,1,1,1,1,1,1,1,1,1,1,1,1
0,0,0,0,0,0,1,1,1,1,1,1,1,4,3,3,3,4,1,1,1,1,1,1,1,1,1,1,1,1,1
0,0,0,0,0,1,1,1,1,1,1,1,1,3,3,3,3,3,1,1,1,1,1,1,1,1,1,1,1,1,1
0,0,0,0,1,1,1,1,1,4,1,1,3,1,3,3,3,1,3,1,1,4,1,1,1,1,1,1,1,1,1
0,0,0,1,1,1,1,1,4,1,1,3,1,4,3,3,3,4,1,3,1,1,4,1,1,1,1,1,1,1,1
0,0,1,1,1,1,1,4,1,1,3,1,1,1,3,3,3,1,1,1,3,1,1,4,1,1,1,1,1,1,1
0,1,1,1,1,1,4,1,1,3,1,1,1,1,3,3,3,1,1,1,1,3,1,1,4,1,1,1,1,1,1
0,1,1,1,1,4,1,3,3,1,1,4,1,4,3,3,3,4,1,4,1,1,3,3,1,4,1,1,1,1,1
1,1,1,1,4,1,1,3,3,1,4,1,1,1,3,3,3,1,1,1,4,1,3,3,1,1,4,1,1,1,1
1,1,1,1,1,1,3,1,1,3,1,1,1,1,3,3,3,1,1,1,1,3,1,1,3,1,1,1,1,1,1
1,1,1,1,1,3,1,1,4,1,3,1,1,1,3,3,3,1,1,1,3,1,4,1,1,3,1,1,1,1,1
1,1,1,1,3,1,1,4,1,1,1,3,1,1,3,3,3,1,1,3,1,1,1,4,1,1,3,1,1,1,1
1,1,4,3,1,1,1,1,1,1,1,1,3,4,5,5,5,4,5,1,1,1,1,1,1,1,1,3,4,1,1
1,1,4,1,1,1,1,4,1,1,1,1,1,5,3,3,3,5,1,1,1,1,1,4,1,1,1,1,4,1,1
1,1,4,3,3,3,3,3,3,3,3,3,3,5,2,3,3,5,3,3,3,3,3,3,3,3,3,3,4,1,1
1,1,4,1,1,1,1,4,1,1,1,1,1,5,3,3,3,5,1,1,1,1,1,4,1,1,1,1,4,1,1
1,1,4,3,1,1,1,1,1,1,1,1,3,4,5,5,5,4,3,1,1,1,1,1,1,1,1,3,4,1,1
1,1,1,1,3,1,1,4,1,1,1,2,1,1,3,3,3,1,1,3,1,1,1,4,1,1,3,1,1,1,1
1,1,1,1,1,3,1,1,4,1,3,1,1,1,3,3,3,1,1,1,3,1,4,1,1,3,1,1,1,1,1
1,1,1,1,1,1,3,1,1,3,1,1,1,1,3,3,3,1,1,1,1,3,1,1,3,1,1,1,1,1,4
1,1,1,1,4,1,1,3,3,1,3,1,1,1,3,2,3,1,1,1,4,1,3,3,1,1,4,1,1,1,1
1,1,1,1,1,4,1,3,3,1,1,4,1,4,3,3,3,4,1,4,1,1,3,3,1,4,1,1,1,1,1
1,1,1,1,1,1,4,1,1,3,1,1,1,1,2,3,3,1,1,1,1,3,1,1,4,1,1,1,1,1,1
1,1,1,1,1,1,1,4,1,1,3,1,1,1,3,3,3,1,1,1,3,4,4,4,1,1,1,1,1,1,1
1,1,1,1,1,1,1,1,4,1,1,3,1,1,3,3,3,1,1,3,4,4,4,4,4,1,1,1,1,1,4
1,1,1,1,1,1,1,1,1,1,1,1,3,1,3,3,3,1,5,4,4,4,4,4,4,4,4,4,4,4,4
1,1,1,1,1,1,1,1,1,1,1,1,1,4,4,4,4,4,4,4,4,4,4,4,4,4,4,4,4,4,4
1,1,1,1,1,1,1,1,1,1,1,1,1,1,1,1,1,4,4,4,4,4,4,4,4,4,4,4,4,4,1
endlayer

layer
0,0,0,0,0,0,0,0,0,0,0,6,0,0,0,0,0,6,0,0,0,6,0,0,7,0,0,6,6,6,0
0,0,0,0,0,0,0,0,0,0,0,6,0,0,0,0,0,6,0,6,6,6,0,0,0,0,0,0,0,6,0
0,0,0,0,0,0,0,0,0,0,0,6,6,0,0,0,0,0,0,6,6,6,6,0,0,6,0,6,6,0,7
0,0,0,0,0,0,0,6,0,0,6,0,0,8,0,0,8,0,0,0,0,7,6,6,6,7,0,6,0,0,0
0,0,0,0,0,0,6,0,0,6,6,0,6,5,9,0,0,3,0,0,0,0,6,6,6,6,0,0,0,6,0
0,0,0,0,0,0,0,0,0,0,0,0,6,0,0,0,0,0,6,0,0,7,0,6,0,0,0,0,6,6,0
0,0,0,0,11,0,0,6,0,2,0,10,0,0,0,0,0,0,0,0,0,3,0,6,0,6,0,0,0,6,0
0,0,0,0,0,6,0,0,3,0,0,0,0,3,0,0,0,3,0,0,6,6,2,12,0,6,0,0,0,0,6
0,0,0,0,0,6,6,3,0,10,0,0,0,0,0,13,13,0,6,0,0,0,0,5,9,0,0,0,0,0,0
0,0,0,0,0,0,3,9,6,0,0,6,0,6,0,0,0,0,7,0,0,0,0,0,3,0,0,0,0,0,6
0,0,0,0,6,3,15,0,0,6,0,3,0,3,0,0,0,3,0,3,6,0,0,0,0,3,0,0,0,14,0
0,0,0,0,3,0,0,0,0,6,3,0,0,6,13,0,0,0,0,0,3,8,0,0,0,0,3,6,0,6,0
6,0,6,0,6,0,0,0,0,3,6,6,6,0,0,0,0,0,0,0,0,3,0,0,0,6,0,0,0,0,0
0,0,0,0,0,0,0,0,3,0,0,0,0,0,0,0,0,0,0,0,0,0,3,0,0,0,0,0,0,0,0
6,6,6,0,0,0,0,3,6,0,0,0,7,0,0,0,0,8,0,0,0,0,0,3,0,0,0,0,0,0,6
6,0,3,0,0,7,16,0,0,0,6,0,0,3,0,0,0,3,9,0,0,0,0,8,0,0,6,0,3,0,0
0,0,3,9,0,6,0,3,6,0,6,0,0,0,18,18,18,0,6,0,7,0,17,3,9,0,0,0,5,0,6
6,0,5,9,0,0,0,0,0,0,0,0,0,0,19,19,19,0,0,0,0,0,0,0,0,0,0,0,3,0,0
0,0,3,9,6,0,6,2,6,6,0,6,6,0,20,20,20,0,0,6,0,0,6,3,0,6,0,0,2,6,6
0,0,2,0,0,0,6,0,0,6,21,6,0,3,0,0,0,3,0,0,0,7,6,7,7,7,0,0,3,6,0
0,0,0,0,0,0,6,3,6,0,21,0,6,7,0,0,0,6,6,0,0,6,6,3,0,0,0,0,0,0,6
6,0,6,6,6,0,6,0,3,7,0,0,0,0,0,0,0,0,0,0,0,0,3,0,0,0,0,0,6,0,0
6,6,0,0,0,0,0,6,6,3,0,6,6,6,0,0,0,6,7,6,0,3,0,0,0,0,0,0,6,6,0
7,6,7,6,3,6,0,0,0,22,3,0,0,8,0,0,0,0,0,0,3,0,0,0,0,0,3,0,0,0,0
0,0,0,0,0,3,12,0,0,6,0,3,6,2,0,0,0,3,6,3,0,0,0,0,6,3,0,23,7,7,7
7,6,0,0,6,0,3,12,0,0,6,6,7,6,0,0,0,0,0,0,0,0,0,7,3,6,0,0,0,0,6
6,6,6,6,0,6,0,3,9,0,0,7,0,0,0,0,0,0,0,0,0,1,1,3,0,0,0,0,0,6,6
0,6,6,0,0,0,0,0,3,0,0,0,6,7,0,0,0,0,0,0,1,1,4,1,1,0,6,0,6,6,1
0,6,0,6,0,0,6,0,6,0,6,0,0,0,0,0,0,0,0,1,1,1,1,1,1,1,1,1,1,1,1
0,0,0,0,0,0,0,0,0,0,0,0,0,3,5,3,3,5,1,1,1,1,1,1,1,1,1,1,1,1,1
6,0,6,0,0,0,0,0,0,6,7,0,0,0,24,13,24,1,1,1,1,1,1,1,1,1,1,1,1,1,0
endlayer

layer
0,0,0,0,0,0,0,0,0,0,0,0,0,0,0,0,0,0,0,0,0,0,0,0,25,0,0,0,0,0,0
0,0,0,0,0,0,0,0,0,0,0,0,0,0,0,0,0,0,0,0,0,0,0,0,0,0,0,0,0,0,0
0,0,0,0,0,0,0,0,0,0,0,0,0,0,0,0,0,0,0,0,0,0,0,0,0,0,0,0,0,0,25
0,0,0,0,0,0,0,0,0,0,0,0,0,8,0,0,8,0,0,0,0,25,0,0,0,25,0,0,0,0,0
0,0,0,0,0,0,0,0,0,0,0,0,17,3,0,0,0,3,0,0,0,0,0,0,0,0,0,0,0,0,0
0,0,0,0,0,0,0,0,0,0,0,0,0,0,0,0,0,0,0,0,0,25,0,0,0,0,0,0,0,0,0
0,0,0,0,0,0,0,0,0,3,0,0,0,0,0,0,0,0,0,0,0,3,0,0,0,0,0,0,0,0,0
0,0,0,0,0,0,0,0,3,0,0,0,0,3,0,0,0,3,0,0,0,0,3,8,0,0,0,0,0,0,0
0,0,0,0,0,0,0,3,0,0,0,0,0,0,0,13,13,0,0,0,0,0,0,3,9,0,0,0,0,0,0
0,0,0,0,0,0,3,9,0,0,0,0,0,0,0,0,0,0,25,0,0,0,0,0,3,0,0,0,0,0,0
0,0,0,0,0,2,13,0,0,0,0,0,0,3,0,0,0,3,0,0,0,0,0,0,0,2,0,0,0,0,0
0,0,0,0,3,0,0,0,0,0,3,0,0,0,13,0,0,0,0,0,3,8,0,0,0,0,3,0,0,0,0
0,0,0,0,0,0,0,0,17,3,0,0,0,0,0,0,0,0,0,0,0,3,0,0,0,0,0,0,0,0,0
0,0,0,0,0,0,0,0,3,13,0,0,0,0,0,0,0,0,0,0,0,0,3,0,0,0,0,0,0,0,0
0,0,0,0,0,0,0,0,0,0,0,0,25,0,0,0,0,8,0,0,0,0,0,0,0,0,0,0,0,0,0
0,0,3,0,0,25,0,0,0,0,0,0,0,3,0,0,0,3,9,0,0,0,0,8,0,0,0,0,5,0,0
0,0,5,9,0,0,0,2,0,0,0,0,0,0,0,0,0,0,0,0,25,0,0,3,9,0,0,0,3,0,0
0,0,3,9,0,0,0,0,0,0,0,0,0,0,0,26,0,0,0,0,0,0,0,0,0,0,0,0,3,0,0
0,0,3,9,0,0,0,3,0,0,0,0,0,0,0,0,0,0,0,0,0,0,0,3,0,0,0,0,2,0,0
0,0,3,0,0,0,0,0,0,0,0,0,0,3,0,0,0,3,0,0,0,25,0,25,25,25,0,0,3,0,0
0,0,0,0,0,0,0,0,0,0,0,0,0,25,0,0,0,0,0,0,0,0,0,0,0,0,0,0,0,0,0
0,0,0,0,0,0,0,0,3,25,0,0,0,0,0,0,0,0,0,0,0,0,3,0,0,0,0,0,0,0,0
0,0,0,0,0,0,0,0,0,3,0,0,0,0,0,0,0,0,25,0,0,3,0,0,0,0,0,0,0,0,0
25,0,25,0,3,0,0,0,0,0,3,0,0,8,0,0,0,0,0,0,3,0,0,0,0,0,3,0,0,0,0
0,0,0,0,0,3,8,0,0,0,0,0,17,3,9,0,0,3,0,0,0,0,0,0,0,3,0,0,25,25,25
25,0,0,0,0,0,3,9,0,0,0,0,25,13,0,0,0,0,0,0,0,0,0,25,3,0,0,0,0,0,0
0,0,0,0,0,0,0,3,0,0,0,25,0,0,0,0,0,0,0,0,0,0,7,3,0,0,0,0,0,0,0
0,0,0,0,0,0,0,0,3,0,0,0,0,25,0,0,0,0,0,0,7,0,3,0,0,0,0,0,0,0,0
0,0,0,0,0,0,0,0,0,0,0,0,0,0,0,0,0,0,0,0,0,0,0,6,0,0,0,0,0,6,0
0,0,0,0,0,0,0,0,0,0,0,0,0,3,0,0,0,3,0,0,0,0,0,0,0,0,23,0,0,7,0
0,0,0,0,0,0,0,0,0,0,25,0,0,0,0,13,0,22,0,0,0,0,0,0,0,0,7,0,6,6,1
endlayer

layer
0,0,0,0,0,0,0,0,0,0,0,0,0,0,0,0,0,0,0,0,0,0,0,0,0,0,0,0,0,0,0
0,0,0,0,0,0,0,0,0,0,0,0,0,0,0,0,0,0,0,0,0,0,0,0,0,0,0,0,0,0,0
0,0,0,0,0,0,0,0,0,0,0,0,0,0,0,0,0,0,0,0,0,0,0,0,0,0,0,0,0,0,0
0,0,0,0,0,0,0,0,0,0,0,0,0,8,0,0,8,0,0,0,0,0,0,0,0,0,0,0,0,0,0
0,0,0,0,0,0,0,0,0,0,0,0,17,3,0,0,0,3,0,0,0,0,0,0,0,0,0,0,0,0,0
0,0,0,0,0,0,0,0,0,0,0,0,0,0,0,0,0,0,0,0,0,0,0,0,0,0,0,0,0,0,0
0,0,0,0,0,0,0,0,0,0,0,0,0,0,0,0,0,0,0,0,0,0,0,0,0,0,0,0,0,0,0
0,0,0,0,0,0,0,0,3,0,0,0,0,3,0,0,0,3,0,0,0,0,3,8,0,0,0,0,0,0,0
0,0,0,0,0,0,0,3,0,0,0,0,0,0,0,13,13,0,0,0,0,0,0,3,9,0,0,0,0,0,0
0,0,0,0,0,0,3,15,0,0,0,0,0,0,0,0,0,0,0,0,0,0,0,0,3,0,0,0,0,0,0
0,0,0,0,0,3,13,0,0,0,0,0,0,3,0,0,0,3,0,0,0,0,0,0,0,3,0,0,0,0,0
0,0,0,0,0,0,0,0,0,0,0,0,0,0,13,0,0,0,0,0,0,8,0,0,0,0,0,0,0,0,0
0,0,0,0,0,0,0,0,17,3,0,0,0,0,0,0,0,0,0,0,0,3,0,0,0,0,0,0,0,0,0
0,0,0,0,0,0,0,0,0,13,0,0,0,0,0,0,0,0,0,0,0,0,0,0,0,0,0,0,0,0,0
0,0,0,0,0,0,0,0,0,0,0,0,0,0,0,0,0,0,0,0,0,0,0,0,0,0,0,0,0,0,0
0,0,3,0,0,0,0,0,0,0,0,0,0,3,0,0,0,3,9,0,0,0,0,8,0,0,0,0,3,0,0
0,0,3,9,0,0,0,3,0,0,0,0,0,0,0,0,0,0,0,0,0,0,0,3,0,0,0,0,3,0,0
0,0,3,9,0,0,0,3,0,0,0,0,0,0,0,0,0,0,0,0,0,0,0,3,0,0,0,0,3,0,0
0,0,3,9,0,0,0,3,0,0,0,0,0,0,0,0,0,0,0,0,0,0,0,3,0,0,0,0,3,0,0
0,0,3,0,0,0,0,0,0,0,0,0,0,3,0,0,0,3,0,0,0,0,0,0,0,0,0,0,3,0,0
0,0,0,0,0,0,0,0,0,0,0,0,0,0,0,0,0,0,0,0,0,0,0,0,0,0,0,0,0,0,0
0,0,0,0,0,0,0,0,0,0,0,0,0,0,0,0,0,0,0,0,0,0,0,0,0,0,0,0,0,0,0
0,0,0,0,0,0,0,0,0,3,0,0,0,0,0,0,0,0,0,0,0,3,0,0,0,0,0,0,0,0,0
0,0,0,0,0,0,0,0,0,0,0,0,0,0,0,0,0,0,0,0,0,0,0,0,0,0,0,0,0,0,0
0,0,0,0,0,3,8,0,0,0,0,0,0,3,0,0,0,2,0,0,0,0,0,0,0,3,0,0,0,0,0
0,0,0,0,0,0,3,9,0,0,0,0,0,13,0,0,0,0,0,0,0,0,0,0,3,0,0,0,0,0,0
0,0,0,0,0,0,0,3,0,0,0,0,0,0,0,0,0,0,0,0,0,0,25,3,0,0,0,0,0,0,0
0,0,0,0,0,0,0,0,0,0,0,0,0,0,0,0,0,0,0,0,25,0,0,0,0,0,0,0,0,0,0
0,0,0,0,0,0,0,0,0,0,0,0,0,0,0,0,0,0,0,0,0,0,0,0,0,0,0,0,0,0,0
0,0,0,0,0,0,0,0,0,0,0,0,0,3,0,0,0,3,0,0,0,0,0,0,0,0,0,0,0,25,0
0,0,0,0,0,0,0,0,0,0,0,0,0,0,0,13,0,0,0,0,0,0,0,0,0,0,25,0,0,0,6
endlayer

layer
0,0,0,0,0,0,0,0,0,0,0,0,0,0,0,0,0,0,0,0,0,0,0,0,0,0,0,0,0,0,0
0,0,0,0,0,0,0,0,0,0,0,0,0,0,0,0,0,0,0,0,0,0,0,0,0,0,0,0,0,0,0
0,0,0,0,0,0,0,0,0,0,0,0,0,0,0,0,0,0,0,0,0,0,0,0,0,0,0,0,0,0,0
0,0,0,0,0,0,0,0,0,0,0,0,0,27,0,0,8,27,0,0,0,0,0,0,0,0,0,0,0,0,0
0,0,0,0,0,0,0,0,0,0,0,0,17,3,3,3,3,3,0,0,0,0,0,0,0,0,0,0,0,0,0
0,0,0,0,0,0,0,0,0,0,0,0,0,0,0,0,0,0,0,0,0,0,0,0,0,0,0,0,0,0,0
0,0,0,0,0,0,0,0,0,0,0,0,0,0,0,0,0,0,0,0,0,0,0,0,0,0,0,0,0,0,0
0,0,0,0,0,0,0,0,3,0,0,0,0,3,3,3,3,3,0,0,0,0,3,8,0,0,0,0,0,0,0
0,0,0,0,0,0,0,2,0,0,0,0,0,0,13,13,13,0,0,0,0,0,0,3,9,0,0,0,0,0,0
0,0,0,0,0,0,3,15,0,0,0,0,0,0,0,0,0,0,0,0,0,0,0,0,3,0,0,0,0,0,0
0,0,0,0,0,3,13,0,0,0,0,0,0,3,3,3,3,3,0,0,0,0,0,0,0,3,0,0,0,0,0
0,0,0,0,0,0,0,0,0,0,0,0,0,0,13,0,0,0,0,0,0,0,0,0,0,0,0,0,0,0,0
0,0,0,0,0,0,0,0,0,0,0,0,0,0,0,0,0,0,0,0,0,0,0,0,0,0,0,0,0,0,0
0,0,0,0,0,0,0,0,0,0,0,0,0,0,0,0,0,0,0,0,0,0,0,0,0,0,0,0,0,0,0
0,0,0,0,0,0,0,0,0,0,0,0,0,0,0,0,0,0,0,0,0,0,0,0,0,0,0,0,0,0,0
0,0,3,0,0,0,0,0,0,0,0,0,0,3,29,0,28,3,9,0,0,0,0,0,0,0,0,0,3,0,0
0,0,3,9,0,0,0,0,0,0,0,0,0,0,0,0,0,0,0,0,0,0,0,0,0,0,0,0,3,0,0
0,0,3,9,0,0,0,3,0,0,0,0,0,0,0,0,0,0,0,0,0,0,0,2,0,0,0,0,3,0,0
0,0,3,9,0,0,0,0,0,0,0,0,0,0,0,0,0,0,0,0,0,0,0,0,0,0,0,0,3,0,0
0,0,3,0,0,0,0,0,0,0,0,0,0,3,29,0,28,2,0,0,0,0,0,0,0,0,0,0,3,0,0
0,0,0,0,0,0,0,0,0,0,0,0,0,0,0,0,0,0,0,0,0,0,0,0,0,0,0,0,0,0,0
0,0,0,0,0,0,0,0,0,0,0,0,0,0,0,0,0,0,0,0,0,0,0,0,0,0,0,0,0,0,0
0,0,0,0,0,0,0,0,0,0,0,0,0,0,0,0,0,0,0,0,0,0,0,0,0,0,0,0,0,0,0
0,0,0,0,0,0,0,0,0,0,0,0,0,8,8,0,0,0,0,0,0,0,0,0,0,0,0,0,0,0,0
0,0,0,0,0,3,8,0,0,0,0,0,17,3,3,3,3,3,0,0,0,0,0,0,0,0,0,0,0,0,0
0,0,0,0,0,17,3,9,0,0,0,0,0,13,0,0,0,0,0,0,0,0,0,0,3,0,0,0,0,0,0
0,0,0,0,0,0,0,3,0,0,0,0,0,0,0,0,0,0,0,0,0,0,0,0,0,0,0,0,0,0,0
0,0,0,0,0,0,0,0,0,0,0,0,0,0,0,0,0,0,0,0,0,0,0,0,0,0,0,0,0,0,0
0,0,0,0,0,0,0,0,0,0,0,0,0,0,0,0,0,0,0,0,0,0,0,0,0,0,0,0,0,0,0
0,0,0,0,0,0,0,0,0,0,0,0,0,3,0,0,0,3,0,0,0,0,0,0,0,0,0,0,0,0,0
0,0,0,0,0,0,0,0,0,0,0,0,0,0,0,13,0,0,0,0,0,0,0,0,0,0,0,0,0,0,0
endlayer

layer
0,0,0,0,0,0,0,0,0,0,0,0,0,0,0,0,0,0,0,0,0,0,0,0,0,0,0,0,0,0,0
0,0,0,0,0,0,0,0,0,0,0,0,0,0,0,0,0,0,0,0,0,0,0,0,0,0,0,0,0,0,0
0,0,0,0,0,0,0,0,0,0,0,0,0,0,0,0,0,0,0,0,0,0,0,0,0,0,0,0,0,0,0
0,0,0,0,0,0,0,0,0,0,0,0,0,0,0,0,0,0,0,0,0,0,0,0,0,0,0,0,0,0,0
0,0,0,0,0,0,0,0,0,0,0,0,0,0,0,0,0,0,0,0,0,0,0,0,0,0,0,0,0,0,0
0,0,0,0,0,0,0,0,0,0,0,0,0,0,0,0,0,0,0,0,0,0,0,0,0,0,0,0,0,0,0
0,0,0,0,0,0,0,0,0,0,0,0,0,0,0,0,0,0,0,0,0,0,0,0,0,0,0,0,0,0,0
0,0,0,0,0,0,0,0,0,0,0,0,0,0,0,0,0,0,0,0,0,0,0,8,0,0,0,0,0,0,0
0,0,0,0,0,0,0,3,0,0,0,0,0,0,0,0,0,0,0,0,0,0,17,3,9,0,0,0,0,0,0
0,0,0,0,0,0,3,15,0,0,0,0,0,0,0,0,0,0,0,0,0,0,0,0,2,0,0,0,0,0,0
0,0,0,0,0,0,13,0,0,0,0,0,0,0,0,0,0,0,0,0,0,0,0,0,0,0,0,0,0,0,0
0,0,0,0,0,0,0,0,0,0,0,0,0,0,0,0,0,0,0,0,0,0,0,0,0,0,0,0,0,0,0
0,0,0,0,0,0,0,0,0,0,0,0,0,0,0,0,0,0,0,0,0,0,0,0,0,0,0,0,0,0,0
0,0,0,0,0,0,0,0,0,0,0,0,0,0,0,0,0,0,0,0,0,0,0,0,0,0,0,0,0,0,0
0,0,0,0,0,0,0,0,0,0,0,0,0,0,0,0,0,0,0,0,0,0,0,0,0,0,0,0,0,0,0
0,0,3,0,0,0,0,0,0,0,0,0,0,30,32,19,31,30,0,0,0,0,0,0,0,0,0,0,3,0,0
0,0,3,9,0,0,0,0,0,0,0,0,0,18,0,0,0,18,0,0,0,0,0,0,0,0,0,0,3,0,0
0,0,3,9,0,0,0,0,0,0,0,0,0,0,0,0,0,0,0,0,0,0,0,0,0,0,0,0,3,0,0
0,0,3,9,0,0,0,0,0,0,0,0,0,20,0,0,0,20,0,0,0,0,0,0,0,0,0,0,3,0,0
0,0,3,0,0,0,0,0,0,0,0,0,0,33,32,19,31,33,0,0,0,0,0,0,0,0,0,0,3,0,0
0,0,0,0,0,0,0,0,0,0,0,0,0,0,0,0,0,0,0,0,0,0,0,0,0,0,0,0,0,0,0
0,0,0,0,0,0,0,0,0,0,0,0,0,0,0,0,0,0,0,0,0,0,0,0,0,0,0,0,0,0,0
0,0,0,0,0,0,0,0,0,0,0,0,0,0,0,0,0,0,0,0,0,0,0,0,0,0,0,0,0,0,0
0,0,0,0,0,0,0,0,0,0,0,0,0,0,0,0,0,0,0,0,0,0,0,0,0,0,0,0,0,0,0
0,0,0,0,0,0,8,0,0,0,0,0,0,0,0,0,0,0,0,0,0,0,0,0,0,0,0,0,0,0,0
0,0,0,0,0,17,3,9,0,0,0,0,0,0,0,0,0,0,0,0,0,0,0,0,0,0,0,0,0,0,0
0,0,0,0,0,0,0,0,0,0,0,0,0,0,0,0,0,0,0,0,0,0,0,0,0,0,0,0,0,0,0
0,0,0,0,0,0,0,0,0,0,0,0,0,0,0,0,0,0,0,0,0,0,0,0,0,0,0,0,0,0,0
0,0,0,0,0,0,0,0,0,0,0,0,0,0,0,0,0,0,0,0,0,0,0,0,0,0,0,0,0,0,0
0,0,0,0,0,0,0,0,0,0,0,0,17,3,3,3,3,3,0,0,0,0,0,0,0,0,0,0,0,0,0
0,0,0,0,0,0,0,0,0,0,0,0,0,13,13,13,0,0,0,0,0,0,0,0,0,0,0,0,0,0,0
endlayer

layer
0,0,0,0,0,0,0,0,0,0,0,0,0,0,0,0,0,0,0,0,0,0,0,0,0,0,0,0,0,0,0
0,0,0,0,0,0,0,0,0,0,0,0,0,0,0,0,0,0,0,0,0,0,0,0,0,0,0,0,0,0,0
0,0,0,0,0,0,0,0,0,0,0,0,0,0,0,0,0,0,0,0,0,0,0,0,0,0,0,0,0,0,0
0,0,0,0,0,0,0,0,0,0,0,0,0,0,0,0,0,0,0,0,0,0,0,0,0,0,0,0,0,0,0
0,0,0,0,0,0,0,0,0,0,0,0,0,0,0,0,0,0,0,0,0,0,0,0,0,0,0,0,0,0,0
0,0,0,0,0,0,0,0,0,0,0,0,0,0,0,0,0,0,0,0,0,0,0,0,0,0,0,0,0,0,0
0,0,0,0,0,0,0,0,0,0,0,0,0,0,0,0,0,0,0,0,0,0,0,0,0,0,0,0,0,0,0
0,0,0,0,0,0,0,0,0,0,0,0,0,0,0,0,0,0,0,0,0,0,0,8,0,0,0,0,0,0,0
0,0,0,0,0,0,0,3,9,0,0,0,0,0,0,0,0,0,0,0,0,0,17,3,9,0,0,0,0,0,0
0,0,0,0,0,0,3,15,0,0,0,0,0,0,0,0,0,0,0,0,0,0,0,0,3,0,0,0,0,0,0
0,0,0,0,0,0,13,0,0,0,0,0,0,0,0,0,0,0,0,0,0,0,0,0,0,0,0,0,0,0,0
0,0,0,0,0,0,0,0,0,0,0,0,0,0,0,0,0,0,0,0,0,0,0,0,0,0,0,0,0,0,0
0,0,0,0,0,0,0,0,0,0,0,0,0,0,0,0,0,0,0,0,0,0,0,0,0,0,0,0,0,0,0
0,0,0,0,0,0,0,0,0,0,0,0,0,0,0,0,0,0,0,0,0,0,0,0,0,0,0,0,0,0,0
0,0,0,0,0,0,0,0,0,0,0,0,0,0,0,0,0,0,0,0,0,0,0,0,0,0,0,0,0,0,0
0,0,0,0,0,0,0,0,0,0,0,0,0,0,0,0,0,0,0,0,0,0,0,0,0,0,0,0,0,0,0
0,0,3,9,0,0,0,0,0,0,0,0,0,30,0,0,0,30,0,0,0,0,0,0,0,0,0,0,3,0,0
0,0,3,35,0,0,0,0,0,0,0,0,0,19,0,0,0,19,0,0,0,0,0,0,0,0,0,34,3,0,0
0,0,3,9,0,0,0,0,0,0,0,0,0,33,0,0,0,33,0,0,0,0,0,0,0,0,0,0,3,0,0
0,0,0,0,0,0,0,0,0,0,0,0,0,0,0,0,0,0,0,0,0,0,0,0,0,0,0,0,0,0,0
0,0,0,0,0,0,0,0,0,0,0,0,0,0,0,0,0,0,0,0,0,0,0,0,0,0,0,0,0,0,0
0,0,0,0,0,0,0,0,0,0,0,0,0,0,0,0,0,0,0,0,0,0,0,0,0,0,0,0,0,0,0
0,0,0,0,0,0,0,0,0,0,0,0,0,0,0,0,0,0,0,0,0,0,0,0,0,0,0,0,0,0,0
0,0,0,0,0,0,0,0,0,0,0,0,0,0,0,0,0,0,0,0,0,0,0,0,0,0,0,0,0,0,0
0,0,0,0,0,0,0,0,0,0,0,0,0,0,0,0,0,0,0,0,0,0,0,0,0,0,0,0,0,0,0
0,0,0,0,0,0,0,0,0,0,0,0,0,0,0,0,0,0,0,0,0,0,0,0,0,0,0,0,0,0,0
0,0,0,0,0,0,0,0,0,0,0,0,0,0,0,0,0,0,0,0,0,0,0,0,0,0,0,0,0,0,0
0,0,0,0,0,0,0,0,0,0,0,0,0,0,0,0,0,0,0,0,0,0,0,0,0,0,0,0,0,0,0
0,0,0,0,0,0,0,0,0,0,0,0,0,0,0,27,0,0,0,0,0,0,0,0,0,0,0,0,0,0,0
0,0,0,0,0,0,0,0,0,0,0,0,0,0,3,3,3,0,0,0,0,0,0,0,0,0,0,0,0,0,0
0,0,0,0,0,0,0,0,0,0,0,0,0,0,0,13,0,0,0,0,0,0,0,0,0,0,0,0,0,0,0
endlayer

layer
0,0,0,0,0,0,0,0,0,0,0,0,0,0,0,0,0,0,0,0,0,0,0,0,0,0,0,0,0,0,0
0,0,0,0,0,0,0,0,0,0,0,0,0,0,0,0,0,0,0,0,0,0,0,0,0,0,0,0,0,0,0
0,0,0,0,0,0,0,0,0,0,0,0,0,0,0,0,0,0,0,0,0,0,0,0,0,0,0,0,0,0,0
0,0,0,0,0,0,0,0,0,0,0,0,0,0,0,0,0,0,0,0,0,0,0,0,0,0,0,0,0,0,0
0,0,0,0,0,0,0,0,0,0,0,0,0,0,0,0,0,0,0,0,0,0,0,0,0,0,0,0,0,0,0
0,0,0,0,0,0,0,0,0,0,0,0,0,0,0,0,0,0,0,0,0,0,0,0,0,0,0,0,0,0,0
0,0,0,0,0,0,0,0,0,0,0,0,0,0,0,0,0,0,0,0,0,0,0,0,0,0,0,0,0,0,0
0,0,0,0,0,0,0,0,0,0,0,0,0,0,0,0,0,0,0,0,0,0,0,0,0,0,0,0,0,0,0
0,0,0,0,0,0,0,0,0,0,0,0,0,0,0,0,0,0,0,0,0,0,0,0,0,0,0,0,0,0,0
0,0,0,0,0,0,0,0,0,0,0,0,0,0,0,0,0,0,0,0,0,0,0,0,0,0,0,0,0,0,0
0,0,0,0,0,0,0,0,0,0,0,0,0,0,0,0,0,0,0,0,0,0,0,0,0,0,0,0,0,0,0
0,0,0,0,0,0,0,0,0,0,0,0,0,0,0,0,0,0,0,0,0,0,0,0,0,0,0,0,0,0,0
0,0,0,0,0,0,0,0,0,0,0,0,0,0,0,0,0,0,0,0,0,0,0,0,0,0,0,0,0,0,0
0,0,0,0,0,0,0,0,0,0,0,0,0,0,0,0,0,0,0,0,0,0,0,0,0,0,0,0,0,0,0
0,0,0,0,0,0,0,0,0,0,0,0,0,0,0,0,0,0,0,0,0,0,0,0,0,0,0,0,0,0,0
0,0,0,0,0,0,0,0,0,0,0,0,0,0,0,0,0,0,0,0,0,0,0,0,0,0,0,0,0,0,0
0,0,0,0,0,0,0,0,0,0,0,0,0,0,0,0,0,0,0,0,0,0,0,0,0,0,0,0,0,0,0
0,0,3,0,0,0,0,0,0,0,0,0,0,0,0,0,0,0,0,0,0,0,0,0,0,0,0,0,3,0,0
0,0,0,0,0,0,0,0,0,0,0,0,0,0,0,0,0,0,0,0,0,0,0,0,0,0,0,0,0,0,0
0,0,0,0,0,0,0,0,0,0,0,0,0,0,0,0,0,0,0,0,0,0,0,0,0,0,0,0,0,0,0
0,0,0,0,0,0,0,0,0,0,0,0,0,0,0,0,0,0,0,0,0,0,0,0,0,0,0,0,0,0,0
0,0,0,0,0,0,0,0,0,0,0,0,0,0,0,0,0,0,0,0,0,0,0,0,0,0,0,0,0,0,0
0,0,0,0,0,0,0,0,0,0,0,0,0,0,0,0,0,0,0,0,0,0,0,0,0,0,0,0,0,0,0
0,0,0,0,0,0,0,0,0,0,0,0,0,0,0,0,0,0,0,0,0,0,0,0,0,0,0,0,0,0,0
0,0,0,0,0,0,0,0,0,0,0,0,0,0,0,0,0,0,0,0,0,0,0,0,0,0,0,0,0,0,0
0,0,0,0,0,0,0,0,0,0,0,0,0,0,0,0,0,0,0,0,0,0,0,0,0,0,0,0,0,0,0
0,0,0,0,0,0,0,0,0,0,0,0,0,0,0,0,0,0,0,0,0,0,0,0,0,0,0,0,0,0,0
0,0,0,0,0,0,0,0,0,0,0,0,0,0,0,0,0,0,0,0,0,0,0,0,0,0,0,0,0,0,0
0,0,0,0,0,0,0,0,0,0,0,0,0,0,0,8,0,0,0,0,0,0,0,0,0,0,0,0,0,0,0
0,0,0,0,0,0,0,0,0,0,0,0,0,0,17,3,9,0,0,0,0,0,0,0,0,0,0,0,0,0,0
0,0,0,0,0,0,0,0,0,0,0,0,0,0,0,13,0,0,0,0,0,0,0,0,0,0,0,0,0,0,0
endlayer

